Workbook

Sheet 월합산
A1: 월 합 산
A2: 매출 | C2: =C3+G3+C5 -> 0 | E2: 시제 | H2: 비 고
A3: 카드매출 | C3: =SUM('1'!C3) -> 0 | E3: 현금매출 | G3: =SUM('1'!G3) -> 0
A4: 금고잔액 | C4: =C21 -> 0 | E4: 입금 | G4: =C17 -> 0
A5: 할인금액 | C5: =C6+G6 -> 0 | E5: 잔금 | G5: =C4-G4 -> 0
A6: 현금할인 | C6: =SUM('1'!C7) -> 0 | E6: 카드할인 | G6: =SUM('1'!G7) -> 0
A7: 할인내역
H8: take out | I8: 매출누계 | K8: =SUM('1'!K9) -> 0
H9: 배달 | I9: 매출누계 | K9: =SUM('1'!K10) -> 0
I10: 배달료누계 | K10: =SUM('1'!K11) -> 0
A11: 중간출금 | H11: 중간입금
A12: 출금내역 | H12: 입금내역
A13: 영업일수 | C13: 일평균매출 | E13: 누적총매출 | H13: 목표일매출 | J13: 목표월매출
A14: =C2 -> 0 | C14: =ROUNDDOWN((E14/A14),-4) -> #DIV/0! | E14: =C2 -> 0
A15: 전 월
A16: 마 감 잔 금 | G16: 마 감 잔 금
A17: 만 | G17: 만
A18: 천 | G18: 천
A19: 오백 | G19: 오백
A20: 백이하 | G20: 백이하
A21: 합계 | C21: =SUM(C17:E20) -> 0 | G21: 합계 | H21: =SUM(H17:K20) -> 0

Sheet 결산
E1: 11월
A4: 고정비용 | F4: 변동비용
A5: 항목 | D5: 항목별 소계 | E5: 매출대비 비율 | F5: 항목 | G5: 업체 | H5: 금액 | J5: 항목별 소계 | M5: 통장입금 | N5: =SUM('1:30'!G6) -> 19222200
A6: 월세 | C6: 6985000 | D6: =C6 -> 6985000 | E6: =D6/$B$45 -> 0.046839648 | F6: 식자재 | G6: 고기 | H6: =SUM('1:30'!I4) -> 36011609 | I6: =H6/$B$45 -> 0.24148477 | J6: =SUM(H6:H18) -> 49967635 | K6: =J6/$B$45 -> 0.33507036
A7: 마케팅 | C7: 2600000 | D7: =C7 -> 2600000 | E7: =D7/$B$45 -> 0.017434944 | G7: 식자재 | H7: =SUM('1:30'!I5) -> 6076926 | I7: =H7/$B$45 -> 0.040750333 | M7: 삼겹살 | N7: =SUM('30'!C15) -> 734
A8: 포스 | C8: 154000 | D8: =C8 -> 154000 | E8: =D8/$B$45 -> 0.0010326852 | G8: 주류 | H8: =SUM('1:30'!I7) -> 3030190 | I8: =H8/$B$45 -> 0.02031969 | M8: 1%목살 | N8: =SUM('30'!C13) -> 251
A9: 수도 | C9: 670000 | D9: =C9 -> 670000 | E9: =D9/$B$45 -> 0.004492851 | G9: 쌀 | H9: =SUM('1:30'!I8) -> 845000 | I9: =H9/$B$45 -> 0.0056663569 | M9: 육회 | N9: =SUM('30'!C17) -> 163
A10: 화재보험 | C10: 66000 | D10: =C10 -> 66000 | E10: =D10/$B$45 -> 0.00044257935 | G10: 참기름 | H10: =SUM('1:30'!I11) -> 200000 | I10: =H10/$B$45 -> 0.0013411496 | M10: 설화갈비 | N10: =SUM('30'!F13) -> 184
A11: 세무사 | C11: 330000 | D11: =C11 -> 330000 | E11: =D11/$B$45 -> 0.0022128968 | G11: 부탄가스 | H11: =SUM('1:30'!I12) -> 53400 | M11: 양념갈비 | N11: =SUM('30'!F15) -> 348
A12: 인터넷 | C12: 48000 | D12: =C12 -> 48000 | E12: =D12/$B$45 -> 0.00032187589 | G12: 코카콜라 | H12: =SUM('1:30'!I13) -> 440000 | I12: =H12/$B$45 -> 0.002950529 | M12: 눈꽃살 | N12: =SUM('30'!F17) -> 265
A13: 쿠쿠(블루문) | C13: 66000 | D13: =C13 -> 66000 | E13: =D13/$B$45 -> 0.00044257935 | G13: 깍두기,계란 | H13: =SUM('1:30'!I14) -> 0 | I13: =H13/$B$45 -> 0 | M13: 황제갈비 | N13: =SUM('30'!C19) -> 387
D14: =C14 -> 0 | E14: =D14/$B$45 -> 0 | G14: 막걸리 | H14: =SUM('1:30'!I17) -> 10000 | I14: =H14/$B$45 -> 6.7057478e-05 | M14: 설화양념갈비 | N14: =SUM('30'!F19) -> 140
D15: =C15 -> 0 | E15: =D15/$B$45 -> 0 | G15: 식자재2 | H15: =SUM('1:30'!I15) -> 3300510 | I15: =H15/$B$45 -> 0.022132388 | M15: 11월 테이블 수 | N15: =SUM('30'!F21) -> 1907
A16: 전기세 | D16: =C16 -> 0 | E16: =D16/$B$45 -> 0
A17: 가스비 | D17: =C17 -> 0 | E17: =D17/$B$45 -> 0
A18: 소 계 | C18: =SUM(D6:D17) -> 10919000 | E18: =SUM(E6:E17) -> 0.07322006
A19: 급여 | B19: 직원A | C19: 3300000 | D19: =SUM(C19:C30) -> 20093000 | E19: =D19/$B$45 -> 0.13473859 | F19: 비품 및 기타경비 | G19: 숯 | H19: =SUM('1:30'!K4) -> 961000 | I19: =H19/$B$45 -> 0.0064442236 | J19: =SUM(H19:H32) -> 3021960 | K19: =J19/$B$45 -> 0.020264502
G20: 음식물스티커 | H20: =SUM('1:30'!K6) -> 112000 | I20: =H20/$B$45 -> 0.00075104375
B21: 직원C | C21: 4000000 | G21: 종량재봉투 | H21: =SUM('1:30'!K7) -> 12500 | I21: =H21/$B$45 -> 8.3821847e-05
B22: 직원D | C22: 3300000 | G22: 뚝배기 | H22: =SUM('1:30'!K9) -> 0 | I22: =H22/$B$45 -> 0
G23: 발매트 | H23: =SUM('1:30'!K10) -> 114400 | I23: =H23/$B$45 -> 0.00076713754
B24: 직원F | C24: 1500000 | G24: 불판세척 | H24: =SUM('1:30'!K11) -> 0 | I24: =H24/$B$45 -> 0
G25: 비품 및 기타경비 | H25: =SUM('1:30'!K15) -> 0 | I25: =H25/$B$45 -> 0
B26: 알바B | C26: =SUM('1:30'!C33) -> 1391000 | G26: 인터넷 주문 | H26: =SUM('1:30'!K16) -> 1802060 | I26: =H26/$B$45 -> 0.01208416
B27: 알바C | C27: =SUM('1:30'!F27) -> 1189500 | G27: 다이소 구매 | H27: =SUM('1:30'!K17) -> 20000 | I27: =H27/$B$45 -> 0.00013411496
B28: 알바X | C28: =SUM('1:30'!F29)+SUM('1:30'!F30)+SUM('1:30'!C32)+SUM('1:30'!C34) -> 630500
B29: 홀 파출 | C29: =SUM('1:30'!F32) -> 1164000
B30: 파출 | C30: =SUM('1:30'!F31) -> 3618000
B31: 합계 | C31: =SUM(C19:C30) -> 20093000
A32: 퇴직금(10%) | C32: =SUM(C19:C22)*0.1 -> 1060000 | D32: =C32 -> 1060000 | E32: =(D32:D33)/$B$45 -> 0.0071080926
A33: 4대보험료 | D33: =C33 -> 0 | F33: 현금수수료 (1%) | H33: =SUM('1:30'!$G$5) -> 184865 | J33: =H33 -> 184865 | K33: =J33/$B$45 -> 0.0012396581
A34: 소 계 | C34: =SUM(C6:D17,C19:C24,C32:C33) -> 34998000 | E34: =SUM(E19:E33) -> 0.14184668 | F34: 카드수수료(2.75%) | H34: =SUM('1:30'!$G$4) -> 3399058.2 | J34: =H34 -> 3399058.2 | K34: =J34/$B$45 -> 0.022793227
A35: 합 계 | E35: =E18+E34 -> 0.21506674 | H35: =SUM(J6:J34) -> 56573518 | K35: =SUM(K6:K34) -> 0.37936774
A38: 항목 | B38: 금액 | C38: 항목 비율 | D38: 매출 비율 | F38: 손익분기점
A39: 고정비용 | B39: =$C$34 -> 34998000 | C39: =B39/$B$41 -> 0.38219307 | D39: =B39/$B$45 -> 0.23468776 | F39: 손익분기점 매출액 X
A40: 변동비용 | B40: =$H$35 -> 56573518 | C40: =B40/$B$41 -> 0.61780693 | D40: =B40/$B$45 -> 0.37936774 | F40: 고정비 | H40: F | K40: =$C$34 -> 34998000
A41: 총비용 | B41: =SUM(B39:B40) -> 91571518 | C41: =SUM(C39:C40) -> 1 | D41: =SUM(D39:D40) -> 0.6140555 | F41: 변동비 | H41: V | K41: =$H$35 -> 56573518
A42: 카드매출 | B42: =SUM('1:30'!C4) -> 129831300 | D42: =B42/$B$45 -> 0.87061595 | F42: 매출액 | H42: S | K42: =$B$45 -> 149125800
A43: 현금매출 | B43: =SUM('1:30'!C5) -> 19294500 | D43: =B43/$B$45 -> 0.12938405 | F43: 변동비율 | H43: V/S | K43: =(K41)/K42 -> 0.37936774
A44: 페이매출 | B44: =SUM('1:30'!C6) -> 0 | D44: =B44/$B$45 -> 0 | F44: 손익분기점 매출액 | H44: X=F/(1-(V/S)) | K44: =K40/(1-K43) -> 56390881
...

Sheet 1
C1: 2025년 | E1: 11월 | F1: 1 | G1: 토요일 | H1: 실영업일수 | I1: =F1-K1 -> 1 | J1: 휴무일수
A2: 매출 | C2: =SUM(C4:D7) -> 4267000 | E2: 시재 | G2: 66200 | H2: 식자재 | J2: 비품 및 기타경비
H3: 업체 | I3: 금액 | J3: 업체 | K3: 금액
A4: 카드 | C4: 3285000 | E4: 카드수수료(2.75%) | G4: =INT(C4*0.0275) -> 90337 | H4: 고기 | I4: =287212+221000+190393+452000+43500+253500 -> 1447605 | J4: 숯
A5: 현금 | C5: 982000 | E5: 현금수수료(1%) | G5: =INT(C5*0.01) -> 9820 | H5: 식자재 | I5: =29656+39380+150000+69000+108000+10500+35820+35040 -> 477396
A6: 페이결제 | E6: 통장입금 | G6: 920000 | J6: 음식물스티커
H7: 주류 | J7: 종량제봉투
A8: 금고 실잔액 | C8: 128300 | E8: 마감잔금 | G8: =C5+G2-G6-C22 -> 128200 | H8: 쌀
J9: 뚝배기
A10: 현금할인 | E10: 카드할인 | J10: 발매트
A11: 할인내역 | H11: 참기름 | J11: 불판세척
A12: 개수 | B12: 목살 | C12: 9 | D12: LA갈비 | F12: 5 | H12: 부탄가스
A13: 매출누계 | C13: =SUM('1'!$C$12) -> 9 | F13: =SUM('1'!$F$12) -> 5 | H13: 코카콜라음료
A14: 개수 | B14: 삼겹살 | C14: 26 | D14: 돼지양념갈비 | F14: 12 | H14: 깍두기,계란
A15: 매출누계 | C15: =SUM('1'!$C$14) -> 26 | F15: =SUM('1'!$F$14) -> 12 | H15: 식자재2 | J15: 비품 및 기타경비
A16: 개수 | B16: 육회 | C16: 3 | D16: 한우업진살 | F16: 10 | J16: 인터넷 주문
A17: 매출누계 | C17: =SUM('1'!$C$16) -> 3 | F17: =SUM('1'!$F$16) -> 10 | H17: 막걸리 | J17: 다이소 구매
A18: 개수 | B18: 소갈비살 | C18: 13 | D18: LA양념갈비 | F18: 4
A19: 매출누계 | C19: =SUM('1'!$C$18) -> 13 | F19: =SUM('1'!$F$18) -> 4
A20: 개수 | D20: 테이블수 | F20: 51
A21: 매출누계 | D21: 누적테이블 | F21: =SUM('1'!$F$20) -> 51
A22: 중간출금
A23: 출금내역 | H23: 식자재합계 | I23: =SUM(I4:I22) -> 1925001 | J23: 기타경비합계 | K23: =SUM(K4:K22) -> 0 | M23: 현금합계 | N23: =C5+C6 -> 982000
A24: 일매출 | C24: 일평균매출 | E24: 누적총매출 | H24: 일매출 | I24: =I23/A25 -> 0.45113686 | J24: 일매출 | K24: =K23/A25 -> 0
A25: =C2 -> 4267000 | C25: =E25/I1 -> 4267000 | E25: =SUM('1'!$A$25) -> 4267000 | H25: 누계 | I25: =SUM('1'!$I$23) -> 1925001 | J25: 누계 | K25: =SUM('1'!$K$23) -> 0
A26: 전 월 | H26: 누적매출 | I26: =I25/$E$25 -> 0.45113686 | J26: 누적매출 | K26: =K25/$E$25 -> 0
A27: 인 건 비 | B27: 직원A | C27: =3300000/31 -> 106451.61 | E27: 알바C | H27: 인건비합계 | I27: =SUM(C27:D34,F27:G32) -> 585322.58
E28: 직원F | F28: =1500000/31 -> 48387.097 | H28: 일매출 | I28: =I27/$A$25 -> 0.13717426
B29: 직원D | C29: =3300000/31 -> 106451.61 | E29: 알바X | H29: 누계 | I29: =SUM('1'!$I$27) -> 585322.58
E30: 알바X | H30: 누적매출 | I30: =I29/$I$27 -> 1
B31: 직원C | C31: =4000000/31 -> 129032.26 | E31: 파출 | F31: 143000
B32: 알바X | E32: 홀 파출
B33: 알바B | C33: =13000*4 -> 52000
B34: 알바X

Sheet 2
C1: 2025년 | E1: 11월 | F1: 2 | G1: 일요일 | H1: 실영업일수 | I1: =F1-K1 -> 2 | J1: 휴무일수
A2: 매출 | C2: =SUM(C4:D7) -> 5074000 | E2: 시재 | G2: 128300 | H2: 식자재 | J2: 비품 및 기타경비
H3: 업체 | I3: 금액 | J3: 업체 | K3: 금액
A4: 카드 | C4: 4295000 | E4: 카드수수료(2.75%) | G4: =INT(C4*0.0275) -> 118112 | H4: 고기 | J4: 숯
A5: 현금 | C5: 779000 | E5: 현금수수료(1%) | G5: =INT(C5*0.01) -> 7790 | H5: 식자재
A6: 페이결제 | E6: 통장입금 | G6: 760000 | J6: 음식물스티커
H7: 주류 | J7: 종량제봉투
A8: 금고 실잔액 | C8: 147300 | E8: 마감잔금 | G8: =C5+G2-G6-C22 -> 147300 | H8: 쌀
J9: 뚝배기
A10: 현금할인 | E10: 카드할인 | J10: 발매트
A11: 할인내역 | H11: 참기름 | J11: 불판세척
A12: 개수 | B12: 목살 | C12: 9 | D12: LA갈비 | F12: 8 | H12: 부탄가스
A13: 매출누계 | C13: =SUM('1:2'!$C$12) -> 18 | F13: =SUM('1:2'!$F$12) -> 13 | H13: 코카콜라음료
A14: 개수 | B14: 삼겹살 | C14: 20 | D14: 돼지양념갈비 | F14: 16 | H14: 깍두기,계란
A15: 매출누계 | C15: =SUM('1:2'!$C$14) -> 46 | F15: =SUM('1:2'!$F$14) -> 28 | H15: 식자재2 | J15: 비품 및 기타경비
A16: 개수 | B16: 육회 | C16: 7 | D16: 한우업진살 | F16: 20 | J16: 인터넷 주문
A17: 매출누계 | C17: =SUM('1:2'!$C$16) -> 10 | F17: =SUM('1:2'!$F$16) -> 30 | H17: 막걸리 | J17: 다이소 구매 | K17: 17200
A18: 개수 | B18: 소갈비살 | C18: 14 | D18: LA양념갈비 | F18: 8
A19: 매출누계 | C19: =SUM('1:2'!$C$18) -> 27 | F19: =SUM('1:2'!$F$18) -> 12
D20: 테이블수 | F20: 69
D21: 누적테이블 | F21: =SUM('1:2'!$F$20) -> 120
A22: 중간출금
A23: 출금내역 | H23: 식자재합계 | I23: =SUM(I4:I22) -> 0 | J23: 기타경비합계 | K23: =SUM(K4:K22) -> 17200 | M23: 현금합계 | N23: =C5+C6 -> 779000
A24: 일매출 | C24: 일평균매출 | E24: 누적총매출 | H24: 일매출 | I24: =I23/A25 -> 0 | J24: 일매출 | K24: =K23/A25 -> 0.0033898305
A25: =C2 -> 5074000 | C25: =E25/I1 -> 2133500 | E25: =SUM('1'!$A$25) -> 4267000 | H25: 누계 | I25: =SUM('1'!$I$23) -> 1925001 | J25: 누계 | K25: =SUM('1'!$K$23) -> 0
A26: 전 월 | H26: 누적매출 | I26: =I25/$E$25 -> 0.45113686 | J26: 누적매출 | K26: =K25/$E$25 -> 0
A27: 인 건 비 | B27: 직원A | C27: =3300000/31 -> 106451.61 | E27: 알바C | H27: 인건비합계 | I27: =SUM(C27:D34,F27:G32) -> 585322.58
E28: 직원F | F28: =1500000/31 -> 48387.097 | H28: 일매출 | I28: =I27/$A$25 -> 0.11535723
B29: 직원D | C29: =3300000/31 -> 106451.61 | E29: 알바X | H29: 누계 | I29: =SUM('1:2'!$I$27) -> 1170645.2
E30: 알바X | H30: 누적매출 | I30: =I29/$I$27 -> 2
B31: 직원C | C31: =4000000/31 -> 129032.26 | E31: 파출 | F31: 143000
B32: 알바X | E32: 홀 파출
B33: 알바B | C33: =13000*4 -> 52000
B34: 알바X

Sheet 3
C1: 2025년 | E1: 11월 | F1: 3 | G1: 월 | H1: 실영업일수 | I1: =F1-K1 -> 3 | J1: 휴무일수
A2: 매출 | C2: =SUM(C4:D7) -> 3816500 | E2: 시재 | G2: 147300 | H2: 식자재 | J2: 비품 및 기타경비
H3: 업체 | I3: 금액 | J3: 업체 | K3: 금액
A4: 카드 | C4: 3061500 | E4: 카드수수료(2.75%) | G4: =C4*0.0275 -> 84191.25 | H4: 고기 | I4: =311087+279910+439200+237276+177485+452000 -> 1896958 | J4: 숯
A5: 현금 | C5: 755000 | E5: 현금수수료(1%) | G5: =INT(C5*0.01) -> 7550 | H5: 식자재 | I5: =29656+78760+100000+34500+36000 -> 278916
A6: 페이결제 | E6: 통장입금 | G6: 760000 | J6: 음식물스티커
H7: 주류 | I7: 44200 | J7: 종량제봉투
A8: 금고 실잔액 | C8: 142300 | E8: 마감잔금 | G8: =C5+G2-G6-C22 -> 142300 | H8: 쌀
J9: 뚝배기
A10: 현금할인 | E10: 카드할인 | J10: 발매트
A11: 할인내역 | H11: 참기름 | J11: 불판세척
A12: 개수 | B12: 목살 | C12: 5 | D12: LA갈비 | F12: 2 | H12: 부탄가스
A13: 매출누계 | C13: =SUM('1:3'!$C$12) -> 23 | F13: =SUM('1:3'!$F$12) -> 15 | H13: 코카콜라음료
A14: 개수 | B14: 삼겹살 | C14: 17 | D14: 돼지양념갈비 | F14: 1 | H14: 깍두기,계란
A15: 매출누계 | C15: =SUM('1:3'!$C$14) -> 63 | F15: =SUM('1:3'!$F$14) -> 29 | H15: 식자재2 | I15: =6000+27200+11800+3500+3500+38000+2450+44000+37500 -> 173950 | J15: 비품 및 기타경비
A16: 개수 | B16: 육회 | C16: 4 | D16: 한우업진살 | F16: 5 | J16: 인터넷 주문
A17: 매출누계 | C17: =SUM('1:3'!$C$16) -> 14 | F17: =SUM('1:3'!$F$16) -> 35 | H17: 막걸리 | J17: 다이소 구매
A18: 개수 | B18: 소갈비살 | C18: 13 | D18: LA양념갈비 | F18: 1
A19: 매출누계 | C19: =SUM('1:3'!$C$18) -> 40 | F19: =SUM('1:3'!$F$18) -> 13
D20: 테이블수 | F20: 64
D21: 누적테이블 | F21: =SUM('1:3'!$F$20) -> 184
A22: 중간출금
A23: 출금내역 | H23: 식자재합계 | I23: =SUM(I4:I22) -> 2394024 | J23: 기타경비합계 | K23: =SUM(K4:K22) -> 0 | M23: 현금합계 | N23: =C5+C6 -> 755000
A24: 일매출 | C24: 일평균매출 | E24: 누적총매출 | H24: 일매출 | I24: =I23/A25 -> 0.62728259 | J24: 일매출 | K24: =K23/A25 -> 0
A25: =C2 -> 3816500 | C25: =E25/I1 -> 4385833.3 | E25: =SUM('1:3'!$A$25) -> 13157500 | H25: 누계 | I25: =SUM('1'!$I$23) -> 1925001 | J25: 누계 | K25: =SUM('1:3'!$K$23) -> 17200
A26: 전 월 | H26: 누적매출 | I26: =I25/$E$25 -> 0.14630447 | J26: 누적매출 | K26: =K25/$E$25 -> 0.0013072392
A27: 인 건 비 | B27: 직원A | C27: =3300000/31 -> 106451.61 | E27: 알바C | F27: =13000*4.5 -> 58500 | H27: 인건비합계 | I27: =SUM(C27:D34,F27:G32) -> 651822.58
E28: 직원F | F28: =1500000/31 -> 48387.097 | H28: 일매출 | I28: =I27/$A$25 -> 0.17079067
B29: 직원D | C29: =3300000/31 -> 106451.61 | E29: 알바X | H29: 누계 | I29: =SUM('1:3'!$I$27) -> 1822467.7
E30: 알바X | H30: 누적매출 | I30: =I29/$I$27 -> 2.7959567
B31: 직원C | C31: =4000000/31 -> 129032.26 | E31: 파출 | F31: 132000
B32: 알바X | E32: 홀 파출 | F32: 71000
B33: 알바B
B34: 알바X

Sheet 4
C1: 2025년 | E1: 11월 | F1: 4 | G1: 화 | H1: 실영업일수 | I1: =F1-K1 -> 4 | J1: 휴무일수
A2: 매출 | C2: =SUM(C4:D7) -> 7304000 | E2: 시재 | G2: 142300 | H2: 식자재 | J2: 비품 및 기타경비
H3: 업체 | I3: 금액 | J3: 업체 | K3: 금액
A4: 카드 | C4: 6812000 | E4: 카드수수료(2.75%) | G4: =INT(C4*0.0275) -> 187330 | H4: 고기 | I4: =596330+180712+452000+468468+221000 -> 1918510 | J4: 숯 | K4: 263000
A5: 현금 | C5: 492000 | E5: 현금수수료(1%) | G5: =INT(C5*0.01) -> 4920 | H5: 식자재 | I5: =50000+34500+16720+44000+53350+23880+17520+40420+7000 -> 287390
A6: 페이결제 | E6: 통장입금 | G6: 500000 | J6: 음식물스티커
H7: 주류 | J7: 종량제봉투
A8: 금고 실잔액 | C8: 134800 | E8: 마감잔금 | G8: =C5+G2-G6-C22 -> 134300 | H8: 쌀 | I8: 65000
J9: 뚝배기
A10: 현금할인 | E10: 카드할인 | J10: 발매트 | K10: 14300
A11: 할인내역 | H11: 참기름 | J11: 불판세척
A12: 개수 | B12: 목살 | D12: LA갈비 | H12: 부탄가스
A13: 매출누계 | C13: =SUM('1:4'!$C$12) -> 23 | F13: =SUM('1:4'!$F$12) -> 15 | H13: 코카콜라음료
A14: 개수 | B14: 삼겹살 | D14: 돼지양념갈비 | H14: 깍두기,계란
A15: 매출누계 | C15: =SUM('1:4'!$C$14) -> 63 | F15: =SUM('1:4'!$F$14) -> 29 | H15: 식자재2 | I15: 93700 | J15: 비품 및 기타경비
A16: 개수 | B16: 육회 | D16: 한우업진살 | J16: 인터넷 주문 | K16: =11680+24300 -> 35980
A17: 매출누계 | C17: =SUM('1:4'!$C$16) -> 14 | F17: =SUM('1:4'!$F$16) -> 35 | H17: 막걸리 | J17: 다이소 구매
A18: 개수 | B18: 소갈비살 | D18: LA양념갈비
A19: 매출누계 | C19: =SUM('1:4'!$C$18) -> 40 | F19: =SUM('1:4'!$F$18) -> 13
D20: 테이블수 | F20: 71
D21: 누적테이블 | F21: =SUM('1:4'!$F$20) -> 255
A22: 중간출금
A23: 출금내역 | H23: 식자재합계 | I23: =SUM(I4:I22) -> 2364600 | J23: 기타경비합계 | K23: =SUM(K4:K22) -> 313280 | M23: 현금합계 | N23: =C5+C6 -> 492000
A24: 일매출 | C24: 일평균매출 | E24: 누적총매출 | H24: 일매출 | I24: =I23/A25 -> 0.32374042 | J24: 일매출 | K24: =K23/A25 -> 0.042891566
A25: =C2 -> 7304000 | C25: =E25/I1 -> 5115375 | E25: =SUM('1:4'!$A$25) -> 20461500 | H25: 누계 | I25: =SUM('1'!$I$23) -> 1925001 | J25: 누계 | K25: =SUM('1:4'!$K$23) -> 330480
A26: 전 월 | H26: 누적매출 | I26: =I25/$E$25 -> 0.094079173 | J26: 누적매출 | K26: =K25/$E$25 -> 0.016151309
A27: 인 건 비 | B27: 직원A | C27: =3300000/31 -> 106451.61 | E27: 알바C | F27: =13000*5 -> 65000 | H27: 인건비합계 | I27: =SUM(C27:D34,F27:G32) -> 639322.58
E28: 직원F | F28: =1500000/31 -> 48387.097 | H28: 일매출 | I28: =I27/$A$25 -> 0.087530474
B29: 직원D | C29: =3300000/31 -> 106451.61 | E29: 알바X | H29: 누계 | I29: =SUM('1:4'!$I$27) -> 2461790.3
E30: 알바X | H30: 누적매출 | I30: =I29/$I$27 -> 3.8506231
B31: 직원C | C31: =4000000/31 -> 129032.26 | E31: 파출 | F31: 132000
B32: 알바X | E32: 홀 파출
B33: 알바B | C33: =13000*4 -> 52000
B34: 알바X

Sheet 5
C1: 2025년 | E1: 11월 | F1: 5 | G1: 수요일 | H1: 실영업일수 | I1: =F1-K1 -> 5 | J1: 휴무일수
A2: 매출 | C2: =SUM(C4:D7) -> 4889000 | E2: 시재 | G2: 134800 | H2: 식자재 | J2: 비품 및 기타경비
H3: 업체 | I3: 금액 | J3: 업체 | K3: 금액
A4: 카드 | C4: 4089000 | E4: 카드수수료(2.75%) | G4: =INT(C4*0.0275) -> 112447 | H4: 고기 | I4: =56220+43500+10+221000 -> 320730 | J4: 숯
A5: 현금 | C5: 800000 | E5: 현금수수료(1%) | G5: =INT(C5*0.01) -> 8000 | H5: 식자재 | I5: =36000+50000 -> 86000
A6: 페이결제 | E6: 통장입금 | G6: 840000 | J6: 음식물스티커
H7: 주류 | I7: 243900 | J7: 종량제봉투
A8: 금고 실잔액 | C8: 94800 | E8: 마감잔금 | G8: =C5+G2-G6 -> 94800 | H8: 쌀
J9: 뚝배기
A10: 현금할인 | C10: 1000 | E10: 카드할인 | J10: 발매트
A11: 할인내역 | C11: 선결제 | H11: 참기름 | J11: 불판세척
A12: 개수 | B12: 목살 | C12: 4 | D12: LA갈비 | F12: 9 | H12: 부탄가스
A13: 매출누계 | C13: =SUM('1:5'!$C$12) -> 27 | F13: =SUM('1:5'!$F$12) -> 24 | H13: 코카콜라음료
A14: 개수 | B14: 삼겹살 | C14: 20 | D14: 돼지양념갈비 | F14: 9 | H14: 깍두기,계란
A15: 매출누계 | C15: =SUM('1:5'!$C$14) -> 83 | F15: =SUM('1:5'!$F$14) -> 38 | H15: 식자재2 | I15: =19200+11800+34000+3900+12500+3500+4250+9800+11500+10600+14000 -> 135050 | J15: 비품 및 기타경비
A16: 개수 | B16: 육회 | C16: 6 | D16: 한우업진살 | F16: 7 | J16: 인터넷 주문
A17: 매출누계 | C17: =SUM('1:5'!$C$16) -> 20 | F17: =SUM('1:5'!$F$16) -> 42 | H17: 막걸리 | J17: 다이소 구매
A18: 개수 | B18: 소갈비살 | C18: 13 | D18: LA양념갈비 | F18: 7
A19: 매출누계 | C19: =SUM('1:5'!$C$18) -> 53 | F19: =SUM('1:5'!$F$18) -> 20
D20: 테이블수 | F20: 53
D21: 누적테이블 | F21: =SUM('1:5'!$F$20) -> 308
A22: 중간출금
A23: 출금내역 | H23: 식자재합계 | I23: =SUM(I4:I22) -> 785680 | J23: 기타경비합계 | K23: =SUM(K4:K22) -> 0 | M23: 현금합계 | N23: =C5+C6 -> 800000
A24: 일매출 | C24: 일평균매출 | E24: 누적총매출 | H24: 일매출 | I24: =I23/A25 -> 0.16070362 | J24: 일매출 | K24: =K23/A25 -> 0
A25: =C2 -> 4889000 | C25: =E25/I1 -> 5070100 | E25: =SUM('1:5'!$A$25) -> 25350500 | H25: 누계 | I25: =SUM('1'!$I$23) -> 1925001 | J25: 누계 | K25: =SUM('1:5'!$K$23) -> 330480
A26: 전 월 | H26: 누적매출 | I26: =I25/$E$25 -> 0.075935425 | J26: 누적매출 | K26: =K25/$E$25 -> 0.013036429
A27: 인 건 비 | B27: 직원A | C27: =3300000/31 -> 106451.61 | E27: 알바C | F27: =13000*4.5 -> 58500 | H27: 인건비합계 | I27: =SUM(C27:D34,F27:G32) -> 620822.58
E28: 직원F | F28: =1500000/31 -> 48387.097 | H28: 일매출 | I28: =I27/$A$25 -> 0.12698355
B29: 직원D | C29: =3300000/31 -> 106451.61 | E29: 알바X | H29: 누계 | I29: =SUM('1:5'!$I$27) -> 3082612.9
E30: 알바X | H30: 누적매출 | I30: =I29/$I$27 -> 4.9653685
B31: 직원C | C31: =4000000/31 -> 129032.26 | E31: 파출 | F31: 120000
B32: 알바X | E32: 홀 파출
B33: 알바B | C33: =13000*4 -> 52000
B34: 알바X

Sheet 6
C1: 2025년 | E1: 11월 | F1: 6 | G1: 목 | H1: 실영업일수 | I1: =F1-K1 -> 6 | J1: 휴무일수
A2: 매출 | C2: =SUM(C4:D7) -> 4090500 | E2: 시재 | G2: 94800 | H2: 식자재 | J2: 비품 및 기타경비
H3: 업체 | I3: 금액 | J3: 업체 | K3: 금액
A4: 카드 | C4: 3537000 | E4: 카드수수료(2.75%) | G4: =INT(C4*0.0275) -> 97267 | H4: 고기 | I4: =285358+574424+56220+452000+249444+203301+221000+30650 -> 2072397 | J4: 숯
A5: 현금 | C5: 553500 | E5: 현금수수료(1%) | G5: =INT(C5*0.01) -> 5535 | H5: 식자재 | I5: =69000+53350+35040+30300 -> 187690
A6: 페이결제 | E6: 통장입금 | G6: 550000 | J6: 음식물스티커
H7: 주류 | J7: 종량제봉투
A8: 금고 실잔액 | C8: 98300 | E8: 마감잔금 | G8: =C5+G2-G6-C22 -> 98300 | H8: 쌀 | I8: 65000
J9: 뚝배기
A10: 현금할인 | C10: 542000 | E10: 카드할인 | J10: 발매트
A11: 할인내역 | C11: 선결제 할인 542,000원 | H11: 참기름 | J11: 불판세척
A12: 개수 | B12: 목살 | C12: 4 | D12: LA갈비 | F12: 4 | H12: 부탄가스
A13: 매출누계 | C13: =SUM('1:6'!$C$12) -> 31 | F13: =SUM('1:6'!$F$12) -> 28 | H13: 코카콜라음료
A14: 개수 | B14: 삼겹살 | C14: 23 | D14: 돼지양념갈비 | F14: 4 | H14: 깍두기,계란
A15: 매출누계 | C15: =SUM('1:6'!$C$14) -> 106 | F15: =SUM('1:6'!$F$14) -> 42 | H15: 식자재2 | I15: =11800+54400+3500+10000+5500+8900 -> 94100 | J15: 비품 및 기타경비
A16: 개수 | B16: 육회 | C16: 4 | D16: 한우업진살 | F16: 7 | J16: 인터넷 주문 | K16: 175770
A17: 매출누계 | C17: =SUM('1:6'!$C$16) -> 24 | F17: =SUM('1:6'!$F$16) -> 49 | H17: 막걸리 | J17: 다이소 구매
A18: 개수 | B18: 소갈비살 | C18: 21 | D18: LA양념갈비 | F18: 7
A19: 매출누계 | C19: =SUM('1:6'!$C$18) -> 74 | F19: =SUM('1:6'!$F$18) -> 27
D20: 테이블수 | F20: 73
D21: 누적테이블 | F21: =SUM('1:6'!$F$20) -> 381
A22: 중간출금
A23: 출금내역 | H23: 식자재합계 | I23: =SUM(I4:I22) -> 2419187 | J23: 기타경비합계 | K23: =SUM(K4:K22) -> 175770 | M23: 현금합계 | N23: =C5+C6 -> 553500
A24: 일매출 | C24: 일평균매출 | E24: 누적총매출 | H24: 일매출 | I24: =I23/A25 -> 0.59141596 | J24: 일매출 | K24: =K23/A25 -> 0.042970297
A25: =C2 -> 4090500 | C25: =E25/I1 -> 4906833.3 | E25: =SUM('1:6'!$A$25) -> 29441000 | H25: 누계 | I25: =SUM('1'!$I$23) -> 1925001 | J25: 누계 | K25: =SUM('1:6'!$K$23) -> 506250
A26: 전 월 | H26: 누적매출 | I26: =I25/$E$25 -> 0.065385041 | J26: 누적매출 | K26: =K25/$E$25 -> 0.017195408
A27: 인 건 비 | B27: 직원A | C27: =3300000/31 -> 106451.61 | E27: 알바C | H27: 인건비합계 | I27: =SUM(C27:D34,F27:G32) -> 633322.58
E28: 직원F | F28: =1500000/31 -> 48387.097 | H28: 일매출 | I28: =I27/$A$25 -> 0.15482767
B29: 직원D | C29: =3300000/31 -> 106451.61 | E29: 알바X | H29: 누계 | I29: =SUM('1:6'!$I$27) -> 3715935.5
E30: 알바X | H30: 누적매출 | I30: =I29/$I$27 -> 5.8673662
B31: 직원C | C31: =4000000/31 -> 129032.26 | E31: 파출 | F31: 120000
B32: 알바X | E32: 홀 파출 | F32: 71000
B33: 알바B | C33: =13000*4 -> 52000
B34: 알바X

Sheet 7
C1: 2025년 | E1: 11월 | F1: 7 | G1: 금 | H1: 실영업일수 | I1: =F1-K1 -> 7 | J1: 휴무일수
A2: 매출 | C2: =SUM(C4:D7) -> 5846000 | E2: 시재 | G2: 98300 | H2: 식자재 | J2: 비품 및 기타경비
H3: 업체 | I3: 금액 | J3: 업체 | K3: 금액
A4: 카드 | C4: 5059000 | E4: 카드수수료(2.75%) | G4: =INT(C4*0.0275) -> 139122 | H4: 고기 | I4: =289646 -> 289646 | J4: 숯
A5: 현금 | C5: 787000 | E5: 현금수수료(1%) | G5: =INT(C5*0.01) -> 7870 | H5: 식자재 | I5: =29656+78760+50000+34500+3500+11940+3200+24720 -> 236276
A6: 페이결제 | E6: 통장입금 | G6: 802200 | J6: 음식물스티커 | K6: 112000
H7: 주류 | I7: =466600-24300 -> 442300 | J7: 종량제봉투
A8: 금고 실잔액 | C8: 83100 | E8: 마감잔금 | G8: =C5+G2-G6-C22 -> 83100 | H8: 쌀 | I8: 130000
J9: 뚝배기
A10: 현금할인 | C10: 100000 | E10: 카드할인 | J10: 발매트
A11: 할인내역 | C11: 선결제 | H11: 참기름 | I11: 100000 | J11: 불판세척
A12: 개수 | B12: 목살 | C12: 5 | D12: LA갈비 | F12: 11 | H12: 부탄가스
A13: 매출누계 | C13: =SUM('1:7'!$C$12) -> 36 | F13: =SUM('1:7'!$F$12) -> 39 | H13: 코카콜라음료 | I13: 200000
A14: 개수 | B14: 삼겹살 | C14: 17 | D14: 돼지양념갈비 | F14: 5 | H14: 깍두기,계란
A15: 매출누계 | C15: =SUM('1:7'!$C$14) -> 123 | F15: =SUM('1:7'!$F$14) -> 47 | H15: 식자재2 | I15: =11800+34000+3500+20000+5500+7500+4900+4200+28000+3500 -> 122900 | J15: 비품 및 기타경비
A16: 개수 | B16: 육회 | C16: 6 | D16: 한우업진살 | F16: 14 | J16: 인터넷 주문 | K16: =443680+11900 -> 455580
A17: 매출누계 | C17: =SUM('1:7'!$C$16) -> 30 | F17: =SUM('1:7'!$F$16) -> 63 | H17: 막걸리 | J17: 다이소 구매
A18: 개수 | B18: 소갈비살 | C18: 18 | D18: LA양념갈비 | F18: 0
A19: 매출누계 | C19: =SUM('1:7'!$C$18) -> 92 | F19: =SUM('1:7'!$F$18) -> 27
D20: 테이블수 | F20: 77
D21: 누적테이블 | F21: =SUM('1:7'!$F$20) -> 458
A22: 중간출금
A23: 출금내역 | H23: 식자재합계 | I23: =SUM(I4:I22) -> 1521122 | J23: 기타경비합계 | K23: =SUM(K4:K22) -> 567580 | M23: 현금합계 | N23: =C5+C6 -> 787000
A24: 일매출 | C24: 일평균매출 | E24: 누적총매출 | H24: 일매출 | I24: =I23/A25 -> 0.26019877 | J24: 일매출 | K24: =K23/A25 -> 0.097088608
A25: =C2 -> 5846000 | C25: =E25/I1 -> 5041000 | E25: =SUM('1:7'!$A$25) -> 35287000 | H25: 누계 | I25: =SUM('1'!$I$23) -> 1925001 | J25: 누계 | K25: =SUM('1:7'!$K$23) -> 1073830
A26: 전 월 | H26: 누적매출 | I26: =I25/$E$25 -> 0.054552696 | J26: 누적매출 | K26: =K25/$E$25 -> 0.03043132
A27: 인 건 비 | B27: 직원A | C27: =3300000/31 -> 106451.61 | E27: 알바C | F27: =13000*5 -> 65000 | H27: 인건비합계 | I27: =SUM(C27:D34,F27:G32) -> 587322.58
E28: 직원F | F28: =1500000/31 -> 48387.097 | H28: 일매출 | I28: =I27/$A$25 -> 0.10046572
B29: 직원D | C29: =3300000/31 -> 106451.61 | E29: 알바X | H29: 누계 | I29: =SUM('1:7'!$I$27) -> 4303258.1
E30: 알바X | H30: 누적매출 | I30: =I29/$I$27 -> 7.3269072
B31: 직원C | C31: =4000000/31 -> 129032.26 | E31: 파출 | F31: 132000
B32: 알바X | E32: 홀 파출
B33: 알바B
B34: 알바X

Sheet 8
C1: 2025년 | E1: 11월 | F1: 8 | G1: 토 | H1: 실영업일수 | I1: =F1-K1 -> 8 | J1: 휴무일수
A2: 매출 | C2: =SUM(C4:D7) -> 5819000 | E2: 시재 | G2: 83100 | H2: 식자재 | J2: 비품 및 기타경비
H3: 업체 | I3: 금액 | J3: 업체 | K3: 금액
A4: 카드 | C4: 5371500 | E4: 카드수수료(2.75%) | G4: =INT(C4*0.0275) -> 147716 | H4: 고기 | I4: =290036+632840+452000+476580+400148 -> 2251604 | J4: 숯
A5: 현금 | C5: 447500 | E5: 현금수수료(1%) | G5: =INT(C5*0.01) -> 4475 | H5: 식자재 | I5: =45430+59312+39380+100000+69000+36000+16720+23880+35040+30300+19530 -> 474592
A6: 페이결제 | E6: 통장입금 | G6: 450000 | J6: 음식물스티커
H7: 주류 | J7: 종량제봉투
A8: 금고 실잔액 | C8: 80600 | E8: 마감잔금 | G8: =C5+G2-G6-C22 -> 80600 | H8: 쌀
J9: 뚝배기
A10: 현금할인 | C10: 60000 | E10: 카드할인 | J10: 발매트
A11: 할인내역 | C11: 슈퍼멤버스 | H11: 참기름 | J11: 불판세척
A12: 개수 | B12: 목살 | C12: 15 | D12: LA갈비 | F12: 15 | H12: 부탄가스
A13: 매출누계 | C13: =SUM('1:8'!$C$12) -> 51 | F13: =SUM('1:8'!$F$12) -> 54 | H13: 코카콜라음료
A14: 개수 | B14: 삼겹살 | C14: 22 | D14: 돼지양념갈비 | F14: 15 | H14: 깍두기,계란
A15: 매출누계 | C15: =SUM('1:8'!$C$14) -> 145 | F15: =SUM('1:8'!$F$14) -> 62 | H15: 식자재2 | I15: =30000+68000+11000+12500+9800+11000+3900+6200+10500 -> 162900 | J15: 비품 및 기타경비
A16: 개수 | B16: 육회 | C16: 8 | D16: 한우업진살 | F16: 10 | J16: 인터넷 주문
A17: 매출누계 | C17: =SUM('1:8'!$C$16) -> 38 | F17: =SUM('1:8'!$F$16) -> 73 | H17: 막걸리 | J17: 다이소 구매
A18: 개수 | B18: 소갈비살 | C18: 16 | D18: LA양념갈비 | F18: 5
A19: 매출누계 | C19: =SUM('1:8'!$C$18) -> 108 | F19: =SUM('1:8'!$F$18) -> 32
D20: 테이블수 | F20: 69
D21: 누적테이블 | F21: =SUM('1:8'!$F$20) -> 527
A22: 중간출금
A23: 출금내역 | H23: 식자재합계 | I23: =SUM(I4:I22) -> 2889096 | J23: 기타경비합계 | K23: =SUM(K4:K22) -> 0 | M23: 현금합계 | N23: =C5+C6 -> 447500
A24: 일매출 | C24: 일평균매출 | E24: 누적총매출 | H24: 일매출 | I24: =I23/A25 -> 0.49649356 | J24: 일매출 | K24: =K23/A25 -> 0
A25: =C2 -> 5819000 | C25: =E25/I1 -> 5138250 | E25: =SUM('1:8'!$A$25) -> 41106000 | H25: 누계 | I25: =SUM('1'!$I$23) -> 1925001 | J25: 누계 | K25: =SUM('1:8'!$K$23) -> 1073830
A26: 전 월 | H26: 누적매출 | I26: =I25/$E$25 -> 0.046830171 | J26: 누적매출 | K26: =K25/$E$25 -> 0.026123437
A27: 인 건 비 | B27: 직원A | C27: =3300000/31 -> 106451.61 | E27: 알바C | H27: 인건비합계 | I27: =SUM(C27:D34,F27:G32) -> 662322.58
E28: 직원F | F28: =1500000/31 -> 48387.097 | H28: 일매출 | I28: =I27/$A$25 -> 0.11382069
B29: 직원D | C29: =3300000/31 -> 106451.61 | E29: 알바X | H29: 누계 | I29: =SUM('1:8'!$I$27) -> 4965580.6 | M29: `
E30: 알바X | H30: 누적매출 | I30: =I29/$I$27 -> 7.4972238
B31: 직원C | C31: =4000000/31 -> 129032.26 | E31: 파출 | F31: =143000 -> 143000
B32: 알바X | E32: 홀 파출 | F32: 77000
B33: 알바B | C33: =13000*4 -> 52000
B34: 알바X

Sheet 9
C1: 2025년 | E1: 11월 | F1: 9 | G1: 일 | H1: 실영업일수 | I1: =F1-K1 -> 9 | J1: 휴무일수
A2: 매출 | C2: =SUM(C4:D7) -> 5832000 | E2: 시재 | G2: 80600 | H2: 식자재 | J2: 비품 및 기타경비
H3: 업체 | I3: 금액 | J3: 업체 | K3: 금액
A4: 카드 | C4: 5106000 | E4: 카드수수료(2.75%) | G4: =INT(C4*0.0275) -> 140415 | H4: 고기 | J4: 숯
A5: 현금 | C5: 726000 | E5: 현금수수료(1%) | G5: =INT(C5*0.01) -> 7260 | H5: 식자재
A6: 페이결제 | E6: 통장입금 | G6: 680000 | J6: 음식물스티커
H7: 주류 | J7: 종량제봉투
A8: 금고 실잔액 | C8: 126600 | E8: 마감잔금 | G8: =C5+G2-G6-C22 -> 126600 | H8: 쌀
J9: 뚝배기
A10: 현금할인 | C10: 60000 | E10: 카드할인 | J10: 발매트
A11: 할인내역 | C11: 슈퍼멤버스 | H11: 참기름 | J11: 불판세척
A12: 개수 | B12: 목살 | C12: 12 | D12: LA갈비 | F12: 3 | H12: 부탄가스
A13: 매출누계 | C13: =SUM('1:9'!$C$12) -> 63 | F13: =SUM('1:9'!$F$12) -> 57 | H13: 코카콜라음료
A14: 개수 | B14: 삼겹살 | C14: 49 | D14: 돼지양념갈비 | F14: 14 | H14: 깍두기,계란
A15: 매출누계 | C15: =SUM('1:9'!$C$14) -> 194 | F15: =SUM('1:9'!$F$14) -> 76 | H15: 식자재2 | J15: 비품 및 기타경비
A16: 개수 | B16: 육회 | C16: 7 | D16: 한우업진살 | F16: 13 | J16: 인터넷 주문 | K16: 181180
A17: 매출누계 | C17: =SUM('1:9'!$C$16) -> 45 | F17: =SUM('1:9'!$F$16) -> 86 | H17: 막걸리 | J17: 다이소 구매
A18: 개수 | B18: 소갈비살 | C18: 39 | D18: LA양념갈비 | F18: 3
A19: 매출누계 | C19: =SUM('1:9'!$C$18) -> 147 | F19: =SUM('1:9'!$F$18) -> 35
D20: 테이블수 | F20: 73
D21: 누적테이블 | F21: =SUM('1:9'!$F$20) -> 600
A22: 중간출금
A23: 출금내역 | H23: 식자재합계 | I23: =SUM(I4:I22) -> 0 | J23: 기타경비합계 | K23: =SUM(K4:K22) -> 181180 | M23: 현금합계 | N23: =C5+C6 -> 726000
A24: 일매출 | C24: 일평균매출 | E24: 누적총매출 | H24: 일매출 | I24: =I23/A25 -> 0 | J24: 일매출 | K24: =K23/A25 -> 0.031066529
A25: =C2 -> 5832000 | C25: =E25/I1 -> 5215333.3 | E25: =SUM('1:9'!$A$25) -> 46938000 | H25: 누계 | I25: =SUM('1'!$I$23) -> 1925001 | J25: 누계 | K25: =SUM('1:9'!$K$23) -> 1255010
A26: 전 월 | H26: 누적매출 | I26: =I25/$E$25 -> 0.041011568 | J26: 누적매출 | K26: =K25/$E$25 -> 0.026737611
A27: 인 건 비 | B27: 직원A | C27: =3300000/31 -> 106451.61 | E27: 알바C | H27: 인건비합계 | I27: =SUM(C27:D34,F27:G32) -> 649322.58
E28: 직원F | F28: =1500000/31 -> 48387.097 | H28: 일매출 | I28: =I27/$A$25 -> 0.11133789
B29: 직원D | C29: =3300000/31 -> 106451.61 | E29: 알바X | H29: 누계 | I29: =SUM('1:9'!$I$27) -> 5614903.2
E30: 알바X | H30: 누적매출 | I30: =I29/$I$27 -> 8.6473248
B31: 직원C | C31: =4000000/31 -> 129032.26 | E31: 파출 | F31: =130000 -> 130000
B32: 알바X | E32: 홀 파출 | F32: 77000
B33: 알바B | C33: =13000*4 -> 52000
B34: 알바X

Sheet 10
C1: 2025년 | E1: 11월 | F1: 10 | G1: 월 | H1: 실영업일수 | I1: =F1-K1 -> 10 | J1: 휴무일수
A2: 매출 | C2: =SUM(C4:D7) -> 4226000 | E2: 시재 | G2: 126600 | H2: 식자재 | J2: 비품 및 기타경비
H3: 업체 | I3: 금액 | J3: 업체 | K3: 금액
A4: 카드 | C4: 3485000 | E4: 카드수수료(2.75%) | G4: =INT(C4*0.0275) -> 95837 | H4: 고기 | I4: =570716+275042+43500+904000+225108+212982+10 -> 2231358 | J4: 숯
A5: 현금 | C5: 741000 | E5: 현금수수료(1%) | G5: =INT(C5*0.01) -> 7410 | H5: 식자재 | I5: =45430+44000+59312+39380+100000+69000+36000 -> 393122
A6: 페이결제 | E6: 통장입금 | G6: 800000 | J6: 음식물스티커
H7: 주류 | J7: 종량제봉투
A8: 금고 실잔액 | C8: 67600 | E8: 마감잔금 | G8: =C5+G2-G6-C22 -> 67600 | H8: 쌀 | I8: 65000
J9: 뚝배기
A10: 현금할인 | C10: 600000 | E10: 카드할인 | J10: 발매트 | K10: 14300
A11: 할인내역 | C11: 슈퍼멤버스 | H11: 참기름 | J11: 불판세척
A12: 개수 | B12: 목살 | C12: 10 | D12: LA갈비 | F12: 7 | H12: 부탄가스
A13: 매출누계 | C13: =SUM('1:10'!$C$12) -> 73 | F13: =SUM('1:10'!$F$12) -> 64 | H13: 코카콜라음료
A14: 개수 | B14: 삼겹살 | C14: 25 | D14: 돼지양념갈비 | F14: 12 | H14: 깍두기,계란
A15: 매출누계 | C15: =SUM('1:10'!$C$14) -> 219 | F15: =SUM('1:10'!$F$14) -> 88 | H15: 식자재2 | I15: =20000+11000+9800+5500+4800+52000+7500+20400+11800+5000+5500+13000+28000+2450+13000 -> 209750 | J15: 비품 및 기타경비
A16: 개수 | B16: 육회 | C16: 3 | D16: 한우업진살 | F16: 7 | J16: 인터넷 주문
A17: 매출누계 | C17: =SUM('1:10'!$C$16) -> 48 | F17: =F19 -> 44 | H17: 막걸리 | J17: 다이소 구매
A18: 개수 | B18: 소갈비살 | C18: 6 | D18: LA양념갈비 | F18: 9
A19: 매출누계 | C19: =SUM('1:10'!$C$18) -> 153 | F19: =SUM('1:10'!$F$18) -> 44
D20: 테이블수 | F20: 57
D21: 누적테이블 | F21: =SUM('1:10'!$F$20) -> 657
A22: 중간출금
A23: 출금내역 | H23: 식자재합계 | I23: =SUM(I4:I22) -> 2899230 | J23: 기타경비합계 | K23: =SUM(K4:K22) -> 14300 | M23: 현금합계 | N23: =C5+C6 -> 741000
A24: 일매출 | C24: 일평균매출 | E24: 누적총매출 | H24: 일매출 | I24: =I23/A25 -> 0.68604591 | J24: 일매출 | K24: =K23/A25 -> 0.0033838145
A25: =C2 -> 4226000 | C25: =E25/I1 -> 5116400 | E25: =SUM('1:10'!$A$25) -> 51164000 | H25: 누계 | I25: =SUM('1'!$I$23) -> 1925001 | J25: 누계 | K25: =SUM('1:10'!$K$21) -> 0
A26: 전 월 | H26: 누적매출 | I26: =I25/$E$25 -> 0.03762413 | J26: 누적매출 | K26: =K25/$E$25 -> 0
A27: 인 건 비 | B27: 직원A | C27: =3300000/31 -> 106451.61 | E27: 알바C | F27: =13000*4.5 -> 58500 | H27: 인건비합계 | I27: =SUM(C27:D34,F27:G32) -> 531822.58
E28: 직원F | F28: =1500000/31 -> 48387.097 | H28: 일매출 | I28: =I27/$A$25 -> 0.12584538
B29: 직원D | C29: =3300000/31 -> 106451.61 | E29: 알바X | H29: 누계 | I29: =SUM('1:10'!$I$25) -> 19250010
E30: 알바X | H30: 누적매출 | I30: =I29/$I$27 -> 36.196301
B31: 직원C | C31: =4000000/31 -> 129032.26 | E31: 파출 | F31: 12000
B32: 알바X | E32: 홀 파출 | F32: 71000
B33: 알바B
B34: 알바X

Sheet 11
C1: 2025년 | E1: 11월 | F1: 11 | G1: 화 | H1: 실영업일수 | I1: =F1-K1 -> 11 | J1: 휴무일수
A2: 매출 | C2: =SUM(C4:D7) -> 3954500 | E2: 시재 | G2: 67600 | H2: 식자재 | J2: 비품 및 기타경비
H3: 업체 | I3: 금액 | J3: 업체 | K3: 금액
A4: 카드 | C4: 3672500 | E4: 카드수수료(2.75%) | G4: =INT(C4*0.0275) -> 100993 | H4: 고기 | I4: =261968+250702+221000+267696+187166+452000 -> 1640532 | J4: 숯 | K4: 294000
A5: 현금 | C5: 282000 | E5: 현금수수료(1%) | G5: =INT(C5*0.01) -> 2820 | H5: 식자재 | I5: =50000+34500+36000+16720+3500+23880+17520+17560 -> 199680
A6: 페이결제 | E6: 통장입금 | G6: 200000 | J6: 음식물스티커
H7: 주류 | J7: 종량제봉투
A8: 금고 실잔액 | C8: 149600 | E8: 마감잔금 | G8: =C5+G2-G6-C22 -> 149600 | H8: 쌀
J9: 뚝배기
A10: 현금할인 | C10: 247000 | E10: 카드할인 | J10: 발매트 | K10: 14300
A11: 할인내역 | C11: 김상현 고객님 선결제 247,000원 | H11: 참기름 | J11: 불판세척
A12: 개수 | B12: 목살 | C12: 5 | D12: LA갈비 | F12: 6 | H12: 부탄가스
A13: 매출누계 | C13: =SUM('1:11'!$C$12) -> 78 | F13: =SUM('1:11'!$F$12) -> 70 | H13: 코카콜라음료
A14: 개수 | B14: 삼겹살 | C14: 6 | D14: 돼지양념갈비 | F14: 10 | H14: 깍두기,계란 | M14: ㄴ
A15: 매출누계 | C15: =SUM('1:11'!$C$14) -> 225 | F15: =SUM('1:11'!$F$14) -> 98 | H15: 식자재2 | I15: =5500+4900+5500+4800+13600+11800+10500+3900+6200+13000 -> 79700 | J15: 비품 및 기타경비
A16: 개수 | B16: 육회 | C16: 8 | D16: 한우업진살 | F16: 5 | J16: 인터넷 주문
A17: 매출누계 | C17: =SUM('1:11'!$C$16) -> 56 | F17: =SUM('1:11'!$F$16) -> 98 | H17: 막걸리 | I17: 3200 | J17: 다이소 구매
A18: 개수 | B18: 소갈비살 | C18: 9 | D18: LA양념갈비 | F18: 5
A19: 매출누계 | C19: =SUM('1:11'!$C$18) -> 162 | F19: =SUM('1:11'!$F$18) -> 49
D20: 테이블수 | F20: 55
D21: 누적테이블 | F21: =SUM('1:11'!$F$20) -> 712
A22: 중간출금
A23: 출금내역 | H23: 식자재합계 | I23: =SUM(I4:I22) -> 1923112 | J23: 기타경비합계 | K23: =SUM(K4:K22) -> 308300 | M23: 현금합계 | N23: =C5+C6 -> 282000
A24: 일매출 | C24: 일평균매출 | E24: 누적총매출 | H24: 일매출 | I24: =I23/A25 -> 0.48630977 | J24: 일매출 | K24: =K23/A25 -> 0.077961816
A25: =C2 -> 3954500 | C25: =E25/I1 -> 5010772.7 | E25: =SUM('1:11'!$A$25) -> 55118500 | H25: 누계 | I25: =SUM('1'!$I$23) -> 1925001 | J25: 누계 | K25: =SUM('1:11'!$K$21) -> 0
A26: 전 월 | H26: 누적매출 | I26: =I25/$E$25 -> 0.034924771 | J26: 누적매출 | K26: =K25/$E$25 -> 0
A27: 인 건 비 | B27: 직원A | C27: =3300000/31 -> 106451.61 | E27: 알바C | F27: =13000*5 -> 65000 | H27: 인건비합계 | I27: =SUM(C27:D34,F27:G32) -> 627322.58
E28: 직원F | F28: =1500000/31 -> 48387.097 | H28: 일매출 | I28: =I27/$A$25 -> 0.15863512
B29: 직원D | C29: =3300000/31 -> 106451.61 | E29: 알바X | H29: 누계 | I29: =SUM('1:11'!$I$25) -> 21175011
E30: 알바X | H30: 누적매출 | I30: =I29/$I$27 -> 33.754581
B31: 직원C | C31: =4000000/31 -> 129032.26 | E31: 파출 | F31: =120000 -> 120000
B32: 알바X | E32: 홀 파출
B33: 알바B | C33: =13000*4 -> 52000
B34: 알바X

Sheet 12
C1: 2025년 | E1: 11월 | F1: 12 | G1: 수 | H1: 실영업일수 | I1: =F1-K1 -> 12 | J1: 휴무일수
A2: 매출 | C2: =SUM(C4:D7) -> 4430000 | E2: 시재 | G2: 149600 | H2: 식자재 | J2: 비품 및 기타경비
H3: 업체 | I3: 금액 | J3: 업체 | K3: 금액
A4: 카드 | C4: 3987000 | E4: 카드수수료(2.75%) | G4: =INT(C4*0.0275) -> 109642 | H4: 고기 | I4: =277476+30650+221000+219024+209755 -> 957905 | J4: 숯
A5: 현금 | C5: 443000 | E5: 현금수수료(1%) | G5: =INT(C5*0.01) -> 4430 | H5: 식자재 | I5: =34500+11940+3200+26675+39490 -> 115805
A6: 페이결제 | E6: 통장입금 | G6: 500000 | J6: 음식물스티커
H7: 주류 | J7: 종량제봉투
A8: 금고 실잔액 | C8: 92600 | E8: 마감잔금 | G8: =C5+G2-G6-C22 -> 92600 | H8: 쌀 | I8: 65000
J9: 뚝배기
A10: 현금할인 | C10: =49000+60000 -> 109000 | E10: 카드할인 | J10: 발매트
A11: 할인내역 | C11: 선결제 49,000원 슈퍼멤버스 60,000원 | H11: 참기름 | J11: 불판세척
A12: 개수 | B12: 목살 | C12: 5 | D12: LA갈비 | F12: 4 | H12: 부탄가스
A13: 매출누계 | C13: =SUM('1:12'!$C$12) -> 83 | F13: =SUM('1:12'!$F$12) -> 74 | H13: 코카콜라음료
A14: 개수 | B14: 삼겹살 | C14: 21 | D14: 돼지양념갈비 | F14: 10 | H14: 깍두기,계란
A15: 매출누계 | C15: =SUM('1:12'!$C$14) -> 246 | F15: =SUM('1:12'!$F$14) -> 108 | H15: 식자재2 | I15: =3500+7500+10500+9600+40800+5900+4200+22000+20500 -> 124500 | J15: 비품 및 기타경비
A16: 개수 | B16: 육회 | C16: 2 | D16: 한우업진살 | F16: 7 | J16: 인터넷 주문
A17: 매출누계 | C17: =SUM('1:12'!$C$16) -> 58 | F17: =SUM('1:12'!$F$16) -> 105 | H17: 막걸리 | J17: 다이소 구매
A18: 개수 | B18: 소갈비살 | C18: 6 | D18: LA양념갈비 | F18: 1
A19: 매출누계 | C19: =SUM('1:12'!$C$18) -> 168 | F19: =SUM('1:12'!$F$18) -> 50
D20: 테이블수 | F20: 58
D21: 누적테이블 | F21: =SUM('1:12'!$F$20) -> 770
A22: 중간출금
A23: 출금내역 | H23: 식자재합계 | I23: =SUM(I4:I22) -> 1263210 | J23: 기타경비합계 | K23: =SUM(K4:K22) -> 0 | M23: 현금합계 | N23: =C5+C6 -> 443000
A24: 일매출 | C24: 일평균매출 | E24: 누적총매출 | H24: 일매출 | I24: =I23/A25 -> 0.28514898 | J24: 일매출 | K24: =K23/A25 -> 0
A25: =C2 -> 4430000 | C25: =E25/I1 -> 4962375 | E25: =SUM('1:12'!$A$25) -> 59548500 | H25: 누계 | I25: =SUM('1'!$I$23) -> 1925001 | J25: 누계 | K25: =SUM('1:12'!$K$21) -> 0
A26: 전 월 | H26: 누적매출 | I26: =I25/$E$25 -> 0.032326608 | J26: 누적매출 | K26: =K25/$E$25 -> 0
A27: 인 건 비 | B27: 직원A | C27: =3300000/31 -> 106451.61 | E27: 알바C | F27: =13000*4.5 -> 58500 | H27: 인건비합계 | I27: =SUM(C27:D34,F27:G32) -> 620822.58
E28: 직원F | F28: =1500000/31 -> 48387.097 | H28: 일매출 | I28: =I27/$A$25 -> 0.14014054
B29: 직원D | C29: =3300000/31 -> 106451.61 | E29: 알바X | H29: 누계 | I29: =SUM('1:12'!$I$25) -> 23100012
E30: 알바X | H30: 누적매출 | I30: =I29/$I$27 -> 37.208717
B31: 직원C | C31: =4000000/31 -> 129032.26 | E31: 파출 | F31: 120000
B32: 알바X | E32: 홀 파출
B33: 알바B | C33: =13000*4 -> 52000
B34: 알바X

Sheet 13
C1: 2025년 | E1: 11월 | F1: 13 | G1: 목 | H1: 실영업일수 | I1: =F1-K1 -> 13 | J1: 휴무일수
A2: 매출 | C2: =SUM(C4:D7) -> 4797500 | E2: 시재 | G2: 92600 | H2: 식자재 | J2: 비품 및 기타경비
H3: 업체 | I3: 금액 | J3: 업체 | K3: 금액
A4: 카드 | C4: 4292000 | E4: 카드수수료(2.75%) | G4: =INT(C4*0.0275) -> 118030 | H4: 고기 | J4: 숯
A5: 현금 | C5: 505500 | E5: 현금수수료(1%) | G5: =INT(C5*0.01) -> 5055 | H5: 식자재 | I5: =50000+34500+36000+16720+44000+78760 -> 259980
A6: 페이결제 | E6: 통장입금 | G6: 500000 | J6: 음식물스티커
H7: 주류 | I7: 391800 | J7: 종량제봉투
A8: 금고 실잔액 | C8: 98100 | E8: 마감잔금 | G8: =C5+G2-G6-C22 -> 98100 | H8: 쌀 | I8: 65000
J9: 뚝배기
A10: 현금할인 | E10: 카드할인 | J10: 발매트
A11: 할인내역 | H11: 참기름 | J11: 불판세척
A12: 개수 | B12: 목살 | C12: 7 | D12: LA갈비 | F12: 6 | H12: 부탄가스
A13: 매출누계 | C13: =SUM('1:13'!$C$12) -> 90 | F13: =SUM('1:13'!$F$12) -> 80 | H13: 코카콜라음료
A14: 개수 | B14: 삼겹살 | C14: 21 | D14: 돼지양념갈비 | F14: 10 | H14: 깍두기,계란
A15: 매출누계 | C15: =SUM('1:13'!$C$14) -> 267 | F15: =SUM('1:13'!$F$14) -> 118 | H15: 식자재2 | I15: =27200+7500+4800+11800+5500+4900+10600 -> 72300 | J15: 비품 및 기타경비
A16: 개수 | B16: 육회 | C16: 10 | D16: 한우업진살 | F16: 8 | J16: 인터넷 주문
A17: 매출누계 | C17: =SUM('1:13'!$C$16) -> 68 | F17: =SUM('1:13'!$F$16) -> 113 | H17: 막걸리 | I17: 3200 | J17: 다이소 구매
A18: 개수 | B18: 소갈비살 | C18: 6 | D18: LA양념갈비 | F18: 3
A19: 매출누계 | C19: =SUM('1:13'!$C$18) -> 174 | F19: =SUM('1:13'!$F$18) -> 53
D20: 테이블수 | F20: 57
D21: 누적테이블 | F21: =SUM('1:13'!$F$20) -> 827
A22: 중간출금
A23: 출금내역 | H23: 식자재합계 | I23: =SUM(I4:I22) -> 792280 | J23: 기타경비합계 | K23: =SUM(K4:K22) -> 0 | M23: 현금합계 | N23: =C5+C6 -> 505500
A24: 일매출 | C24: 일평균매출 | E24: 누적총매출 | H24: 일매출 | I24: =I23/A25 -> 0.16514435 | J24: 일매출 | K24: =K23/A25 -> 0
A25: =C2 -> 4797500 | C25: =E25/I1 -> 4949692.3 | E25: =SUM('1:13'!$A$25) -> 64346000 | H25: 누계 | I25: =SUM('1'!$I$23) -> 1925001 | J25: 누계 | K25: =SUM('1:13'!$K$21) -> 0
A26: 전 월 | H26: 누적매출 | I26: =I25/$E$25 -> 0.029916405 | J26: 누적매출 | K26: =K25/$E$25 -> 0
A27: 인 건 비 | B27: 직원A | C27: =3300000/31 -> 106451.61 | E27: 알바C | F27: =13000*5 -> 65000 | H27: 인건비합계 | I27: =SUM(C27:D34,F27:G32) -> 685822.58
E28: 직원F | F28: =1500000/31 -> 48387.097 | H28: 일매출 | I28: =I27/$A$25 -> 0.14295416
B29: 직원D | C29: =3300000/31 -> 106451.61 | E29: 알바X | F29: =11700*5 -> 58500 | H29: 누계 | I29: =SUM('1:13'!$I$25) -> 25025013
E30: 알바X | H30: 누적매출 | I30: =I29/$I$27 -> 36.489048
B31: 직원C | C31: =4000000/31 -> 129032.26 | E31: 파출 | F31: 120000
B32: 알바X | E32: 홀 파출
B33: 알바B | C33: =13000*4 -> 52000
B34: 알바X

Sheet 14
C1: 2025년 | E1: 11월 | F1: 14 | G1: 금 | H1: 실영업일수 | I1: =F1-K1 -> 14 | J1: 휴무일수
A2: 매출 | C2: =SUM(C4:D7) -> 4628000 | E2: 시재 | G2: 98100 | H2: 식자재 | J2: 비품 및 기타경비
H3: 업체 | I3: 금액 | J3: 업체 | K3: 금액
A4: 카드 | C4: 4187000 | E4: 카드수수료(2.75%) | G4: =INT(C4*0.0275) -> 115142 | H4: 고기 | I4: =904000+227136+56220 -> 1187356 | J4: 숯
A5: 현금 | C5: 441000 | E5: 현금수수료(1%) | G5: =INT(C5*0.01) -> 4410 | H5: 식자재 | I5: =3500+16000+30300+50000+34500+11940+17520 -> 163760
A6: 페이결제 | E6: 통장입금 | G6: 440000 | J6: 음식물스티커
H7: 주류 | I7: =276890-24300 -> 252590 | J7: 종량제봉투
A8: 금고 실잔액 | C8: 99100 | E8: 마감잔금 | G8: =C5+G2-G6-C22 -> 99100 | H8: 쌀
J9: 뚝배기
A10: 현금할인 | C10: =59000+60000 -> 119000 | E10: 카드할인 | J10: 발매트
A11: 할인내역 | C11: 슈퍼멤버스 | H11: 참기름 | J11: 불판세척
A12: 개수 | B12: 목살 | C12: 10 | D12: LA갈비 | F12: 6 | H12: 부탄가스
A13: 매출누계 | C13: =SUM('1:14'!$C$12) -> 100 | F13: =SUM('1:14'!$F$12) -> 86 | H13: 코카콜라음료
A14: 개수 | B14: 삼겹살 | C14: 29 | D14: 돼지양념갈비 | F14: 16 | H14: 깍두기,계란
A15: 매출누계 | C15: =SUM('1:14'!$C$14) -> 296 | F15: =SUM('1:14'!$F$14) -> 134 | H15: 식자재2 | I15: =4800+34000+11800+3900+7200 -> 61700 | J15: 비품 및 기타경비
A16: 개수 | B16: 육회 | C16: 4 | D16: 한우업진살 | F16: 9 | J16: 인터넷 주문
A17: 매출누계 | C17: =SUM('1:14'!$C$16) -> 72 | F17: =SUM('1:14'!$F$16) -> 122 | H17: 막걸리 | J17: 다이소 구매
A18: 개수 | B18: 소갈비살 | C18: 8 | D18: LA양념갈비 | F18: 1
A19: 매출누계 | C19: =SUM('1:14'!$C$18) -> 182 | F19: =SUM('1:14'!$F$18) -> 54
D20: 테이블수 | F20: 72
D21: 누적테이블 | F21: =SUM('1:14'!$F$20) -> 899
A22: 중간출금
A23: 출금내역 | H23: 식자재합계 | I23: =SUM(I4:I22) -> 1665406 | J23: 기타경비합계 | K23: =SUM(K4:K22) -> 0 | M23: 현금합계 | N23: =C5+C6 -> 441000
A24: 일매출 | C24: 일평균매출 | E24: 누적총매출 | H24: 일매출 | I24: =I23/A25 -> 0.35985436 | J24: 일매출 | K24: =K23/A25 -> 0
A25: =C2 -> 4628000 | C25: =E25/I1 -> 4926714.3 | E25: =SUM('1:14'!$A$25) -> 68974000 | H25: 누계 | I25: =SUM('1'!$I$23) -> 1925001 | J25: 누계 | K25: =SUM('1:14'!$K$21) -> 0
A26: 전 월 | H26: 누적매출 | I26: =I25/$E$25 -> 0.027909082 | J26: 누적매출 | K26: =K25/$E$25 -> 0
A27: 인 건 비 | B27: 직원A | C27: =3300000/31 -> 106451.61 | E27: 알바C | F27: =13000*5 -> 65000 | H27: 인건비합계 | I27: =SUM(C27:D34,F27:G32) -> 616272.58
E28: 직원F | F28: =1500000/31 -> 48387.097 | H28: 일매출 | I28: =I27/$A$25 -> 0.13316175
B29: 직원D | C29: =3300000/31 -> 106451.61 | E29: 알바X | F29: =11700*3.5 -> 40950 | H29: 누계 | I29: =SUM('1:14'!$I$25) -> 26950014 | M29: `
E30: 알바X | H30: 누적매출 | I30: =I29/$I$27 -> 43.730672
B31: 직원C | C31: =4000000/31 -> 129032.26 | E31: 파출 | F31: 120000
B32: 알바X | E32: 홀 파출
B33: 알바B
B34: 알바X

Sheet 15
C1: 2025년 | E1: 11월 | F1: 15 | G1: 토 | H1: 실영업일수 | I1: =F1-K1 -> 15 | J1: 휴무일수
A2: 매출 | C2: =SUM(C4:D7) -> 6282300 | E2: 시재 | G2: 99100 | H2: 식자재 | J2: 비품 및 기타경비
H3: 업체 | I3: 금액 | J3: 업체 | K3: 금액
A4: 카드 | C4: 5205300 | E4: 카드수수료(2.75%) | H4: 고기 | I4: =285358+439200+229117+10+452000 -> 1405685 | J4: 숯
A5: 현금 | C5: 1077000 | E5: 현금수수료(1%) | G5: =INT(C5*0.01) -> 10770 | H5: 식자재
A6: 페이결제 | E6: 통장입금 | G6: 1100000 | J6: 음식물스티커
H7: 주류 | J7: 종량제봉투
A8: 금고 실잔액 | C8: 76100 | E8: 마감잔금 | G8: =C5+G2-G6-C22 -> 76100 | H8: 쌀
J9: 뚝배기
A10: 현금할인 | C10: 77700 | E10: 카드할인 | J10: 발매트
A11: 할인내역 | C11: 슈퍼멤버스 | H11: 참기름 | J11: 불판세척
A12: 개수 | B12: 목살 | C12: 8 | D12: LA갈비 | F12: 16 | H12: 부탄가스
A13: 매출누계 | C13: =SUM('1:15'!$C$12) -> 108 | F13: =SUM('1:15'!$F$12) -> 102 | H13: 코카콜라음료
A14: 개수 | B14: 삼겹살 | C14: 32 | D14: 돼지양념갈비 | F14: 36 | H14: 깍두기,계란
A15: 매출누계 | C15: =SUM('1:15'!$C$14) -> 328 | F15: =SUM('1:15'!$F$14) -> 170 | H15: 식자재2 | I15: =6200+3500+5500+9800+12500+2450+28800+44000+3900+234000+28000+10500+54400+7500+5500+30000 -> 486550 | J15: 비품 및 기타경비
A16: 개수 | B16: 육회 | C16: 11 | D16: 한우업진살 | F16: 14 | J16: 인터넷 주문
A17: 매출누계 | C17: =SUM('1:15'!$C$16) -> 83 | F17: =SUM('1:15'!$F$16) -> 136 | H17: 막걸리 | I17: 1600 | J17: 다이소 구매
A18: 개수 | B18: 소갈비살 | C18: 15 | D18: LA양념갈비 | F18: 3
A19: 매출누계 | C19: =SUM('1:15'!$C$18) -> 197 | F19: =SUM('1:15'!$F$18) -> 57
D20: 테이블수 | F20: 88
D21: 누적테이블 | F21: =SUM('1:15'!$F$20) -> 987
A22: 중간출금
A23: 출금내역 | H23: 식자재합계 | I23: =SUM(I4:I22) -> 1893835 | J23: 기타경비합계 | K23: =SUM(K4:K22) -> 0 | M23: 현금합계 | N23: =C5+C6 -> 1077000
A24: 일매출 | C24: 일평균매출 | E24: 누적총매출 | H24: 일매출 | I24: =I23/A25 -> 0.30145568 | J24: 일매출 | K24: =K23/A25 -> 0
A25: =C2 -> 6282300 | C25: =E25/I1 -> 5017086.7 | E25: =SUM('1:15'!$A$25) -> 75256300 | H25: 누계 | I25: =SUM('1'!$I$23) -> 1925001 | J25: 누계 | K25: =SUM('1:15'!$K$21) -> 0
A26: 전 월 | H26: 누적매출 | I26: =I25/$E$25 -> 0.025579267 | J26: 누적매출 | K26: =K25/$E$25 -> 0
A27: 인 건 비 | B27: 직원A | C27: =3300000/31 -> 106451.61 | E27: 알바C | H27: 인건비합계 | I27: =SUM(C27:D34,F27:G32) -> 799822.58
E28: 직원F | F28: =1500000/31 -> 48387.097 | H28: 일매출 | I28: =I27/$A$25 -> 0.12731366
B29: 직원D | C29: =3300000/31 -> 106451.61 | E29: 알바X | F29: =11700*5 -> 58500 | H29: 누계 | I29: =SUM('1:15'!$I$25) -> 28875015
E30: 알바X | H30: 누적매출 | I30: =I29/$I$27 -> 36.101775
B31: 직원C | C31: =4000000/31 -> 129032.26 | E31: 파출 | F31: 132000
B32: 알바X | E32: 홀 파출 | F32: =77000+77000 -> 154000
B33: 알바B | C33: =13000*5 -> 65000
B34: 알바X

Sheet 16
C1: 2025년 | E1: 11월 | F1: 16 | G1: 일 | H1: 실영업일수 | I1: =F1-K1 -> 16 | J1: 휴무일수
A2: 매출 | C2: =SUM(C4:D7) -> 4497000 | E2: 시재 | G2: 76100 | H2: 식자재 | J2: 비품 및 기타경비
H3: 업체 | I3: 금액 | J3: 업체 | K3: 금액
A4: 카드 | C4: 3866000 | E4: 카드수수료(2.75%) | G4: =INT(C4*0.0275) -> 106315 | H4: 고기 | J4: 숯
A5: 현금 | C5: 631000 | E5: 현금수수료(1%) | G5: =INT(C5*0.01) -> 6310 | H5: 식자재
A6: 페이결제 | E6: 통장입금 | G6: 630000 | J6: 음식물스티커
H7: 주류 | J7: 종량제봉투
A8: 금고 실잔액 | C8: 77100 | E8: 마감잔금 | G8: =C5+G2-G6-C22 -> 77100 | H8: 쌀
J9: 뚝배기
A10: 현금할인 | E10: 카드할인 | J10: 발매트
A11: 할인내역 | H11: 참기름 | J11: 불판세척
A12: 개수 | B12: 목살 | C12: 9 | D12: LA갈비 | F12: 10 | H12: 부탄가스
A13: 매출누계 | C13: =SUM('1:16'!$C$12) -> 117 | F13: =SUM('1:16'!$F$12) -> 112 | H13: 코카콜라음료
A14: 개수 | B14: 삼겹살 | C14: 36 | D14: 돼지양념갈비 | F14: 9 | H14: 깍두기,계란
A15: 매출누계 | C15: =SUM('1:16'!$C$14) -> 364 | F15: =SUM('1:16'!$F$14) -> 179 | H15: 식자재2 | J15: 비품 및 기타경비
A16: 개수 | B16: 육회 | C16: 2 | D16: 한우업진살 | F16: 1 | J16: 인터넷 주문 | K16: 526240
A17: 매출누계 | C17: =SUM('1:16'!$C$16) -> 85 | F17: =SUM('1:16'!$F$16) -> 137 | H17: 막걸리 | J17: 다이소 구매
A18: 개수 | B18: 소갈비살 | C18: 23 | D18: LA양념갈비 | F18: 6
A19: 매출누계 | C19: =SUM('1:16'!$C$18) -> 220 | F19: =SUM('1:16'!$F$18) -> 63
D20: 테이블수 | F20: 63
D21: 누적테이블 | F21: =SUM('1:16'!$F$20) -> 1050
A22: 중간출금
A23: 출금내역 | H23: 식자재합계 | I23: =SUM(I4:I22) -> 0 | J23: 기타경비합계 | K23: =SUM(K4:K22) -> 526240 | M23: 현금합계 | N23: =C5+C6 -> 631000
A24: 일매출 | C24: 일평균매출 | E24: 누적총매출 | H24: 일매출 | I24: =I23/A25 -> 0 | J24: 일매출 | K24: =K23/A25 -> 0.11702024
A25: =C2 -> 4497000 | C25: =E25/I1 -> 4984581.2 | E25: =SUM('1:16'!$A$25) -> 79753300 | H25: 누계 | I25: =SUM('1'!$I$23) -> 1925001 | J25: 누계 | K25: =SUM('1:16'!$K$21) -> 0
A26: 전 월 | H26: 누적매출 | I26: =I25/$E$25 -> 0.024136945 | J26: 누적매출 | K26: =K25/$E$25 -> 0
A27: 인 건 비 | B27: 직원A | C27: =3300000/31 -> 106451.61 | E27: 알바C | H27: 인건비합계 | I27: =SUM(C27:D34,F27:G32) -> 702322.58
E28: 직원F | F28: =1500000/31 -> 48387.097 | H28: 일매출 | I28: =I27/$A$25 -> 0.1561758
B29: 직원D | C29: =3300000/31 -> 106451.61 | E29: 알바X | F29: =11700*5 -> 58500 | H29: 누계 | I29: =SUM('1:16'!$I$25) -> 30800016
E30: 알바X | H30: 누적매출 | I30: =I29/$I$27 -> 43.854515
B31: 직원C | C31: =4000000/31 -> 129032.26 | E31: 파출 | F31: 130000
B32: 알바X | E32: 홀 파출
B33: 알바B | C33: =13000*9.5 -> 123500
B34: 알바X

Sheet 17
C1: 2025년 | E1: 11월 | F1: 17 | G1: 월 | H1: 실영업일수 | I1: =F1-K1 -> 17 | J1: 휴무일수
A2: 매출 | C2: =SUM(C4:D7) -> 4924000 | E2: 시재 | G2: 77100 | H2: 식자재 | J2: 비품 및 기타경비
H3: 업체 | I3: 금액 | J3: 업체 | K3: 금액
A4: 카드 | C4: 4402000 | E4: 카드수수료(2.75%) | G4: =INT(C4*0.0275) -> 121055 | H4: 고기 | J4: 숯
A5: 현금 | C5: 522000 | E5: 현금수수료(1%) | G5: =INT(C5*0.01) -> 5220 | H5: 식자재 | I5: =150000+69000+72000+16720+29656+39380+4170+12920+17760+6490+3200 -> 421296
A6: 페이결제 | E6: 통장입금 | G6: 520000 | J6: 음식물스티커
H7: 주류 | I7: =260300-43600 -> 216700 | J7: 종량제봉투
A8: 금고 실잔액 | C8: 79100 | E8: 마감잔금 | G8: =C5+G2-G6-C22 -> 79100 | H8: 쌀 | I8: 65000
J9: 뚝배기
A10: 현금할인 | C10: 80000 | E10: 카드할인 | J10: 발매트 | K10: 14300
A11: 할인내역 | H11: 참기름 | J11: 불판세척
A12: 개수 | B12: 목살 | C12: 2 | D12: LA갈비 | F12: 11 | H12: 부탄가스
A13: 매출누계 | C13: =SUM('1:17'!$C$12) -> 119 | F13: =SUM('1:17'!$F$12) -> 123 | H13: 코카콜라음료
A14: 개수 | B14: 삼겹살 | C14: 18 | D14: 돼지양념갈비 | F14: 5 | H14: 깍두기,계란
A15: 매출누계 | C15: =SUM('1:17'!$C$14) -> 382 | F15: =SUM('1:17'!$F$14) -> 184 | H15: 식자재2 | I15: =5500+5500+9800+11800+3500+13000+20400+5000+5500+20500+4800 -> 105300 | J15: 비품 및 기타경비
A16: 개수 | B16: 육회 | C16: 6 | D16: 한우업진살 | F16: 2 | J16: 인터넷 주문
A17: 매출누계 | C17: =SUM('1:17'!$C$16) -> 91 | F17: =SUM('1:17'!$F$16) -> 139 | H17: 막걸리 | J17: 다이소 구매
A18: 개수 | B18: 소갈비살 | C18: 8 | D18: LA양념갈비 | F18: 15
A19: 매출누계 | C19: =SUM('1:17'!$C$18) -> 228 | F19: =SUM('1:17'!$F$18) -> 78
D20: 테이블수 | F20: 61
D21: 누적테이블 | F21: =SUM('1:17'!$F$20) -> 1111
A22: 중간출금
A23: 출금내역 | H23: 식자재합계 | I23: =SUM(I4:I22) -> 808296 | J23: 기타경비합계 | K23: =SUM(K4:K22) -> 14300 | M23: 현금합계 | N23: =C5+C6 -> 522000
A24: 일매출 | C24: 일평균매출 | E24: 누적총매출 | H24: 일매출 | I24: =I23/A25 -> 0.16415435 | J24: 일매출 | K24: =K23/A25 -> 0.002904143
A25: =C2 -> 4924000 | C25: =E25/I1 -> 4981017.6 | E25: =SUM('1:17'!$A$25) -> 84677300 | H25: 누계 | I25: =SUM('1'!$I$23) -> 1925001 | J25: 누계 | K25: =SUM('1:17'!$K$21) -> 0
A26: 전 월 | H26: 누적매출 | I26: =I25/$E$25 -> 0.022733377 | J26: 누적매출 | K26: =K25/$E$25 -> 0
A27: 인 건 비 | B27: 직원A | C27: =3300000/31 -> 106451.61 | E27: 알바C | F27: =13000*5 -> 65000 | H27: 인건비합계 | I27: =SUM(C27:D34,F27:G32) -> 575322.58
E28: 직원F | F28: =1500000/31 -> 48387.097 | H28: 일매출 | I28: =I27/$A$25 -> 0.11684049
B29: 직원D | C29: =3300000/31 -> 106451.61 | E29: 알바X | H29: 누계 | I29: =SUM('1:17'!$I$25) -> 32725017
E30: 알바X | H30: 누적매출 | I30: =I29/$I$27 -> 56.881162
B31: 직원C | C31: =4000000/31 -> 129032.26 | E31: 파출 | F31: 120000
B32: 알바X | E32: 홀 파출
B33: 알바B
B34: 알바X

Sheet 18
C1: 2025년 | E1: 11월 | F1: 18 | G1: 화 | H1: 실영업일수 | I1: =F1-K1 -> 18 | J1: 휴무일수
A2: 매출 | C2: =SUM(C4:D7) -> 3827500 | E2: 시재 | G2: 79100 | H2: 식자재 | J2: 비품 및 기타경비
H3: 업체 | I3: 금액 | J3: 업체 | K3: 금액
A4: 카드 | C4: 3280000 | E4: 카드수수료(2.75%) | G4: =INT(C4*0.0275) -> 90200 | H4: 고기 | I4: =254951+277476+43500+452000+221000+225108+248479+10 -> 1722524 | J4: 숯 | K4: =63000+57000 -> 120000
A5: 현금 | C5: 547500 | E5: 현금수수료(1%) | G5: =INT(C5*0.01) -> 5475 | H5: 식자재 | I5: =50000+69000+36000+12920+17760+10390+26675+59312 -> 282057
A6: 페이결제 | E6: 통장입금 | G6: 470000 | J6: 음식물스티커
H7: 주류 | I7: =226900-19300 -> 207600 | J7: 종량제봉투 | K7: 12500
A8: 금고 실잔액 | C8: 156600 | E8: 마감잔금 | G8: =C5+G2-G6-C22 -> 156600 | H8: 쌀
J9: 뚝배기
A10: 현금할인 | E10: 카드할인 | J10: 발매트
A11: 할인내역 | H11: 참기름 | J11: 불판세척
A12: 개수 | B12: 목살 | C12: 7 | D12: LA갈비 | F12: 2 | H12: 부탄가스
A13: 매출누계 | C13: =SUM('1:18'!$C$12) -> 126 | F13: =SUM('1:18'!$F$12) -> 125 | H13: 코카콜라음료
A14: 개수 | B14: 삼겹살 | C14: 18 | D14: 돼지양념갈비 | F14: 13 | H14: 깍두기,계란
A15: 매출누계 | C15: =SUM('1:18'!$C$14) -> 400 | F15: =SUM('1:18'!$F$14) -> 197 | H15: 식자재2 | I15: =7500+34000+20000+19200+5500+7800+6200+21000+7200+11800 -> 140200 | J15: 비품 및 기타경비
A16: 개수 | B16: 육회 | C16: 3 | D16: 한우업진살 | F16: 7 | J16: 인터넷 주문
A17: 매출누계 | C17: =SUM('1:18'!$C$16) -> 94 | F17: =SUM('1:18'!$F$16) -> 146 | H17: 막걸리 | J17: 다이소 구매
A18: 개수 | B18: 소갈비살 | C18: 10 | D18: LA양념갈비 | F18: 6
A19: 매출누계 | C19: =SUM('1:18'!$C$18) -> 238 | F19: =SUM('1:18'!$F$18) -> 84
D20: 테이블수 | F20: 53
D21: 누적테이블 | F21: =SUM('1:18'!$F$20) -> 1164
A22: 중간출금
A23: 출금내역 | H23: 식자재합계 | I23: =SUM(I4:I22) -> 2352381 | J23: 기타경비합계 | K23: =SUM(K4:K22) -> 132500 | M23: 현금합계 | N23: =C5+C6 -> 547500
A24: 일매출 | C24: 일평균매출 | E24: 누적총매출 | H24: 일매출 | I24: =I23/A25 -> 0.61459987 | J24: 일매출 | K24: =K23/A25 -> 0.034617897
A25: =C2 -> 3827500 | C25: =E25/I1 -> 4916933.3 | E25: =SUM('1:18'!$A$25) -> 88504800 | H25: 누계 | I25: =SUM('1'!$I$23) -> 1925001 | J25: 누계 | K25: =SUM('1:18'!$K$21) -> 0
A26: 전 월 | H26: 누적매출 | I26: =I25/$E$25 -> 0.021750244 | J26: 누적매출 | K26: =K25/$E$25 -> 0
A27: 인 건 비 | B27: 직원A | C27: =3300000/31 -> 106451.61 | E27: 알바C | F27: =13000*4.5 -> 58500 | H27: 인건비합계 | I27: =SUM(C27:D34,F27:G32) -> 614322.58
E28: 직원F | F28: =1500000/31 -> 48387.097 | H28: 일매출 | I28: =I27/$A$25 -> 0.16050231
B29: 직원D | C29: =3300000/31 -> 106451.61 | E29: 알바X | H29: 누계 | I29: =SUM('1:18'!$I$25) -> 34650018
E30: 알바X | H30: 누적매출 | I30: =I29/$I$27 -> 56.403621
B31: 직원C | C31: =4000000/31 -> 129032.26 | E31: 파출 | F31: 120000
B32: 알바X | E32: 홀 파출
B33: 알바B | C33: =13000*3.5 -> 45500
B34: 알바X

Sheet 19
C1: 2025년 | E1: 11월 | F1: 19 | G1: 수 | H1: 실영업일수 | I1: =F1-K1 -> 19 | J1: 휴무일수
A2: 매출 | C2: =SUM(C4:D7) -> 4270000 | E2: 시재 | G2: 156600 | H2: 식자재 | J2: 비품 및 기타경비
H3: 업체 | I3: 금액 | J3: 업체 | K3: 금액
A4: 카드 | C4: 3446000 | E4: 카드수수료(2.75%) | G4: =INT(C4*0.0275) -> 94765 | H4: 고기 | I4: =554343+545216+452000+221000+458328 -> 2230887 | J4: 숯
A5: 현금 | C5: 824000 | E5: 현금수수료(1%) | G5: =INT(C5*0.01) -> 8240 | H5: 식자재 | I5: =50000+69000+36000+60500+3100+25840+30160+17760+26675+39490+59312+44000 -> 461837
A6: 페이결제 | E6: 통장입금 | G6: 900000 | J6: 음식물스티커
H7: 주류 | J7: 종량제봉투
A8: 금고 실잔액 | C8: 80600 | E8: 마감잔금 | G8: =C5+G2-G6-C22 -> 80600 | H8: 쌀 | I8: 65000
J9: 뚝배기
A10: 현금할인 | C10: =54000+60000 -> 114000 | E10: 카드할인 | J10: 발매트
A11: 할인내역 | C11: 슈퍼멤버스 | H11: 참기름 | J11: 불판세척
A12: 개수 | B12: 목살 | C12: 4 | D12: LA갈비 | F12: 4 | H12: 부탄가스
A13: 매출누계 | C13: =SUM('1:19'!$C$12) -> 130 | F13: =SUM('1:19'!$F$12) -> 129 | H13: 코카콜라음료
A14: 개수 | B14: 삼겹살 | C14: 16 | D14: 돼지양념갈비 | F14: 10 | H14: 깍두기,계란
A15: 매출누계 | C15: =SUM('1:19'!$C$14) -> 416 | F15: =SUM('1:19'!$F$14) -> 207 | H15: 식자재2 | I15: =13600+5500+5900+52000+3500+4600 -> 85100 | J15: 비품 및 기타경비
A16: 개수 | B16: 육회 | C16: 3 | D16: 한우업진살 | F16: 10 | J16: 인터넷 주문
A17: 매출누계 | C17: =SUM('1:19'!$C$16) -> 97 | F17: =SUM('1:19'!$F$16) -> 156 | H17: 막걸리 | J17: 다이소 구매
A18: 개수 | B18: 소갈비살 | C18: 26 | D18: LA양념갈비 | F18: 4
A19: 매출누계 | C19: =SUM('1:19'!$C$18) -> 264 | F19: =SUM('1:19'!$F$18) -> 88
D20: 테이블수 | F20: 60
D21: 누적테이블 | F21: =SUM('1:19'!$F$20) -> 1224
A22: 중간출금
A23: 출금내역 | H23: 식자재합계 | I23: =SUM(I4:I22) -> 2842824 | J23: 기타경비합계 | K23: =SUM(K4:K22) -> 0 | M23: 현금합계 | N23: =C5+C6 -> 824000
A24: 일매출 | C24: 일평균매출 | E24: 누적총매출 | H24: 일매출 | I24: =I23/A25 -> 0.66576674 | J24: 일매출 | K24: =K23/A25 -> 0
A25: =C2 -> 4270000 | C25: =E25/I1 -> 4882884.2 | E25: =SUM('1:19'!$A$25) -> 92774800 | H25: 누계 | I25: =SUM('1'!$I$23) -> 1925001 | J25: 누계 | K25: =SUM('1:18'!$K$21) -> 0
A26: 전 월 | H26: 누적매출 | I26: =I25/$E$25 -> 0.02074918 | J26: 누적매출 | K26: =K25/$E$25 -> 0
A27: 인 건 비 | B27: 직원A | C27: =3300000/31 -> 106451.61 | E27: 알바C | F27: =13000*5 -> 65000 | H27: 인건비합계 | I27: =SUM(C27:D34,F27:G32) -> 627322.58
E28: 직원F | F28: =1500000/31 -> 48387.097 | H28: 일매출 | I28: =I27/$A$25 -> 0.14691395
B29: 직원D | C29: =3300000/31 -> 106451.61 | E29: 알바X | H29: 누계 | I29: =SUM('1:18'!$I$25) -> 34650018
E30: 알바X | H30: 누적매출 | I30: =I29/$I$27 -> 55.234769
B31: 직원C | C31: =4000000/31 -> 129032.26 | E31: 파출 | F31: 120000
B32: 알바X | E32: 홀 파출
B33: 알바B | C33: =13000*4 -> 52000
B34: 알바X

Sheet 20
C1: 2025년 | E1: 11월 | F1: 20 | G1: 목 | H1: 실영업일수 | I1: =F1-K1 -> 20 | J1: 휴무일수
A2: 매출 | C2: =SUM(C4:D7) -> 5755500 | E2: 시재 | G2: 80600 | H2: 식자재 | J2: 비품 및 기타경비
H3: 업체 | I3: 금액 | J3: 업체 | K3: 금액
A4: 카드 | C4: 5083500 | E4: 카드수수료(2.75%) | G4: =INT(C4*0.0275) -> 139796 | H4: 고기 | I4: =290036+313986+56220+439200+452000+221000+486720+183939+10 -> 2443111 | J4: 숯
A5: 현금 | C5: 672000 | E5: 현금수수료(1%) | G5: =INT(C5*0.01) -> 6720 | H5: 식자재 | I5: =50000+34500+36000+33440+6460+25840+39380 -> 225620
A6: 페이결제 | E6: 통장입금 | G6: 600000 | J6: 음식물스티커
H7: 주류 | J7: 종량제봉투
A8: 금고 실잔액 | C8: 152600 | E8: 마감잔금 | G8: =C5+G2-G6-C22 -> 152600 | H8: 쌀
J9: 뚝배기
A10: 현금할인 | E10: 카드할인 | J10: 발매트
A11: 할인내역 | H11: 참기름 | J11: 불판세척
A12: 개수 | B12: 목살 | C12: 4 | D12: LA갈비 | F12: 2 | H12: 부탄가스
A13: 매출누계 | C13: =SUM('1:20'!$C$12) -> 134 | F13: =SUM('1:20'!$F$12) -> 131 | H13: 코카콜라음료
A14: 개수 | B14: 삼겹살 | C14: 7 | D14: 돼지양념갈비 | F14: 17 | H14: 깍두기,계란
A15: 매출누계 | C15: =SUM('1:20'!$C$14) -> 423 | F15: =SUM('1:20'!$F$14) -> 224 | H15: 식자재2 | I15: =27200+11800+6200+4500+3500+4200+5500+7500+14500+3360+17600 -> 105860 | J15: 비품 및 기타경비
A16: 개수 | B16: 육회 | C16: 5 | D16: 한우업진살 | F16: 14 | J16: 인터넷 주문
A17: 매출누계 | C17: =SUM('1:20'!$C$16) -> 102 | F17: =SUM('1:20'!$F$16) -> 170 | H17: 막걸리 | J17: 다이소 구매
A18: 개수 | B18: 소갈비살 | C18: 19 | D18: LA양념갈비 | F18: 5
A19: 매출누계 | C19: =SUM('1:20'!$C$18) -> 283 | F19: =SUM('1:20'!$F$18) -> 93
D20: 테이블수 | F20: 58
D21: 누적테이블 | F21: =SUM('1:20'!$F$20) -> 1282
A22: 중간출금
A23: 출금내역 | H23: 식자재합계 | I23: =SUM(I4:I22) -> 2774591 | J23: 기타경비합계 | K23: =SUM(K4:K22) -> 0 | M23: 현금합계 | N23: =C5+C6 -> 672000
A24: 일매출 | C24: 일평균매출 | E24: 누적총매출 | H24: 일매출 | I24: =I23/A25 -> 0.48207645 | J24: 일매출 | K24: =K23/A25 -> 0
A25: =C2 -> 5755500 | C25: =E25/I1 -> 4926515 | E25: =SUM('1:20'!$A$25) -> 98530300 | H25: 누계 | I25: =SUM('1'!$I$23) -> 1925001 | J25: 누계 | K25: =SUM('1:20'!$K$21) -> 0
A26: 전 월 | H26: 누적매출 | I26: =I25/$E$25 -> 0.019537147 | J26: 누적매출 | K26: =K25/$E$25 -> 0
A27: 인 건 비 | B27: 직원A | C27: =3300000/31 -> 106451.61 | E27: 알바C | F27: =13000*5 -> 65000 | H27: 인건비합계 | I27: =SUM(C27:D34,F27:G32) -> 627322.58
E28: 직원F | F28: =1500000/31 -> 48387.097 | H28: 일매출 | I28: =I27/$A$25 -> 0.10899532
B29: 직원D | C29: =3300000/31 -> 106451.61 | E29: 알바X | H29: 누계 | I29: =SUM('1:20'!$I$25) -> 38500020
E30: 알바X | H30: 누적매출 | I30: =I29/$I$27 -> 61.371966
B31: 직원C | C31: =4000000/31 -> 129032.26 | E31: 파출 | F31: 120000
B32: 알바X | E32: 홀 파출
B33: 알바B | C33: =13000*4 -> 52000
B34: 알바X

Sheet 21
C1: 2025년 | E1: 11월 | F1: 21 | G1: 금 | H1: 실영업일수 | I1: =F1-K1 -> 21 | J1: 휴무일수
A2: 매출 | C2: =SUM(C4:D7) -> 5110500 | E2: 시재 | G2: 152600 | H2: 식자재 | J2: 비품 및 기타경비
H3: 업체 | I3: 금액 | J3: 업체 | K3: 금액
A4: 카드 | C4: 4538500 | E4: 카드수수료(2.75%) | G4: =INT(C4*0.0275) -> 124808 | H4: 고기 | I4: =237276+221000+180712 -> 638988 | J4: 숯
A5: 현금 | C5: 572000 | E5: 현금수수료(1%) | G5: =INT(C5*0.01) -> 5720 | H5: 식자재 | I5: =50000+69000+36000+39380 -> 194380
A6: 페이결제 | E6: 통장입금 | G6: 650000 | J6: 음식물스티커
H7: 주류 | J7: 종량제봉투
A8: 금고 실잔액 | C8: 74600 | E8: 마감잔금 | G8: =C5+G2-G6-C22 -> 74600 | H8: 쌀 | I8: 130000
J9: 뚝배기
A10: 현금할인 | E10: 카드할인 | J10: 발매트
A11: 할인내역 | H11: 참기름 | J11: 불판세척
A12: 개수 | B12: 목살 | C12: 14 | D12: LA갈비 | F12: 4 | H12: 부탄가스
A13: 매출누계 | C13: =SUM('1:21'!$C$12) -> 148 | F13: =SUM('1:21'!$F$12) -> 135 | H13: 코카콜라음료
A14: 개수 | B14: 삼겹살 | C14: 40 | D14: 돼지양념갈비 | F14: 12 | H14: 깍두기,계란
A15: 매출누계 | C15: =SUM('1:21'!$C$14) -> 463 | F15: =SUM('1:21'!$F$14) -> 236 | H15: 식자재2 | I15: =9800+54400+11800+9600+5500+8700+10500 -> 110300 | J15: 비품 및 기타경비
A16: 개수 | B16: 육회 | C16: 4 | D16: 한우업진살 | F16: 2 | J16: 인터넷 주문
A17: 매출누계 | C17: =SUM('1:21'!$C$16) -> 106 | F17: =SUM('1:21'!$F$16) -> 172 | H17: 막걸리 | J17: 다이소 구매
A18: 개수 | B18: 소갈비살 | C18: 11 | D18: LA양념갈비 | F18: 5
A19: 매출누계 | C19: =SUM('1:21'!$C$18) -> 294 | F19: =SUM('1:21'!$F$18) -> 98
D20: 테이블수 | F20: 72
D21: 누적테이블 | F21: =SUM('1:21'!$F$20) -> 1354
A22: 중간출금
A23: 출금내역 | H23: 식자재합계 | I23: =SUM(I4:I22) -> 1073668 | J23: 기타경비합계 | K23: =SUM(K4:K22) -> 0 | M23: 현금합계 | N23: =C5+C6 -> 572000
A24: 일매출 | C24: 일평균매출 | E24: 누적총매출 | H24: 일매출 | I24: =I23/A25 -> 0.2100906 | J24: 일매출 | K24: =K23/A25 -> 0
A25: =C2 -> 5110500 | C25: =E25/I1 -> 4935276.2 | E25: =SUM('1:21'!$A$25) -> 103640800 | H25: 누계 | I25: =SUM('1'!$I$23) -> 1925001 | J25: 누계 | K25: =SUM('1:21'!$K$21) -> 0
A26: 전 월 | H26: 누적매출 | I26: =I25/$E$25 -> 0.018573776 | J26: 누적매출 | K26: =K25/$E$25 -> 0
A27: 인 건 비 | B27: 직원A | C27: =3300000/31 -> 106451.61 | E27: 알바C | F27: =13000*5 -> 65000 | H27: 인건비합계 | I27: =SUM(C27:D34,F27:G32) -> 640322.58
E28: 직원F | F28: =1500000/31 -> 48387.097 | H28: 일매출 | I28: =I27/$A$25 -> 0.12529549
B29: 직원D | C29: =3300000/31 -> 106451.61 | E29: 알바X | H29: 누계 | I29: =SUM('1:21'!$I$25) -> 40425021
E30: 알바X | F30: =13000*5 -> 65000 | H30: 누적매출 | I30: =I29/$I$27 -> 63.132275
B31: 직원C | C31: =4000000/31 -> 129032.26 | E31: 파출 | F31: 120000
B32: 알바X | E32: 홀 파출
B33: 알바B
B34: 알바X

Sheet 22
C1: 2025년 | E1: 11월 | F1: 22 | G1: 토 | H1: 실영업일수 | I1: =F1-K1 -> 22 | J1: 휴무일수
A2: 매출 | C2: =SUM(C4:D7) -> 4437000 | E2: 시재 | G2: 74600 | H2: 식자재 | J2: 비품 및 기타경비
H3: 업체 | I3: 금액 | J3: 업체 | K3: 금액
A4: 카드 | C4: 3967000 | E4: 카드수수료(2.75%) | G4: =INT(C4*0.0275) -> 109092 | H4: 고기 | I4: =287212+452000+229164+221000+177485 -> 1366861 | J4: 숯
A5: 현금 | C5: 470000 | E5: 현금수수료(1%) | G5: =INT(C5*0.01) -> 4700 | H5: 식자재
A6: 페이결제 | E6: 통장입금 | G6: 450000 | J6: 음식물스티커
H7: 주류 | J7: 종량제봉투
A8: 금고 실잔액 | C8: 94600 | E8: 마감잔금 | G8: =C5+G2-G6-C22 -> 94600 | H8: 쌀
J9: 뚝배기
A10: 현금할인 | C10: 58000 | E10: 카드할인 | J10: 발매트
A11: 할인내역 | C11: 이수진 슈퍼멤버스 블랙 58,000원 | H11: 참기름 | J11: 불판세척
A12: 개수 | B12: 목살 | C12: 7 | D12: LA갈비 | F12: 6 | H12: 부탄가스
A13: 매출누계 | C13: =SUM('1:22'!$C$12) -> 155 | F13: =SUM('1:22'!$F$12) -> 141 | H13: 코카콜라음료
A14: 개수 | B14: 삼겹살 | C14: 28 | D14: 돼지양념갈비 | F14: 6 | H14: 깍두기,계란
A15: 매출누계 | C15: =SUM('1:22'!$C$14) -> 491 | F15: =SUM('1:22'!$F$14) -> 242 | H15: 식자재2 | I15: =44000+14700+54400+7200+11000+15500+5500+26400+27000+28000 -> 233700 | J15: 비품 및 기타경비
A16: 개수 | B16: 육회 | C16: 9 | D16: 한우업진살 | F16: 8 | J16: 인터넷 주문
A17: 매출누계 | C17: =SUM('1:22'!$C$16) -> 115 | F17: =SUM('1:22'!$F$16) -> 180 | H17: 막걸리 | J17: 다이소 구매 | K17: 2800
A18: 개수 | B18: 소갈비살 | C18: 19 | D18: LA양념갈비 | F18: 7
A19: 매출누계 | C19: =SUM('1:22'!$C$18) -> 313 | F19: =SUM('1:22'!$F$18) -> 105
D20: 테이블수 | F20: 52
D21: 누적테이블 | F21: =SUM('1:22'!$F$20) -> 1406
A22: 중간출금
A23: 출금내역 | H23: 식자재합계 | I23: =SUM(I4:I22) -> 1600561 | J23: 기타경비합계 | K23: =SUM(K4:K22) -> 2800 | M23: 현금합계 | N23: =C5+C6 -> 470000
A24: 일매출 | C24: 일평균매출 | E24: 누적총매출 | H24: 일매출 | I24: =I23/A25 -> 0.36073045 | J24: 일매출 | K24: =K23/A25 -> 0.00063105702
A25: =C2 -> 4437000 | C25: =E25/I1 -> 4912627.3 | E25: =SUM('1:22'!$A$25) -> 108077800 | H25: 누계 | I25: =SUM('1'!$I$23) -> 1925001 | J25: 누계 | K25: =SUM('1:22'!$K$21) -> 0
A26: 전 월 | H26: 누적매출 | I26: =I25/$E$25 -> 0.017811253 | J26: 누적매출 | K26: =K25/$E$25 -> 0
A27: 인 건 비 | B27: 직원A | C27: =3300000/31 -> 106451.61 | E27: 알바C | H27: 인건비합계 | I27: =SUM(C27:D34,F27:G32) -> 797522.58
E28: 직원F | F28: =1500000/31 -> 48387.097 | H28: 일매출 | I28: =I27/$A$25 -> 0.17974365
B29: 직원D | C29: =3300000/31 -> 106451.61 | E29: 알바X | H29: 누계 | I29: =SUM('1:22'!$I$25) -> 42350022
E30: 알바X | H30: 누적매출 | I30: =I29/$I$27 -> 53.101972
B31: 직원C | C31: =4000000/31 -> 129032.26 | E31: 파출 | F31: 130000
B32: 알바X | C32: =11700*6 -> 70200 | E32: 홀 파출 | F32: 77000
B33: 알바B | C33: =13000*10 -> 130000
B34: 알바X

Sheet 23
C1: 2025년 | E1: 11월 | F1: 23 | G1: 일 | H1: 실영업일수 | I1: =F1-K1 -> 23 | J1: 휴무일수
A2: 매출 | C2: =SUM(C4:D7) -> 6148000 | E2: 시재 | G2: 94600 | H2: 식자재 | J2: 비품 및 기타경비
H3: 업체 | I3: 금액 | J3: 업체 | K3: 금액
A4: 카드 | C4: 5340000 | E4: 카드수수료(2.75%) | G4: =INT(C4*0.0275) -> 146850 | H4: 고기 | J4: 숯
