Workbook

Sheet 월합산
A1: 월 합 산
A2: 매출 | C2: =C3+G3+C5 -> 0 | E2: 시제 | H2: 비 고
A3: 카드매출 | C3: =SUM('1'!C3) -> 0 | E3: 현금매출 | G3: =SUM('1'!G3) -> 0
A4: 금고잔액 | C4: =C21 -> 0 | E4: 입금 | G4: =C17 -> 0
A5: 할인금액 | C5: =C6+G6 -> 0 | E5: 잔금 | G5: =C4-G4 -> 0
A6: 현금할인 | C6: =SUM('1'!C7) -> 0 | E6: 카드할인 | G6: =SUM('1'!G7) -> 0
A7: 할인내역
H8: take out | I8: 매출누계 | K8: =SUM('1'!K9) -> 0
H9: 배달 | I9: 매출누계 | K9: =SUM('1'!K10) -> 0
I10: 배달료누계 | K10: =SUM('1'!K11) -> 15714.286
A11: 중간출금 | H11: 중간입금
A12: 출금내역 | H12: 입금내역
A13: 영업일수 | C13: 일평균매출 | E13: 누적총매출 | H13: 목표일매출 | J13: 목표월매출
A14: =C2 -> 0 | C14: =ROUNDDOWN((E14/A14),-4) -> #DIV/0! | E14: =C2 -> 0
A15: 전 월
A16: 마 감 잔 금 | G16: 마 감 잔 금
A17: 만 | G17: 만
A18: 천 | G18: 천
A19: 오백 | G19: 오백
A20: 백이하 | G20: 백이하
A21: 합계 | C21: =SUM(C17:E20) -> 0 | G21: 합계 | H21: =SUM(H17:K20) -> 0

Sheet 결산
E1: 2월
A4: 고정비용 | F4: 변동비용
A5: 항목 | D5: 항목별 소계 | E5: 매출대비 비율 | F5: 항목 | G5: 업체 | H5: 금액 | J5: 항목별 소계 | M5: 통장입금 | N5: =SUM('1:28'!G6) -> 12150500
A6: 월세 | C6: 6985000 | D6: =C6 -> 6985000 | E6: =D6/$B$45 -> 0.063289992 | F6: 식자재 | G6: 고기 | H6: =SUM('1:28'!I4) -> 27944029 | I6: =H6/$B$45 -> 0.25319648 | J6: =SUM(H6:H18) -> 39871805 | K6: =J6/$B$45 -> 0.36127219
A7: 마케팅 | C7: 2600000 | D7: =C7 -> 2600000 | E7: =D7/$B$45 -> 0.023558193 | G7: 식자재 | H7: =SUM('1:28'!I5) -> 3952626 | I7: =H7/$B$45 -> 0.035814126 | M7: 생갈비 | N7: =SUM('28'!C15) -> 1183
A8: 포스 | C8: 154000 | D8: =C8 -> 154000 | E8: =D8/$B$45 -> 0.0013953699 | G8: 주류 | H8: =SUM('1:28'!I7) -> 3070250 | I8: =H8/$B$45 -> 0.027819055 | M8: 목살 | N8: =SUM('28'!C13) -> 358
A9: 수도 | C9: 670000 | D9: =C9 -> 670000 | E9: =D9/$B$45 -> 0.0060707652 | G9: 쌀 | H9: =SUM('1:28'!I8) -> 670000 | I9: =H9/$B$45 -> 0.0060707652 | M9: 육회 | N9: =SUM('28'!C17) -> 194
A10: 화재보험 | C10: 66000 | D10: =C10 -> 66000 | E10: =D10/$B$45 -> 0.00059801568 | G10: 참기름 | H10: =SUM('1:28'!I11) -> 300000 | I10: =H10/$B$45 -> 0.0027182531 | M10: LA갈비 | N10: =SUM('28'!F13) -> 240
A11: 세무사 | C11: 330000 | D11: =C11 -> 330000 | E11: =D11/$B$45 -> 0.0029900784 | G11: 부탄가스 | H11: =SUM('1:28'!I12) -> 0 | I11: =H11/$B$45 -> 0 | M11: 돼지양념갈비 | N11: =SUM('28'!F15) -> 481
A12: 인터넷 | C12: 48000 | D12: =C12 -> 48000 | E12: =D12/$B$45 -> 0.00043492049 | G12: 코카콜라 | H12: =SUM('1:28'!I13) -> 240000 | I12: =H12/$B$45 -> 0.0021746025 | M12: 한우업진살 | N12: =SUM('28'!F17) -> 389
A13: 쿠쿠(블루문) | C13: 66000 | D13: =C13 -> 66000 | E13: =D13/$B$45 -> 0.00059801568 | G13: 깍두기,계란 | H13: =SUM('1:28'!I14) -> 0 | I13: =H13/$B$45 -> 0 | M13: 소갈비살 | N13: =SUM('28'!C19) -> 897
D14: =C14 -> 0 | E14: =D14/$B$45 -> 0 | G14: 막걸리 | H14: =SUM('1:28'!I17) -> 16500 | I14: =H14/$B$45 -> 0.00014950392 | M14: LA양념갈비 | N14: =SUM('28'!F19) -> 333
D15: =C15 -> 0 | E15: =D15/$B$45 -> 0 | G15: 식자재2 | H15: =SUM('1:28'!I15) -> 3678400 | I15: =H15/$B$45 -> 0.033329407 | M15: 2월 테이블수 | N15: =SUM('28'!F21) -> 1513
A16: 전기세 | C16: 1191660 | D16: =C16 -> 1191660 | E16: =D16/$B$45 -> 0.010797445
A17: 가스비 | C17: 1445570 | D17: =C17 -> 1445570 | E17: =D17/$B$45 -> 0.013098084
A18: 소 계 | C18: =SUM(D6:D17) -> 13556230 | E18: =SUM(E6:E17) -> 0.12283088
A19: 급여 | B19: 직원A | C19: 4000000 | D19: =SUM(C19:C30) -> 23529000 | E19: =D19/$B$45 -> 0.21319259 | F19: 비품 및 기타경비 | G19: 숯 | H19: =SUM('1:28'!K4) -> 1651000 | I19: =H19/$B$45 -> 0.014959453 | J19: =SUM(H19:H32) -> 3821959 | K19: =J19/$B$45 -> 0.034630173
B20: 직원B | C20: 3800000 | G20: 음식물스티커 | H20: =SUM('1:28'!K6) -> 84000 | I20: =H20/$B$45 -> 0.00076111086
B21: 직원C | C21: 3500000 | G21: 종량재봉투 | H21: =SUM('1:28'!K7) -> 37500 | I21: =H21/$B$45 -> 0.00033978163
B22: 직원D | C22: 3200000 | G22: 뚝배기 | H22: =SUM('1:28'!K9) -> 117000 | I22: =H22/$B$45 -> 0.0010601187
B23: 직원E | C23: 3400000 | G23: 발매트 | H23: =SUM('1:28'!K10) -> 25000 | I23: =H23/$B$45 -> 0.00022652109
G24: 불판세척 | H24: =SUM('1:28'!K11) -> 440000 | I24: =H24/$B$45 -> 0.0039867712
B25: 알바A | C25: =SUM('1:28'!C31) -> 448000 | G25: 비품 및 기타경비 | H25: =SUM('1:28'!K15) -> 6200 | I25: =H25/$B$45 -> 5.617723e-05
G26: 인터넷 주문 | H26: =SUM('1:28'!K16) -> 1418759 | I26: =H26/$B$45 -> 0.012855153
G27: 다이소 구매 | H27: =SUM('1:28'!K17) -> 42500 | I27: =H27/$B$45 -> 0.00038508585
B28: 알바X | C28: =SUM('1:28'!F27)+SUM('1:28'!F28)+SUM('1:28'!F29) -> 1599000
B29: 홀파출 | C29: =SUM('1:28'!F31) -> 132000
B30: 파출 | C30: =SUM('1:28'!F30) -> 3450000
B31: 합계 | C31: =SUM(C19:C30) -> 23529000
A32: 퇴직금(10%) | C32: =SUM(C19:C24)*0.1 -> 1790000 | D32: =C32 -> 1790000 | E32: =(D32:D33)/$B$45 -> 0.01621891
A33: 4대보험료 | D33: =C33 -> 0 | F33: 현금수수료 (1%) | H33: =SUM('1:28'!$G$5) -> 112922 | J33: =H33 -> 112922 | K33: =J33/$B$45 -> 0.0010231686
A34: 소 계 | C34: =SUM(C6:D17,C19:C24,C32:C33) -> 46802460 | E34: =SUM(E19:E33) -> 0.2294115 | F34: 카드수수료(2.75%) | H34: =SUM('1:28'!$G$4) -> 2702765.5 | J34: =H34 -> 2702765.5 | K34: =J34/$B$45 -> 0.024489335
A35: 합 계 | E35: =E18+E34 -> 0.35224238 | H35: =SUM(J6:J34) -> 46509452 | K35: =SUM(K6:K34) -> 0.42141486
A38: 항목 | B38: 금액 | C38: 항목 비율 | D38: 매출 비율 | F38: 손익분기점
A39: 고정비용 | B39: =$C$34 -> 46802460 | C39: =B39/$B$41 -> 0.50157005 | D39: =B39/$B$45 -> 0.42406977 | F39: 손익분기점 매출액 X
A40: 변동비용 | B40: =$H$35 -> 46509452 | C40: =B40/$B$41 -> 0.49842995 | D40: =B40/$B$45 -> 0.42141486 | F40: 고정비 | H40: F | K40: =$C$34 -> 46802460
A41: 총비용 | B41: =SUM(B39:B40) -> 93311912 | C41: =SUM(C39:C40) -> 1 | D41: =SUM(D39:D40) -> 0.84548463 | F41: 변동비 | H41: V | K41: =$H$35 -> 46509452
A42: 카드매출 | B42: =SUM('1:28'!C4) -> 98282750 | D42: =B42/$B$45 -> 0.89052462 | F42: 매출액 | H42: S | K42: =$B$45 -> 110365000
A43: 현금매출 | B43: =SUM('1:28'!C5) -> 12082250 | D43: =B43/$B$45 -> 0.10947538 | F43: 변동비율 | H43: V/S | K43: =(K41)/K42 -> 0.42141486
A44: 페이매출 | B44: =SUM('1:28'!C6) -> 0 | D44: =B44/$B$45 -> 0 | F44: 손익분기점 매출액 | H44: X=F/(1-(V/S)) | K44: =K40/(1-K43) -> 80891224
...

Sheet 1
C1: 2025년 | E1: 2월 | F1: 1 | G1: 토 | H1: 실영업일수 | I1: =F1-K1 -> 1 | J1: 휴무일수
A2: 매출 | C2: =SUM(C4:D7) -> 4665000 | E2: 시재 | G2: 156600 | H2: 식자재 | J2: 비품 및 기타경비
H3: 업체 | I3: 금액 | J3: 업체 | K3: 금액
A4: 카드 | C4: 3381000 | E4: 카드수수료(2.75%) | G4: =INT(C4*0.0275) -> 92977 | H4: 고기 | I4: =588101+445200+549666+831000+207102 -> 2621069 | J4: 숯
A5: 현금 | C5: 1284000 | E5: 현금수수료(1%) | G5: =INT(C5*0.01) -> 12840 | H5: 식자재
A6: 페이결제 | E6: 통장입금 | G6: 1300000 | J6: 음식물스티커
H7: 주류 | J7: 종량제봉투
A8: 금고 실잔액 | C8: 140600 | E8: 마감잔금 | G8: =C5+G2-G6-C22 -> 140600 | H8: 쌀
J9: 뚝배기
A10: 현금할인 | E10: 카드할인 | J10: 발매트
A11: 할인내역 | H11: 참기름 | J11: 불판세척 | K11: =440000/28 -> 15714.286
A12: 개수 | B12: 목살 | C12: 12 | D12: LA갈비 | F12: 12 | H12: 부탄가스
A13: 매출누계 | C13: =SUM('1'!$C$12) -> 12 | F13: =SUM('1'!$F$12) -> 12 | H13: 코카콜라음료
A14: 개수 | B14: 생갈비 | C14: 33 | D14: 돼지양념갈비 | F14: 17 | H14: 깍두기,계란
A15: 매출누계 | C15: =SUM('1'!$C$14) -> 33 | F15: =SUM('1'!$F$14) -> 17 | H15: 식자재2 | I15: =13000+11000+51000+22000+5500+38400+13500+91500+27500+8500+11000+11800+6600+2500+29400+11000+2200+10800+4900+8900+26500 -> 407500 | J15: 비품 및 기타경비
A16: 개수 | B16: 육회 | C16: 9 | D16: 한우업진살 | F16: 34 | J16: 인터넷 주문 | K16: 99071
A17: 매출누계 | C17: =SUM('1'!$C$16) -> 9 | F17: =SUM('1'!$F$16) -> 34 | H17: 막걸리 | I17: 1700 | J17: 다이소 구매
A18: 개수 | B18: 소갈비살 | C18: 65 | D18: LA양념갈비 | F18: 17
A19: 매출누계 | C19: =SUM('1'!$C$18) -> 65 | F19: =SUM('1'!$F$18) -> 17
A20: 개수 | D20: 테이블수 | F20: 62
A21: 매출누계 | D21: 누적테이블 | F21: =SUM('1'!$F$20) -> 62
A22: 중간출금
A23: 출금내역 | H23: 식자재합계 | I23: =SUM(I4:I22) -> 3030269 | J23: 기타경비합계 | K23: =SUM(K4:K22) -> 114785.29 | M23: 현금합계 | N23: =C5+C6 -> 1284000
A24: 일매출 | C24: 일평균매출 | E24: 누적총매출 | H24: 일매출 | I24: =I23/A25 -> 0.64957535 | J24: 일매출 | K24: =K23/A25 -> 0.024605635
A25: =C2 -> 4665000 | C25: =E25/I1 -> 4665000 | E25: =SUM('1'!$A$25) -> 4665000 | H25: 누계 | I25: =SUM('1'!$I$23) -> 3030269 | J25: 누계 | K25: =SUM('1'!$K$23) -> 114785.29
A26: 전 월 | H26: 누적매출 | I26: =I25/$E$25 -> 0.64957535 | J26: 누적매출 | K26: =K25/$E$25 -> 0.024605635
A27: 인 건 비 | B27: 직원A | C27: =4000000/28 -> 142857.14 | E27: 알바X | H27: 인건비합계 | I27: =SUM(C27:D34,F27:G30) -> 866235.71
B28: 직원B | C28: =3800000/28 -> 135714.29 | E28: 알바X | H28: 일매출 | I28: =I27/$A$25 -> 0.18568826
B29: 직원D | C29: =3200000/28 -> 114285.71 | E29: 알바X | F29: =11700*3.5 -> 40950 | H29: 누계 | I29: =SUM('1'!$I$27) -> 866235.71
B30: 직원E | C30: =3400000/28 -> 121428.57 | E30: 파출 | F30: 130000 | H30: 누적매출 | I30: =I29/$I$27 -> 1
B31: 알바A | C31: =14000*4 -> 56000
B33: 직원C | C33: =3500000/28 -> 125000

Sheet 2
C1: 2025년 | E1: 2월 | F1: 2 | G1: 일 | H1: 실영업일수 | I1: =F1-K1 -> 2 | J1: 휴무일수
A2: 매출 | C2: =SUM(C4:D7) -> 2765500 | E2: 시재 | G2: 140600 | H2: 식자재 | J2: 비품 및 기타경비
H3: 업체 | I3: 금액 | J3: 업체 | K3: 금액
A4: 카드 | C4: 2190500 | E4: 카드수수료(2.75%) | G4: =INT(C4*0.0275) -> 60238 | H4: 고기 | J4: 숯
A5: 현금 | C5: 575000 | E5: 현금수수료(1%) | G5: =INT(C5*0.01) -> 5750 | H5: 식자재
A6: 페이결제 | E6: 통장입금 | G6: 600000 | J6: 음식물스티커
H7: 주류 | J7: 종량제봉투
A8: 금고 실잔액 | C8: 115600 | E8: 마감잔금 | G8: =C5+G2-G6-C22 -> 115600 | H8: 쌀
J9: 뚝배기
A10: 현금할인 | E10: 카드할인 | J10: 발매트
A11: 할인내역 | H11: 참기름 | J11: 불판세척 | K11: =440000/28 -> 15714.286
A12: 개수 | B12: 목살 | C12: 6 | D12: LA갈비 | F12: 8 | H12: 부탄가스
A13: 매출누계 | C13: =SUM('1:2'!$C$12) -> 18 | F13: =SUM('1:2'!$F$12) -> 20 | H13: 코카콜라음료
A14: 개수 | B14: 생갈비 | C14: 49 | D14: 돼지양념갈비 | F14: 22 | H14: 깍두기,계란
A15: 매출누계 | C15: =SUM('1:2'!$C$14) -> 82 | F15: =SUM('1:2'!$F$14) -> 39 | H15: 식자재2 | J15: 비품 및 기타경비
A16: 개수 | B16: 육회 | C16: 6 | D16: 한우업진살 | F16: 8 | J16: 인터넷 주문 | K16: =132490+54000 -> 186490
A17: 매출누계 | C17: =SUM('1:2'!$C$16) -> 15 | F17: =SUM('1:2'!$F$16) -> 42 | H17: 막걸리 | J17: 다이소 구매
A18: 개수 | B18: 소갈비살 | C18: 14 | D18: LA양념갈비 | F18: 5
A19: 매출누계 | C19: =SUM('1:2'!$C$18) -> 79 | F19: =SUM('1:2'!$F$18) -> 22
D20: 테이블수 | F20: 40
D21: 누적테이블 | F21: =SUM('1:2'!$F$20) -> 102
A22: 중간출금
A23: 출금내역 | H23: 식자재합계 | I23: =SUM(I4:I22) -> 0 | J23: 기타경비합계 | K23: =SUM(K4:K22) -> 202204.29 | M23: 현금합계 | N23: =C5+C6 -> 575000
A24: 일매출 | C24: 일평균매출 | E24: 누적총매출 | H24: 일매출 | I24: =I23/A25 -> 0 | J24: 일매출 | K24: =K23/A25 -> 0.073116719
A25: =C2 -> 2765500 | C25: =E25/I1 -> 3715250 | E25: =SUM('1:2'!$A$25) -> 7430500 | H25: 누계 | I25: =SUM('1:2'!$I$23) -> 3030269 | J25: 누계 | K25: =SUM('1:2'!$K$23) -> 316989.57
A26: 전 월 | H26: 누적매출 | I26: =I25/$E$25 -> 0.40781495 | J26: 누적매출 | K26: =K25/$E$25 -> 0.042660598
A27: 인 건 비 | B27: 직원A | C27: =4000000/28 -> 142857.14 | E27: 알바X | H27: 인건비합계 | I27: =SUM(C27:D34,F27:G30) -> 814835.71
B28: 직원B | C28: =3800000/28 -> 135714.29 | E28: 알바X | H28: 일매출 | I28: =I27/$A$25 -> 0.29464318
B29: 직원D | C29: =3200000/28 -> 114285.71 | E29: 알바X | F29: =11700*1.5 -> 17550 | H29: 누계 | I29: =SUM('1:2'!$I$27) -> 1681071.4
B30: 직원E | C30: =3400000/28 -> 121428.57 | E30: 파출 | F30: 130000 | H30: 누적매출 | I30: =I29/$I$27 -> 2.0630802
B31: 알바A | C31: =14000*2 -> 28000
B33: 직원C | C33: =3500000/28 -> 125000

Sheet 3
C1: 2025년 | E1: 2월 | F1: 3 | G1: 월 | H1: 실영업일수 | I1: =F1-K1 -> 3 | J1: 휴무일수
A2: 매출 | C2: =SUM(C4:D7) -> 2237000 | E2: 시재 | G2: 115600 | H2: 식자재 | J2: 비품 및 기타경비
H3: 업체 | I3: 금액 | J3: 업체 | K3: 금액
A4: 카드 | C4: 2079000 | E4: 카드수수료(2.75%) | G4: =C4*0.0275 -> 57172.5 | H4: 고기 | J4: 숯
A5: 현금 | C5: 158000 | E5: 현금수수료(1%) | G5: =INT(C5*0.01) -> 1580 | H5: 식자재 | I5: =137200+51200+6000+88968+29100+36080 -> 348548
A6: 페이결제 | E6: 통장입금 | G6: 200000 | J6: 음식물스티커
H7: 주류 | I7: =58370-43600 -> 14770 | J7: 종량제봉투
A8: 금고 실잔액 | C8: 73600 | E8: 마감잔금 | G8: =C5+G2-G6-C22 -> 73600 | H8: 쌀 | I8: 55000
J9: 뚝배기
A10: 현금할인 | E10: 카드할인 | J10: 발매트 | K10: 6000
A11: 할인내역 | H11: 참기름 | J11: 불판세척 | K11: =440000/28 -> 15714.286
A12: 개수 | B12: 목살 | C12: 3 | D12: LA갈비 | F12: 6 | H12: 부탄가스
A13: 매출누계 | C13: =SUM('1:3'!$C$12) -> 21 | F13: =SUM('1:3'!$F$12) -> 26 | H13: 코카콜라음료
A14: 개수 | B14: 생갈비 | C14: 21 | D14: 돼지양념갈비 | F14: 2 | H14: 깍두기,계란
A15: 매출누계 | C15: =SUM('1:3'!$C$14) -> 103 | F15: =SUM('1:3'!$F$14) -> 41 | H15: 식자재2 | I15: =11800+3200+9800+18300+17400+21000 -> 81500 | J15: 비품 및 기타경비
A16: 개수 | B16: 육회 | C16: 2 | D16: 한우업진살 | F16: 0 | J16: 인터넷 주문 | K16: 45040
A17: 매출누계 | C17: =SUM('1:3'!$C$16) -> 17 | F17: =SUM('1:3'!$F$16) -> 42 | H17: 막걸리 | J17: 다이소 구매
A18: 개수 | B18: 소갈비살 | C18: 28 | D18: LA양념갈비 | F18: 7
A19: 매출누계 | C19: =SUM('1:3'!$C$18) -> 107 | F19: =SUM('1:3'!$F$18) -> 29
D20: 테이블수 | F20: 38
D21: 누적테이블 | F21: =SUM('1:3'!$F$20) -> 140
A22: 중간출금
A23: 출금내역 | H23: 식자재합계 | I23: =SUM(I4:I22) -> 499818 | J23: 기타경비합계 | K23: =SUM(K4:K22) -> 66754.286 | M23: 현금합계 | N23: =C5+C6 -> 158000
A24: 일매출 | C24: 일평균매출 | E24: 누적총매출 | H24: 일매출 | I24: =I23/A25 -> 0.22343228 | J24: 일매출 | K24: =K23/A25 -> 0.029840986
A25: =C2 -> 2237000 | C25: =E25/I1 -> 3222500 | E25: =SUM('1:3'!$A$25) -> 9667500 | H25: 누계 | I25: =SUM('1:3'!$I$23) -> 3530087 | J25: 누계 | K25: =SUM('1:3'!$K$23) -> 383743.86
A26: 전 월 | H26: 누적매출 | I26: =I25/$E$25 -> 0.36514994 | J26: 누적매출 | K26: =K25/$E$25 -> 0.039694218
A27: 인 건 비 | B27: 직원A | C27: =4000000/28 -> 142857.14 | E27: 알바X | F27: =13000*5 -> 65000 | H27: 인건비합계 | I27: =SUM(C27:D34,F27:G30) -> 850285.71
B28: 직원B | C28: =3800000/28 -> 135714.29 | E28: 알바X | F28: =13000*2 -> 26000 | H28: 일매출 | I28: =I27/$A$25 -> 0.3801009
B29: 직원D | C29: =3200000/28 -> 114285.71 | E29: 알바X | H29: 누계 | I29: =SUM('1:3'!$I$27) -> 2531357.1
B30: 직원E | C30: =3400000/28 -> 121428.57 | E30: 파출 | F30: 120000 | H30: 누적매출 | I30: =I29/$I$27 -> 2.9770665
B31: 알바A
B33: 직원C | C33: =3500000/28 -> 125000

Sheet 4
C1: 2025년 | E1: 2월 | F1: 4 | G1: 화 | H1: 실영업일수 | I1: =F1-K1 -> 4 | J1: 휴무일수
A2: 매출 | C2: =SUM(C4:D7) -> 4134000 | E2: 시재 | G2: 73600 | H2: 식자재 | J2: 비품 및 기타경비
H3: 업체 | I3: 금액 | J3: 업체 | K3: 금액
A4: 카드 | C4: 3193000 | E4: 카드수수료(2.75%) | G4: =INT(C4*0.0275) -> 87807 | H4: 고기 | I4: =415500+405000+219356+224568+445200+857298 -> 2566922 | J4: 숯
A5: 현금 | C5: 941000 | E5: 현금수수료(1%) | G5: =INT(C5*0.01) -> 9410 | H5: 식자재 | I5: =25600+10+51600+41250+59312+36080 -> 213852
A6: 페이결제 | E6: 통장입금 | G6: 900000 | J6: 음식물스티커
H7: 주류 | J7: 종량제봉투
A8: 금고 실잔액 | C8: 114100 | E8: 마감잔금 | G8: =C5+G2-G6-C22 -> 114100 | H8: 쌀
J9: 뚝배기
A10: 현금할인 | E10: 카드할인 | J10: 발매트
A11: 할인내역 | H11: 참기름 | J11: 불판세척 | K11: =440000/28 -> 15714.286
A12: 개수 | B12: 목살 | C12: 9 | D12: LA갈비 | F12: 8 | H12: 부탄가스
A13: 매출누계 | C13: =SUM('1:4'!$C$12) -> 30 | F13: =SUM('1:4'!$F$12) -> 34 | H13: 코카콜라음료
A14: 개수 | B14: 생갈비 | C14: 32 | D14: 돼지양념갈비 | F14: 28 | H14: 깍두기,계란
A15: 매출누계 | C15: =SUM('1:4'!$C$14) -> 135 | F15: =SUM('1:4'!$F$14) -> 69 | H15: 식자재2 | I15: =35000+11800+67100+3500+12000+5500 -> 134900 | J15: 비품 및 기타경비
A16: 개수 | B16: 육회 | C16: 6 | D16: 한우업진살 | F16: 12 | J16: 인터넷 주문 | K16: 77420
A17: 매출누계 | C17: =SUM('1:4'!$C$16) -> 23 | F17: =SUM('1:4'!$F$16) -> 54 | H17: 막걸리 | J17: 다이소 구매 | K17: 25500
A18: 개수 | B18: 소갈비살 | C18: 39 | D18: LA양념갈비 | F18: 20
A19: 매출누계 | C19: =SUM('1:4'!$C$18) -> 146 | F19: =SUM('1:4'!$F$18) -> 49
D20: 테이블수 | F20: 59
D21: 누적테이블 | F21: =SUM('1:4'!$F$20) -> 199
A22: 중간출금 | C22: 500
A23: 출금내역 | C23: 잔돈교환 (간식) 500원 | H23: 식자재합계 | I23: =SUM(I4:I22) -> 2915674 | J23: 기타경비합계 | K23: =SUM(K4:K22) -> 118634.29 | M23: 현금합계 | N23: =C5+C6 -> 941000
A24: 일매출 | C24: 일평균매출 | E24: 누적총매출 | H24: 일매출 | I24: =I23/A25 -> 0.70529124 | J24: 일매출 | K24: =K23/A25 -> 0.028697215
A25: =C2 -> 4134000 | C25: =E25/I1 -> 3450375 | E25: =SUM('1:4'!$A$25) -> 13801500 | H25: 누계 | I25: =SUM('1:4'!$I$23) -> 6445761 | J25: 누계 | K25: =SUM('1:4'!$K$23) -> 502378.14
A26: 전 월 | H26: 누적매출 | I26: =I25/$E$25 -> 0.46703337 | J26: 누적매출 | K26: =K25/$E$25 -> 0.036400257
A27: 인 건 비 | B27: 직원A | C27: =4000000/28 -> 142857.14 | E27: 알바X | F27: =13000*5 -> 65000 | H27: 인건비합계 | I27: =SUM(C27:D34,F27:G30) -> 824285.71
B28: 직원B | C28: =3800000/28 -> 135714.29 | E28: 알바X | H28: 일매출 | I28: =I27/$A$25 -> 0.1993918
B29: 직원D | C29: =3200000/28 -> 114285.71 | E29: 알바X | H29: 누계 | I29: =SUM('1:4'!$I$27) -> 3355642.9
B30: 직원E | C30: =3400000/28 -> 121428.57 | E30: 파출 | F30: 120000 | H30: 누적매출 | I30: =I29/$I$27 -> 4.0709705
B31: 알바A
B33: 직원C | C33: =3500000/28 -> 125000

Sheet 5
C1: 2025년 | E1: 2월 | F1: 5 | G1: 수 | H1: 실영업일수 | I1: =F1-K1 -> 5 | J1: 휴무일수
A2: 매출 | C2: =SUM(C4:D7) -> 3536000 | E2: 시재 | G2: 114100 | H2: 식자재 | J2: 비품 및 기타경비
H3: 업체 | I3: 금액 | J3: 업체 | K3: 금액
A4: 카드 | C4: 2986000 | E4: 카드수수료(2.75%) | G4: =INT(C4*0.0275) -> 82115 | H4: 고기 | I4: =415500+56200+445200 -> 916900 | J4: 숯 | K4: 171000
A5: 현금 | C5: 550000 | E5: 현금수수료(1%) | G5: =INT(C5*0.01) -> 5500 | H5: 식자재 | I5: =21900+3200+51600+25600 -> 102300
A6: 페이결제 | E6: 통장입금 | G6: 560000 | J6: 음식물스티커
H7: 주류 | J7: 종량제봉투
A8: 금고 실잔액 | C8: 104100 | E8: 마감잔금 | G8: =C5+G2-G6-C22 -> 104100 | H8: 쌀 | I8: 55000
J9: 뚝배기
A10: 현금할인 | E10: 카드할인 | J10: 발매트
A11: 할인내역 | H11: 참기름 | J11: 불판세척 | K11: =440000/28 -> 15714.286
A12: 개수 | B12: 목살 | C12: 23 | D12: LA갈비 | F12: 10 | H12: 부탄가스
A13: 매출누계 | C13: =SUM('1:5'!$C$12) -> 53 | F13: =SUM('1:5'!$F$12) -> 44 | H13: 코카콜라음료
A14: 개수 | B14: 생갈비 | C14: 29 | D14: 돼지양념갈비 | F14: 11 | H14: 깍두기,계란
A15: 매출누계 | C15: =SUM('1:5'!$C$14) -> 164 | F15: =SUM('1:5'!$F$14) -> 80 | H15: 식자재2 | I15: =11800+24000+5500+4900 -> 46200 | J15: 비품 및 기타경비
A16: 개수 | B16: 육회 | C16: 1 | D16: 한우업진살 | F16: 13 | J16: 인터넷 주문 | K16: 41860
A17: 매출누계 | C17: =SUM('1:5'!$C$16) -> 24 | F17: =SUM('1:5'!$F$16) -> 67 | H17: 막걸리 | J17: 다이소 구매
A18: 개수 | B18: 소갈비살 | C18: 25 | D18: LA양념갈비 | F18: 11
A19: 매출누계 | C19: =SUM('1:5'!$C$18) -> 171 | F19: =SUM('1:5'!$F$18) -> 60
D20: 테이블수 | F20: 44
D21: 누적테이블 | F21: =SUM('1:5'!$F$20) -> 243
A22: 중간출금
A23: 출금내역 | H23: 식자재합계 | I23: =SUM(I4:I22) -> 1120400 | J23: 기타경비합계 | K23: =SUM(K4:K22) -> 228574.29 | M23: 현금합계 | N23: =C5+C6 -> 550000
A24: 일매출 | C24: 일평균매출 | E24: 누적총매출 | H24: 일매출 | I24: =I23/A25 -> 0.3168552 | J24: 일매출 | K24: =K23/A25 -> 0.064642049
A25: =C2 -> 3536000 | C25: =E25/I1 -> 3467500 | E25: =SUM('1:5'!$A$25) -> 17337500 | H25: 누계 | I25: =SUM('1:5'!$I$23) -> 7566161 | J25: 누계 | K25: =SUM('1:5'!$K$23) -> 730952.43
A26: 전 월 | H26: 누적매출 | I26: =I25/$E$25 -> 0.43640438 | J26: 누적매출 | K26: =K25/$E$25 -> 0.042160198
A27: 인 건 비 | B27: 직원A | C27: =4000000/28 -> 142857.14 | E27: 알바X | F27: =13000*5 -> 65000 | H27: 인건비합계 | I27: =SUM(C27:D34,F27:G30) -> 876285.71
B28: 직원B | C28: =3800000/28 -> 135714.29 | E28: 알바X | F28: =13000*4 -> 52000 | H28: 일매출 | I28: =I27/$A$25 -> 0.24781836
B29: 직원D | C29: =3200000/28 -> 114285.71 | E29: 알바X | H29: 누계 | I29: =SUM('1:5'!$I$27) -> 4231928.6
B30: 직원E | C30: =3400000/28 -> 121428.57 | E30: 파출 | F30: 120000 | H30: 누적매출 | I30: =I29/$I$27 -> 4.8293935
B31: 알바A
B33: 직원C | C33: =3500000/28 -> 125000

Sheet 6
C1: 2025년 | E1: 2월 | F1: 6 | G1: 목 | H1: 실영업일수 | I1: =F1-K1 -> 6 | J1: 휴무일수
A2: 매출 | C2: =SUM(C4:D7) -> 4313000 | E2: 시재 | G2: 104100 | H2: 식자재 | J2: 비품 및 기타경비
H3: 업체 | I3: 금액 | J3: 업체 | K3: 금액
A4: 카드 | C4: 3989000 | E4: 카드수수료(2.75%) | G4: =INT(C4*0.0275) -> 109697 | H4: 고기 | I4: =415500+61300 -> 476800 | J4: 숯
A5: 현금 | C5: 324000 | E5: 현금수수료(1%) | G5: =INT(C5*0.01) -> 3240 | H5: 식자재 | I5: =60500+36080 -> 96580
A6: 페이결제 | E6: 통장입금 | G6: 340000 | J6: 음식물스티커
H7: 주류 | I7: =257200-34800 -> 222400 | J7: 종량제봉투
A8: 금고 실잔액 | C8: 88100 | E8: 마감잔금 | G8: =C5+G2-G6-C22 -> 88100 | H8: 쌀
J9: 뚝배기
A10: 현금할인 | E10: 카드할인 | J10: 발매트
A11: 할인내역 | H11: 참기름 | I11: 100000 | J11: 불판세척 | K11: =440000/28 -> 15714.286
A12: 개수 | B12: 목살 | C12: 16 | D12: LA갈비 | F12: 14 | H12: 부탄가스
A13: 매출누계 | C13: =SUM('1:6'!$C$12) -> 69 | F13: =SUM('1:6'!$F$12) -> 58 | H13: 코카콜라음료
A14: 개수 | B14: 생갈비 | C14: 46 | D14: 돼지양념갈비 | F14: 19 | H14: 깍두기,계란
A15: 매출누계 | C15: =SUM('1:6'!$C$14) -> 210 | F15: =SUM('1:6'!$F$14) -> 99 | H15: 식자재2 | I15: =17400+24400+11800+14250 -> 67850 | J15: 비품 및 기타경비
A16: 개수 | B16: 육회 | C16: 14 | D16: 한우업진살 | F16: 8 | J16: 인터넷 주문
A17: 매출누계 | C17: =SUM('1:6'!$C$16) -> 38 | F17: =SUM('1:6'!$F$16) -> 75 | H17: 막걸리 | J17: 다이소 구매
A18: 개수 | B18: 소갈비살 | C18: 40 | D18: LA양념갈비 | F18: 4
A19: 매출누계 | C19: =SUM('1:6'!$C$18) -> 211 | F19: =SUM('1:6'!$F$18) -> 64
D20: 테이블수 | F20: 58
D21: 누적테이블 | F21: =SUM('1:6'!$F$20) -> 301
A22: 중간출금
A23: 출금내역 | H23: 식자재합계 | I23: =SUM(I4:I22) -> 963630 | J23: 기타경비합계 | K23: =SUM(K4:K22) -> 15714.286 | M23: 현금합계 | N23: =C5+C6 -> 324000
A24: 일매출 | C24: 일평균매출 | E24: 누적총매출 | H24: 일매출 | I24: =I23/A25 -> 0.22342453 | J24: 일매출 | K24: =K23/A25 -> 0.0036434699
A25: =C2 -> 4313000 | C25: =E25/I1 -> 3608416.7 | E25: =SUM('1:6'!$A$25) -> 21650500 | H25: 누계 | I25: =SUM('1:6'!$I$23) -> 8529791 | J25: 누계 | K25: =SUM('1:6'!$K$23) -> 746666.71
A26: 전 월 | H26: 누적매출 | I26: =I25/$E$25 -> 0.39397663 | J26: 누적매출 | K26: =K25/$E$25 -> 0.034487273
A27: 인 건 비 | B27: 직원A | C27: =4000000/28 -> 142857.14 | E27: 알바X | F27: =13000*5 -> 65000 | H27: 인건비합계 | I27: =SUM(C27:D34,F27:G30) -> 876285.71
B28: 직원B | C28: =3800000/28 -> 135714.29 | E28: 알바X | F28: =13000*4 -> 52000 | H28: 일매출 | I28: =I27/$A$25 -> 0.20317313
B29: 직원D | C29: =3200000/28 -> 114285.71 | E29: 알바X | H29: 누계 | I29: =SUM('1:6'!$I$27) -> 5108214.3
B30: 직원E | C30: =3400000/28 -> 121428.57 | E30: 파출 | F30: 120000 | H30: 누적매출 | I30: =I29/$I$27 -> 5.8293935
B31: 알바A
B33: 직원C | C33: =3500000/28 -> 125000

Sheet 7
C1: 2025년 | E1: 2월 | F1: 7 | G1: 금 | H1: 실영업일수 | I1: =F1-K1 -> 7 | J1: 휴무일수
A2: 매출 | C2: =SUM(C4:D7) -> 4071000 | E2: 시재 | G2: 88100 | H2: 식자재 | J2: 비품 및 기타경비
H3: 업체 | I3: 금액 | J3: 업체 | K3: 금액
A4: 카드 | C4: 3392000 | E4: 카드수수료(2.75%) | G4: =INT(C4*0.0275) -> 93280 | H4: 고기 | I4: =415500+232200+387655 -> 1035355 | J4: 숯
A5: 현금 | C5: 679000 | E5: 현금수수료(1%) | G5: =INT(C5*0.01) -> 6790 | H5: 식자재 | I5: =59312+36080+40700+51600+25600 -> 213292
A6: 페이결제 | E6: 통장입금 | G6: 700000 | J6: 음식물스티커
H7: 주류 | I7: =312600-14200 -> 298400 | J7: 종량제봉투
A8: 금고 실잔액 | C8: 67100 | E8: 마감잔금 | G8: =C5+G2-G6-C22 -> 67100 | H8: 쌀 | I8: 55000
J9: 뚝배기
A10: 현금할인 | E10: 카드할인 | J10: 발매트
A11: 할인내역 | H11: 참기름 | J11: 불판세척 | K11: =440000/28 -> 15714.286
A12: 개수 | B12: 목살 | C12: 13 | D12: LA갈비 | F12: 9 | H12: 부탄가스
A13: 매출누계 | C13: =SUM('1:7'!$C$12) -> 82 | F13: =SUM('1:7'!$F$12) -> 67 | H13: 코카콜라음료
A14: 개수 | B14: 생갈비 | C14: 33 | D14: 돼지양념갈비 | F14: 14 | H14: 깍두기,계란
A15: 매출누계 | C15: =SUM('1:7'!$C$14) -> 243 | F15: =SUM('1:7'!$F$14) -> 113 | H15: 식자재2 | I15: =3500+11800+7500+52000+38400+4900+5500+24400 -> 148000 | J15: 비품 및 기타경비
A16: 개수 | B16: 육회 | C16: 5 | D16: 한우업진살 | F16: 16 | J16: 인터넷 주문 | K16: 95660
A17: 매출누계 | C17: =SUM('1:7'!$C$16) -> 43 | F17: =SUM('1:7'!$F$16) -> 91 | H17: 막걸리 | J17: 다이소 구매
A18: 개수 | B18: 소갈비살 | C18: 28 | D18: LA양념갈비 | F18: 20
A19: 매출누계 | C19: =SUM('1:7'!$C$18) -> 239 | F19: =SUM('1:7'!$F$18) -> 84
D20: 테이블수 | F20: 61
D21: 누적테이블 | F21: =SUM('1:7'!$F$20) -> 362
A22: 중간출금
A23: 출금내역 | H23: 식자재합계 | I23: =SUM(I4:I22) -> 1750047 | J23: 기타경비합계 | K23: =SUM(K4:K22) -> 111374.29 | M23: 현금합계 | N23: =C5+C6 -> 679000
A24: 일매출 | C24: 일평균매출 | E24: 누적총매출 | H24: 일매출 | I24: =I23/A25 -> 0.42988136 | J24: 일매출 | K24: =K23/A25 -> 0.027357968
A25: =C2 -> 4071000 | C25: =E25/I1 -> 3674500 | E25: =SUM('1:7'!$A$25) -> 25721500 | H25: 누계 | I25: =SUM('1:7'!$I$23) -> 10279838 | J25: 누계 | K25: =SUM('1:7'!$K$23) -> 858041
A26: 전 월 | H26: 누적매출 | I26: =I25/$E$25 -> 0.39965935 | J26: 누적매출 | K26: =K25/$E$25 -> 0.033358902
A27: 인 건 비 | B27: 직원A | C27: =4000000/28 -> 142857.14 | E27: 알바X | F27: =13000*5 -> 65000 | H27: 인건비합계 | I27: =SUM(C27:D34,F27:G30) -> 824285.71
B28: 직원B | C28: =3800000/28 -> 135714.29 | E28: 알바X | H28: 일매출 | I28: =I27/$A$25 -> 0.20247745
B29: 직원D | C29: =3200000/28 -> 114285.71 | E29: 알바X | H29: 누계 | I29: =SUM('1:7'!$I$27) -> 5932500
B30: 직원E | C30: =3400000/28 -> 121428.57 | E30: 파출 | F30: 120000 | H30: 누적매출 | I30: =I29/$I$27 -> 7.1971404
B31: 알바A
B33: 직원C | C33: =3500000/28 -> 125000

Sheet 8
C1: 2025년 | E1: 2월 | F1: 8 | G1: 토 | H1: 실영업일수 | I1: =F1-K1 -> 8 | J1: 휴무일수
A2: 매출 | C2: =SUM(C4:D7) -> 4177500 | E2: 시재 | G2: 67100 | H2: 식자재 | J2: 비품 및 기타경비
H3: 업체 | I3: 금액 | J3: 업체 | K3: 금액
A4: 카드 | C4: 3807500 | E4: 카드수수료(2.75%) | G4: =INT(C4*0.0275) -> 104706 | H4: 고기 | I4: =415500+226800+187140+445200+300846 -> 1575486 | J4: 숯
A5: 현금 | C5: 370000 | E5: 현금수수료(1%) | G5: =INT(C5*0.01) -> 3700 | H5: 식자재 | I5: =77880+25600+31640+65700 -> 200820
A6: 페이결제 | E6: 통장입금 | G6: 300500 | J6: 음식물스티커
H7: 주류 | J7: 종량제봉투
A8: 금고 실잔액 | C8: 136600 | E8: 마감잔금 | G8: =C5+G2-G6-C22 -> 136600 | H8: 쌀
J9: 뚝배기
A10: 현금할인 | E10: 카드할인 | J10: 발매트
A11: 할인내역 | H11: 참기름 | J11: 불판세척 | K11: =440000/28 -> 15714.286
A12: 개수 | B12: 목살 | C12: 18 | D12: LA갈비 | F12: 11 | H12: 부탄가스
A13: 매출누계 | C13: =SUM('1:8'!$C$12) -> 100 | F13: =SUM('1:8'!$F$12) -> 78 | H13: 코카콜라음료
A14: 개수 | B14: 생갈비 | C14: 42 | D14: 돼지양념갈비 | F14: 34 | H14: 깍두기,계란
A15: 매출누계 | C15: =SUM('1:8'!$C$14) -> 285 | F15: =SUM('1:8'!$F$14) -> 147 | H15: 식자재2 | I15: =97600+8550+17400+13000+16500+21000+4900+3900+4600+13500+38400+2500+4000 -> 245850 | J15: 비품 및 기타경비
A16: 개수 | B16: 육회 | C16: 9 | D16: 한우업진살 | F16: 12 | J16: 인터넷 주문
A17: 매출누계 | C17: =SUM('1:8'!$C$16) -> 52 | F17: =SUM('1:8'!$F$16) -> 103 | H17: 막걸리 | I17: 1600 | J17: 다이소 구매
A18: 개수 | B18: 소갈비살 | C18: 39 | D18: LA양념갈비 | F18: 16
A19: 매출누계 | C19: =SUM('1:8'!$C$18) -> 278 | F19: =SUM('1:8'!$F$18) -> 100
D20: 테이블수 | F20: 56
D21: 누적테이블 | F21: =SUM('1:8'!$F$20) -> 418
A22: 중간출금
A23: 출금내역 | H23: 식자재합계 | I23: =SUM(I4:I22) -> 2023756 | J23: 기타경비합계 | K23: =SUM(K4:K22) -> 15714.286 | M23: 현금합계 | N23: =C5+C6 -> 370000
A24: 일매출 | C24: 일평균매출 | E24: 누적총매출 | H24: 일매출 | I24: =I23/A25 -> 0.48444189 | J24: 일매출 | K24: =K23/A25 -> 0.0037616483
A25: =C2 -> 4177500 | C25: =E25/I1 -> 3737375 | E25: =SUM('1:8'!$A$25) -> 29899000 | H25: 누계 | I25: =SUM('1:8'!$I$23) -> 12303594 | J25: 누계 | K25: =SUM('1:8'!$K$23) -> 873755.29
A26: 전 월 | H26: 누적매출 | I26: =I25/$E$25 -> 0.4115052 | J26: 누적매출 | K26: =K25/$E$25 -> 0.029223562
A27: 인 건 비 | B27: 직원A | C27: =4000000/28 -> 142857.14 | E27: 알바X | H27: 인건비합계 | I27: =SUM(C27:D34,F27:G30) -> 891935.71
B28: 직원B | C28: =3800000/28 -> 135714.29 | E28: 알바X | H28: 일매출 | I28: =I27/$A$25 -> 0.21350945
B29: 직원D | C29: =3200000/28 -> 114285.71 | E29: 알바X | F29: =11700*4.5 -> 52650 | H29: 누계 | I29: =SUM('1:8'!$I$27) -> 6824435.7 | M29: `
B30: 직원E | C30: =3400000/28 -> 121428.57 | E30: 파출 | F30: 130000 | H30: 누적매출 | I30: =I29/$I$27 -> 7.6512641
B31: 알바A | C31: =14000*5 -> 70000
B33: 직원C | C33: =3500000/28 -> 125000

Sheet 9
A1: ` | C1: 2025년 | E1: 2월 | F1: 9 | G1: 일 | H1: 실영업일수 | I1: =F1-K1 -> 9 | J1: 휴무일수
A2: 매출 | C2: =SUM(C4:D7) -> 3823500 | E2: 시재 | G2: 136600 | H2: 식자재 | J2: 비품 및 기타경비
H3: 업체 | I3: 금액 | J3: 업체 | K3: 금액
A4: 카드 | C4: 3254500 | E4: 카드수수료(2.75%) | G4: =INT(C4*0.0275) -> 89498 | H4: 고기 | J4: 숯
A5: 현금 | C5: 569000 | E5: 현금수수료(1%) | G5: =INT(C5*0.01) -> 5690 | H5: 식자재
A6: 페이결제 | E6: 통장입금 | G6: 560000 | J6: 음식물스티커
H7: 주류 | J7: 종량제봉투 | K7: 12500
A8: 금고 실잔액 | C8: 145600 | E8: 마감잔금 | G8: =C5+G2-G6-C22 -> 145600 | H8: 쌀
J9: 뚝배기
A10: 현금할인 | E10: 카드할인 | J10: 발매트
A11: 할인내역 | H11: 참기름 | J11: 불판세척 | K11: =440000/28 -> 15714.286
A12: 개수 | B12: 목살 | C12: 11 | D12: LA갈비 | F12: 11 | H12: 부탄가스
A13: 매출누계 | C13: =SUM('1:9'!$C$12) -> 111 | F13: =SUM('1:9'!$F$12) -> 89 | H13: 코카콜라음료
A14: 개수 | B14: 생갈비 | C14: 61 | D14: 돼지양념갈비 | F14: 36 | H14: 깍두기,계란
A15: 매출누계 | C15: =SUM('1:9'!$C$14) -> 346 | F15: =SUM('1:9'!$F$14) -> 183 | H15: 식자재2 | I15: 230550 | J15: 비품 및 기타경비
A16: 개수 | B16: 육회 | C16: 5 | D16: 한우업진살 | F16: 20 | J16: 인터넷 주문
A17: 매출누계 | C17: =SUM('1:9'!$C$16) -> 57 | F17: =SUM('1:9'!$F$16) -> 123 | H17: 막걸리 | J17: 다이소 구매
A18: 개수 | B18: 소갈비살 | C18: 18 | D18: LA양념갈비 | F18: 10
A19: 매출누계 | C19: =SUM('1:9'!$C$18) -> 296 | F19: =SUM('1:9'!$F$18) -> 110
D20: 테이블수 | F20: 50
D21: 누적테이블 | F21: =SUM('1:9'!$F$20) -> 468
A22: 중간출금
A23: 출금내역 | H23: 식자재합계 | I23: =SUM(I4:I22) -> 230550 | J23: 기타경비합계 | K23: =SUM(K4:K22) -> 28214.286 | M23: 현금합계 | N23: =C5+C6 -> 569000
A24: 일매출 | C24: 일평균매출 | E24: 누적총매출 | H24: 일매출 | I24: =I23/A25 -> 0.060298156 | J24: 일매출 | K24: =K23/A25 -> 0.0073791776
A25: =C2 -> 3823500 | C25: =E25/I1 -> 3746944.4 | E25: =SUM('1:9'!$A$25) -> 33722500 | H25: 누계 | I25: =SUM('1:9'!$I$23) -> 12534144 | J25: 누계 | K25: =SUM('1:9'!$K$23) -> 901969.57
A26: 전 월 | H26: 누적매출 | I26: =I25/$E$25 -> 0.3716849 | J26: 누적매출 | K26: =K25/$E$25 -> 0.026746818
A27: 인 건 비 | B27: 직원A | C27: =4000000/28 -> 142857.14 | E27: 알바X | H27: 인건비합계 | I27: =SUM(C27:D34,F27:G30) -> 847535.71
B28: 직원B | C28: =3800000/28 -> 135714.29 | E28: 알바X | H28: 일매출 | I28: =I27/$A$25 -> 0.22166489
B29: 직원D | C29: =3200000/28 -> 114285.71 | E29: 알바X | F29: =11700*2.5 -> 29250 | H29: 누계 | I29: =SUM('1:9'!$I$27) -> 7671971.4
B30: 직원E | C30: =3400000/28 -> 121428.57 | E30: 파출 | F30: 130000 | H30: 누적매출 | I30: =I29/$I$27 -> 9.0520922
B31: 알바A | C31: =14000*3.5 -> 49000
B33: 직원C | C33: =3500000/28 -> 125000

Sheet 10
C1: 2025년 | E1: 2월 | F1: 10 | G1: 월 | H1: 실영업일수 | I1: =F1-K1 -> 10 | J1: 휴무일수
A2: 매출 | C2: =SUM(C4:D7) -> 3665500 | E2: 시재 | G2: 145600 | H2: 식자재 | J2: 비품 및 기타경비
H3: 업체 | I3: 금액 | J3: 업체 | K3: 금액
A4: 카드 | C4: 3261500 | E4: 카드수수료(2.75%) | G4: =INT(C4*0.0275) -> 89691 | H4: 고기 | I4: =221400+187209+275964+445200 -> 1129773 | J4: 숯
A5: 현금 | C5: 404000 | E5: 현금수수료(1%) | G5: =INT(C5*0.01) -> 4040 | H5: 식자재 | I5: =88968+72160+103200+51200 -> 315528
A6: 페이결제 | E6: 통장입금 | G6: 440000 | J6: 음식물스티커
H7: 주류 | J7: 종량제봉투
A8: 금고 실잔액 | C8: 108600 | E8: 마감잔금 | G8: =C5+G2-G6-C22 -> 109600 | H8: 쌀 | I8: 55000
J9: 뚝배기 | K9: 117000
A10: 현금할인 | E10: 카드할인 | J10: 발매트 | K10: 13000
A11: 할인내역 | H11: 참기름 | J11: 불판세척 | K11: =440000/28 -> 15714.286
A12: 개수 | B12: 목살 | C12: 7 | D12: LA갈비 | F12: 7 | H12: 부탄가스
A13: 매출누계 | C13: =SUM('1:10'!$C$12) -> 118 | F13: =SUM('1:10'!$F$12) -> 96 | H13: 코카콜라음료
A14: 개수 | B14: 생갈비 | C14: 25 | D14: 돼지양념갈비 | F14: 28 | H14: 깍두기,계란
A15: 매출누계 | C15: =SUM('1:10'!$C$14) -> 371 | F15: =SUM('1:10'!$F$14) -> 211 | H15: 식자재2 | I15: =15500+4900+19200+11800+21000+3500+6600+222000 -> 304500 | J15: 비품 및 기타경비
A16: 개수 | B16: 육회 | C16: 8 | D16: 한우업진살 | F16: 16 | J16: 인터넷 주문 | K16: 185594
A17: 매출누계 | C17: =SUM('1:10'!$C$16) -> 65 | F17: =SUM('1:10'!$F$16) -> 139 | H17: 막걸리 | J17: 다이소 구매
A18: 개수 | B18: 소갈비살 | C18: 37 | D18: LA양념갈비 | F18: 5
A19: 매출누계 | C19: =SUM('1:10'!$C$18) -> 333 | F19: =SUM('1:10'!$F$18) -> 115
D20: 테이블수 | F20: 52
D21: 누적테이블 | F21: =SUM('1:10'!$F$20) -> 520
A22: 중간출금
A23: 출금내역 | H23: 식자재합계 | I23: =SUM(I4:I22) -> 1804801 | J23: 기타경비합계 | K23: =SUM(K4:K22) -> 331308.29 | M23: 현금합계 | N23: =C5+C6 -> 404000
A24: 일매출 | C24: 일평균매출 | E24: 누적총매출 | H24: 일매출 | I24: =I23/A25 -> 0.49237512 | J24: 일매출 | K24: =K23/A25 -> 0.090385564
A25: =C2 -> 3665500 | C25: =E25/I1 -> 3738800 | E25: =SUM('1:10'!$A$25) -> 37388000 | H25: 누계 | I25: =SUM('1:10'!$I$21) -> 0 | J25: 누계 | K25: =SUM('1:10'!$K$21) -> 0
A26: 전 월 | H26: 누적매출 | I26: =I25/$E$25 -> 0 | J26: 누적매출 | K26: =K25/$E$25 -> 0
A27: 인 건 비 | B27: 직원A | C27: =4000000/28 -> 142857.14 | E27: 알바X | H27: 인건비합계 | I27: =SUM(C27:D34,F27:G30) -> 816485.71
B28: 직원B | C28: =3800000/28 -> 135714.29 | E28: 알바X | F28: =13000*3.5 -> 45500 | H28: 일매출 | I28: =I27/$A$25 -> 0.2227488
B29: 직원D | C29: =3200000/28 -> 114285.71 | E29: 알바X | F29: =11700*1 -> 11700 | H29: 누계 | I29: =SUM('1:10'!$I$25) -> 67249914
B30: 직원E | C30: =3400000/28 -> 121428.57 | E30: 파출 | F30: 120000 | H30: 누적매출 | I30: =I29/$I$27 -> 82.365083
B31: 알바A
B33: 직원C | C33: =3500000/28 -> 125000

Sheet 11
C1: 2025년 | E1: 2월 | F1: 11 | G1: 화 | H1: 실영업일수 | I1: =F1-K1 -> 11 | J1: 휴무일수
A2: 매출 | C2: =SUM(C4:D7) -> 3645500 | E2: 시재 | G2: 108600 | H2: 식자재 | J2: 비품 및 기타경비
H3: 업체 | I3: 금액 | J3: 업체 | K3: 금액
A4: 카드 | C4: 3458500 | E4: 카드수수료(2.75%) | G4: =INT(C4*0.0275) -> 95108 | H4: 고기 | I4: =415500+221400+206119+168426+291798+56200 -> 1359443 | J4: 숯
A5: 현금 | C5: 187000 | E5: 현금수수료(1%) | G5: =INT(C5*0.01) -> 1870 | H5: 식자재 | I5: =47300+41250 -> 88550
A6: 페이결제 | E6: 통장입금 | G6: 200000 | J6: 음식물스티커
H7: 주류 | I7: =177400-24300 -> 153100 | J7: 종량제봉투
A8: 금고 실잔액 | C8: 95600 | E8: 마감잔금 | G8: =C5+G2-G6-C22 -> 95600 | H8: 쌀
J9: 뚝배기
A10: 현금할인 | E10: 카드할인 | J10: 발매트
A11: 할인내역 | H11: 참기름 | J11: 불판세척 | K11: =440000/28 -> 15714.286
A12: 개수 | B12: 목살 | C12: 7 | D12: LA갈비 | F12: 2 | H12: 부탄가스
A13: 매출누계 | C13: =SUM('1:11'!$C$12) -> 125 | F13: =SUM('1:11'!$F$12) -> 98 | H13: 코카콜라음료
A14: 개수 | B14: 생갈비 | C14: 34 | D14: 돼지양념갈비 | F14: 12 | H14: 깍두기,계란
A15: 매출누계 | C15: =SUM('1:11'!$C$14) -> 405 | F15: =SUM('1:11'!$F$14) -> 223 | H15: 식자재2 | I15: =11800+27500+17400+48800 -> 105500 | J15: 비품 및 기타경비
A16: 개수 | B16: 육회 | C16: 3 | D16: 한우업진살 | F16: 12 | J16: 인터넷 주문 | K16: 25550
A17: 매출누계 | C17: =SUM('1:11'!$C$16) -> 68 | F17: =SUM('1:11'!$F$16) -> 151 | H17: 막걸리 | I17: =1600*4+1700*4 -> 13200 | J17: 다이소 구매
A18: 개수 | B18: 소갈비살 | C18: 26 | D18: LA양념갈비 | F18: 9
A19: 매출누계 | C19: =SUM('1:11'!$C$18) -> 359 | F19: =SUM('1:11'!$F$18) -> 124
D20: 테이블수 | F20: 60
D21: 누적테이블 | F21: =SUM('1:11'!$F$20) -> 580
A22: 중간출금
A23: 출금내역 | H23: 식자재합계 | I23: =SUM(I4:I22) -> 1719793 | J23: 기타경비합계 | K23: =SUM(K4:K22) -> 41264.286 | M23: 현금합계 | N23: =C5+C6 -> 187000
A24: 일매출 | C24: 일평균매출 | E24: 누적총매출 | H24: 일매출 | I24: =I23/A25 -> 0.47175778 | J24: 일매출 | K24: =K23/A25 -> 0.011319239
A25: =C2 -> 3645500 | C25: =E25/I1 -> 3730318.2 | E25: =SUM('1:11'!$A$25) -> 41033500 | H25: 누계 | I25: =SUM('1:11'!$I$21) -> 0 | J25: 누계 | K25: =SUM('1:11'!$K$21) -> 0
A26: 전 월 | H26: 누적매출 | I26: =I25/$E$25 -> 0 | J26: 누적매출 | K26: =K25/$E$25 -> 0
A27: 인 건 비 | B27: 직원A | C27: =4000000/28 -> 142857.14 | E27: 알바X | F27: =13000*5 -> 65000 | H27: 인건비합계 | I27: =SUM(C27:D34,F27:G30) -> 824285.71
B28: 직원B | C28: =3800000/28 -> 135714.29 | E28: 알바X | H28: 일매출 | I28: =I27/$A$25 -> 0.22611047
B29: 직원D | C29: =3200000/28 -> 114285.71 | E29: 알바X | H29: 누계 | I29: =SUM('1:11'!$I$25) -> 67249914
B30: 직원E | C30: =3400000/28 -> 121428.57 | E30: 파출 | F30: 120000 | H30: 누적매출 | I30: =I29/$I$27 -> 81.585684
B31: 알바A
B33: 직원C | C33: =3500000/28 -> 125000

Sheet 12
C1: 2025년 | E1: 2월 | F1: 12 | G1: 수 | H1: 실영업일수 | I1: =F1-K1 -> 12 | J1: 휴무일수
A2: 매출 | C2: =SUM(C4:D7) -> 3944000 | E2: 시재 | G2: 95600 | H2: 식자재 | J2: 비품 및 기타경비
H3: 업체 | I3: 금액 | J3: 업체 | K3: 금액
A4: 카드 | C4: 3733000 | E4: 카드수수료(2.75%) | G4: =INT(C4*0.0275) -> 102657 | H4: 고기 | I4: =275964+445200 -> 721164 | J4: 숯 | K4: 342000
A5: 현금 | C5: 211000 | E5: 현금수수료(1%) | G5: =INT(C5*0.01) -> 2110 | H5: 식자재 | I5: =10+40700+29656 -> 70366
A6: 페이결제 | E6: 통장입금 | G6: 220000 | J6: 음식물스티커
H7: 주류 | I7: =224720-10100 -> 214620 | J7: 종량제봉투
A8: 금고 실잔액 | C8: 86600 | E8: 마감잔금 | G8: =C5+G2-G6-C22 -> 86600 | H8: 쌀 | I8: 55000
J9: 뚝배기
A10: 현금할인 | E10: 카드할인 | J10: 발매트
A11: 할인내역 | H11: 참기름 | J11: 불판세척 | K11: =440000/28 -> 15714.286
A12: 개수 | B12: 목살 | C12: 15 | D12: LA갈비 | F12: 6 | H12: 부탄가스
A13: 매출누계 | C13: =SUM('1:12'!$C$12) -> 140 | F13: =SUM('1:12'!$F$12) -> 104 | H13: 코카콜라음료 | I13: 240000
A14: 개수 | B14: 생갈비 | C14: 32 | D14: 돼지양념갈비 | F14: 5 | H14: 깍두기,계란
A15: 매출누계 | C15: =SUM('1:12'!$C$14) -> 437 | F15: =SUM('1:12'!$F$14) -> 228 | H15: 식자재2 | J15: 비품 및 기타경비
A16: 개수 | B16: 육회 | C16: 12 | D16: 한우업진살 | F16: 17 | I16: =2200+3200+53000+19200+11000+23600+61000+11500+9800+16500+3150+13000+3400 -> 230550 | J16: 인터넷 주문
A17: 매출누계 | C17: =SUM('1:12'!$C$16) -> 80 | F17: =SUM('1:12'!$F$16) -> 168 | H17: 막걸리 | J17: 다이소 구매 | K17: 13000
A18: 개수 | B18: 소갈비살 | C18: 38 | D18: LA양념갈비 | F18: 20
A19: 매출누계 | C19: =SUM('1:12'!$C$18) -> 397 | F19: =SUM('1:12'!$F$18) -> 144
D20: 테이블수 | F20: 37
D21: 누적테이블 | F21: =SUM('1:12'!$F$20) -> 617
A22: 중간출금
A23: 출금내역 | H23: 식자재합계 | I23: =SUM(I4:I22) -> 1531700 | J23: 기타경비합계 | K23: =SUM(K4:K22) -> 370714.29 | M23: 현금합계 | N23: =C5+C6 -> 211000
A24: 일매출 | C24: 일평균매출 | E24: 누적총매출 | H24: 일매출 | I24: =I23/A25 -> 0.38836207 | J24: 일매출 | K24: =K23/A25 -> 0.093994494
A25: =C2 -> 3944000 | C25: =E25/I1 -> 3748125 | E25: =SUM('1:12'!$A$25) -> 44977500 | H25: 누계 | I25: =SUM('1:12'!$I$21) -> 0 | J25: 누계 | K25: =SUM('1:12'!$K$21) -> 0
A26: 전 월 | H26: 누적매출 | I26: =I25/$E$25 -> 0 | J26: 누적매출 | K26: =K25/$E$25 -> 0
A27: 인 건 비 | B27: 직원A | C27: =4000000/28 -> 142857.14 | E27: 알바X | F27: =13000*5 -> 65000 | H27: 인건비합계 | I27: =SUM(C27:D34,F27:G30) -> 876285.71
B28: 직원B | C28: =3800000/28 -> 135714.29 | E28: 알바X | F28: =13000*4 -> 52000 | H28: 일매출 | I28: =I27/$A$25 -> 0.22218198
B29: 직원D | C29: =3200000/28 -> 114285.71 | E29: 알바X | H29: 누계 | I29: =SUM('1:12'!$I$25) -> 67249914
B30: 직원E | C30: =3400000/28 -> 121428.57 | E30: 파출 | F30: =120000 -> 120000 | H30: 누적매출 | I30: =I29/$I$27 -> 76.744277
B31: 알바A
B33: 직원C | C33: =3500000/28 -> 125000

Sheet 13
C1: 2025년 | E1: 2월 | F1: 13 | G1: 목 | H1: 실영업일수 | I1: =F1-K1 -> 13 | J1: 휴무일수
A2: 매출 | C2: =SUM(C4:D7) -> 3096500 | E2: 시재 | G2: 86600 | H2: 식자재 | J2: 비품 및 기타경비
H3: 업체 | I3: 금액 | J3: 업체 | K3: 금액
A4: 카드 | C4: 2979500 | E4: 카드수수료(2.75%) | G4: =INT(C4*0.0275) -> 81936 | H4: 고기 | I4: =205200+402351+211792+415500 -> 1234843 | J4: 숯
A5: 현금 | C5: 117000 | E5: 현금수수료(1%) | G5: =INT(C5*0.01) -> 1170 | H5: 식자재
A6: 페이결제 | E6: 통장입금 | G6: 100000 | J6: 음식물스티커
H7: 주류 | I7: =344220-19300 -> 324920 | J7: 종량제봉투
A8: 금고 실잔액 | C8: 103600 | E8: 마감잔금 | G8: =C5+G2-G6-C22 -> 103600 | H8: 쌀
J9: 뚝배기
A10: 현금할인 | E10: 카드할인 | J10: 발매트
A11: 할인내역 | H11: 참기름 | J11: 불판세척 | K11: =440000/28 -> 15714.286
A12: 개수 | B12: 목살 | C12: 13 | D12: LA갈비 | F12: 11 | H12: 부탄가스
A13: 매출누계 | C13: =SUM('1:13'!$C$12) -> 153 | F13: =SUM('1:13'!$F$12) -> 115 | H13: 코카콜라음료
A14: 개수 | B14: 생갈비 | C14: 36 | D14: 돼지양념갈비 | F14: 10 | H14: 깍두기,계란
A15: 매출누계 | C15: =SUM('1:13'!$C$14) -> 473 | F15: =SUM('1:13'!$F$14) -> 238 | H15: 식자재2 | J15: 비품 및 기타경비 | K15: 6200
A16: 개수 | B16: 육회 | C16: 6 | D16: 한우업진살 | F16: 16 | J16: 인터넷 주문 | K16: 86672
A17: 매출누계 | C17: =SUM('1:13'!$C$16) -> 86 | F17: =SUM('1:13'!$F$16) -> 184 | H17: 막걸리 | J17: 다이소 구매
A18: 개수 | B18: 소갈비살 | C18: 8 | D18: LA양념갈비 | F18: 4
A19: 매출누계 | C19: =SUM('1:13'!$C$18) -> 405 | F19: =SUM('1:13'!$F$18) -> 148
D20: 테이블수 | F20: 50
D21: 누적테이블 | F21: =SUM('1:13'!$F$20) -> 667
A22: 중간출금
A23: 출금내역 | H23: 식자재합계 | I23: =SUM(I4:I22) -> 1559763 | J23: 기타경비합계 | K23: =SUM(K4:K22) -> 108586.29 | M23: 현금합계 | N23: =C5+C6 -> 117000
A24: 일매출 | C24: 일평균매출 | E24: 누적총매출 | H24: 일매출 | I24: =I23/A25 -> 0.50371807 | J24: 일매출 | K24: =K23/A25 -> 0.035067426
A25: =C2 -> 3096500 | C25: =E25/I1 -> 3698000 | E25: =SUM('1:13'!$A$25) -> 48074000 | H25: 누계 | I25: =SUM('1:13'!$I$21) -> 0 | J25: 누계 | K25: =SUM('1:13'!$K$21) -> 0
A26: 전 월 | H26: 누적매출 | I26: =I25/$E$25 -> 0 | J26: 누적매출 | K26: =K25/$E$25 -> 0
A27: 인 건 비 | B27: 직원A | C27: =4000000/28 -> 142857.14 | E27: 알바X | F27: =13000*5 -> 65000 | H27: 인건비합계 | I27: =SUM(C27:D34,F27:G30) -> 863285.71
B28: 직원B | C28: =3800000/28 -> 135714.29 | E28: 알바X | F28: =13000*3 -> 39000 | H28: 일매출 | I28: =I27/$A$25 -> 0.27879403
B29: 직원D | C29: =3200000/28 -> 114285.71 | E29: 알바X | H29: 누계 | I29: =SUM('1:13'!$I$25) -> 67249914
B30: 직원E | C30: =3400000/28 -> 121428.57 | E30: 파출 | F30: 120000 | H30: 누적매출 | I30: =I29/$I$27 -> 77.89995
B31: 알바A
B33: 직원C | C33: =3500000/28 -> 125000

Sheet 14
C1: 2025년 | E1: 2월 | F1: 14 | G1: 금요일 | H1: 실영업일수 | I1: =F1-K1 -> 14 | J1: 휴무일수
A2: 매출 | C2: =SUM(C4:D7) -> 4966500 | E2: 시재 | G2: 103600 | H2: 식자재 | J2: 비품 및 기타경비
H3: 업체 | I3: 금액 | J3: 업체 | K3: 금액
A4: 카드 | C4: 4542500 | E4: 카드수수료(2.75%) | G4: =INT(C4*0.0275) -> 124918 | H4: 고기 | I4: =210600+262392 -> 472992 | J4: 숯
A5: 현금 | C5: 424000 | E5: 현금수수료(1%) | G5: =INT(C5*0.01) -> 4240 | H5: 식자재 | I5: =29656+26220+34540+43120+38940+36080 -> 208556
A6: 페이결제 | E6: 통장입금 | G6: 410000 | J6: 음식물스티커
H7: 주류 | I7: =415490-14700 -> 400790 | J7: 종량제봉투
A8: 금고 실잔액 | C8: 117600 | E8: 마감잔금 | G8: =C5+G2-G6-C22 -> 117600 | H8: 쌀 | I8: 55000
J9: 뚝배기
A10: 현금할인 | E10: 카드할인 | J10: 발매트
A11: 할인내역 | H11: 참기름 | J11: 불판세척 | K11: =440000/28 -> 15714.286
A12: 개수 | B12: 목살 | C12: 24 | D12: LA갈비 | F12: 6 | H12: 부탄가스
A13: 매출누계 | C13: =SUM('1:14'!$C$12) -> 177 | F13: =SUM('1:14'!$F$12) -> 121 | H13: 코카콜라음료
A14: 개수 | B14: 생갈비 | C14: 63 | D14: 돼지양념갈비 | F14: 9 | H14: 깍두기,계란
A15: 매출누계 | C15: =SUM('1:14'!$C$14) -> 536 | F15: =SUM('1:14'!$F$14) -> 247 | H15: 식자재2 | I15: =17700+61000+16500+19200+13500+3900+4900+2500+3500+35000 -> 177700 | J15: 비품 및 기타경비
A16: 개수 | B16: 육회 | C16: 15 | D16: 한우업진살 | F16: 11 | H16: 햇반 | J16: 인터넷 주문
A17: 매출누계 | C17: =SUM('1:14'!$C$16) -> 101 | F17: =SUM('1:14'!$F$16) -> 195 | H17: 막걸리 | J17: 다이소 구매
A18: 개수 | B18: 소갈비살 | C18: 34 | D18: LA양념갈비 | F18: 4
A19: 매출누계 | C19: =SUM('1:14'!$C$18) -> 439 | F19: =SUM('1:14'!$F$18) -> 152
D20: 테이블수 | F20: 67
D21: 누적테이블 | F21: =SUM('1:14'!$F$20) -> 734
A22: 중간출금
A23: 출금내역 | H23: 식자재합계 | I23: =SUM(I4:I22) -> 1315038 | J23: 기타경비합계 | K23: =SUM(K4:K22) -> 15714.286 | M23: 현금합계 | N23: =C5+C6 -> 424000
A24: 일매출 | C24: 일평균매출 | E24: 누적총매출 | H24: 일매출 | I24: =I23/A25 -> 0.26478164 | J24: 일매출 | K24: =K23/A25 -> 0.0031640563
A25: =C2 -> 4966500 | C25: =E25/I1 -> 3788607.1 | E25: =SUM('1:14'!$A$25) -> 53040500 | H25: 누계 | I25: =SUM('1:14'!$I$21) -> 0 | J25: 누계 | K25: =SUM('1:14'!$K$21) -> 0
A26: 전 월 | H26: 누적매출 | I26: =I25/$E$25 -> 0 | J26: 누적매출 | K26: =K25/$E$25 -> 0
A27: 인 건 비 | B27: 직원A | C27: =4000000/28 -> 142857.14 | E27: 알바X | F27: =13000*5 -> 65000 | H27: 인건비합계 | I27: =SUM(C27:D34,F27:G30) -> 882785.71
B28: 직원B | C28: =3800000/28 -> 135714.29 | E28: 알바X | F28: =13000*4.5 -> 58500 | H28: 일매출 | I28: =I27/$A$25 -> 0.17774805
B29: 직원D | C29: =3200000/28 -> 114285.71 | E29: 알바X | H29: 누계 | I29: =SUM('1:14'!$I$25) -> 67249914 | M29: `
B30: 직원E | C30: =3400000/28 -> 121428.57 | E30: 파출 | F30: 120000 | H30: 누적매출 | I30: =I29/$I$27 -> 76.179205
B31: 알바A
B33: 직원C | C33: =3500000/28 -> 125000

Sheet 15
C1: 2025년 | E1: 2월 | F1: 15 | G1: 토 | H1: 실영업일수 | I1: =F1-K1 -> 15 | J1: 휴무일수
A2: 매출 | C2: =SUM(C4:D7) -> 4793500 | E2: 시재 | G2: 117600 | H2: 식자재 | J2: 비품 및 기타경비
H3: 업체 | I3: 금액 | J3: 업체 | K3: 금액
A4: 카드 | C4: 4226500 | E4: 카드수수료(2.75%) | G4: =INT(C4*0.0275) -> 116228 | H4: 고기 | I4: =383400+194773+177783+266916+56200+415500 -> 1494572 | J4: 숯
A5: 현금 | C5: 567000 | E5: 현금수수료(1%) | G5: =INT(C5*0.01) -> 5670 | H5: 식자재 | I5: =59312+29100+13110+68600 -> 170122
A6: 페이결제 | E6: 통장입금 | G6: 550000 | J6: 음식물스티커
H7: 주류 | J7: 종량제봉투
A8: 금고 실잔액 | C8: 134600 | E8: 마감잔금 | G8: =C5+G2-G6-C22 -> 134600 | H8: 쌀
J9: 뚝배기
A10: 현금할인 | E10: 카드할인 | J10: 발매트
A11: 할인내역 | H11: 참기름 | J11: 불판세척 | K11: =440000/28 -> 15714.286
A12: 개수 | B12: 목살 | C12: 12 | D12: LA갈비 | F12: 5 | H12: 부탄가스
A13: 매출누계 | C13: =SUM('1:15'!$C$12) -> 189 | F13: =SUM('1:15'!$F$12) -> 126 | H13: 코카콜라음료
A14: 개수 | B14: 생갈비 | C14: 72 | D14: 돼지양념갈비 | F14: 38 | H14: 깍두기,계란
A15: 매출누계 | C15: =SUM('1:15'!$C$14) -> 608 | F15: =SUM('1:15'!$F$14) -> 285 | H15: 식자재2 | I15: =9000+24400+5500+3200+2200+6600+19200+17500+27500+8900 -> 124000 | J15: 비품 및 기타경비
A16: 개수 | B16: 육회 | C16: 13 | D16: 한우업진살 | F16: 19 | J16: 인터넷 주문 | K16: 17640
A17: 매출누계 | C17: =SUM('1:15'!$C$16) -> 114 | F17: =SUM('1:15'!$F$16) -> 214 | H17: 막걸리 | J17: 다이소 구매
A18: 개수 | B18: 소갈비살 | C18: 37 | D18: LA양념갈비 | F18: 13
A19: 매출누계 | C19: =SUM('1:15'!$C$18) -> 476 | F19: =SUM('1:15'!$F$18) -> 165
D20: 테이블수 | F20: 61
D21: 누적테이블 | F21: =SUM('1:15'!$F$20) -> 795
A22: 중간출금
A23: 출금내역 | H23: 식자재합계 | I23: =SUM(I4:I22) -> 1788694 | J23: 기타경비합계 | K23: =SUM(K4:K22) -> 33354.286 | M23: 현금합계 | N23: =C5+C6 -> 567000
A24: 일매출 | C24: 일평균매출 | E24: 누적총매출 | H24: 일매출 | I24: =I23/A25 -> 0.37314989 | J24: 일매출 | K24: =K23/A25 -> 0.0069582321
A25: =C2 -> 4793500 | C25: =E25/I1 -> 3855600 | E25: =SUM('1:15'!$A$25) -> 57834000 | H25: 누계 | I25: =SUM('1:15'!$I$21) -> 0 | J25: 누계 | K25: =SUM('1:15'!$K$21) -> 0
A26: 전 월 | H26: 누적매출 | I26: =I25/$E$25 -> 0 | J26: 누적매출 | K26: =K25/$E$25 -> 0
A27: 인 건 비 | B27: 직원A | C27: =4000000/28 -> 142857.14 | E27: 알바X | H27: 인건비합계 | I27: =SUM(C27:D34,F27:G30) -> 872085.71
B28: 직원B | C28: =3800000/28 -> 135714.29 | E28: 알바X | H28: 일매출 | I28: =I27/$A$25 -> 0.18193089
B29: 직원D | C29: =3200000/28 -> 114285.71 | E29: 알바X | F29: =11700*4 -> 46800 | H29: 누계 | I29: =SUM('1:15'!$I$25) -> 67249914
B30: 직원E | C30: =3400000/28 -> 121428.57 | E30: 파출 | F30: 130000 | H30: 누적매출 | I30: =I29/$I$27 -> 77.113881
B31: 알바A | C31: =14000*4 -> 56000
B33: 직원C | C33: =3500000/28 -> 125000

Sheet 16
C1: 2025년 | E1: 2월 | F1: 16 | G1: 일 | H1: 실영업일수 | I1: =F1-K1 -> 16 | J1: 휴무일수
A2: 매출 | C2: =SUM(C4:D7) -> 3819000 | E2: 시재 | G2: 134600 | H2: 식자재 | J2: 비품 및 기타경비
H3: 업체 | I3: 금액 | J3: 업체 | K3: 금액
A4: 카드 | C4: 2994000 | E4: 카드수수료(2.75%) | G4: =INT(C4*0.0275) -> 82335 | H4: 고기 | J4: 숯
A5: 현금 | C5: 825000 | E5: 현금수수료(1%) | G5: =INT(C5*0.01) -> 8250 | H5: 식자재
A6: 페이결제 | E6: 통장입금 | G6: 800000 | J6: 음식물스티커
H7: 주류 | J7: 종량제봉투
A8: 금고 실잔액 | C8: 159600 | E8: 마감잔금 | G8: =C5+G2-G6-C22 -> 159600 | H8: 쌀
J9: 뚝배기
A10: 현금할인 | E10: 카드할인 | J10: 발매트
A11: 할인내역 | H11: 참기름 | J11: 불판세척 | K11: =440000/28 -> 15714.286
A12: 개수 | B12: 목살 | C12: 22 | D12: LA갈비 | F12: 11 | H12: 부탄가스
A13: 매출누계 | C13: =SUM('1:16'!$C$12) -> 211 | F13: =SUM('1:16'!$F$12) -> 137 | H13: 코카콜라음료
A14: 개수 | B14: 생갈비 | C14: 64 | D14: 돼지양념갈비 | F14: 14 | H14: 깍두기,계란
A15: 매출누계 | C15: =SUM('1:16'!$C$14) -> 672 | F15: =SUM('1:16'!$F$14) -> 299 | H15: 식자재2 | J15: 비품 및 기타경비
A16: 개수 | B16: 육회 | C16: 7 | D16: 한우업진살 | F16: 9 | J16: 인터넷 주문 | K16: 16746
A17: 매출누계 | C17: =SUM('1:16'!$C$16) -> 121 | F17: =SUM('1:16'!$F$16) -> 223 | H17: 막걸리 | J17: 다이소 구매
A18: 개수 | B18: 소갈비살 | C18: 29 | D18: LA양념갈비 | F18: 14
A19: 매출누계 | C19: =SUM('1:16'!$C$18) -> 505 | F19: =SUM('1:16'!$F$18) -> 179
D20: 테이블수 | F20: 57
D21: 누적테이블 | F21: =SUM('1:16'!$F$20) -> 852
A22: 중간출금
A23: 출금내역 | H23: 식자재합계 | I23: =SUM(I4:I22) -> 0 | J23: 기타경비합계 | K23: =SUM(K4:K22) -> 32460.286 | M23: 현금합계 | N23: =C5+C6 -> 825000
A24: 일매출 | C24: 일평균매출 | E24: 누적총매출 | H24: 일매출 | I24: =I23/A25 -> 0 | J24: 일매출 | K24: =K23/A25 -> 0.008499682
A25: =C2 -> 3819000 | C25: =E25/I1 -> 3853312.5 | E25: =SUM('1:16'!$A$25) -> 61653000 | H25: 누계 | I25: =SUM('1:16'!$I$21) -> 0 | J25: 누계 | K25: =SUM('1:16'!$K$21) -> 0
A26: 전 월 | H26: 누적매출 | I26: =I25/$E$25 -> 0 | J26: 누적매출 | K26: =K25/$E$25 -> 0
A27: 인 건 비 | B27: 직원A | C27: =4000000/28 -> 142857.14 | E27: 알바X | H27: 인건비합계 | I27: =SUM(C27:D34,F27:G30) -> 860385.71
B28: 직원B | C28: =3800000/28 -> 135714.29 | E28: 알바X | H28: 일매출 | I28: =I27/$A$25 -> 0.22529084
B29: 직원D | C29: =3200000/28 -> 114285.71 | E29: 알바X | F29: =11700*3 -> 35100 | H29: 누계 | I29: =SUM('1:16'!$I$25) -> 67249914
B30: 직원E | C30: =3400000/28 -> 121428.57 | E30: 파출 | F30: 130000 | H30: 누적매출 | I30: =I29/$I$27 -> 78.162518
B31: 알바A | C31: =14000*4 -> 56000
B33: 직원C | C33: =3500000/28 -> 125000

Sheet 17
C1: 2025년 | E1: 2월 | F1: 17 | G1: 월 | H1: 실영업일수 | I1: =F1-K1 -> 17 | J1: 휴무일수
A2: 매출 | C2: =SUM(C4:D7) -> 3353000 | E2: 시재 | G2: 159600 | H2: 식자재 | J2: 비품 및 기타경비
H3: 업체 | I3: 금액 | J3: 업체 | K3: 금액
A4: 카드 | C4: 3156000 | E4: 카드수수료(2.75%) | G4: =INT(C4*0.0275) -> 86790 | H4: 고기 | I4: =168426+183427+226800+415500+269178+445200 -> 1708531 | J4: 숯
A5: 현금 | C5: 197000 | E5: 현금수수료(1%) | G5: =INT(C5*0.01) -> 1970 | H5: 식자재
A6: 페이결제 | E6: 통장입금 | G6: 230000 | J6: 음식물스티커
H7: 주류 | I7: =217300-43100 -> 174200 | J7: 종량제봉투 | K7: 12500
A8: 금고 실잔액 | C8: 126600 | E8: 마감잔금 | G8: =C5+G2-G6-C22 -> 126600 | H8: 쌀 | I8: 57000
J9: 뚝배기
A10: 현금할인 | E10: 카드할인 | J10: 발매트 | K10: 6000
A11: 할인내역 | H11: 참기름 | J11: 불판세척 | K11: =440000/28 -> 15714.286
A12: 개수 | B12: 목살 | C12: 10 | D12: LA갈비 | F12: 4 | H12: 부탄가스
A13: 매출누계 | C13: =SUM('1:17'!$C$12) -> 221 | F13: =SUM('1:17'!$F$12) -> 141 | H13: 코카콜라음료
A14: 개수 | B14: 생갈비 | C14: 31 | D14: 돼지양념갈비 | F14: 10 | H14: 깍두기,계란
A15: 매출누계 | C15: =SUM('1:17'!$C$14) -> 703 | F15: =SUM('1:17'!$F$14) -> 309 | H15: 식자재2 | I15: =48800+5500+3500+11800+9600+26500+4900+52000+15000 -> 177600 | J15: 비품 및 기타경비
A16: 개수 | B16: 육회 | C16: 4 | D16: 한우업진살 | F16: 7 | J16: 인터넷 주문
A17: 매출누계 | C17: =SUM('1:17'!$C$16) -> 125 | F17: =SUM('1:17'!$F$16) -> 230 | H17: 막걸리 | J17: 다이소 구매
A18: 개수 | B18: 소갈비살 | C18: 31 | D18: LA양념갈비 | F18: 13
A19: 매출누계 | C19: =SUM('1:17'!$C$18) -> 536 | F19: =SUM('1:17'!$F$18) -> 192
D20: 테이블수 | F20: 47
D21: 누적테이블 | F21: =SUM('1:17'!$F$20) -> 899
A22: 중간출금
A23: 출금내역 | H23: 식자재합계 | I23: =SUM(I4:I22) -> 2117331 | J23: 기타경비합계 | K23: =SUM(K4:K22) -> 34214.286 | M23: 현금합계 | N23: =C5+C6 -> 197000
A24: 일매출 | C24: 일평균매출 | E24: 누적총매출 | H24: 일매출 | I24: =I23/A25 -> 0.63147361 | J24: 일매출 | K24: =K23/A25 -> 0.010204082
A25: =C2 -> 3353000 | C25: =E25/I1 -> 3823882.4 | E25: =SUM('1:17'!$A$25) -> 65006000 | H25: 누계 | I25: =SUM('1:17'!$I$21) -> 0 | J25: 누계 | K25: =SUM('1:17'!$K$21) -> 0
A26: 전 월 | H26: 누적매출 | I26: =I25/$E$25 -> 0 | J26: 누적매출 | K26: =K25/$E$25 -> 0
A27: 인 건 비 | B27: 직원A | C27: =4000000/28 -> 142857.14 | E27: 알바X | H27: 인건비합계 | I27: =SUM(C27:D34,F27:G30) -> 804785.71
B28: 직원B | C28: =3800000/28 -> 135714.29 | E28: 알바X | F28: =13000*3.5 -> 45500 | H28: 일매출 | I28: =I27/$A$25 -> 0.2400196
B29: 직원D | C29: =3200000/28 -> 114285.71 | E29: 알바X | H29: 누계 | I29: =SUM('1:17'!$I$25) -> 67249914
B30: 직원E | C30: =3400000/28 -> 121428.57 | E30: 파출 | F30: 120000 | H30: 누적매출 | I30: =I29/$I$27 -> 83.56251
B31: 알바A
B33: 직원C | C33: =3500000/28 -> 125000

Sheet 18
C1: 2025년 | E1: 2월 | F1: 18 | G1: 화 | H1: 실영업일수 | I1: =F1-K1 -> 18 | J1: 휴무일수
A2: 매출 | C2: =SUM(C4:D7) -> 3460500 | E2: 시재 | G2: 126600 | H2: 식자재 | J2: 비품 및 기타경비
H3: 업체 | I3: 금액 | J3: 업체 | K3: 금액
A4: 카드 | C4: 3155500 | E4: 카드수수료(2.75%) | G4: =INT(C4*0.0275) -> 86776 | H4: 고기 | I4: =210600+415500+190259 -> 816359 | J4: 숯
A5: 현금 | C5: 305000 | E5: 현금수수료(1%) | G5: =INT(C5*0.01) -> 3050 | H5: 식자재 | I5: =10+59312+36080+25600+43800+8900+12980+22000 -> 208682
A6: 페이결제 | E6: 통장입금 | G6: 320000 | J6: 음식물스티커
H7: 주류 | J7: 종량제봉투
A8: 금고 실잔액 | C8: 111600 | E8: 마감잔금 | G8: =C5+G2-G6-C22 -> 111600 | H8: 쌀
J9: 뚝배기
A10: 현금할인 | E10: 카드할인 | J10: 발매트
A11: 할인내역 | H11: 참기름 | J11: 불판세척 | K11: =440000/28 -> 15714.286
A12: 개수 | B12: 목살 | C12: 13 | D12: LA갈비 | F12: 8 | H12: 부탄가스
A13: 매출누계 | C13: =SUM('1:18'!$C$12) -> 234 | F13: =SUM('1:18'!$F$12) -> 149 | H13: 코카콜라음료
A14: 개수 | B14: 생갈비 | C14: 22 | D14: 돼지양념갈비 | F14: 6 | H14: 깍두기,계란
A15: 매출누계 | C15: =SUM('1:18'!$C$14) -> 725 | F15: =SUM('1:18'!$F$14) -> 315 | H15: 식자재2 | I15: =12500+13500 -> 26000 | J15: 비품 및 기타경비
A16: 개수 | B16: 육회 | C16: 5 | D16: 한우업진살 | F16: 9 | J16: 인터넷 주문 | K16: 111668
A17: 매출누계 | C17: =SUM('1:18'!$C$16) -> 130 | F17: =SUM('1:18'!$F$16) -> 239 | H17: 막걸리 | J17: 다이소 구매
A18: 개수 | B18: 소갈비살 | C18: 39 | D18: LA양념갈비 | F18: 13
A19: 매출누계 | C19: =SUM('1:18'!$C$18) -> 575 | F19: =SUM('1:18'!$F$18) -> 205
D20: 테이블수 | F20: 48
D21: 누적테이블 | F21: =SUM('1:18'!$F$20) -> 947
A22: 중간출금
A23: 출금내역 | H23: 식자재합계 | I23: =SUM(I4:I22) -> 1051041 | J23: 기타경비합계 | K23: =SUM(K4:K22) -> 127382.29 | M23: 현금합계 | N23: =C5+C6 -> 305000
A24: 일매출 | C24: 일평균매출 | E24: 누적총매출 | H24: 일매출 | I24: =I23/A25 -> 0.30372518 | J24: 일매출 | K24: =K23/A25 -> 0.03681037
A25: =C2 -> 3460500 | C25: =E25/I1 -> 3803694.4 | E25: =SUM('1:18'!$A$25) -> 68466500 | H25: 누계 | I25: =SUM('1:18'!$I$21) -> 0 | J25: 누계 | K25: =SUM('1:18'!$K$21) -> 0
A26: 전 월 | H26: 누적매출 | I26: =I25/$E$25 -> 0 | J26: 누적매출 | K26: =K25/$E$25 -> 0
A27: 인 건 비 | B27: 직원A | C27: =4000000/28 -> 142857.14 | E27: 알바X | H27: 인건비합계 | I27: =SUM(C27:D34,F27:G30) -> 759285.71
B28: 직원B | C28: =3800000/28 -> 135714.29 | E28: 알바X | H28: 일매출 | I28: =I27/$A$25 -> 0.21941503
B29: 직원D | C29: =3200000/28 -> 114285.71 | E29: 알바X | H29: 누계 | I29: =SUM('1:18'!$I$25) -> 67249914
B30: 직원E | C30: =3400000/28 -> 121428.57 | E30: 파출 | F30: 120000 | H30: 누적매출 | I30: =I29/$I$27 -> 88.569971
B31: 알바A
B33: 직원C | C33: =3500000/28 -> 125000

Sheet 19
C1: 2025년 | E1: 2월 | F1: 19 | G1: 수 | H1: 실영업일수 | I1: =F1-K1 -> 19 | J1: 휴무일수
A2: 매출 | C2: =SUM(C4:D7) -> 3590000 | E2: 시재 | G2: 111600 | H2: 식자재 | J2: 비품 및 기타경비
H3: 업체 | I3: 금액 | J3: 업체 | K3: 금액
A4: 카드 | C4: 3432000 | E4: 카드수수료(2.75%) | G4: =INT(C4*0.0275) -> 94380 | H4: 고기 | I4: =415500+221400+185318+56200+61300+300846 -> 1240564 | J4: 숯 | K4: 278000
A5: 현금 | C5: 158000 | E5: 현금수수료(1%) | G5: =INT(C5*0.01) -> 1580 | H5: 식자재 | I5: =47300+41250+38940+88968+144320 -> 360778
A6: 페이결제 | E6: 통장입금 | G6: 150000 | J6: 음식물스티커
H7: 주류 | I7: -24800 | J7: 종량제봉투
A8: 금고 실잔액 | C8: 119600 | E8: 마감잔금 | G8: =C5+G2-G6-C22 -> 119600 | H8: 쌀 | I8: 55000
J9: 뚝배기
A10: 현금할인 | E10: 카드할인 | J10: 발매트
A11: 할인내역 | C11: 선결제 105,000원 | H11: 참기름 | J11: 불판세척 | K11: =440000/28 -> 15714.286
A12: 개수 | B12: 목살 | C12: 4 | D12: LA갈비 | F12: 6 | H12: 부탄가스
A13: 매출누계 | C13: =SUM('1:19'!$C$12) -> 238 | F13: =SUM('1:19'!$F$12) -> 155 | H13: 코카콜라음료
A14: 개수 | B14: 생갈비 | C14: 48 | D14: 돼지양념갈비 | F14: 12 | H14: 깍두기,계란
A15: 매출누계 | C15: =SUM('1:19'!$C$14) -> 773 | F15: =SUM('1:19'!$F$14) -> 327 | H15: 식자재2 | I15: =5500+5500+30500+23600+7500+17600+3200+3500+27500+9600+4900+19200+6200 -> 164300 | J15: 비품 및 기타경비
A16: 개수 | B16: 육회 | C16: 6 | D16: 한우업진살 | F16: 2 | J16: 인터넷 주문 | K16: 8890
A17: 매출누계 | C17: =SUM('1:19'!$C$16) -> 136 | F17: =SUM('1:19'!$F$16) -> 241 | H17: 막걸리 | J17: 다이소 구매
A18: 개수 | B18: 소갈비살 | C18: 26 | D18: LA양념갈비 | F18: 9
A19: 매출누계 | C19: =SUM('1:19'!$C$18) -> 601 | F19: =SUM('1:19'!$F$18) -> 214
D20: 테이블수 | F20: 54
D21: 누적테이블 | F21: =SUM('1:19'!$F$20) -> 1001
A22: 중간출금
A23: 출금내역 | H23: 식자재합계 | I23: =SUM(I4:I22) -> 1795842 | J23: 기타경비합계 | K23: =SUM(K4:K22) -> 302604.29 | M23: 현금합계 | N23: =C5+C6 -> 158000
A24: 일매출 | C24: 일평균매출 | E24: 누적총매출 | H24: 일매출 | I24: =I23/A25 -> 0.50023454 | J24: 일매출 | K24: =K23/A25 -> 0.084290887
A25: =C2 -> 3590000 | C25: =E25/I1 -> 3792447.4 | E25: =SUM('1:19'!$A$25) -> 72056500 | H25: 누계 | I25: =SUM('1:18'!$I$21) -> 0 | J25: 누계 | K25: =SUM('1:18'!$K$21) -> 0
A26: 전 월 | H26: 누적매출 | I26: =I25/$E$25 -> 0 | J26: 누적매출 | K26: =K25/$E$25 -> 0
A27: 인 건 비 | B27: 직원A | C27: =4000000/28 -> 142857.14 | E27: 알바X | H27: 인건비합계 | I27: =SUM(C27:D34,F27:G30) -> 804785.71
B28: 직원B | C28: =3800000/28 -> 135714.29 | E28: 알바X | F28: =13000*3.5 -> 45500 | H28: 일매출 | I28: =I27/$A$25 -> 0.22417429
B29: 직원D | C29: =3200000/28 -> 114285.71 | E29: 알바X | H29: 누계 | I29: =SUM('1:18'!$I$25) -> 67249914
B30: 직원E | C30: =3400000/28 -> 121428.57 | E30: 파출 | F30: 120000 | H30: 누적매출 | I30: =I29/$I$27 -> 83.56251
B31: 알바A
B33: 직원C | C33: =3500000/28 -> 125000

Sheet 20
C1: 2025년 | E1: 2월 | F1: 20 | G1: 목 | H1: 실영업일수 | I1: =F1-K1 -> 20 | J1: 휴무일수
A2: 매출 | C2: =SUM(C4:D7) -> 4182000 | E2: 시재 | G2: 119600 | H2: 식자재 | J2: 비품 및 기타경비
H3: 업체 | I3: 금액 | J3: 업체 | K3: 금액
A4: 카드 | C4: 3851000 | E4: 카드수수료(2.75%) | G4: =INT(C4*0.0275) -> 105902 | H4: 고기 | I4: =221400+177754+253344+445200 -> 1097698 | J4: 숯
A5: 현금 | C5: 331000 | E5: 현금수수료(1%) | G5: =INT(C5*0.01) -> 3310 | H5: 식자재 | I5: =51600+25600+17500 -> 94700
A6: 페이결제 | E6: 통장입금 | G6: 300000 | J6: 음식물스티커
H7: 주류 | I7: 354750 | J7: 종량제봉투
A8: 금고 실잔액 | C8: 150600 | E8: 마감잔금 | G8: =C5+G2-G6-C22 -> 150600 | H8: 쌀
J9: 뚝배기
A10: 현금할인 | E10: 카드할인 | J10: 발매트
A11: 할인내역 | H11: 참기름 | I11: 200000 | J11: 불판세척 | K11: =440000/28 -> 15714.286
A12: 개수 | B12: 목살 | C12: 15 | D12: LA갈비 | F12: 11 | H12: 부탄가스
A13: 매출누계 | C13: =SUM('1:20'!$C$12) -> 253 | F13: =SUM('1:20'!$F$12) -> 166 | H13: 코카콜라음료
A14: 개수 | B14: 생갈비 | C14: 55 | D14: 돼지양념갈비 | F14: 22 | H14: 깍두기,계란
A15: 매출누계 | C15: =SUM('1:20'!$C$14) -> 828 | F15: =SUM('1:20'!$F$14) -> 349 | H15: 식자재2 | I15: =18300+26500+4900+5500+23600+52000+19500+11000 -> 161300 | J15: 비품 및 기타경비
A16: 개수 | B16: 육회 | C16: 6 | D16: 한우업진살 | F16: 9 | J16: 인터넷 주문 | K16: 41373
A17: 매출누계 | C17: =SUM('1:20'!$C$16) -> 142 | F17: =SUM('1:20'!$F$16) -> 250 | H17: 막걸리 | J17: 다이소 구매
A18: 개수 | B18: 소갈비살 | C18: 18 | D18: LA양념갈비 | F18: 17
A19: 매출누계 | C19: =SUM('1:20'!$C$18) -> 619 | F19: =SUM('1:20'!$F$18) -> 231
D20: 테이블수 | F20: 54
D21: 누적테이블 | F21: =SUM('1:20'!$F$20) -> 1055
A22: 중간출금
A23: 출금내역 | H23: 식자재합계 | I23: =SUM(I4:I22) -> 1908448 | J23: 기타경비합계 | K23: =SUM(K4:K22) -> 57087.286 | M23: 현금합계 | N23: =C5+C6 -> 331000
A24: 일매출 | C24: 일평균매출 | E24: 누적총매출 | H24: 일매출 | I24: =I23/A25 -> 0.45634816 | J24: 일매출 | K24: =K23/A25 -> 0.013650714
A25: =C2 -> 4182000 | C25: =E25/I1 -> 3811925 | E25: =SUM('1:20'!$A$25) -> 76238500 | H25: 누계 | I25: =SUM('1:20'!$I$21) -> 0 | J25: 누계 | K25: =SUM('1:20'!$K$21) -> 0
A26: 전 월 | H26: 누적매출 | I26: =I25/$E$25 -> 0 | J26: 누적매출 | K26: =K25/$E$25 -> 0
A27: 인 건 비 | B27: 직원A | C27: =4000000/28 -> 142857.14 | E27: 알바X | H27: 인건비합계 | I27: =SUM(C27:D34,F27:G30) -> 811285.71
B28: 직원B | C28: =3800000/28 -> 135714.29 | E28: 알바X | F28: =13000*4 -> 52000 | H28: 일매출 | I28: =I27/$A$25 -> 0.19399467
B29: 직원D | C29: =3200000/28 -> 114285.71 | E29: 알바X | H29: 누계 | I29: =SUM('1:20'!$I$25) -> 67249914
B30: 직원E | C30: =3400000/28 -> 121428.57 | E30: 파출 | F30: 120000 | H30: 누적매출 | I30: =I29/$I$27 -> 82.893009
B31: 알바A
B33: 직원C | C33: =3500000/28 -> 125000

Sheet 21
C1: 2025년 | E1: 2월 | F1: 21 | G1: 금 | H1: 실영업일수 | I1: =F1-K1 -> 21 | J1: 휴무일수
A2: 매출 | C2: =SUM(C4:D7) -> 4447500 | E2: 시재 | G2: 150600 | H2: 식자재 | J2: 비품 및 기타경비
H3: 업체 | I3: 금액 | J3: 업체 | K3: 금액
A4: 카드 | C4: 4112500 | E4: 카드수수료(2.75%) | G4: =INT(C4*0.0275) -> 113093 | H4: 고기 | I4: =415500+221400+192882+177783+10+271440 -> 1279015 | J4: 숯
A5: 현금 | C5: 335000 | E5: 현금수수료(1%) | G5: =INT(C5*0.01) -> 3350 | H5: 식자재 | I5: =5500+17800+39180+21900 -> 84380
A6: 페이결제 | E6: 통장입금 | G6: 400000 | J6: 음식물스티커
H7: 주류 | I7: =351200-15100 -> 336100 | J7: 종량제봉투
A8: 금고 실잔액 | C8: 85700 | E8: 마감잔금 | G8: =C5+G2-G6-C22 -> 85600 | H8: 쌀 | I8: 57000
J9: 뚝배기
A10: 현금할인 | E10: 카드할인 | J10: 발매트
A11: 할인내역 | H11: 참기름 | J11: 불판세척 | K11: =440000/28 -> 15714.286
A12: 개수 | B12: 목살 | C12: 13 | D12: LA갈비 | F12: 16 | H12: 부탄가스
A13: 매출누계 | C13: =SUM('1:21'!$C$12) -> 266 | F13: =SUM('1:21'!$F$12) -> 182 | H13: 코카콜라음료
A14: 개수 | B14: 생갈비 | C14: 48 | D14: 돼지양념갈비 | F14: 20 | H14: 깍두기,계란
A15: 매출누계 | C15: =SUM('1:21'!$C$14) -> 876 | F15: =SUM('1:21'!$F$14) -> 369 | H15: 식자재2 | I15: =48800+4900+5500+11800+17500+3500+12000+3900+1700 -> 109600 | J15: 비품 및 기타경비
A16: 개수 | B16: 육회 | C16: 9 | D16: 한우업진살 | F16: 17 | J16: 인터넷 주문 | K16: 23934
A17: 매출누계 | C17: =SUM('1:21'!$C$16) -> 151 | F17: =SUM('1:21'!$F$16) -> 267 | H17: 막걸리 | J17: 다이소 구매 | K17: 4000
A18: 개수 | B18: 소갈비살 | C18: 27 | D18: LA양념갈비 | F18: 12
A19: 매출누계 | C19: =SUM('1:21'!$C$18) -> 646 | F19: =SUM('1:21'!$F$18) -> 243
D20: 테이블수 | F20: 65
D21: 누적테이블 | F21: =SUM('1:21'!$F$20) -> 1120
A22: 중간출금
A23: 출금내역 | H23: 식자재합계 | I23: =SUM(I4:I22) -> 1866095 | J23: 기타경비합계 | K23: =SUM(K4:K22) -> 43648.286 | M23: 현금합계 | N23: =C5+C6 -> 335000
A24: 일매출 | C24: 일평균매출 | E24: 누적총매출 | H24: 일매출 | I24: =I23/A25 -> 0.41958291 | J24: 일매출 | K24: =K23/A25 -> 0.0098141171
A25: =C2 -> 4447500 | C25: =E25/I1 -> 3842190.5 | E25: =SUM('1:21'!$A$25) -> 80686000 | H25: 누계 | I25: =SUM('1:21'!$I$21) -> 0 | J25: 누계 | K25: =SUM('1:21'!$K$21) -> 0
A26: 전 월 | H26: 누적매출 | I26: =I25/$E$25 -> 0 | J26: 누적매출 | K26: =K25/$E$25 -> 0
A27: 인 건 비 | B27: 직원A | C27: =4000000/28 -> 142857.14 | E27: 알바X | H27: 인건비합계 | I27: =SUM(C27:D34,F27:G30) -> 824285.71
B28: 직원B | C28: =3800000/28 -> 135714.29 | E28: 알바X | F28: =13000*5 -> 65000 | H28: 일매출 | I28: =I27/$A$25 -> 0.18533687
B29: 직원D | C29: =3200000/28 -> 114285.71 | E29: 알바X | H29: 누계 | I29: =SUM('1:21'!$I$25) -> 67249914
B30: 직원E | C30: =3400000/28 -> 121428.57 | E30: 파출 | F30: 120000 | H30: 누적매출 | I30: =I29/$I$27 -> 81.585684
B31: 알바A
B33: 직원C | C33: =3500000/28 -> 125000

Sheet 22
C1: 2025년 | E1: 2월 | F1: 22 | G1: 토요일 | H1: 실영업일수 | I1: =F1-K1 -> 22 | J1: 휴무일수
A2: 매출 | C2: =SUM(C4:D7) -> 4322000 | E2: 시재 | G2: 85700 | H2: 식자재 | J2: 비품 및 기타경비
H3: 업체 | I3: 금액 | J3: 업체 | K3: 금액
A4: 카드 | C4: 3817750 | E4: 카드수수료(2.75%) | G4: =INT(C4*0.0275) -> 104988 | H4: 고기 | I4: =415500+232200+371161+529308 -> 1548169 | J4: 숯
A5: 현금 | C5: 504250 | E5: 현금수수료(1%) | G5: =INT(C5*0.01) -> 5042 | H5: 식자재 | I5: =34540+41250+59312+36080+51600+25600 -> 248382
A6: 페이결제 | E6: 통장입금 | G6: 450000 | J6: 음식물스티커
H7: 주류 | J7: 종량제봉투
A8: 금고 실잔액 | C8: 139950 | E8: 마감잔금 | G8: =C5+G2-G6-C22 -> 139950 | H8: 쌀
J9: 뚝배기
A10: 현금할인 | E10: 카드할인 | J10: 발매트
A11: 할인내역 | H11: 참기름 | J11: 불판세척 | K11: =440000/28 -> 15714.286
A12: 개수 | B12: 목살 | C12: 19 | D12: LA갈비 | F12: 2 | H12: 부탄가스
A13: 매출누계 | C13: =SUM('1:22'!$C$12) -> 285 | F13: =SUM('1:22'!$F$12) -> 184 | H13: 코카콜라음료
A14: 개수 | B14: 생갈비 | C14: 57 | D14: 돼지양념갈비 | F14: 31 | H14: 깍두기,계란
A15: 매출누계 | C15: =SUM('1:22'!$C$14) -> 933 | F15: =SUM('1:22'!$F$14) -> 400 | H15: 식자재2 | I15: =38400+12500+13500+4000+20400+53000+58000+4900+5500+7500+20000 -> 237700 | J15: 비품 및 기타경비
A16: 개수 | B16: 육회 | C16: 5 | D16: 한우업진살 | F16: 18 | J16: 인터넷 주문 | K16: =32900+14430 -> 47330
A17: 매출누계 | C17: =SUM('1:22'!$C$16) -> 156 | F17: =SUM('1:22'!$F$16) -> 285 | H17: 막걸리 | J17: 다이소 구매
A18: 개수 | B18: 소갈비살 | C18: 40 | D18: LA양념갈비 | F18: 17
A19: 매출누계 | C19: =SUM('1:22'!$C$18) -> 686 | F19: =SUM('1:22'!$F$18) -> 260
D20: 테이블수 | F20: 38
D21: 누적테이블 | F21: =SUM('1:22'!$F$20) -> 1158
A22: 중간출금
A23: 출금내역 | H23: 식자재합계 | I23: =SUM(I4:I22) -> 2034251 | J23: 기타경비합계 | K23: =SUM(K4:K22) -> 63044.286 | M23: 현금합계 | N23: =C5+C6 -> 504250
A24: 일매출 | C24: 일평균매출 | E24: 누적총매출 | H24: 일매출 | I24: =I23/A25 -> 0.47067353 | J24: 일매출 | K24: =K23/A25 -> 0.014586831
A25: =C2 -> 4322000 | C25: =E25/I1 -> 3864000 | E25: =SUM('1:22'!$A$25) -> 85008000 | H25: 누계 | I25: =SUM('1:22'!$I$21) -> 0 | J25: 누계 | K25: =SUM('1:22'!$K$21) -> 0
A26: 전 월 | H26: 누적매출 | I26: =I25/$E$25 -> 0 | J26: 누적매출 | K26: =K25/$E$25 -> 0
