Workbook

Sheet 월합산
A1: 월 합 산
A2: 매출 | C2: =C3+G3+C5 -> 0 | E2: 시제 | H2: 비 고
A3: 카드매출 | C3: =SUM('1'!C3) -> 0 | E3: 현금매출 | G3: =SUM('1'!G3) -> 0
A4: 금고잔액 | C4: =C21 -> 0 | E4: 입금 | G4: =C17 -> 0
A5: 할인금액 | C5: =C6+G6 -> 0 | E5: 잔금 | G5: =C4-G4 -> 0
A6: 현금할인 | C6: =SUM('1'!C7) -> 0 | E6: 카드할인 | G6: =SUM('1'!G7) -> 0
A7: 할인내역
H8: take out | I8: 매출누계 | K8: =SUM('1'!K9) -> 0
H9: 배달 | I9: 매출누계 | K9: =SUM('1'!K10) -> 14300
I10: 배달료누계 | K10: =SUM('1'!K11) -> 0
A11: 중간출금 | H11: 중간입금
A12: 출금내역 | H12: 입금내역
A13: 영업일수 | C13: 일평균매출 | E13: 누적총매출 | H13: 목표일매출 | J13: 목표월매출
A14: =C2 -> 0 | C14: =ROUNDDOWN((E14/A14),-4) -> #DIV/0! | E14: =C2 -> 0
A15: 전 월
A16: 마 감 잔 금 | G16: 마 감 잔 금
A17: 만 | G17: 만
A18: 천 | G18: 천
A19: 오백 | G19: 오백
A20: 백이하 | G20: 백이하
A21: 합계 | C21: =SUM(C17:E20) -> 0 | G21: 합계 | H21: =SUM(H17:K20) -> 0

Sheet 결산
E1: 12월
A4: 고정비용 | F4: 변동비용
A5: 항목 | D5: 항목별 소계 | E5: 매출대비 비율 | F5: 항목 | G5: 업체 | H5: 금액 | J5: 항목별 소계 | M5: 통장입금 | N5: =SUM('1:31'!G6) -> 19793000
A6: 월세 | C6: 6985000 | D6: =C6 -> 6985000 | E6: =D6/$B$45 -> 0.045916942 | F6: 식자재 | G6: 고기 | H6: =SUM('1:31'!I4) -> 32761105 | I6: =H6/$B$45 -> 0.21536002 | J6: =SUM(H6:H18) -> 50089586 | K6: =J6/$B$45 -> 0.32927138
A7: 마케팅 | C7: 2600000 | D7: =C7 -> 2600000 | E7: =D7/$B$45 -> 0.017091489 | G7: 식자재 | H7: =SUM('1:31'!I5) -> 6986991 | I7: =H7/$B$45 -> 0.04593003 | M7: 삼겹살 | N7: =SUM('31'!C15) -> 389
A8: 포스 | C8: 154000 | D8: =C8 -> 154000 | E8: =D8/$B$45 -> 0.001012342 | G8: 주류 | H8: =SUM('1:31'!I7) -> 5407690 | I8: =H8/$B$45 -> 0.035548259 | M8: 목살 | N8: =SUM('31'!C13) -> 320
A9: 수도 | C9: 670000 | D9: =C9 -> 670000 | E9: =D9/$B$45 -> 0.0044043452 | G9: 쌀 | H9: =SUM('1:31'!I8) -> 845000 | I9: =H9/$B$45 -> 0.0055547338 | M9: 육회 | N9: =SUM('31'!C17) -> 136
A10: 화재보험 | C10: 66000 | D10: =C10 -> 66000 | E10: =D10/$B$45 -> 0.00043386087 | G10: 참기름 | H10: =SUM('1:31'!I11) -> 0 | I10: =H10/$B$45 -> 0 | M10: LA갈비 | N10: =SUM('31'!F13) -> 82
A11: 세무사 | C11: 330000 | D11: =C11 -> 330000 | E11: =D11/$B$45 -> 0.0021693043 | G11: 부탄가스 | H11: =SUM('1:31'!I12) -> 0 | I11: =H11/$B$45 -> 0 | M11: 돼지양념갈비 | N11: =SUM('31'!F15) -> 315
A12: 인터넷 | C12: 48000 | D12: =C12 -> 48000 | E12: =D12/$B$45 -> 0.00031553518 | G12: 코카콜라 | H12: =SUM('1:31'!I13) -> 480000 | I12: =H12/$B$45 -> 0.0031553518 | M12: 한우업진살 | N12: =SUM('31'!F17) -> 284
A13: 쿠쿠(블루문) | C13: 66000 | D13: =C13 -> 66000 | E13: =D13/$B$45 -> 0.00043386087 | G13: 깍두기,계란 | H13: =SUM('1:31'!I14) -> 0 | I13: =H13/$B$45 -> 0 | M13: 소갈비살 | N13: =SUM('31'!C19) -> 434
D14: =C14 -> 0 | E14: =D14/$B$45 -> 0 | G14: 막걸리 | H14: =SUM('1:31'!I17) -> 9600 | I14: =H14/$B$45 -> 6.3107035e-05 | M14: LA양념갈비 | N14: =SUM('31'!F19) -> 69
D15: =C15 -> 0 | E15: =D15/$B$45 -> 0 | G15: 식자재2 | H15: =SUM('1:31'!I15) -> 3599200 | I15: =H15/$B$45 -> 0.023659879 | M15: 12월 테이블수 | N15: =SUM('31'!F21) -> 1498
A16: 전기세 | D16: =C16 -> 0 | E16: =D16/$B$45 -> 0
A17: 가스비 | C17: 1298410 | D17: =C17 -> 1298410 | E17: =D17/$B$45 -> 0.0085352923
A18: 소 계 | C18: =SUM(D6:D17) -> 12217410 | E18: =SUM(E6:E17) -> 0.080312971
A19: 급여 | B19: 직원A | C19: 3300000 | D19: =SUM(C19:C30) -> 21279000 | E19: =D19/$B$45 -> 0.13988069 | F19: 비품 및 기타경비 | G19: 숯 | H19: =SUM('1:31'!K4) -> 1202000 | I19: =H19/$B$45 -> 0.0079015267 | J19: =SUM(H19:H32) -> 4162520 | K19: =J19/$B$45 -> 0.027362948
G20: 음식물스티커 | H20: =SUM('1:31'!K6) -> 504000 | I20: =H20/$B$45 -> 0.0033131194
B21: 직원C | C21: 4000000 | G21: 종량재봉투 | H21: =SUM('1:31'!K7) -> 25000 | I21: =H21/$B$45 -> 0.00016434124
B22: 직원D | C22: 3300000 | G22: 뚝배기 | H22: =SUM('1:31'!K9) -> 328900 | I22: =H22/$B$45 -> 0.0021620733
G23: 발매트 | H23: =SUM('1:31'!K10) -> 71500 | I23: =H23/$B$45 -> 0.00047001594
B24: 직원F | C24: 1500000 | G24: 불판세척 | H24: =SUM('1:31'!K11) -> 0 | I24: =H24/$B$45 -> 0
G25: 비품 및 기타경비 | H25: =SUM('1:31'!K15) -> 0 | I25: =H25/$B$45 -> 0
B26: 알바B | C26: =SUM('1:31'!F28) -> 2509000 | G26: 인터넷 주문 | H26: =SUM('1:31'!K16) -> 1996920 | I26: =H26/$B$45 -> 0.013127052
B27: 알바C | C27: =SUM('1:31'!F27) -> 1361750 | G27: 다이소 구매 | H27: =SUM('1:31'!K17) -> 34200 | I27: =H27/$B$45 -> 0.00022481881
B28: 알바X | C28: =SUM('1:31'!F29)+SUM('1:31'!F30) -> 1108250
B29: 홀 파출 | C29: =SUM('1:31'!F32) -> 2238000
B30: 파출 | C30: =SUM('1:31'!F31) -> 1962000
B31: 합계 | C31: =SUM(C19:C30) -> 21279000
A32: 퇴직금(10%) | C32: =SUM(C19:C22)*0.1 -> 1060000 | D32: =C32 -> 1060000 | E32: =(D32:D33)/$B$45 -> 0.0069680685
A33: 4대보험료 | D33: =C33 -> 0 | F33: 현금수수료 (1%) | H33: =SUM('1:31'!$G$5) -> 191757 | J33: =H33 -> 191757 | K33: =J33/$B$45 -> 0.0012605433
A34: 소 계 | C34: =SUM(C6:D17,C19:C24,C32:C33) -> 37594820 | E34: =SUM(E19:E33) -> 0.14684876 | F34: 카드수수료(2.75%) | H34: =SUM('1:31'!$G$4) -> 3475661.5 | J34: =H34 -> 3475661.5 | K34: =J34/$B$45 -> 0.022847781
A35: 합 계 | E35: =E18+E34 -> 0.22716173 | H35: =SUM(J6:J34) -> 57919524 | K35: =SUM(K6:K34) -> 0.38074265
A38: 항목 | B38: 금액 | C38: 항목 비율 | D38: 매출 비율 | F38: 손익분기점
A39: 고정비용 | B39: =$C$34 -> 37594820 | C39: =B39/$B$41 -> 0.39360392 | D39: =B39/$B$45 -> 0.24713517 | F39: 손익분기점 매출액 X
A40: 변동비용 | B40: =$H$35 -> 57919524 | C40: =B40/$B$41 -> 0.60639608 | D40: =B40/$B$45 -> 0.38074265 | F40: 고정비 | H40: F | K40: =$C$34 -> 37594820
A41: 총비용 | B41: =SUM(B39:B40) -> 95514344 | C41: =SUM(C39:C40) -> 1 | D41: =SUM(D39:D40) -> 0.62787782 | F41: 변동비 | H41: V | K41: =$H$35 -> 57919524
A42: 카드매출 | B42: =SUM('1:31'!C4) -> 1.324118e+08 | D42: =B42/$B$45 -> 0.87042877 | F42: 매출액 | H42: S | K42: =$B$45 -> 1.521225e+08
A43: 현금매출 | B43: =SUM('1:31'!C5) -> 19710700 | D43: =B43/$B$45 -> 0.12957123 | F43: 변동비율 | H43: V/S | K43: =(K41)/K42 -> 0.38074265
A44: 페이매출 | B44: =SUM('1:31'!C6) -> 0 | D44: =B44/$B$45 -> 0 | F44: 손익분기점 매출액 | H44: X=F/(1-(V/S)) | K44: =K40/(1-K43) -> 60709526
...

Sheet 1
C1: 2025년 | E1: 12월 | F1: 1 | G1: 월 | H1: 실영업일수 | I1: =F1-K1 -> 1 | J1: 휴무일수
A2: 매출 | C2: =SUM(C4:D7) -> 3335500 | E2: 시재 | G2: 144100 | H2: 식자재 | J2: 비품 및 기타경비
H3: 업체 | I3: 금액 | J3: 업체 | K3: 금액
A4: 카드 | C4: 2762500 | E4: 카드수수료(2.75%) | G4: =INT(C4*0.0275) -> 75968 | H4: 고기 | I4: =287697+294514+439200+221000+223080+190393-(14604+15091+9937+12168+6328+18946+3894+6081+15413+9122+152035+17281) -> 1374984 | J4: 숯
A5: 현금 | C5: 573000 | E5: 현금수수료(1%) | G5: =INT(C5*0.01) -> 5730 | H5: 식자재 | I5: =90860+44000+44000+72000+69000+100000+16720+17060+6440+27540+35520+121000 -> 644140
A6: 페이결제 | E6: 통장입금 | G6: 660000 | J6: 음식물스티커
H7: 주류 | I7: 202100 | J7: 종량제봉투
A8: 금고 실잔액 | E8: 마감잔금 | G8: =C5+G2-G6-C22 -> 57100 | H8: 쌀
J9: 뚝배기
A10: 현금할인 | C10: 10000 | E10: 카드할인 | J10: 발매트 | K10: 14300
A11: 할인내역 | C11: 김효택님 선결제 10,000원 | H11: 참기름 | J11: 불판세척
A12: 개수 | B12: 목살 | C12: 9 | D12: LA갈비 | F12: 4 | H12: 부탄가스
A13: 매출누계 | C13: =SUM('1'!$C$12) -> 9 | F13: =SUM('1'!$F$12) -> 4 | H13: 코카콜라음료
A14: 개수 | B14: 삼겹살 | C14: 11 | D14: 돼지양념갈비 | F14: 7 | H14: 깍두기,계란
A15: 매출누계 | C15: =SUM('1'!$C$14) -> 11 | F15: =SUM('1'!$F$14) -> 7 | H15: 식자재2 | I15: =13600+5500+5500+3500+9600+5900+22000+10500+4200+13500+7000 -> 100800 | J15: 비품 및 기타경비
A16: 개수 | B16: 육회 | C16: 5 | D16: 한우업진살 | F16: 0 | J16: 인터넷 주문 | K16: 315400
A17: 매출누계 | C17: =SUM('1'!$C$16) -> 5 | F17: =SUM('1'!$F$16) -> 0 | H17: 막걸리 | J17: 다이소 구매
A18: 개수 | B18: 소갈비살 | C18: 4 | D18: LA양념갈비 | F18: 1
A19: 매출누계 | C19: =SUM('1'!$C$18) -> 4 | F19: =SUM('1'!$F$18) -> 1
A20: 개수 | D20: 테이블수 | F20: 40
A21: 매출누계 | D21: 누적테이블 | F21: =SUM('1'!$F$20) -> 40
A22: 중간출금
A23: 출금내역 | H23: 식자재합계 | I23: =SUM(I4:I22) -> 2322024 | J23: 기타경비합계 | K23: =SUM(K4:K22) -> 329700 | M23: 현금합계 | N23: =C5+C6 -> 573000
A24: 일매출 | C24: 일평균매출 | E24: 누적총매출 | H24: 일매출 | I24: =I23/A25 -> 0.6961547 | J24: 일매출 | K24: =K23/A25 -> 0.09884575
A25: =C2 -> 3335500 | C25: =E25/I1 -> 3335500 | E25: =SUM('1'!$A$25) -> 3335500 | H25: 누계 | I25: =SUM('1'!$I$23) -> 2322024 | J25: 누계 | K25: =SUM('1'!$K$23) -> 329700
A26: 전 월 | H26: 누적매출 | I26: =I25/$E$25 -> 0.6961547 | J26: 누적매출 | K26: =K25/$E$25 -> 0.09884575
A27: 인 건 비 | B27: 직원A | C27: =3300000/31 -> 106451.61 | E27: 알바C | F27: =13000*4 -> 52000 | H27: 인건비합계 | I27: =SUM(C27:D34,F27:G32) -> 633322.58
B28: 직원C | C28: =4000000/31 -> 129032.26 | E28: 알바B | H28: 일매출 | I28: =I27/$A$25 -> 0.18987336
B29: 직원D | C29: =3300000/31 -> 106451.61 | E29: 알바X | H29: 누계 | I29: =SUM('1'!$I$27) -> 633322.58
B30: 직원F | C30: =1500000/31 -> 48387.097 | E30: 알바X | H30: 누적매출 | I30: =I29/$I$27 -> 1
E31: 파출 | F31: 120000
E32: 홀 파출 | F32: 71000

Sheet 2
C1: 2025년 | E1: 12월 | F1: 2 | G1: 화 | H1: 실영업일수 | I1: =F1-K1 -> 2 | J1: 휴무일수
A2: 매출 | C2: =SUM(C4:D7) -> 4820500 | E2: 시재 | G2: 57100 | H2: 식자재 | J2: 비품 및 기타경비
H3: 업체 | I3: 금액 | J3: 업체 | K3: 금액
A4: 카드 | C4: 4480500 | E4: 카드수수료(2.75%) | G4: =INT(C4*0.0275) -> 123213 | H4: 고기 | I4: =284778+452000+247416 -> 984194 | J4: 숯 | K4: 126000
A5: 현금 | C5: 340000 | E5: 현금수수료(1%) | G5: =INT(C5*0.01) -> 3400 | H5: 식자재 | I5: =50000+69000+60320+30300+36000+3220+27540+17760 -> 294140
A6: 페이결제 | E6: 통장입금 | G6: 300000 | J6: 음식물스티커 | K6: 168000
H7: 주류 | J7: 종량제봉투
A8: 금고 실잔액 | C8: 97100 | E8: 마감잔금 | G8: =C5+G2-G6-C22 -> 97100 | H8: 쌀 | I8: 65000
J9: 뚝배기
A10: 현금할인 | C10: 66000 | E10: 카드할인 | J10: 발매트
A11: 할인내역 | C11: 선결제 할인 (심재일 고객님) 66,000원 | H11: 참기름 | J11: 불판세척
A12: 개수 | B12: 목살 | C12: 8 | D12: LA갈비 | F12: 7 | H12: 부탄가스
A13: 매출누계 | C13: =SUM('1:2'!$C$12) -> 17 | F13: =SUM('1:2'!$F$12) -> 11 | H13: 코카콜라음료
A14: 개수 | B14: 삼겹살 | C14: 12 | D14: 돼지양념갈비 | F14: 5 | H14: 깍두기,계란
A15: 매출누계 | C15: =SUM('1:2'!$C$14) -> 23 | F15: =SUM('1:2'!$F$14) -> 12 | H15: 식자재2 | I15: =20400+4800+11800+4900+28000+3900+6200+6600 -> 86600 | J15: 비품 및 기타경비
A16: 개수 | B16: 육회 | C16: 7 | D16: 한우업진살 | F16: 16 | J16: 인터넷 주문 | K16: =27600+6500+11460 -> 45560
A17: 매출누계 | C17: =SUM('1:2'!$C$16) -> 12 | F17: =SUM('1:2'!$F$16) -> 16 | H17: 막걸리 | I17: 4800 | J17: 다이소 구매
A18: 개수 | B18: 소갈비살 | C18: 16 | D18: LA양념갈비 | F18: 3
A19: 매출누계 | C19: =SUM('1:2'!$C$18) -> 20 | F19: =SUM('1:2'!$F$18) -> 4
D20: 테이블수 | F20: 52
D21: 누적테이블 | F21: =SUM('1:2'!$F$20) -> 92
A22: 중간출금
A23: 출금내역 | H23: 식자재합계 | I23: =SUM(I4:I22) -> 1434734 | J23: 기타경비합계 | K23: =SUM(K4:K22) -> 339560 | M23: 현금합계 | N23: =C5+C6 -> 340000
A24: 일매출 | C24: 일평균매출 | E24: 누적총매출 | H24: 일매출 | I24: =I23/A25 -> 0.29763178 | J24: 일매출 | K24: =K23/A25 -> 0.070440826
A25: =C2 -> 4820500 | C25: =E25/I1 -> 1667750 | E25: =SUM('1'!$A$25) -> 3335500 | H25: 누계 | I25: =SUM('1:2'!$I$23) -> 3756758 | J25: 누계 | K25: =SUM('1'!$K$23) -> 329700
A26: 전 월 | H26: 누적매출 | I26: =I25/$E$25 -> 1.1262953 | J26: 누적매출 | K26: =K25/$E$25 -> 0.09884575
A27: 인 건 비 | B27: 직원A | C27: =3300000/31 -> 106451.61 | E27: 알바C | F27: =13000*5 -> 65000 | H27: 인건비합계 | I27: =SUM(C27:D34,F27:G32) -> 752822.58
B28: 직원C | C28: =4000000/31 -> 129032.26 | E28: 알바B | F28: =13000*3.5 -> 45500 | H28: 일매출 | I28: =I27/$A$25 -> 0.15617106
B29: 직원D | C29: =3300000/31 -> 106451.61 | E29: 알바X | H29: 누계 | I29: =SUM('1:2'!$I$27) -> 1386145.2
B30: 직원F | C30: =1500000/31 -> 48387.097 | E30: 알바X | H30: 누적매출 | I30: =I29/$I$27 -> 1.8412641
E31: 파출 | F31: 120000
E32: 홀 파출 | F32: 132000

Sheet 3
C1: 2025년 | E1: 12월 | F1: 3 | G1: 수 | H1: 실영업일수 | I1: =F1-K1 -> 3 | J1: 휴무일수
A2: 매출 | C2: =SUM(C4:D7) -> 3763000 | E2: 시재 | G2: 97100 | H2: 식자재 | J2: 비품 및 기타경비
H3: 업체 | I3: 금액 | J3: 업체 | K3: 금액
A4: 카드 | C4: 3305000 | E4: 카드수수료(2.75%) | G4: =C4*0.0275 -> 90887.5 | H4: 고기 | I4: =306684+221000+243360+452000+10 -> 1223054 | J4: 숯
A5: 현금 | C5: 458000 | E5: 현금수수료(1%) | G5: =INT(C5*0.01) -> 4580 | H5: 식자재 | I5: 34500
A6: 페이결제 | E6: 통장입금 | G6: 500000 | J6: 음식물스티커 | K6: 168000
H7: 주류 | I7: 333500 | J7: 종량제봉투
A8: 금고 실잔액 | C8: 55100 | E8: 마감잔금 | G8: =C5+G2-G6-C22 -> 55100 | H8: 쌀
J9: 뚝배기
A10: 현금할인 | E10: 카드할인 | J10: 발매트
A11: 할인내역 | H11: 참기름 | J11: 불판세척
A12: 개수 | B12: 목살 | C12: 6 | D12: LA갈비 | F12: 12 | H12: 부탄가스
A13: 매출누계 | C13: =SUM('1:3'!$C$12) -> 23 | F13: =SUM('1:3'!$F$12) -> 23 | H13: 코카콜라음료
A14: 개수 | B14: 삼겹살 | C14: 13 | D14: 돼지양념갈비 | F14: 2 | H14: 깍두기,계란
A15: 매출누계 | C15: =SUM('1:3'!$C$14) -> 36 | F15: =SUM('1:3'!$F$14) -> 14 | H15: 식자재2 | I15: =40800+19200+11800+24800+5500+4500+52000 -> 158600 | J15: 비품 및 기타경비
A16: 개수 | B16: 육회 | C16: 3 | D16: 한우업진살 | F16: 11 | J16: 인터넷 주문
A17: 매출누계 | C17: =SUM('1:3'!$C$16) -> 15 | F17: =SUM('1:3'!$F$16) -> 27 | H17: 막걸리 | J17: 다이소 구매
A18: 개수 | B18: 소갈비살 | C18: 9 | D18: LA양념갈비 | F18: 5
A19: 매출누계 | C19: =SUM('1:3'!$C$18) -> 29 | F19: =SUM('1:3'!$F$18) -> 9
D20: 테이블수 | F20: 49
D21: 누적테이블 | F21: =SUM('1:3'!$F$20) -> 141
A22: 중간출금
A23: 출금내역 | H23: 식자재합계 | I23: =SUM(I4:I22) -> 1749654 | J23: 기타경비합계 | K23: =SUM(K4:K22) -> 168000 | M23: 현금합계 | N23: =C5+C6 -> 458000
A24: 일매출 | C24: 일평균매출 | E24: 누적총매출 | H24: 일매출 | I24: =I23/A25 -> 0.46496253 | J24: 일매출 | K24: =K23/A25 -> 0.04464523
A25: =C2 -> 3763000 | C25: =E25/I1 -> 3973000 | E25: =SUM('1:3'!$A$25) -> 11919000 | H25: 누계 | I25: =SUM('1:3'!$I$23) -> 5506412 | J25: 누계 | K25: =SUM('1:3'!$K$23) -> 837260
A26: 전 월 | H26: 누적매출 | I26: =I25/$E$25 -> 0.46198607 | J26: 누적매출 | K26: =K25/$E$25 -> 0.070245826
A27: 인 건 비 | B27: 직원A | C27: =3300000/31 -> 106451.61 | E27: 알바C | F27: =13000*5 -> 65000 | H27: 인건비합계 | I27: =SUM(C27:D34,F27:G32) -> 627322.58
B28: 직원C | C28: =4000000/31 -> 129032.26 | E28: 알바B | F28: =13000*4 -> 52000 | H28: 일매출 | I28: =I27/$A$25 -> 0.1667081
B29: 직원D | C29: =3300000/31 -> 106451.61 | E29: 알바X | H29: 누계 | I29: =SUM('1:3'!$I$27) -> 2013467.7
B30: 직원F | C30: =1500000/31 -> 48387.097 | E30: 알바X | H30: 누적매출 | I30: =I29/$I$27 -> 3.209621
E31: 파출 | F31: 120000
E32: 홀 파출

Sheet 4
C1: 2025년 | E1: 12월 | F1: 4 | G1: 목 | H1: 실영업일수 | I1: =F1-K1 -> 4 | J1: 휴무일수
A2: 매출 | C2: =SUM(C4:D7) -> 4907000 | E2: 시재 | G2: 55100 | H2: 식자재 | J2: 비품 및 기타경비
H3: 업체 | I3: 금액 | J3: 업체 | K3: 금액
A4: 카드 | C4: 4044000 | E4: 카드수수료(2.75%) | G4: =INT(C4*0.0275) -> 111210 | H4: 고기 | I4: =304250+273663+452000 -> 1029913 | J4: 숯
A5: 현금 | C5: 863000 | E5: 현금수수료(1%) | G5: =INT(C5*0.01) -> 8630 | H5: 식자재 | I5: =50000+29656+39380+34500+27540+60500 -> 241576
A6: 페이결제 | E6: 통장입금 | G6: 800000 | J6: 음식물스티커
H7: 주류 | I7: 203400 | J7: 종량제봉투
A8: 금고 실잔액 | C8: 118100 | E8: 마감잔금 | G8: =C5+G2-G6-C22 -> 118100 | H8: 쌀 | I8: 65000
J9: 뚝배기
A10: 현금할인 | C10: 56000 | E10: 카드할인 | J10: 발매트
A11: 할인내역 | C11: 선결제 56,000원 | H11: 참기름 | J11: 불판세척
A12: 개수 | B12: 목살 | C12: 12 | D12: LA갈비 | F12: 0 | H12: 부탄가스
A13: 매출누계 | C13: =SUM('1:4'!$C$12) -> 35 | F13: =SUM('1:4'!$F$12) -> 23 | H13: 코카콜라음료
A14: 개수 | B14: 삼겹살 | C14: 13 | D14: 돼지양념갈비 | F14: 9 | H14: 깍두기,계란
A15: 매출누계 | C15: =SUM('1:4'!$C$14) -> 49 | F15: =SUM('1:4'!$F$14) -> 23 | H15: 식자재2 | I15: =34000+5900+9300+5500+22000+4900+28000+5500+5000+22000+13000+7000+10500+5500 -> 178100 | J15: 비품 및 기타경비
A16: 개수 | B16: 육회 | C16: 7 | D16: 한우업진살 | F16: 8 | J16: 인터넷 주문
A17: 매출누계 | C17: =SUM('1:4'!$C$16) -> 22 | F17: =SUM('1:4'!$F$16) -> 35 | H17: 막걸리 | J17: 다이소 구매
A18: 개수 | B18: 소갈비살 | C18: 15 | D18: LA양념갈비 | F18: 5
A19: 매출누계 | C19: =SUM('1:4'!$C$18) -> 44 | F19: =SUM('1:4'!$F$18) -> 14
D20: 테이블수 | F20: 55
D21: 누적테이블 | F21: =SUM('1:4'!$F$20) -> 196
A22: 중간출금
A23: 출금내역 | H23: 식자재합계 | I23: =SUM(I4:I22) -> 1717989 | J23: 기타경비합계 | K23: =SUM(K4:K22) -> 0 | M23: 현금합계 | N23: =C5+C6 -> 863000
A24: 일매출 | C24: 일평균매출 | E24: 누적총매출 | H24: 일매출 | I24: =I23/A25 -> 0.35010984 | J24: 일매출 | K24: =K23/A25 -> 0
A25: =C2 -> 4907000 | C25: =E25/I1 -> 4206500 | E25: =SUM('1:4'!$A$25) -> 16826000 | H25: 누계 | I25: =SUM('1:4'!$I$23) -> 7224401 | J25: 누계 | K25: =SUM('1:4'!$K$23) -> 837260
A26: 전 월 | H26: 누적매출 | I26: =I25/$E$25 -> 0.42935938 | J26: 누적매출 | K26: =K25/$E$25 -> 0.049759895
A27: 인 건 비 | B27: 직원A | C27: =3300000/31 -> 106451.61 | E27: 알바C | F27: =13000*5 -> 65000 | H27: 인건비합계 | I27: =SUM(C27:D34,F27:G32) -> 617322.58
B28: 직원C | C28: =4000000/31 -> 129032.26 | E28: 알바B | F28: =13000*7 -> 91000 | H28: 일매출 | I28: =I27/$A$25 -> 0.12580448
B29: 직원D | C29: =3300000/31 -> 106451.61 | E29: 알바X | H29: 누계 | I29: =SUM('1:4'!$I$27) -> 2630790.3
B30: 직원F | C30: =1500000/31 -> 48387.097 | E30: 알바X | H30: 누적매출 | I30: =I29/$I$27 -> 4.2616136
E31: 파출
E32: 홀 파출 | F32: 71000

Sheet 5
C1: 2025년 | E1: 12월 | F1: 5 | G1: 금 | H1: 실영업일수 | I1: =F1-K1 -> 5 | J1: 휴무일수
A2: 매출 | C2: =SUM(C4:D7) -> 5641000.3 | E2: 시재 | G2: 118100 | H2: 식자재 | J2: 비품 및 기타경비
H3: 업체 | I3: 금액 | J3: 업체 | K3: 금액
A4: 카드 | C4: 5099500.3 | E4: 카드수수료(2.75%) | G4: =INT(C4*0.0275) -> 140236 | H4: 고기 | I4: =43500+452000+221000+190393 -> 906893 | J4: 숯
A5: 현금 | C5: 541500 | E5: 현금수수료(1%) | G5: =INT(C5*0.01) -> 5415 | H5: 식자재 | I5: =29656+50000+34500+36000 -> 150156
A6: 페이결제 | E6: 통장입금 | G6: 550000 | J6: 음식물스티커
H7: 주류 | I7: =309700-24800 -> 284900 | J7: 종량제봉투 | K7: 12500
A8: 금고 실잔액 | C8: 109600 | E8: 마감잔금 | G8: =C5+G2-G6 -> 109600 | H8: 쌀 | I8: 65000
J9: 뚝배기
A10: 현금할인 | E10: 카드할인 | J10: 발매트
A11: 할인내역 | H11: 참기름 | J11: 불판세척
A12: 개수 | B12: 목살 | C12: 10 | D12: LA갈비 | F12: 0 | H12: 부탄가스
A13: 매출누계 | C13: =SUM('1:5'!$C$12) -> 45 | F13: =SUM('1:5'!$F$12) -> 23 | H13: 코카콜라음료
A14: 개수 | B14: 삼겹살 | C14: 23 | D14: 돼지양념갈비 | F14: 7 | H14: 깍두기,계란
A15: 매출누계 | C15: =SUM('1:5'!$C$14) -> 72 | F15: =SUM('1:5'!$F$14) -> 30 | H15: 식자재2 | J15: 비품 및 기타경비
A16: 개수 | B16: 육회 | C16: 8 | D16: 한우업진살 | F16: 29 | J16: 인터넷 주문
A17: 매출누계 | C17: =SUM('1:5'!$C$16) -> 30 | F17: =SUM('1:5'!$F$16) -> 64 | H17: 막걸리 | J17: 다이소 구매
A18: 개수 | B18: 소갈비살 | C18: 18 | D18: LA양념갈비 | F18: 3
A19: 매출누계 | C19: =SUM('1:5'!$C$18) -> 62 | F19: =SUM('1:5'!$F$18) -> 17
D20: 테이블수 | F20: 50
D21: 누적테이블 | F21: =SUM('1:5'!$F$20) -> 246
A22: 중간출금
A23: 출금내역 | H23: 식자재합계 | I23: =SUM(I4:I22) -> 1406949 | J23: 기타경비합계 | K23: =SUM(K4:K22) -> 12500 | M23: 현금합계 | N23: =C5+C6 -> 541500
A24: 일매출 | C24: 일평균매출 | E24: 누적총매출 | H24: 일매출 | I24: =I23/A25 -> 0.24941481 | J24: 일매출 | K24: =K23/A25 -> 0.002215919
A25: =C2 -> 5641000.3 | C25: =E25/I1 -> 4493400.1 | E25: =SUM('1:5'!$A$25) -> 22467000 | H25: 누계 | I25: =SUM('1:5'!$I$23) -> 8631350 | J25: 누계 | K25: =SUM('1:5'!$K$23) -> 849760
A26: 전 월 | H26: 누적매출 | I26: =I25/$E$25 -> 0.38417901 | J26: 누적매출 | K26: =K25/$E$25 -> 0.037822584
A27: 인 건 비 | B27: 직원A | C27: =3300000/31 -> 106451.61 | E27: 알바C | H27: 인건비합계 | I27: =SUM(C27:D34,F27:G32) -> 467322.58
B28: 직원C | C28: =4000000/31 -> 129032.26 | E28: 알바B | H28: 일매출 | I28: =I27/$A$25 -> 0.082843921
B29: 직원D | C29: =3300000/31 -> 106451.61 | E29: 알바X | H29: 누계 | I29: =SUM('1:5'!$I$27) -> 3098112.9
B30: 직원F | C30: =1500000/31 -> 48387.097 | E30: 알바X | H30: 누적매출 | I30: =I29/$I$27 -> 6.6294954
E31: 파출
E32: 홀 파출 | F32: 77000
E33: 홀 파출 | G33: 132000

Sheet 6
C1: 2025년 | E1: 12월 | F1: 6 | G1: 토 | H1: 실영업일수 | I1: =F1-K1 -> 6 | J1: 휴무일수
A2: 매출 | C2: =SUM(C4:D7) -> 6477000 | E2: 시재 | G2: 109600 | H2: 식자재 | J2: 비품 및 기타경비
H3: 업체 | I3: 금액 | J3: 업체 | K3: 금액
A4: 카드 | C4: 5926000 | E4: 카드수수료(2.75%) | G4: =INT(C4*0.0275) -> 162965 | H4: 고기 | I4: =570716+907882+221000+239304+174258+452000 -> 2565160 | J4: 숯
A5: 현금 | C5: 551000 | E5: 현금수수료(1%) | G5: =INT(C5*0.01) -> 5510 | H5: 식자재 | I5: =27540+35520+100000+103500+72000+60500+39380 -> 438440
A6: 페이결제 | E6: 통장입금 | G6: 500000 | J6: 음식물스티커
H7: 주류 | J7: 종량제봉투
A8: 금고 실잔액 | C8: 160600 | E8: 마감잔금 | G8: =C5+G2-G6-C22 -> 160600 | H8: 쌀
J9: 뚝배기
A10: 현금할인 | E10: 카드할인 | J10: 발매트
A11: 할인내역 | H11: 참기름 | J11: 불판세척
A12: 개수 | B12: 목살 | C12: 7 | D12: LA갈비 | F12: 0 | H12: 부탄가스
A13: 매출누계 | C13: =SUM('1:6'!$C$12) -> 52 | F13: =SUM('1:6'!$F$12) -> 23 | H13: 코카콜라음료
A14: 개수 | B14: 삼겹살 | C14: 36 | D14: 돼지양념갈비 | F14: 7 | H14: 깍두기,계란
A15: 매출누계 | C15: =SUM('1:6'!$C$14) -> 108 | F15: =SUM('1:6'!$F$14) -> 37 | H15: 식자재2 | I15: 136400 | J15: 비품 및 기타경비
A16: 개수 | B16: 육회 | D16: 한우업진살 | F16: 43 | J16: 인터넷 주문
A17: 매출누계 | C17: =SUM('1:6'!$C$16) -> 30 | F17: =SUM('1:6'!$F$16) -> 107 | H17: 막걸리 | J17: 다이소 구매
A18: 개수 | B18: 소갈비살 | C18: 9 | D18: LA양념갈비 | F18: 0
A19: 매출누계 | C19: =SUM('1:6'!$C$18) -> 71 | F19: =SUM('1:6'!$F$18) -> 17
D20: 테이블수 | F20: 44
D21: 누적테이블 | F21: =SUM('1:6'!$F$20) -> 290
A22: 중간출금
A23: 출금내역 | H23: 식자재합계 | I23: =SUM(I4:I22) -> 3140000 | J23: 기타경비합계 | K23: =SUM(K4:K22) -> 0 | M23: 현금합계 | N23: =C5+C6 -> 551000
A24: 일매출 | C24: 일평균매출 | E24: 누적총매출 | H24: 일매출 | I24: =I23/A25 -> 0.48479234 | J24: 일매출 | K24: =K23/A25 -> 0
A25: =C2 -> 6477000 | C25: =E25/I1 -> 4824000 | E25: =SUM('1:6'!$A$25) -> 28944000 | H25: 누계 | I25: =SUM('1:6'!$I$23) -> 11771350 | J25: 누계 | K25: =SUM('1:6'!$K$23) -> 849760
A26: 전 월 | H26: 누적매출 | I26: =I25/$E$25 -> 0.40669396 | J26: 누적매출 | K26: =K25/$E$25 -> 0.029358761
A27: 인 건 비 | B27: 직원A | C27: =3300000/31 -> 106451.61 | E27: 알바C | H27: 인건비합계 | I27: =SUM(C27:D34,F27:G32) -> 929822.58
B28: 직원C | C28: =4000000/31 -> 129032.26 | E28: 알바B | F28: =13000*9.5 -> 123500 | H28: 일매출 | I28: =I27/$A$25 -> 0.1435576
B29: 직원D | C29: =3300000/31 -> 106451.61 | E29: 알바X | F29: =13000*12 -> 156000 | H29: 누계 | I29: =SUM('1:6'!$I$27) -> 4027935.5
B30: 직원F | C30: =1500000/31 -> 48387.097 | E30: 알바X | H30: 누적매출 | I30: =I29/$I$27 -> 4.3319398
E31: 파출 | F31: 130000
E32: 홀 파출 | F32: 130000

Sheet 7
C1: 2025년 | E1: 12월 | F1: 7 | G1: 일 | H1: 실영업일수 | I1: =F1-K1 -> 7 | J1: 휴무일수
A2: 매출 | C2: =SUM(C4:D7) -> 5656000 | E2: 시재 | G2: 160600 | H2: 식자재 | J2: 비품 및 기타경비
H3: 업체 | I3: 금액 | J3: 업체 | K3: 금액
A4: 카드 | C4: 4947000 | E4: 카드수수료(2.75%) | G4: =INT(C4*0.0275) -> 136042 | H4: 고기 | J4: 숯
A5: 현금 | C5: 709000 | E5: 현금수수료(1%) | G5: =INT(C5*0.01) -> 7090 | H5: 식자재
A6: 페이결제 | E6: 통장입금 | G6: 770000 | J6: 음식물스티커
H7: 주류 | J7: 종량제봉투
A8: 금고 실잔액 | C8: 99600 | E8: 마감잔금 | G8: =C5+G2-G6-C22 -> 99600 | H8: 쌀
J9: 뚝배기
A10: 현금할인 | C10: 60000 | E10: 카드할인 | J10: 발매트
A11: 할인내역 | C11: 슈퍼멤버스 | H11: 참기름 | J11: 불판세척
A12: 개수 | B12: 목살 | C12: 11 | D12: LA갈비 | F12: 3 | H12: 부탄가스
A13: 매출누계 | C13: =SUM('1:7'!$C$12) -> 63 | F13: =SUM('1:7'!$F$12) -> 26 | H13: 코카콜라음료
A14: 개수 | B14: 삼겹살 | C14: 28 | D14: 돼지양념갈비 | F14: 7 | H14: 깍두기,계란
A15: 매출누계 | C15: =SUM('1:7'!$C$14) -> 136 | F15: =SUM('1:7'!$F$14) -> 44 | H15: 식자재2 | J15: 비품 및 기타경비
A16: 개수 | B16: 육회 | C16: 5 | D16: 한우업진살 | F16: 12 | J16: 인터넷 주문 | K16: =501980+17000 -> 518980
A17: 매출누계 | C17: =SUM('1:7'!$C$16) -> 35 | F17: =SUM('1:7'!$F$16) -> 119 | H17: 막걸리 | J17: 다이소 구매
A18: 개수 | B18: 소갈비살 | C18: 14 | D18: LA양념갈비 | F18: 7
A19: 매출누계 | C19: =SUM('1:7'!$C$18) -> 85 | F19: =SUM('1:7'!$F$18) -> 24
D20: 테이블수 | F20: 49
D21: 누적테이블 | F21: =SUM('1:7'!$F$20) -> 339
A22: 중간출금
A23: 출금내역 | H23: 식자재합계 | I23: =SUM(I4:I22) -> 0 | J23: 기타경비합계 | K23: =SUM(K4:K22) -> 518980 | M23: 현금합계 | N23: =C5+C6 -> 709000
A24: 일매출 | C24: 일평균매출 | E24: 누적총매출 | H24: 일매출 | I24: =I23/A25 -> 0 | J24: 일매출 | K24: =K23/A25 -> 0.091757426
A25: =C2 -> 5656000 | C25: =E25/I1 -> 4942857.2 | E25: =SUM('1:7'!$A$25) -> 34600000 | H25: 누계 | I25: =SUM('1:7'!$I$23) -> 11771350 | J25: 누계 | K25: =SUM('1:7'!$K$23) -> 1368740
A26: 전 월 | H26: 누적매출 | I26: =I25/$E$25 -> 0.34021242 | J26: 누적매출 | K26: =K25/$E$25 -> 0.039558959
A27: 인 건 비 | B27: 직원A | C27: =3300000/31 -> 106451.61 | E27: 알바C | H27: 인건비합계 | I27: =SUM(C27:D34,F27:G32) -> 876822.58
B28: 직원C | C28: =4000000/31 -> 129032.26 | E28: 알바B | F28: =13000*9 -> 117000 | H28: 일매출 | I28: =I27/$A$25 -> 0.15502521
B29: 직원D | C29: =3300000/31 -> 106451.61 | E29: 알바X | F29: =13000*11.5 -> 149500 | H29: 누계 | I29: =SUM('1:7'!$I$27) -> 4904758.1
B30: 직원F | C30: =1500000/31 -> 48387.097 | E30: 알바X | H30: 누적매출 | I30: =I29/$I$27 -> 5.5937862
E31: 파출 | F31: 143000
E32: 홀 파출 | F32: 77000

Sheet 8
C1: 2025년 | E1: 12월 | F1: 8 | G1: 월 | H1: 실영업일수 | I1: =F1-K1 -> 8 | J1: 휴무일수
A2: 매출 | C2: =SUM(C4:D7) -> 4252000 | E2: 시재 | G2: 99600 | H2: 식자재 | J2: 비품 및 기타경비
H3: 업체 | I3: 금액 | J3: 업체 | K3: 금액
A4: 카드 | C4: 3638000 | E4: 카드수수료(2.75%) | G4: =INT(C4*0.0275) -> 100045 | H4: 고기 | I4: =56220+452000+221000+235248+212982 -> 1177450 | J4: 숯
A5: 현금 | C5: 614000 | E5: 현금수수료(1%) | G5: =INT(C5*0.01) -> 6140 | H5: 식자재 | I5: =45430+29656+39380+50000+34500+72000+3590+27540+16720 -> 318816
A6: 페이결제 | E6: 통장입금 | G6: 650000 | J6: 음식물스티커
H7: 주류 | I7: 295100 | J7: 종량제봉투
A8: 금고 실잔액 | C8: 63600 | E8: 마감잔금 | G8: =C5+G2-G6-C22 -> 63600 | H8: 쌀
J9: 뚝배기
A10: 현금할인 | E10: 카드할인 | J10: 발매트
A11: 할인내역 | H11: 참기름 | J11: 불판세척
A12: 개수 | B12: 목살 | C12: 8 | D12: LA갈비 | F12: 2 | H12: 부탄가스
A13: 매출누계 | C13: =SUM('1:8'!$C$12) -> 71 | F13: =SUM('1:8'!$F$12) -> 28 | H13: 코카콜라음료
A14: 개수 | B14: 삼겹살 | C14: 12 | D14: 돼지양념갈비 | F14: 9 | H14: 깍두기,계란
A15: 매출누계 | C15: =SUM('1:8'!$C$14) -> 148 | F15: =SUM('1:8'!$F$14) -> 53 | H15: 식자재2 | I15: 435050 | J15: 비품 및 기타경비
A16: 개수 | B16: 육회 | C16: 2 | D16: 한우업진살 | F16: 12 | J16: 인터넷 주문
A17: 매출누계 | C17: =SUM('1:8'!$C$16) -> 37 | F17: =SUM('1:8'!$F$16) -> 131 | H17: 막걸리 | J17: 다이소 구매
A18: 개수 | B18: 소갈비살 | C18: 7 | D18: LA양념갈비 | F18: 6
A19: 매출누계 | C19: =SUM('1:8'!$C$18) -> 92 | F19: =SUM('1:8'!$F$18) -> 30
D20: 테이블수 | F20: 52
D21: 누적테이블 | F21: =SUM('1:8'!$F$20) -> 391
A22: 중간출금
A23: 출금내역 | H23: 식자재합계 | I23: =SUM(I4:I22) -> 2226416 | J23: 기타경비합계 | K23: =SUM(K4:K22) -> 0 | M23: 현금합계 | N23: =C5+C6 -> 614000
A24: 일매출 | C24: 일평균매출 | E24: 누적총매출 | H24: 일매출 | I24: =I23/A25 -> 0.52361618 | J24: 일매출 | K24: =K23/A25 -> 0
A25: =C2 -> 4252000 | C25: =E25/I1 -> 4856500 | E25: =SUM('1:8'!$A$25) -> 38852000 | H25: 누계 | I25: =SUM('1:8'!$I$23) -> 13997766 | J25: 누계 | K25: =SUM('1:8'!$K$23) -> 1368740
A26: 전 월 | H26: 누적매출 | I26: =I25/$E$25 -> 0.36028431 | J26: 누적매출 | K26: =K25/$E$25 -> 0.035229589
A27: 인 건 비 | B27: 직원A | C27: =3300000/31 -> 106451.61 | E27: 알바C | F27: =13000*5 -> 65000 | H27: 인건비합계 | I27: =SUM(C27:D34,F27:G32) -> 698972.58
B28: 직원C | C28: =4000000/31 -> 129032.26 | E28: 알바B | H28: 일매출 | I28: =I27/$A$25 -> 0.16438678
B29: 직원D | C29: =3300000/31 -> 106451.61 | E29: 알바X | H29: 누계 | I29: =SUM('1:8'!$I$27) -> 5603730.6 | M29: `
B30: 직원F | C30: =1500000/31 -> 48387.097 | E30: 알바X | F30: =11700*4.5 -> 52650 | H30: 누적매출 | I30: =I29/$I$27 -> 8.0170965
E31: 파출 | F31: 120000
E32: 홀 파출 | F32: 71000

Sheet 9
C1: 2025년 | E1: 12월 | F1: 9 | G1: 화 | H1: 실영업일수 | I1: =F1-K1 -> 9 | J1: 휴무일수
A2: 매출 | C2: =SUM(C4:D7) -> 4851500 | E2: 시재 | G2: 63600 | H2: 식자재 | J2: 비품 및 기타경비
H3: 업체 | I3: 금액 | J3: 업체 | K3: 금액
A4: 카드 | C4: 4278500 | E4: 카드수수료(2.75%) | G4: =INT(C4*0.0275) -> 117658 | H4: 고기 | I4: =306409+287212+452000+241332+416283+56220 -> 1759456 | J4: 숯 | K4: 256000
A5: 현금 | C5: 573000 | E5: 현금수수료(1%) | G5: =INT(C5*0.01) -> 5730 | H5: 식자재 | I5: =33440+50000+7180+7790 -> 98410
A6: 페이결제 | E6: 통장입금 | G6: 492000 | J6: 음식물스티커
H7: 주류 | J7: 종량제봉투
A8: 금고 실잔액 | C8: 144100 | E8: 마감잔금 | G8: =C5+G2-G6-C22 -> 144600 | H8: 쌀 | I8: 65000
J9: 뚝배기
A10: 현금할인 | E10: 카드할인 | J10: 발매트
A11: 할인내역 | H11: 참기름 | J11: 불판세척
A12: 개수 | B12: 목살 | D12: LA갈비 | H12: 부탄가스
A13: 매출누계 | C13: =SUM('1:9'!$C$12) -> 71 | F13: =SUM('1:9'!$F$12) -> 28 | H13: 코카콜라음료
A14: 개수 | B14: 삼겹살 | D14: 돼지양념갈비 | H14: 깍두기,계란
A15: 매출누계 | C15: =SUM('1:9'!$C$14) -> 148 | F15: =SUM('1:9'!$F$14) -> 53 | H15: 식자재2 | I15: =34000+5900+4800+11500+4200 -> 60400 | J15: 비품 및 기타경비
A16: 개수 | B16: 육회 | D16: 한우업진살 | J16: 인터넷 주문 | K16: 61250
A17: 매출누계 | C17: =SUM('1:9'!$C$16) -> 37 | F17: =SUM('1:9'!$F$16) -> 131 | H17: 막걸리 | J17: 다이소 구매
A18: 개수 | B18: 소갈비살 | D18: LA양념갈비
A19: 매출누계 | C19: =SUM('1:9'!$C$18) -> 92 | F19: =SUM('1:9'!$F$18) -> 30
D20: 테이블수 | F20: 55
D21: 누적테이블 | F21: =SUM('1:9'!$F$20) -> 446
A22: 중간출금
A23: 출금내역 | H23: 식자재합계 | I23: =SUM(I4:I22) -> 1983266 | J23: 기타경비합계 | K23: =SUM(K4:K22) -> 317250 | M23: 현금합계 | N23: =C5+C6 -> 573000
A24: 일매출 | C24: 일평균매출 | E24: 누적총매출 | H24: 일매출 | I24: =I23/A25 -> 0.40879439 | J24: 일매출 | K24: =K23/A25 -> 0.065392147
A25: =C2 -> 4851500 | C25: =E25/I1 -> 4855944.5 | E25: =SUM('1:9'!$A$25) -> 43703500 | H25: 누계 | I25: =SUM('1:9'!$I$23) -> 15981032 | J25: 누계 | K25: =SUM('1:9'!$K$23) -> 1685990
A26: 전 월 | H26: 누적매출 | I26: =I25/$E$25 -> 0.36566938 | J26: 누적매출 | K26: =K25/$E$25 -> 0.038577917
A27: 인 건 비 | B27: 직원A | C27: =3300000/31 -> 106451.61 | E27: 알바C | F27: =13000*5 -> 65000 | H27: 인건비합계 | I27: =SUM(C27:D34,F27:G32) -> 833422.58
B28: 직원C | C28: =4000000/31 -> 129032.26 | E28: 알바B | H28: 일매출 | I28: =I27/$A$25 -> 0.17178658
B29: 직원D | C29: =3300000/31 -> 106451.61 | E29: 알바X | H29: 누계 | I29: =SUM('1:9'!$I$27) -> 6437153.2
B30: 직원F | C30: =1500000/31 -> 48387.097 | E30: 알바X | F30: =11700*3 -> 35100 | H30: 누적매출 | I30: =I29/$I$27 -> 7.7237567
E31: 파출 | F31: 130000
E32: 홀 파출 | F32: =71000*3 -> 213000

Sheet 10
C1: 2025년 | E1: 12월 | F1: 10 | G1: 수 | H1: 실영업일수 | I1: =F1-K1 -> 10 | J1: 휴무일수
A2: 매출 | C2: =SUM(C4:D7) -> 4086500 | E2: 시재 | G2: 144100 | H2: 식자재 | J2: 비품 및 기타경비
H3: 업체 | I3: 금액 | J3: 업체 | K3: 금액
A4: 카드 | C4: 3352500 | E4: 카드수수료(2.75%) | G4: =INT(C4*0.0275) -> 92193 | H4: 고기 | I4: =272608+221000+249444 -> 743052 | J4: 숯
A5: 현금 | C5: 734000 | E5: 현금수수료(1%) | G5: =INT(C5*0.01) -> 7340 | H5: 식자재 | I5: =29656+39380 -> 69036
A6: 페이결제 | E6: 통장입금 | G6: 800000 | J6: 음식물스티커
H7: 주류 | J7: 종량제봉투
A8: 금고 실잔액 | C8: 78100 | E8: 마감잔금 | G8: =C5+G2-G6-C22 -> 78100 | H8: 쌀
J9: 뚝배기
A10: 현금할인 | C10: 242000 | E10: 카드할인 | J10: 발매트 | K10: 14300
A11: 할인내역 | C11: 김유미님 선결제 할인 242,000원 | H11: 참기름 | J11: 불판세척
A12: 개수 | B12: 목살 | C12: 15 | D12: LA갈비 | F12: 2 | H12: 부탄가스 | K12: 40800
A13: 매출누계 | C13: =SUM('1:10'!$C$12) -> 86 | F13: =SUM('1:10'!$F$12) -> 30 | H13: 코카콜라음료
A14: 개수 | B14: 삼겹살 | C14: 9 | D14: 돼지양념갈비 | F14: 15 | H14: 깍두기,계란
A15: 매출누계 | C15: =SUM('1:10'!$C$14) -> 157 | F15: =SUM('1:10'!$F$14) -> 68 | H15: 식자재2 | I15: =11000+9600+54400+11800+18400+15500+21000+11400+3500+13000 -> 169600 | J15: 비품 및 기타경비
A16: 개수 | B16: 육회 | C16: 3 | D16: 한우업진살 | F16: 9 | J16: 인터넷 주문
A17: 매출누계 | C17: =SUM('1:10'!$C$16) -> 40 | F17: =F19 -> 35 | H17: 막걸리 | J17: 다이소 구매
A18: 개수 | B18: 소갈비살 | C18: 9 | D18: LA양념갈비 | F18: 5
A19: 매출누계 | C19: =SUM('1:10'!$C$18) -> 101 | F19: =SUM('1:10'!$F$18) -> 35
D20: 테이블수 | F20: 58
D21: 누적테이블 | F21: =SUM('1:10'!$F$20) -> 504
A22: 중간출금
A23: 출금내역 | H23: 식자재합계 | I23: =SUM(I4:I22) -> 981688 | J23: 기타경비합계 | K23: =SUM(K4:K22) -> 55100 | M23: 현금합계 | N23: =C5+C6 -> 734000
A24: 일매출 | C24: 일평균매출 | E24: 누적총매출 | H24: 일매출 | I24: =I23/A25 -> 0.24022709 | J24: 일매출 | K24: =K23/A25 -> 0.013483421
A25: =C2 -> 4086500 | C25: =E25/I1 -> 4779000 | E25: =SUM('1:10'!$A$25) -> 47790000 | H25: 누계 | I25: =SUM('1:10'!$I$23) -> 16962720 | J25: 누계 | K25: =SUM('1:10'!$K$21) -> 0
A26: 전 월 | H26: 누적매출 | I26: =I25/$E$25 -> 0.35494287 | J26: 누적매출 | K26: =K25/$E$25 -> 0
A27: 인 건 비 | B27: 직원A | C27: =3300000/31 -> 106451.61 | E27: 알바C | F27: =13000*5 -> 65000 | H27: 인건비합계 | I27: =SUM(C27:D34,F27:G32) -> 835322.58
B28: 직원C | C28: =4000000/31 -> 129032.26 | E28: 알바B | F28: =13000*4 -> 52000 | H28: 일매출 | I28: =I27/$A$25 -> 0.20441027
B29: 직원D | C29: =3300000/31 -> 106451.61 | E29: 알바X | H29: 누계 | I29: =SUM('1:10'!$I$25) -> 97925163
B30: 직원F | C30: =1500000/31 -> 48387.097 | E30: 알바X | H30: 누적매출 | I30: =I29/$I$27 -> 117.23036
E31: 파출 | F31: 125000
E32: 홀 파출 | F32: =132000+71000 -> 203000

Sheet 11
C1: 2025년 | E1: 12월 | F1: 11 | G1: 목 | H1: 실영업일수 | I1: =F1-K1 -> 11 | J1: 휴무일수
A2: 매출 | C2: =SUM(C4:D7) -> 4341000 | E2: 시재 | G2: 78100 | H2: 식자재 | J2: 비품 및 기타경비
H3: 업체 | I3: 금액 | J3: 업체 | K3: 금액
A4: 카드 | C4: 3942000 | E4: 카드수수료(2.75%) | G4: =INT(C4*0.0275) -> 108405 | H4: 고기 | I4: =282344+43500+452000+221000+243360+209755 -> 1451959 | J4: 숯
A5: 현금 | C5: 399000 | E5: 현금수수료(1%) | G5: =INT(C5*0.01) -> 3990 | H5: 식자재 | I5: =50000+34500+9890 -> 94390
A6: 페이결제 | E6: 통장입금 | G6: 350000 | J6: 음식물스티커
H7: 주류 | I7: 122000 | J7: 종량제봉투
A8: 금고 실잔액 | C8: 127100 | E8: 마감잔금 | G8: =C5+G2-G6-C22 -> 127100 | H8: 쌀 | I8: 65000
J9: 뚝배기
A10: 현금할인 | C10: 838000 | E10: 카드할인 | J10: 발매트
A11: 할인내역 | C11: 선결제 할인 박부경 752,000 + 86,000 = 838,000원 | H11: 참기름 | J11: 불판세척
A12: 개수 | B12: 목살 | C12: 15 | D12: LA갈비 | F12: 5 | H12: 부탄가스
A13: 매출누계 | C13: =SUM('1:11'!$C$12) -> 101 | F13: =SUM('1:11'!$F$12) -> 35 | H13: 코카콜라음료
A14: 개수 | B14: 삼겹살 | C14: 27 | D14: 돼지양념갈비 | F14: 6 | H14: 깍두기,계란 | M14: ㄴ
A15: 매출누계 | C15: =SUM('1:11'!$C$14) -> 184 | F15: =SUM('1:11'!$F$14) -> 74 | H15: 식자재2 | I15: =9600+11800+20400+9300+7000+9800+22000+33000+5500 -> 128400 | J15: 비품 및 기타경비
A16: 개수 | B16: 육회 | C16: 7 | D16: 한우업진살 | F16: 19 | J16: 인터넷 주문
A17: 매출누계 | C17: =SUM('1:11'!$C$16) -> 47 | F17: =SUM('1:11'!$F$16) -> 159 | H17: 막걸리 | J17: 다이소 구매
A18: 개수 | B18: 소갈비살 | C18: 11 | D18: LA양념갈비 | F18: 9
A19: 매출누계 | C19: =SUM('1:11'!$C$18) -> 112 | F19: =SUM('1:11'!$F$18) -> 44
D20: 테이블수
D21: 누적테이블 | F21: =SUM('1:11'!$F$20) -> 504
A22: 중간출금
A23: 출금내역 | H23: 식자재합계 | I23: =SUM(I4:I22) -> 1861749 | J23: 기타경비합계 | K23: =SUM(K4:K22) -> 0 | M23: 현금합계 | N23: =C5+C6 -> 399000
A24: 일매출 | C24: 일평균매출 | E24: 누적총매출 | H24: 일매출 | I24: =I23/A25 -> 0.4288756 | J24: 일매출 | K24: =K23/A25 -> 0
A25: =C2 -> 4341000 | C25: =E25/I1 -> 4739181.8 | E25: =SUM('1:11'!$A$25) -> 52131000 | H25: 누계 | I25: =SUM('1:11'!$I$23) -> 18824469 | J25: 누계 | K25: =SUM('1:11'!$K$21) -> 0
A26: 전 월 | H26: 누적매출 | I26: =I25/$E$25 -> 0.36109932 | J26: 누적매출 | K26: =K25/$E$25 -> 0
A27: 인 건 비 | B27: 직원A | C27: =3300000/31 -> 106451.61 | E27: 알바C | F27: =13000*5 -> 65000 | H27: 인건비합계 | I27: =SUM(C27:D34,F27:G32) -> 782822.58
B28: 직원C | C28: =4000000/31 -> 129032.26 | E28: 알바B | F28: =13000*10.5 -> 136500 | H28: 일매출 | I28: =I27/$A$25 -> 0.18033232
B29: 직원D | C29: =3300000/31 -> 106451.61 | E29: 알바X | H29: 누계 | I29: =SUM('1:11'!$I$25) -> 116749632
B30: 직원F | C30: =1500000/31 -> 48387.097 | E30: 알바X | H30: 누적매출 | I30: =I29/$I$27 -> 149.13933
E31: 파출 | F31: 120000
E32: 홀 파출 | F32: 71000

Sheet 12
C1: 2025년 | E1: 12월 | F1: 12 | G1: 금 | H1: 실영업일수 | I1: =F1-K1 -> 12 | J1: 휴무일수
A2: 매출 | C2: =SUM(C4:D7) -> 6365000 | E2: 시재 | G2: 127100 | H2: 식자재 | J2: 비품 및 기타경비
H3: 업체 | I3: 금액 | J3: 업체 | K3: 금액
A4: 카드 | C4: 5840500 | E4: 카드수수료(2.75%) | G4: =INT(C4*0.0275) -> 160613 | H4: 고기 | I4: =452000+221000+180712 -> 853712 | J4: 숯
A5: 현금 | C5: 524500 | E5: 현금수수료(1%) | G5: =INT(C5*0.01) -> 5245 | H5: 식자재 | I5: =17760+39380 -> 57140
A6: 페이결제 | E6: 통장입금 | G6: 590000 | J6: 음식물스티커
H7: 주류 | I7: 593500 | J7: 종량제봉투
A8: 금고 실잔액 | C8: 61600 | E8: 마감잔금 | G8: =C5+G2-G6-C22 -> 61600 | H8: 쌀
J9: 뚝배기
A10: 현금할인 | C10: 536000 | E10: 카드할인 | J10: 발매트
A11: 할인내역 | C11: 선결제 | H11: 참기름 | J11: 불판세척
A12: 개수 | B12: 목살 | C12: 7 | D12: LA갈비 | F12: 1 | H12: 부탄가스
A13: 매출누계 | C13: =SUM('1:12'!$C$12) -> 108 | F13: =SUM('1:12'!$F$12) -> 36 | H13: 코카콜라음료
A14: 개수 | B14: 삼겹살 | C14: 20 | D14: 돼지양념갈비 | F14: 11 | H14: 깍두기,계란
A15: 매출누계 | C15: =SUM('1:12'!$C$14) -> 204 | F15: =SUM('1:12'!$F$14) -> 85 | H15: 식자재2 | I15: 332400 | J15: 비품 및 기타경비
A16: 개수 | B16: 육회 | C16: 8 | D16: 한우업진살 | F16: 8 | J16: 인터넷 주문
A17: 매출누계 | C17: =SUM('1:12'!$C$16) -> 55 | F17: =SUM('1:12'!$F$16) -> 167 | H17: 막걸리 | J17: 다이소 구매
A18: 개수 | B18: 소갈비살 | C18: 22 | D18: LA양념갈비 | F18: 2
A19: 매출누계 | C19: =SUM('1:12'!$C$18) -> 134 | F19: =SUM('1:12'!$F$18) -> 46
D20: 테이블수 | F20: 70
D21: 누적테이블 | F21: =SUM('1:12'!$F$20) -> 574
A22: 중간출금
A23: 출금내역 | H23: 식자재합계 | I23: =SUM(I4:I22) -> 1836752 | J23: 기타경비합계 | K23: =SUM(K4:K22) -> 0 | M23: 현금합계 | N23: =C5+C6 -> 524500
A24: 일매출 | C24: 일평균매출 | E24: 누적총매출 | H24: 일매출 | I24: =I23/A25 -> 0.28857062 | J24: 일매출 | K24: =K23/A25 -> 0
A25: =C2 -> 6365000 | C25: =E25/I1 -> 4874666.7 | E25: =SUM('1:12'!$A$25) -> 58496000 | H25: 누계 | I25: =SUM('1:12'!$I$23) -> 20661221 | J25: 누계 | K25: =SUM('1:12'!$K$21) -> 0
A26: 전 월 | H26: 누적매출 | I26: =I25/$E$25 -> 0.35320741 | J26: 누적매출 | K26: =K25/$E$25 -> 0
A27: 인 건 비 | B27: 직원A | C27: =3300000/31 -> 106451.61 | E27: 알바C | F27: =13000*5 -> 65000 | H27: 인건비합계 | I27: =SUM(C27:D34,F27:G32) -> 763322.58
B28: 직원C | C28: =4000000/31 -> 129032.26 | E28: 알바B | F28: =13000*9 -> 117000 | H28: 일매출 | I28: =I27/$A$25 -> 0.11992499
B29: 직원D | C29: =3300000/31 -> 106451.61 | E29: 알바X | H29: 누계 | I29: =SUM('1:12'!$I$25) -> 137410853
B30: 직원F | C30: =1500000/31 -> 48387.097 | E30: 알바X | H30: 누적매출 | I30: =I29/$I$27 -> 180.01675
E31: 파출 | F31: 120000
E32: 홀 파출 | F32: 71000

Sheet 13
C1: 2025년 | E1: 12월 | F1: 13 | G1: 토 | H1: 실영업일수 | I1: =F1-K1 -> 13 | J1: 휴무일수
A2: 매출 | C2: =SUM(C4:D7) -> 4261000 | E2: 시재 | G2: 61600 | H2: 식자재 | J2: 비품 및 기타경비
H3: 업체 | I3: 금액 | J3: 업체 | K3: 금액
A4: 카드 | C4: 3614000 | E4: 카드수수료(2.75%) | G4: =INT(C4*0.0275) -> 99385 | H4: 고기 | J4: 숯
A5: 현금 | C5: 647000 | E5: 현금수수료(1%) | G5: =INT(C5*0.01) -> 6470 | H5: 식자재
A6: 페이결제 | E6: 통장입금 | G6: 650000 | J6: 음식물스티커
H7: 주류 | J7: 종량제봉투
A8: 금고 실잔액 | C8: 58600 | E8: 마감잔금 | G8: =C5+G2-G6-C22 -> 58600 | H8: 쌀
J9: 뚝배기
A10: 현금할인 | C10: 60000 | E10: 카드할인 | J10: 발매트
A11: 할인내역 | C11: 슈퍼멤버스 | H11: 참기름 | J11: 불판세척
A12: 개수 | B12: 목살 | C12: 7 | D12: LA갈비 | F12: 4 | H12: 부탄가스
A13: 매출누계 | C13: =SUM('1:13'!$C$12) -> 115 | F13: =SUM('1:13'!$F$12) -> 40 | H13: 코카콜라음료
A14: 개수 | B14: 삼겹살 | C14: 10 | D14: 돼지양념갈비 | F14: 4 | H14: 깍두기,계란
A15: 매출누계 | C15: =SUM('1:13'!$C$14) -> 214 | F15: =SUM('1:13'!$F$14) -> 89 | H15: 식자재2 | J15: 비품 및 기타경비
A16: 개수 | B16: 육회 | C16: 5 | D16: 한우업진살 | F16: 11 | J16: 인터넷 주문
A17: 매출누계 | C17: =SUM('1:13'!$C$16) -> 60 | F17: =SUM('1:13'!$F$16) -> 178 | H17: 막걸리 | J17: 다이소 구매
A18: 개수 | B18: 소갈비살 | C18: 6 | D18: LA양념갈비 | F18: 2
A19: 매출누계 | C19: =SUM('1:13'!$C$18) -> 140 | F19: =SUM('1:13'!$F$18) -> 48
D20: 테이블수 | F20: 31
D21: 누적테이블 | F21: =SUM('1:13'!$F$20) -> 605
A22: 중간출금
A23: 출금내역 | H23: 식자재합계 | I23: =SUM(I4:I22) -> 0 | J23: 기타경비합계 | K23: =SUM(K4:K22) -> 0 | M23: 현금합계 | N23: =C5+C6 -> 647000
A24: 일매출 | C24: 일평균매출 | E24: 누적총매출 | H24: 일매출 | I24: =I23/A25 -> 0 | J24: 일매출 | K24: =K23/A25 -> 0
A25: =C2 -> 4261000 | C25: =E25/I1 -> 4827461.6 | E25: =SUM('1:13'!$A$25) -> 62757000 | H25: 누계 | I25: =SUM('1:13'!$I$23) -> 20661221 | J25: 누계 | K25: =SUM('1:13'!$K$21) -> 0
A26: 전 월 | H26: 누적매출 | I26: =I25/$E$25 -> 0.32922576 | J26: 누적매출 | K26: =K25/$E$25 -> 0
A27: 인 건 비 | B27: 직원A | C27: =3300000/31 -> 106451.61 | E27: 알바C | H27: 인건비합계 | I27: =SUM(C27:D34,F27:G32) -> 869822.58
B28: 직원C | C28: =4000000/31 -> 129032.26 | E28: 알바B | F28: =13000*9.5 -> 123500 | H28: 일매출 | I28: =I27/$A$25 -> 0.20413579
B29: 직원D | C29: =3300000/31 -> 106451.61 | E29: 알바X | F29: =13000*11 -> 143000 | H29: 누계 | I29: =SUM('1:13'!$I$25) -> 158072074
B30: 직원F | C30: =1500000/31 -> 48387.097 | E30: 알바X | H30: 누적매출 | I30: =I29/$I$27 -> 181.7291
E31: 파출 | F31: =142000-6000 -> 136000
E32: 홀 파출 | F32: 77000

Sheet 14
C1: 2025년 | E1: 12월 | F1: 14 | G1: 일 | H1: 실영업일수 | I1: =F1-K1 -> 14 | J1: 휴무일수
A2: 매출 | C2: =SUM(C4:D7) -> 5192600 | E2: 시재 | G2: 58600 | H2: 식자재 | J2: 비품 및 기타경비
H3: 업체 | I3: 금액 | J3: 업체 | K3: 금액
A4: 카드 | C4: 4156600 | E4: 카드수수료(2.75%) | G4: =INT(C4*0.0275) -> 114306 | H4: 고기 | J4: 숯
A5: 현금 | C5: 1036000 | E5: 현금수수료(1%) | G5: =INT(C5*0.01) -> 10360 | H5: 식자재
A6: 페이결제 | E6: 통장입금 | G6: 1000000 | J6: 음식물스티커
H7: 주류 | J7: 종량제봉투
A8: 금고 실잔액 | C8: 95600 | E8: 마감잔금 | G8: =C5+G2-G6-C22 -> 94600 | H8: 쌀
J9: 뚝배기
A10: 현금할인 | C10: 275400 | E10: 카드할인 | J10: 발매트
A11: 할인내역 | C11: 슈퍼멤버스, 선결제 할인 180,000원 | H11: 참기름 | J11: 불판세척
A12: 개수 | B12: 목살 | C12: 17 | D12: LA갈비 | F12: 8 | H12: 부탄가스
A13: 매출누계 | C13: =SUM('1:14'!$C$12) -> 132 | F13: =SUM('1:14'!$F$12) -> 48 | H13: 코카콜라음료
A14: 개수 | B14: 삼겹살 | C14: 31 | D14: 돼지양념갈비 | F14: 17 | H14: 깍두기,계란
A15: 매출누계 | C15: =SUM('1:14'!$C$14) -> 245 | F15: =SUM('1:14'!$F$14) -> 106 | H15: 식자재2 | J15: 비품 및 기타경비
A16: 개수 | B16: 육회 | C16: 7 | D16: 한우업진살 | F16: 9 | J16: 인터넷 주문
A17: 매출누계 | C17: =SUM('1:14'!$C$16) -> 67 | F17: =SUM('1:14'!$F$16) -> 187 | H17: 막걸리 | J17: 다이소 구매
A18: 개수 | B18: 소갈비살 | C18: 12 | D18: LA양념갈비 | F18: 11
A19: 매출누계 | C19: =SUM('1:14'!$C$18) -> 152 | F19: =SUM('1:14'!$F$18) -> 59
D20: 테이블수 | F20: 59
D21: 누적테이블 | F21: =SUM('1:14'!$F$20) -> 664
A22: 중간출금
A23: 출금내역 | H23: 식자재합계 | I23: =SUM(I4:I22) -> 0 | J23: 기타경비합계 | K23: =SUM(K4:K22) -> 0 | M23: 현금합계 | N23: =C5+C6 -> 1036000
A24: 일매출 | C24: 일평균매출 | E24: 누적총매출 | H24: 일매출 | I24: =I23/A25 -> 0 | J24: 일매출 | K24: =K23/A25 -> 0
A25: =C2 -> 5192600 | C25: =E25/I1 -> 4853542.9 | E25: =SUM('1:14'!$A$25) -> 67949600 | H25: 누계 | I25: =SUM('1:14'!$I$23) -> 20661221 | J25: 누계 | K25: =SUM('1:14'!$K$21) -> 0
A26: 전 월 | H26: 누적매출 | I26: =I25/$E$25 -> 0.30406685 | J26: 누적매출 | K26: =K25/$E$25 -> 0
A27: 인 건 비 | B27: 직원A | C27: =3300000/31 -> 106451.61 | E27: 알바C | H27: 인건비합계 | I27: =SUM(C27:D34,F27:G32) -> 876822.58
B28: 직원C | C28: =4000000/31 -> 129032.26 | E28: 알바B | F28: =13000*10 -> 130000 | H28: 일매출 | I28: =I27/$A$25 -> 0.16886003
B29: 직원D | C29: =3300000/31 -> 106451.61 | E29: 알바X | F29: =13000*11.5 -> 149500 | H29: 누계 | I29: =SUM('1:14'!$I$25) -> 178733295 | M29: `
B30: 직원F | C30: =1500000/31 -> 48387.097 | E30: 알바X | H30: 누적매출 | I30: =I29/$I$27 -> 203.84203
E31: 파출 | F31: 130000
E32: 홀 파출 | F32: 77000

Sheet 15
C1: 2025년 | E1: 12월 | F1: 15 | G1: 월 | H1: 실영업일수 | I1: =F1-K1 -> 15 | J1: 휴무일수
A2: 매출 | C2: =SUM(C4:D7) -> 5596000 | E2: 시재 | G2: 95600 | H2: 식자재 | J2: 비품 및 기타경비
H3: 업체 | I3: 금액 | J3: 업체 | K3: 금액
A4: 카드 | C4: 5129000 | E4: 카드수수료(2.75%) | H4: 고기 | I4: =289646+452000+221000+196847 -> 1159493 | J4: 숯
A5: 현금 | C5: 467000 | E5: 현금수수료(1%) | G5: =INT(C5*0.01) -> 4670 | H5: 식자재 | I5: =29656+39380+50000+34500+36000+27540+18350 -> 235426
A6: 페이결제 | E6: 통장입금 | G6: 500000 | J6: 음식물스티커 | K6: 168000
H7: 주류 | I7: 313450 | J7: 종량제봉투
A8: 금고 실잔액 | C8: 52600 | E8: 마감잔금 | G8: =C5+G2-G6-C22 -> 62600 | H8: 쌀 | I8: 65000
J9: 뚝배기
A10: 현금할인 | E10: 카드할인 | J10: 발매트 | K10: 14300
A11: 할인내역 | H11: 참기름 | J11: 불판세척
A12: 개수 | B12: 목살 | C12: 16 | D12: LA갈비 | F12: 3 | H12: 부탄가스 | K12: 40800
A13: 매출누계 | C13: =SUM('1:15'!$C$12) -> 148 | F13: =SUM('1:15'!$F$12) -> 51 | H13: 코카콜라음료
A14: 개수 | B14: 삼겹살 | C14: 25 | D14: 돼지양념갈비 | F14: 16 | H14: 깍두기,계란
A15: 매출누계 | C15: =SUM('1:15'!$C$14) -> 270 | F15: =SUM('1:15'!$F$14) -> 122 | H15: 식자재2 | I15: 89500 | J15: 비품 및 기타경비
A16: 개수 | B16: 육회 | C16: 0 | D16: 한우업진살 | F16: 8 | J16: 인터넷 주문 | K16: 302830
A17: 매출누계 | C17: =SUM('1:15'!$C$16) -> 67 | F17: =SUM('1:15'!$F$16) -> 195 | H17: 막걸리 | J17: 다이소 구매
A18: 개수 | B18: 소갈비살 | C18: 24 | D18: LA양념갈비 | F18: 0
A19: 매출누계 | C19: =SUM('1:15'!$C$18) -> 176 | F19: =SUM('1:15'!$F$18) -> 59
D20: 테이블수 | F20: 60
D21: 누적테이블 | F21: =SUM('1:15'!$F$20) -> 724
A22: 중간출금
A23: 출금내역 | H23: 식자재합계 | I23: =SUM(I4:I22) -> 1862869 | J23: 기타경비합계 | K23: =SUM(K4:K22) -> 525930 | M23: 현금합계 | N23: =C5+C6 -> 467000
A24: 일매출 | C24: 일평균매출 | E24: 누적총매출 | H24: 일매출 | I24: =I23/A25 -> 0.33289296 | J24: 일매출 | K24: =K23/A25 -> 0.093983202
A25: =C2 -> 5596000 | C25: =E25/I1 -> 4903040 | E25: =SUM('1:15'!$A$25) -> 73545600 | H25: 누계 | I25: =SUM('1:15'!$I$23) -> 22524090 | J25: 누계 | K25: =SUM('1:15'!$K$21) -> 0
A26: 전 월 | H26: 누적매출 | I26: =I25/$E$25 -> 0.3062602 | J26: 누적매출 | K26: =K25/$E$25 -> 0
A27: 인 건 비 | B27: 직원A | C27: =3300000/31 -> 106451.61 | E27: 알바C | H27: 인건비합계 | I27: =SUM(C27:D34,F27:G32) -> 716322.58
B28: 직원C | C28: =4000000/31 -> 129032.26 | E28: 알바B | F28: =13000*10 -> 130000 | H28: 일매출 | I28: =I27/$A$25 -> 0.12800618
B29: 직원D | C29: =3300000/31 -> 106451.61 | E29: 알바X | H29: 누계 | I29: =SUM('1:15'!$I$25) -> 201257385
B30: 직원F | C30: =1500000/31 -> 48387.097 | E30: 알바X | H30: 누적매출 | I30: =I29/$I$27 -> 280.95915
E31: 파출 | F31: 125000
E32: 홀 파출 | F32: 71000

Sheet 16
C1: 2025년 | E1: 12월 | F1: 16 | G1: 화 | H1: 실영업일수 | I1: =F1-K1 -> 16 | J1: 휴무일수
A2: 매출 | C2: =SUM(C4:D7) -> 4748000 | E2: 시재 | G2: 52600 | H2: 식자재 | J2: 비품 및 기타경비
H3: 업체 | I3: 금액 | J3: 업체 | K3: 금액
A4: 카드 | C4: 3789500 | E4: 카드수수료(2.75%) | G4: =INT(C4*0.0275) -> 104211 | H4: 고기 | I4: =294714+296112+452000+221000+195738+211576 -> 1671140 | J4: 숯 | K4: 256000
A5: 현금 | C5: 958500 | E5: 현금수수료(1%) | G5: =INT(C5*0.01) -> 9585 | H5: 식자재 | I5: =50000+16720+18350+39490+60500+26675+29656+44000+39380+5070+13770 -> 343611
A6: 페이결제 | E6: 통장입금 | G6: 900000 | J6: 음식물스티커
H7: 주류 | I7: 207650 | J7: 종량제봉투
A8: 금고 실잔액 | C8: 111100 | E8: 마감잔금 | G8: =C5+G2-G6-C22 -> 111100 | H8: 쌀
J9: 뚝배기
A10: 현금할인 | E10: 카드할인 | J10: 발매트
A11: 할인내역 | H11: 참기름 | J11: 불판세척
A12: 개수 | B12: 목살 | C12: 10 | D12: LA갈비 | F12: 2 | H12: 부탄가스
A13: 매출누계 | C13: =SUM('1:16'!$C$12) -> 158 | F13: =SUM('1:16'!$F$12) -> 53 | H13: 코카콜라음료
A14: 개수 | B14: 삼겹살 | C14: 15 | D14: 돼지양념갈비 | F14: 10 | H14: 깍두기,계란
A15: 매출누계 | C15: =SUM('1:16'!$C$14) -> 285 | F15: =SUM('1:16'!$F$14) -> 132 | H15: 식자재2 | I15: =2450+11800+5500+26000+52000+7200+34000+11500+10500+50000 -> 210950 | J15: 비품 및 기타경비
A16: 개수 | B16: 육회 | C16: 1 | D16: 한우업진살 | F16: 22 | J16: 인터넷 주문 | K16: 78760
A17: 매출누계 | C17: =SUM('1:16'!$C$16) -> 68 | F17: =SUM('1:16'!$F$16) -> 217 | H17: 막걸리 | J17: 다이소 구매
A18: 개수 | B18: 소갈비살 | C18: 10 | D18: LA양념갈비 | F18: 5
A19: 매출누계 | C19: =SUM('1:16'!$C$18) -> 186 | F19: =SUM('1:16'!$F$18) -> 64
D20: 테이블수 | F20: 52
D21: 누적테이블 | F21: =SUM('1:16'!$F$20) -> 776
A22: 중간출금
A23: 출금내역 | H23: 식자재합계 | I23: =SUM(I4:I22) -> 2433351 | J23: 기타경비합계 | K23: =SUM(K4:K22) -> 334760 | M23: 현금합계 | N23: =C5+C6 -> 958500
A24: 일매출 | C24: 일평균매출 | E24: 누적총매출 | H24: 일매출 | I24: =I23/A25 -> 0.51250021 | J24: 일매출 | K24: =K23/A25 -> 0.070505476
A25: =C2 -> 4748000 | C25: =E25/I1 -> 4893350 | E25: =SUM('1:16'!$A$25) -> 78293600 | H25: 누계 | I25: =SUM('1:16'!$I$23) -> 24957441 | J25: 누계 | K25: =SUM('1:16'!$K$21) -> 0
A26: 전 월 | H26: 누적매출 | I26: =I25/$E$25 -> 0.31876732 | J26: 누적매출 | K26: =K25/$E$25 -> 0
A27: 인 건 비 | B27: 직원A | C27: =3300000/31 -> 106451.61 | E27: 알바C | F27: =13000*5 -> 65000 | H27: 인건비합계 | I27: =SUM(C27:D34,F27:G32) -> 776322.58
B28: 직원C | C28: =4000000/31 -> 129032.26 | E28: 알바B | F28: =13000*10 -> 130000 | H28: 일매출 | I28: =I27/$A$25 -> 0.16350518
B29: 직원D | C29: =3300000/31 -> 106451.61 | E29: 알바X | H29: 누계 | I29: =SUM('1:16'!$I$25) -> 226214826
B30: 직원F | C30: =1500000/31 -> 48387.097 | E30: 알바X | H30: 누적매출 | I30: =I29/$I$27 -> 291.39282
E31: 파출 | F31: 120000
E32: 홀 파출 | F32: 71000

Sheet 17
C1: 2025년 | E1: 12월 | F1: 17 | G1: 수 | H1: 실영업일수 | I1: =F1-K1 -> 17 | J1: 휴무일수
A2: 매출 | C2: =SUM(C4:D7) -> 4992500 | E2: 시재 | G2: 111100 | H2: 식자재 | J2: 비품 및 기타경비
H3: 업체 | I3: 금액 | J3: 업체 | K3: 금액
A4: 카드 | C4: 4340500 | E4: 카드수수료(2.75%) | G4: =INT(C4*0.0275) -> 119363 | H4: 고기 | I4: =202606+10+301731+452000+221556 -> 1177903 | J4: 숯
A5: 현금 | C5: 652000 | E5: 현금수수료(1%) | G5: =INT(C5*0.01) -> 6520 | H5: 식자재 | I5: =34500+36000+18350+9770 -> 98620
A6: 페이결제 | E6: 통장입금 | G6: 680000 | J6: 음식물스티커
H7: 주류 | I7: 155100 | J7: 종량제봉투
A8: 금고 실잔액 | C8: 83100 | E8: 마감잔금 | G8: =C5+G2-G6-C22 -> 83100 | H8: 쌀 | I8: 65000
J9: 뚝배기
A10: 현금할인 | C10: 193000 | E10: 카드할인 | J10: 발매트
A11: 할인내역 | C11: 신정인님 선결제 할인, 슈퍼멤버스 | H11: 참기름 | J11: 불판세척
A12: 개수 | B12: 목살 | C12: 13 | D12: LA갈비 | F12: 7 | H12: 부탄가스
A13: 매출누계 | C13: =SUM('1:17'!$C$12) -> 171 | F13: =SUM('1:17'!$F$12) -> 60 | H13: 코카콜라음료
A14: 개수 | B14: 삼겹살 | C14: 25 | D14: 돼지양념갈비 | F14: 7 | H14: 깍두기,계란
A15: 매출누계 | C15: =SUM('1:17'!$C$14) -> 310 | F15: =SUM('1:17'!$F$14) -> 139 | H15: 식자재2 | I15: =47600+4900+7200+10500+5900+5000+5500+28000+3900+13000+5500+3500 -> 140500 | J15: 비품 및 기타경비
A16: 개수 | B16: 육회 | C16: 10 | D16: 한우업진살 | F16: 21 | J16: 인터넷 주문
A17: 매출누계 | C17: =SUM('1:17'!$C$16) -> 78 | F17: =SUM('1:17'!$F$16) -> 238 | H17: 막걸리 | I17: 4800 | J17: 다이소 구매
A18: 개수 | B18: 소갈비살 | C18: 4 | D18: LA양념갈비 | F18: 2
A19: 매출누계 | C19: =SUM('1:17'!$C$18) -> 190 | F19: =SUM('1:17'!$F$18) -> 66
D20: 테이블수 | F20: 53
D21: 누적테이블 | F21: =SUM('1:17'!$F$20) -> 829
A22: 중간출금
A23: 출금내역 | H23: 식자재합계 | I23: =SUM(I4:I22) -> 1641923 | J23: 기타경비합계 | K23: =SUM(K4:K22) -> 0 | M23: 현금합계 | N23: =C5+C6 -> 652000
A24: 일매출 | C24: 일평균매출 | E24: 누적총매출 | H24: 일매출 | I24: =I23/A25 -> 0.32887792 | J24: 일매출 | K24: =K23/A25 -> 0
A25: =C2 -> 4992500 | C25: =E25/I1 -> 4899182.4 | E25: =SUM('1:17'!$A$25) -> 83286100 | H25: 누계 | I25: =SUM('1:17'!$I$23) -> 26599364 | J25: 누계 | K25: =SUM('1:17'!$K$21) -> 0
A26: 전 월 | H26: 누적매출 | I26: =I25/$E$25 -> 0.31937339 | J26: 누적매출 | K26: =K25/$E$25 -> 0
A27: 인 건 비 | B27: 직원A | C27: =3300000/31 -> 106451.61 | E27: 알바C | F27: =13000*5 -> 65000 | H27: 인건비합계 | I27: =SUM(C27:D34,F27:G32) -> 707322.58
B28: 직원C | C28: =4000000/31 -> 129032.26 | E28: 알바B | H28: 일매출 | I28: =I27/$A$25 -> 0.14167703
B29: 직원D | C29: =3300000/31 -> 106451.61 | E29: 알바X | H29: 누계 | I29: =SUM('1:17'!$I$25) -> 252814190
B30: 직원F | C30: =1500000/31 -> 48387.097 | E30: 알바X | H30: 누적매출 | I30: =I29/$I$27 -> 357.42418
E31: 파출 | F31: 132000
E32: 홀 파출 | F32: 120000

Sheet 18
C1: 2025년 | E1: 12월 | F1: 18 | G1: 목 | H1: 실영업일수 | I1: =F1-K1 -> 18 | J1: 휴무일수
A2: 매출 | C2: =SUM(C4:D7) -> 4586500 | E2: 시재 | G2: 83100 | H2: 식자재 | J2: 비품 및 기타경비
H3: 업체 | I3: 금액 | J3: 업체 | K3: 금액
A4: 카드 | C4: 4308500 | E4: 카드수수료(2.75%) | G4: =INT(C4*0.0275) -> 118483 | H4: 고기 | I4: =43500+0+221556 -> 265056 | J4: 숯
A5: 현금 | C5: 278000 | E5: 현금수수료(1%) | G5: =INT(C5*0.01) -> 2780 | H5: 식자재 | I5: =26675+50000+34500+36000+16720+5200+27540+10390 -> 207025
A6: 페이결제 | E6: 통장입금 | G6: 250000 | J6: 음식물스티커
H7: 주류 | I7: 342800 | J7: 종량제봉투
A8: 금고 실잔액 | C8: 111100 | E8: 마감잔금 | G8: =C5+G2-G6-C22 -> 111100 | H8: 쌀
J9: 뚝배기
A10: 현금할인 | C10: 110000 | E10: 카드할인 | J10: 발매트
A11: 할인내역 | C11: 슈퍼멤버스 x 2 | H11: 참기름 | J11: 불판세척
A12: 개수 | B12: 목살 | C12: 1 | D12: LA갈비 | F12: 14 | H12: 부탄가스
A13: 매출누계 | C13: =SUM('1:18'!$C$12) -> 172 | F13: =SUM('1:18'!$F$12) -> 74 | H13: 코카콜라음료
A14: 개수 | B14: 삼겹살 | C14: 3 | D14: 돼지양념갈비 | F14: 52 | H14: 깍두기,계란
A15: 매출누계 | C15: =SUM('1:18'!$C$14) -> 313 | F15: =SUM('1:18'!$F$14) -> 191 | H15: 식자재2 | I15: =20400+4900+5500+4800+11800+26000+11800 -> 85200 | J15: 비품 및 기타경비
A16: 개수 | B16: 육회 | C16: 4 | D16: 한우업진살 | F16: 36 | J16: 인터넷 주문
A17: 매출누계 | C17: =SUM('1:18'!$C$16) -> 82 | F17: =SUM('1:18'!$F$16) -> 274 | H17: 막걸리 | J17: 다이소 구매
A18: 개수 | B18: 소갈비살 | C18: 17 | D18: LA양념갈비 | F18: 3
A19: 매출누계 | C19: =SUM('1:18'!$C$18) -> 207 | F19: =SUM('1:18'!$F$18) -> 69
D20: 테이블수 | F20: 32
D21: 누적테이블 | F21: =SUM('1:18'!$F$20) -> 861
A22: 중간출금
A23: 출금내역 | H23: 식자재합계 | I23: =SUM(I4:I22) -> 900081 | J23: 기타경비합계 | K23: =SUM(K4:K22) -> 0 | M23: 현금합계 | N23: =C5+C6 -> 278000
A24: 일매출 | C24: 일평균매출 | E24: 누적총매출 | H24: 일매출 | I24: =I23/A25 -> 0.19624572 | J24: 일매출 | K24: =K23/A25 -> 0
A25: =C2 -> 4586500 | C25: =E25/I1 -> 4881811.1 | E25: =SUM('1:18'!$A$25) -> 87872600 | H25: 누계 | I25: =SUM('1:18'!$I$23) -> 27499445 | J25: 누계 | K25: =SUM('1:18'!$K$21) -> 0
A26: 전 월 | H26: 누적매출 | I26: =I25/$E$25 -> 0.31294675 | J26: 누적매출 | K26: =K25/$E$25 -> 0
A27: 인 건 비 | B27: 직원A | C27: =3300000/31 -> 106451.61 | E27: 알바C | F27: =13000*5 -> 65000 | H27: 인건비합계 | I27: =SUM(C27:D34,F27:G32) -> 658322.58
B28: 직원C | C28: =4000000/31 -> 129032.26 | E28: 알바B | H28: 일매출 | I28: =I27/$A$25 -> 0.14353485
B29: 직원D | C29: =3300000/31 -> 106451.61 | E29: 알바X | H29: 누계 | I29: =SUM('1:18'!$I$25) -> 280313635
B30: 직원F | C30: =1500000/31 -> 48387.097 | E30: 알바X | H30: 누적매출 | I30: =I29/$I$27 -> 425.79982
E31: 파출
E32: 홀 파출 | F32: =71000+132000 -> 203000

Sheet 19
C1: 2025년 | E1: 12월 | F1: 19 | G1: 금 | H1: 실영업일수 | I1: =F1-K1 -> 19 | J1: 휴무일수
A2: 매출 | C2: =SUM(C4:D7) -> 4964000 | E2: 시재 | G2: 111100 | H2: 식자재 | J2: 비품 및 기타경비
H3: 업체 | I3: 금액 | J3: 업체 | K3: 금액
A4: 카드 | C4: 4509000 | E4: 카드수수료(2.75%) | G4: =INT(C4*0.0275) -> 123997 | H4: 고기 | I4: =452000+235528+233512 -> 921040 | J4: 숯
A5: 현금 | C5: 455000 | E5: 현금수수료(1%) | G5: =INT(C5*0.01) -> 4550 | H5: 식자재 | I5: =44000+39380+50000+34500+36000+18350+45430-26675 -> 240985
A6: 페이결제 | E6: 통장입금 | G6: 450000 | J6: 음식물스티커 | M6: ` | O6: ` | P6: `
H7: 주류 | I7: 193300 | J7: 종량제봉투
A8: 금고 실잔액 | C8: 116100 | E8: 마감잔금 | G8: =C5+G2-G6-C22 -> 116100 | H8: 쌀 | I8: 65000
J9: 뚝배기
A10: 현금할인 | C10: 56000 | E10: 카드할인 | J10: 발매트
A11: 할인내역 | C11: 슈퍼멤버스 | H11: 참기름 | J11: 불판세척
A12: 개수 | B12: 목살 | C12: 11 | D12: LA갈비 | F12: 0 | H12: 부탄가스
A13: 매출누계 | C13: =SUM('1:19'!$C$12) -> 183 | F13: =SUM('1:19'!$F$12) -> 74 | H13: 코카콜라음료
A14: 개수 | B14: 삼겹살 | C14: 26 | D14: 돼지양념갈비 | F14: 13 | H14: 깍두기,계란
A15: 매출누계 | C15: =SUM('1:19'!$C$14) -> 339 | F15: =SUM('1:19'!$F$14) -> 204 | H15: 식자재2 | I15: 81600 | J15: 비품 및 기타경비
A16: 개수 | B16: 육회 | C16: 3 | D16: 한우업진살 | F16: 10 | J16: 인터넷 주문
A17: 매출누계 | C17: =SUM('1:19'!$C$16) -> 85 | F17: =SUM('1:19'!$F$16) -> 284 | H17: 막걸리 | J17: 다이소 구매
A18: 개수 | B18: 소갈비살 | C18: 10 | D18: LA양념갈비
A19: 매출누계 | C19: =SUM('1:19'!$C$18) -> 217 | F19: =SUM('1:19'!$F$18) -> 69
D20: 테이블수 | F20: 60
D21: 누적테이블 | F21: =SUM('1:19'!$F$20) -> 921
A22: 중간출금
A23: 출금내역 | H23: 식자재합계 | I23: =SUM(I4:I22) -> 1501925 | J23: 기타경비합계 | K23: =SUM(K4:K22) -> 0 | M23: 현금합계 | N23: =C5+C6 -> 455000
A24: 일매출 | C24: 일평균매출 | E24: 누적총매출 | H24: 일매출 | I24: =I23/A25 -> 0.30256346 | J24: 일매출 | K24: =K23/A25 -> 0
A25: =C2 -> 4964000 | C25: =E25/I1 -> 4886136.9 | E25: =SUM('1:19'!$A$25) -> 92836600 | H25: 누계 | I25: =SUM('1:19'!$I$23) -> 29001370 | J25: 누계 | K25: =SUM('1:18'!$K$21) -> 0
A26: 전 월 | H26: 누적매출 | I26: =I25/$E$25 -> 0.31239156 | J26: 누적매출 | K26: =K25/$E$25 -> 0
A27: 인 건 비 | B27: 직원A | C27: =3300000/31 -> 106451.61 | E27: 알바C | F27: =13000*5.5 -> 71500 | H27: 인건비합계 | I27: =SUM(C27:D34,F27:G32) -> 662822.58
B28: 직원C | C28: =4000000/31 -> 129032.26 | E28: 알바B | F28: =13000*10 -> 130000 | H28: 일매출 | I28: =I27/$A$25 -> 0.1335259
B29: 직원D | C29: =3300000/31 -> 106451.61 | E29: 알바X | H29: 누계 | I29: =SUM('1:18'!$I$25) -> 280313635 | L29: ㅑ
B30: 직원F | C30: =1500000/31 -> 48387.097 | E30: 알바X | H30: 누적매출 | I30: =I29/$I$27 -> 422.909
E31: 파출
E32: 홀 파출 | F32: 71000

Sheet 20
C1: 2025년 | E1: 12월 | F1: 20 | G1: 토 | H1: 실영업일수 | I1: =F1-K1 -> 20 | J1: 휴무일수
A2: 매출 | C2: =SUM(C4:D7) -> 5150000 | E2: 시재 | G2: 116100 | H2: 식자재 | J2: 비품 및 기타경비
H3: 업체 | I3: 금액 | J3: 업체 | K3: 금액
A4: 카드 | C4: 4595000 | E4: 카드수수료(2.75%) | G4: =INT(C4*0.0275) -> 126362 | H4: 고기 | I4: =235528+192304+10+304070+756624+250740 -> 1739276 | J4: 숯
A5: 현금 | C5: 555000 | E5: 현금수수료(1%) | G5: =INT(C5*0.01) -> 5550 | H5: 식자재 | I5: =59312+50000+34500+18350+9900+27540+60320 -> 259922
A6: 페이결제 | E6: 통장입금 | G6: 625000 | J6: 음식물스티커
H7: 주류 | J7: 종량제봉투
A8: 금고 실잔액 | C8: 46100 | E8: 마감잔금 | G8: =C5+G2-G6-C22 -> 46100 | H8: 쌀
J9: 뚝배기
A10: 현금할인 | E10: 카드할인 | J10: 발매트
A11: 할인내역 | H11: 참기름 | J11: 불판세척
A12: 개수 | B12: 목살 | D12: LA갈비 | H12: 부탄가스
A13: 매출누계 | C13: =SUM('1:20'!$C$12) -> 183 | F13: =SUM('1:20'!$F$12) -> 74 | H13: 코카콜라음료
A14: 개수 | B14: 삼겹살 | D14: 돼지양념갈비 | H14: 깍두기,계란
A15: 매출누계 | C15: =SUM('1:20'!$C$14) -> 339 | F15: =SUM('1:20'!$F$14) -> 204 | H15: 식자재2 | I15: =19200+40800+4900+5500+5900+1700+39000+10500+5500 -> 133000 | J15: 비품 및 기타경비
A16: 개수 | B16: 육회 | D16: 한우업진살 | J16: 인터넷 주문
A17: 매출누계 | C17: =SUM('1:20'!$C$16) -> 85 | F17: =SUM('1:20'!$F$16) -> 284 | H17: 막걸리 | J17: 다이소 구매 | K17: 34200
A18: 개수 | B18: 소갈비살 | D18: LA양념갈비
A19: 매출누계 | C19: =SUM('1:20'!$C$18) -> 217 | F19: =SUM('1:20'!$F$18) -> 69
D20: 테이블수 | F20: 44
D21: 누적테이블 | F21: =SUM('1:20'!$F$20) -> 965
A22: 중간출금
A23: 출금내역 | H23: 식자재합계 | I23: =SUM(I4:I22) -> 2132198 | J23: 기타경비합계 | K23: =SUM(K4:K22) -> 34200 | M23: 현금합계 | N23: =C5+C6 -> 555000
A24: 일매출 | C24: 일평균매출 | E24: 누적총매출 | H24: 일매출 | I24: =I23/A25 -> 0.41401903 | J24: 일매출 | K24: =K23/A25 -> 0.0066407767
A25: =C2 -> 5150000 | C25: =E25/I1 -> 4899330 | E25: =SUM('1:20'!$A$25) -> 97986600 | H25: 누계 | I25: =SUM('1:20'!$I$23) -> 31133568 | J25: 누계 | K25: =SUM('1:20'!$K$21) -> 0
A26: 전 월 | H26: 누적매출 | I26: =I25/$E$25 -> 0.31773291 | J26: 누적매출 | K26: =K25/$E$25 -> 0
A27: 인 건 비 | B27: 직원A | C27: =3300000/31 -> 106451.61 | E27: 알바C | H27: 인건비합계 | I27: =SUM(C27:D34,F27:G32) -> 584822.58
B28: 직원C | C28: =4000000/31 -> 129032.26 | E28: 알바B | F28: =13000*9.5 -> 123500 | H28: 일매출 | I28: =I27/$A$25 -> 0.11355778
B29: 직원D | C29: =3300000/31 -> 106451.61 | E29: 알바X | H29: 누계 | I29: =SUM('1:20'!$I$25) -> 340448573
B30: 직원F | C30: =1500000/31 -> 48387.097 | E30: 알바X | H30: 누적매출 | I30: =I29/$I$27 -> 582.13992
E31: 파출
E32: 홀 파출 | F32: 71000

Sheet 21
C1: 2025년 | E1: 12월 | F1: 21 | G1: 일 | H1: 실영업일수 | I1: =F1-K1 -> 21 | J1: 휴무일수
A2: 매출 | C2: =SUM(C4:D7) -> 4459000 | E2: 시재 | G2: 46100 | H2: 식자재 | J2: 비품 및 기타경비
H3: 업체 | I3: 금액 | J3: 업체 | K3: 금액
A4: 카드 | C4: 3533000 | E4: 카드수수료(2.75%) | G4: =INT(C4*0.0275) -> 97157 | H4: 고기 | J4: 숯
A5: 현금 | C5: 926000 | E5: 현금수수료(1%) | G5: =INT(C5*0.01) -> 9260 | H5: 식자재
A6: 페이결제 | E6: 통장입금 | G6: 880000 | J6: 음식물스티커
H7: 주류 | J7: 종량제봉투
A8: 금고 실잔액 | C8: 92100 | E8: 마감잔금 | G8: =C5+G2-G6-C22 -> 92100 | H8: 쌀
J9: 뚝배기
A10: 현금할인 | C10: 175000 | E10: 카드할인 | J10: 발매트
A11: 할인내역 | C11: 슈퍼멤버스 2팀 + 선결제 | H11: 참기름 | J11: 불판세척
A12: 개수 | B12: 목살 | D12: LA갈비 | H12: 부탄가스
A13: 매출누계 | C13: =SUM('1:21'!$C$12) -> 183 | F13: =SUM('1:21'!$F$12) -> 74 | H13: 코카콜라음료
A14: 개수 | B14: 삼겹살 | D14: 돼지양념갈비 | H14: 깍두기,계란
A15: 매출누계 | C15: =SUM('1:21'!$C$14) -> 339 | F15: =SUM('1:21'!$F$14) -> 204 | H15: 식자재2 | J15: 비품 및 기타경비
A16: 개수 | B16: 육회 | D16: 한우업진살 | J16: 인터넷 주문 | K16: 418340
A17: 매출누계 | C17: =SUM('1:21'!$C$16) -> 85 | F17: =SUM('1:21'!$F$16) -> 284 | H17: 막걸리 | J17: 다이소 구매
A18: 개수 | B18: 소갈비살 | D18: LA양념갈비
A19: 매출누계 | C19: =SUM('1:21'!$C$18) -> 217 | F19: =SUM('1:21'!$F$18) -> 69
D20: 테이블수
D21: 누적테이블 | F21: =SUM('1:21'!$F$20) -> 965
A22: 중간출금
A23: 출금내역 | H23: 식자재합계 | I23: =SUM(I4:I22) -> 0 | J23: 기타경비합계 | K23: =SUM(K4:K22) -> 418340 | M23: 현금합계 | N23: =C5+C6 -> 926000
A24: 일매출 | C24: 일평균매출 | E24: 누적총매출 | H24: 일매출 | I24: =I23/A25 -> 0 | J24: 일매출 | K24: =K23/A25 -> 0.093819242
A25: =C2 -> 4459000 | C25: =E25/I1 -> 4878361.9 | E25: =SUM('1:21'!$A$25) -> 1.024456e+08 | H25: 누계 | I25: =SUM('1:21'!$I$23) -> 31133568 | J25: 누계 | K25: =SUM('1:21'!$K$21) -> 0
A26: 전 월 | H26: 누적매출 | I26: =I25/$E$25 -> 0.30390342 | J26: 누적매출 | K26: =K25/$E$25 -> 0
A27: 인 건 비 | B27: 직원A | C27: =3300000/31 -> 106451.61 | E27: 알바C | H27: 인건비합계 | I27: =SUM(C27:D34,F27:G32) -> 720822.58
B28: 직원C | C28: =4000000/31 -> 129032.26 | E28: 알바B | F28: =13000*9.5 -> 123500 | H28: 일매출 | I28: =I27/$A$25 -> 0.16165566
B29: 직원D | C29: =3300000/31 -> 106451.61 | E29: 알바X | F29: =13000*10 -> 130000 | H29: 누계 | I29: =SUM('1:21'!$I$25) -> 371582141
B30: 직원F | C30: =1500000/31 -> 48387.097 | E30: 알바X | H30: 누적매출 | I30: =I29/$I$27 -> 515.49737
E31: 파출
E32: 홀 파출 | F32: 77000

Sheet 22
C1: 2025년 | E1: 12월 | F1: 22 | G1: 월 | H1: 실영업일수 | I1: =F1-K1 -> 22 | J1: 휴무일수
A2: 매출 | C2: =SUM(C4:D7) -> 4248000 | E2: 시재 | G2: 92100 | H2: 식자재 | J2: 비품 및 기타경비
H3: 업체 | I3: 금액 | J3: 업체 | K3: 금액
A4: 카드 | C4: 3537000 | E4: 카드수수료(2.75%) | G4: =INT(C4*0.0275) -> 97267 | H4: 고기 | I4: =655854+217564+236946 -> 1110364 | J4: 숯
A5: 현금 | C5: 711000 | E5: 현금수수료(1%) | G5: =INT(C5*0.01) -> 7110 | H5: 식자재 | I5: =29656+50000+34500+36000+4950+13770+18350+1513248+10 -> 1700484
A6: 페이결제 | E6: 통장입금 | G6: 750000 | J6: 음식물스티커
H7: 주류 | I7: =308900-44000 -> 264900 | J7: 종량제봉투
A8: 금고 실잔액 | C8: 53100 | E8: 마감잔금 | G8: =C5+G2-G6-C22 -> 53100 | H8: 쌀 | I8: 65000
J9: 뚝배기
A10: 현금할인 | C10: 60000 | E10: 카드할인 | J10: 발매트 | K10: 14300
A11: 할인내역 | C11: 슈퍼멤버스 할인 | H11: 참기름 | J11: 불판세척
A12: 개수 | B12: 목살 | D12: LA갈비 | H12: 부탄가스
A13: 매출누계 | C13: =SUM('1:22'!$C$12) -> 183 | F13: =SUM('1:22'!$F$12) -> 74 | H13: 코카콜라음료
A14: 개수 | B14: 삼겹살 | D14: 돼지양념갈비 | H14: 깍두기,계란
A15: 매출누계 | C15: =SUM('1:22'!$C$14) -> 339 | F15: =SUM('1:22'!$F$14) -> 204 | H15: 식자재2 | I15: =9800+22000+5500+14000+52000+27200+6200+28000+33000+4200 -> 201900 | J15: 비품 및 기타경비
A16: 개수 | B16: 육회 | D16: 한우업진살 | J16: 인터넷 주문 | K16: =101970+19990+29200 -> 151160
A17: 매출누계 | C17: =SUM('1:22'!$C$16) -> 85 | F17: =SUM('1:22'!$F$16) -> 284 | H17: 막걸리 | J17: 다이소 구매
A18: 개수 | B18: 소갈비살 | D18: LA양념갈비
A19: 매출누계 | C19: =SUM('1:22'!$C$18) -> 217 | F19: =SUM('1:22'!$F$18) -> 69
D20: 테이블수 | F20: 49
D21: 누적테이블 | F21: =SUM('1:22'!$F$20) -> 1014
A22: 중간출금
A23: 출금내역 | H23: 식자재합계 | I23: =SUM(I4:I22) -> 3342648 | J23: 기타경비합계 | K23: =SUM(K4:K22) -> 165460 | M23: 현금합계 | N23: =C5+C6 -> 711000
A24: 일매출 | C24: 일평균매출 | E24: 누적총매출 | H24: 일매출 | I24: =I23/A25 -> 0.78687571 | J24: 일매출 | K24: =K23/A25 -> 0.038950094
A25: =C2 -> 4248000 | C25: =E25/I1 -> 4849709.1 | E25: =SUM('1:22'!$A$25) -> 1.066936e+08 | H25: 누계 | I25: =SUM('1:22'!$I$23) -> 34476216 | J25: 누계 | K25: =SUM('1:22'!$K$21) -> 0
A26: 전 월 | H26: 누적매출 | I26: =I25/$E$25 -> 0.32313293 | J26: 누적매출 | K26: =K25/$E$25 -> 0
A27: 인 건 비 | B27: 직원A | C27: =3300000/31 -> 106451.61 | E27: 알바C | F27: =13000*4.5 -> 58500 | H27: 인건비합계 | I27: =SUM(C27:D34,F27:G32) -> 630322.58
B28: 직원C | C28: =4000000/31 -> 129032.26 | E28: 알바B | F28: =13000*8.5 -> 110500 | H28: 일매출 | I28: =I27/$A$25 -> 0.14838102
B29: 직원D | C29: =3300000/31 -> 106451.61 | E29: 알바X | H29: 누계 | I29: =SUM('1:22'!$I$25) -> 406058357
B30: 직원F | C30: =1500000/31 -> 48387.097 | E30: 알바X | H30: 누적매출 | I30: =I29/$I$27 -> 644.20722
E31: 파출 | F31: 71000
E32: 홀 파출

Sheet 23
C1: 2025년 | E1: 12월 | F1: 23 | G1: 화 | H1: 실영업일수 | I1: =F1-K1 -> 23 | J1: 휴무일수
A2: 매출 | C2: =SUM(C4:D7) -> 5065000 | E2: 시재 | G2: 53100 | H2: 식자재 | J2: 비품 및 기타경비
H3: 업체 | I3: 금액 | J3: 업체 | K3: 금액
A4: 카드 | C4: 4530000 | E4: 카드수수료(2.75%) | G4: =INT(C4*0.0275) -> 124575 | H4: 고기 | I4: =331428+452000+213572+243814 -> 1240814 | J4: 숯 | K4: 256000
A5: 현금 | C5: 535000 | E5: 현금수수료(1%) | G5: 0 | H5: 식자재 | I5: =44000+39380+46900+50000+34500 -> 214780
A6: 페이결제 | E6: 통장입금 | G6: 521000 | J6: 음식물스티커
H7: 주류 | J7: 종량제봉투
A8: 금고 실잔액 | C8: 67100 | E8: 마감잔금 | G8: =C5+G2-G6-C22 -> 67100 | H8: 쌀
J9: 뚝배기
A10: 현금할인 | E10: 카드할인 | J10: 발매트
A11: 할인내역 | H11: 참기름 | J11: 불판세척
A12: 개수 | B12: 목살 | D12: LA갈비 | H12: 부탄가스
A13: 매출누계 | C13: =SUM('1:23'!$C$12) -> 183 | F13: =SUM('1:23'!$F$12) -> 74 | H13: 코카콜라음료 | I13: 480000
