Workbook

Sheet 월합산
A1: 월 합 산
A2: 매출 | C2: =C3+G3+C5 -> 0 | E2: 시제 | H2: 비 고
A3: 카드매출 | C3: =SUM('1'!C3) -> 0 | E3: 현금매출 | G3: =SUM('1'!G3) -> 0
A4: 금고잔액 | C4: =C21 -> 0 | E4: 입금 | G4: =C17 -> 0
A5: 할인금액 | C5: =C6+G6 -> 0 | E5: 잔금 | G5: =C4-G4 -> 0
A6: 현금할인 | C6: =SUM('1'!C7) -> 0 | E6: 카드할인 | G6: =SUM('1'!G7) -> 0
A7: 할인내역
H8: take out | I8: 매출누계 | K8: =SUM('1'!K9) -> 0
H9: 배달 | I9: 매출누계 | K9: =SUM('1'!K10) -> 0
I10: 배달료누계 | K10: =SUM('1'!K11) -> 14193.548
A11: 중간출금 | H11: 중간입금
A12: 출금내역 | H12: 입금내역
A13: 영업일수 | C13: 일평균매출 | E13: 누적총매출 | H13: 목표일매출 | J13: 목표월매출
A14: =C2 -> 0 | C14: =ROUNDDOWN((E14/A14),-4) -> #DIV/0! | E14: =C2 -> 0
A15: 전 월
A16: 마 감 잔 금 | G16: 마 감 잔 금
A17: 만 | G17: 만
A18: 천 | G18: 천
A19: 오백 | G19: 오백
A20: 백이하 | G20: 백이하
A21: 합계 | C21: =SUM(C17:E20) -> 0 | G21: 합계 | H21: =SUM(H17:K20) -> 0

Sheet 결산
E1: 5월
A4: 고정비용 | F4: 변동비용
A5: 항목 | D5: 항목별 소계 | E5: 매출대비 비율 | F5: 항목 | G5: 업체 | H5: 금액 | J5: 항목별 소계 | M5: 통장입금 | N5: =SUM('1:31'!G6) -> 19105000
A6: 월세 | C6: 6985000 | D6: =C6 -> 6985000 | E6: =D6/$B$45 -> 0.051828811 | F6: 식자재 | G6: 고기 | H6: =SUM('1:31'!I4) -> 37053972 | I6: =H6/$B$45 -> 0.27494106 | J6: =SUM(H6:H18) -> 50277464 | K6: =J6/$B$45 -> 0.37305958
A7: 마케팅 | C7: 2600000 | D7: =C7 -> 2600000 | E7: =D7/$B$45 -> 0.019292041 | G7: 식자재 | H7: =SUM('1:31'!I5) -> 4689702 | I7: =H7/$B$45 -> 0.034797664 | M7: 생갈비 | N7: =SUM('31'!C15) -> 1268
A8: 포스 | C8: 154000 | D8: =C8 -> 154000 | E8: =D8/$B$45 -> 0.0011426825 | G8: 주류 | H8: =SUM('1:31'!I7) -> 3607440 | I8: =H8/$B$45 -> 0.026767262 | M8: 목살 | N8: =SUM('31'!C13) -> 529
A9: 수도 | C9: 670000 | D9: =C9 -> 670000 | E9: =D9/$B$45 -> 0.0049714107 | G9: 쌀 | H9: =SUM('1:31'!I8) -> 784000 | I9: =H9/$B$45 -> 0.0058172925 | M9: 육회 | N9: =SUM('31'!C17) -> 191
A10: 화재보험 | C10: 66000 | D10: =C10 -> 66000 | E10: =D10/$B$45 -> 0.00048972105 | G10: 참기름 | H10: =SUM('1:31'!I11) -> 300000 | I10: =H10/$B$45 -> 0.0022260048 | M10: LA갈비 | N10: =SUM('31'!F13) -> 342
A11: 세무사 | C11: 330000 | D11: =C11 -> 330000 | E11: =D11/$B$45 -> 0.0024486053 | G11: 부탄가스 | H11: =SUM('1:31'!I12) -> 0 | I11: =H11/$B$45 -> 0 | M11: 돼지양념갈비 | N11: =SUM('31'!F15) -> 635
A12: 인터넷 | C12: 48000 | D12: =C12 -> 48000 | E12: =D12/$B$45 -> 0.00035616077 | G12: 코카콜라 | H12: =SUM('1:31'!I13) -> 240000 | I12: =H12/$B$45 -> 0.0017808038 | M12: 한우업진살 | N12: =SUM('31'!F17) -> 542
A13: 쿠쿠(블루문) | C13: 66000 | D13: =C13 -> 66000 | E13: =D13/$B$45 -> 0.00048972105 | G13: 깍두기,계란 | H13: =SUM('1:31'!I14) -> 0 | I13: =H13/$B$45 -> 0 | M13: 소갈비살 | N13: =SUM('31'!C19) -> 1122
D14: =C14 -> 0 | E14: =D14/$B$45 -> 0 | G14: 막걸리 | H14: =SUM('1:31'!I17) -> 3200 | I14: =H14/$B$45 -> 2.3744051e-05 | M14: LA양념갈비 | N14: =SUM('31'!F19) -> 448
D15: =C15 -> 0 | E15: =D15/$B$45 -> 0 | G15: 식자재2 | H15: =SUM('1:31'!I15) -> 3599150 | I15: =H15/$B$45 -> 0.02670575 | M15: 5월 테이블수 | N15: =SUM('31'!F21) -> 1961
A16: 전기세 | D16: =C16 -> 0 | E16: =D16/$B$45 -> 0
A17: 가스비 | D17: =C17 -> 0 | E17: =D17/$B$45 -> 0
A18: 소 계 | C18: 0 | E18: =SUM(E6:E17) -> 0.081019154
A19: 급여 | B19: 직원A | C19: 4000000 | D19: =SUM(C19:C30) -> 23080000 | E19: =D19/$B$45 -> 0.17125397 | F19: 비품 및 기타경비 | G19: 숯 | H19: =SUM('1:31'!K4) -> 1003000 | I19: =H19/$B$45 -> 0.007442276 | J19: =SUM(H19:H32) -> 3701517 | K19: =J19/$B$45 -> 0.027465315
B20: 직원B | C20: 3800000 | G20: 음식물스티커 | H20: =SUM('1:31'!K6) -> 0 | I20: =H20/$B$45 -> 0
B21: 직원C | C21: 3500000 | G21: 종량재봉투 | H21: =SUM('1:31'!K7) -> 37500 | I21: =H21/$B$45 -> 0.0002782506
B22: 직원D | C22: 3200000 | G22: 뚝배기 | H22: =SUM('1:31'!K9) -> 0 | I22: =H22/$B$45 -> 0
G23: 발매트 | H23: =SUM('1:31'!K10) -> 38000 | I23: =H23/$B$45 -> 0.00028196061
G24: 불판세척 | H24: =SUM('1:31'!K11) -> 440000 | I24: =H24/$B$45 -> 0.003264807
B25: 알바A | C25: =SUM('1:31'!C32) -> 616000 | G25: 비품 및 기타경비 | H25: =SUM('1:31'!K15) -> 298500 | I25: =H25/$B$45 -> 0.0022148748
B26: 알바B | C26: =SUM('1:31'!C33) -> 1274000 | G26: 인터넷 주문 | H26: =SUM('1:31'!K16) -> 1884517 | I26: =H26/$B$45 -> 0.013983146
G27: 다이소 구매 | H27: =SUM('1:31'!K17) -> 0 | I27: =H27/$B$45 -> 0
B28: 알바X | C28: =SUM('1:31'!C34) -> 728000
B29: 홀파출 | C29: =SUM('1:31'!F32) -> 2122000
B30: 파출 | C30: =SUM('1:31'!F31) -> 3840000
B31: 합계 | C31: =SUM(C19:C30) -> 23080000
A32: 퇴직금(10%) | C32: =(C19+C20+C21+C22+C24)*0.1 -> 1450000 | D32: =C32 -> 1450000 | E32: =(D32:D33)/$B$45 -> 0.010759023
A33: 4대보험료 | D33: =C33 -> 0 | F33: 현금수수료 (1%) | H33: =SUM('1:31'!$G$5) -> 185240 | J33: =H33 -> 185240 | K33: =J33/$B$45 -> 0.0013744838
A34: 소 계 | C34: =SUM(C6:D17,C19:C24,C32:C33) -> 37788000 | E34: =SUM(E19:E33) -> 0.18201299 | F34: 카드수수료(2.75%) | H34: =SUM('1:31'!$G$4) -> 3177577 | J34: =H34 -> 3177577 | K34: =J34/$B$45 -> 0.023577672
A35: 합 계 | E35: =E18+E34 -> 0.26303214 | H35: =SUM(J6:J34) -> 57341798 | K35: =SUM(K6:K34) -> 0.42547706
A38: 항목 | B38: 금액 | C38: 항목 비율 | D38: 매출 비율 | F38: 손익분기점
A39: 고정비용 | B39: =$C$34 -> 37788000 | C39: =B39/$B$41 -> 0.39722569 | D39: =B39/$B$45 -> 0.28038756 | F39: 손익분기점 매출액 X
A40: 변동비용 | B40: =$H$35 -> 57341798 | C40: =B40/$B$41 -> 0.60277431 | D40: =B40/$B$45 -> 0.42547706 | F40: 고정비 | H40: F | K40: =$C$34 -> 37788000
A41: 총비용 | B41: =SUM(B39:B40) -> 95129798 | C41: =SUM(C39:C40) -> 1 | D41: =SUM(D39:D40) -> 0.70586462 | F41: 변동비 | H41: V | K41: =$H$35 -> 57341798
A42: 카드매출 | B42: =SUM('1:31'!C4) -> 115548600 | D42: =B42/$B$45 -> 0.85737245 | F42: 매출액 | H42: S | K42: =$B$45 -> 134770600
A43: 현금매출 | B43: =SUM('1:31'!C5) -> 19222000 | D43: =B43/$B$45 -> 0.14262755 | F43: 변동비율 | H43: V/S | K43: =(K41)/K42 -> 0.42547706
A44: 페이매출 | B44: =SUM('1:31'!C6) -> 0 | D44: =B44/$B$45 -> 0 | F44: 손익분기점 매출액 | H44: X=F/(1-(V/S)) | K44: =K40/(1-K43) -> 65772830
...

Sheet 1
C1: 2025년 | E1: 5 | F1: 1 | G1: 목 | H1: 실영업일수 | I1: =F1-K1 -> 1 | J1: 휴무일수
A2: 매출 | C2: =SUM(C4:D7) -> 5495500 | E2: 시재 | G2: 71850 | H2: 식자재 | J2: 비품 및 기타경비
H3: 업체 | I3: 금액 | J3: 업체 | K3: 금액
A4: 카드 | C4: 4490000 | E4: 카드수수료(2.75%) | G4: =INT(C4*0.0275) -> 123475 | H4: 고기 | I4: =56220+30650+477600+904000+205200+200446+184021 -> 2058137 | J4: 숯
A5: 현금 | C5: 1005500 | E5: 현금수수료(1%) | G5: =INT(C5*0.01) -> 10055 | H5: 식자재 | I5: =41250+38940+29656+36080+48300+51200+20130+8780+34540+40700 -> 349576
A6: 페이결제 | E6: 통장입금 | G6: 940000 | J6: 음식물스티커
H7: 주류 | J7: 종량제봉투
A8: 금고 실잔액 | C8: 141250 | E8: 마감잔금 | G8: =C5+G2-G6-C22 -> 137350 | H8: 쌀
J9: 뚝배기
A10: 현금할인 | C10: 50000 | E10: 카드할인 | J10: 발매트
A11: 할인내역 | C11: 체험단 50,000원 | H11: 참기름 | I11: 100000 | J11: 불판세척 | K11: =440000/31 -> 14193.548
A12: 개수 | B12: 목살 | C12: 21 | D12: LA갈비 | F12: 11 | H12: 부탄가스
A13: 매출누계 | C13: =SUM('1'!$C$12) -> 21 | F13: =SUM('1'!$F$12) -> 11 | H13: 코카콜라음료
A14: 개수 | B14: 생갈비 | C14: 30 | D14: 돼지양념갈비 | F14: 30 | H14: 깍두기,계란
A15: 매출누계 | C15: =SUM('1'!$C$14) -> 30 | F15: =SUM('1'!$F$14) -> 30 | H15: 식자재2 | J15: 비품 및 기타경비
A16: 개수 | B16: 육회 | C16: 10 | D16: 한우업진살 | F16: 24 | J16: 인터넷 주문 | K16: 14350
A17: 매출누계 | C17: =SUM('1'!$C$16) -> 10 | F17: =SUM('1'!$F$16) -> 24 | H17: 막걸리 | J17: 다이소 구매
A18: 개수 | B18: 소갈비살 | C18: 71 | D18: LA양념갈비 | F18: 25
A19: 매출누계 | C19: =SUM('1'!$C$18) -> 71 | F19: =SUM('1'!$F$18) -> 25
A20: 개수 | D20: 테이블수 | F20: 80
A21: 매출누계 | D21: 누적테이블 | F21: =SUM('1'!$F$20) -> 80
A22: 중간출금
A23: 출금내역 | H23: 식자재합계 | I23: =SUM(I4:I22) -> 2507713 | J23: 기타경비합계 | K23: =SUM(K4:K22) -> 28543.548 | M23: 현금합계 | N23: =C5+C6 -> 1005500
A24: 일매출 | C24: 일평균매출 | E24: 누적총매출 | H24: 일매출 | I24: =I23/A25 -> 0.45632117 | J24: 일매출 | K24: =K23/A25 -> 0.0051939857
A25: =C2 -> 5495500 | C25: =E25/I1 -> 5495500 | E25: =SUM('1'!$A$25) -> 5495500 | H25: 누계 | I25: =SUM('1'!$I$23) -> 2507713 | J25: 누계 | K25: =SUM('1'!$K$23) -> 28543.548
A26: 전 월 | H26: 누적매출 | I26: =I25/$E$25 -> 0.45632117 | J26: 누적매출 | K26: =K25/$E$25 -> 0.0051939857
A27: 인 건 비 | B27: 직원A | C27: =4000000/31 -> 129032.26 | H27: 인건비합계 | I27: =SUM(C27:D34,F27:G32) -> 781741.94
B28: 직원B | C28: =3800000/31 -> 122580.65 | H28: 일매출 | I28: =I27/$A$25 -> 0.14225128
B29: 직원D | C29: =3200000/31 -> 103225.81 | H29: 누계 | I29: =SUM('1'!$I$27) -> 781741.94
H30: 누적매출 | I30: =I29/$I$27 -> 1
B31: 직원C | C31: =3500000/31 -> 112903.23 | E31: 파출 | F31: 130000
B32: 알바A | E32: 홀 파출 | F32: 132000
B33: 알바B | C33: =13000*4 -> 52000

Sheet 2
C1: 2025년 | E1: 5 | F1: 2 | G1: 금요일 | H1: 실영업일수 | I1: =F1-K1 -> 2 | J1: 휴무일수
A2: 매출 | C2: =SUM(C4:D7) -> 4980600 | E2: 시재 | G2: 141250 | H2: 식자재 | J2: 비품 및 기타경비
H3: 업체 | I3: 금액 | J3: 업체 | K3: 금액
A4: 카드 | C4: 4427600 | E4: 카드수수료(2.75%) | G4: =INT(C4*0.0275) -> 121759 | H4: 고기 | J4: 숯
A5: 현금 | C5: 553000 | E5: 현금수수료(1%) | G5: =INT(C5*0.01) -> 5530 | H5: 식자재
A6: 페이결제 | E6: 통장입금 | G6: 500000 | J6: 음식물스티커
H7: 주류 | J7: 종량제봉투
A8: 금고 실잔액 | C8: 194250 | E8: 마감잔금 | G8: =C5+G2-G6-C22 -> 194250 | H8: 쌀 | I8: 112000
J9: 뚝배기
A10: 현금할인 | E10: 카드할인 | J10: 발매트
A11: 할인내역 | H11: 참기름 | J11: 불판세척 | K11: =440000/31 -> 14193.548
A12: 개수 | B12: 목살 | C12: 23 | D12: LA갈비 | F12: 10 | H12: 부탄가스
A13: 매출누계 | C13: =SUM('1:2'!$C$12) -> 44 | F13: =SUM('1:2'!$F$12) -> 21 | H13: 코카콜라음료
A14: 개수 | B14: 생갈비 | C14: 35 | D14: 돼지양념갈비 | F14: 12 | H14: 깍두기,계란
A15: 매출누계 | C15: =SUM('1:2'!$C$14) -> 65 | F15: =SUM('1:2'!$F$14) -> 42 | H15: 식자재2 | I15: =11000+4900+39000+3200+4500+11800+6200+24000+7500+13500 -> 125600 | J15: 비품 및 기타경비
A16: 개수 | B16: 육회 | C16: 8 | D16: 한우업진살 | F16: 0 | J16: 인터넷 주문 | K16: 315800
A17: 매출누계 | C17: =SUM('1:2'!$C$16) -> 18 | F17: =SUM('1:2'!$F$16) -> 24 | H17: 막걸리 | J17: 다이소 구매
A18: 개수 | B18: 소갈비살 | C18: 55 | D18: LA양념갈비 | F18: 17
A19: 매출누계 | C19: =SUM('1:2'!$C$18) -> 126 | F19: =SUM('1:2'!$F$18) -> 42
D20: 테이블수 | F20: 70
D21: 누적테이블 | F21: =SUM('1:2'!$F$20) -> 150
A22: 중간출금
A23: 출금내역 | H23: 식자재합계 | I23: =SUM(I4:I22) -> 237600 | J23: 기타경비합계 | K23: =SUM(K4:K22) -> 329993.55 | M23: 현금합계 | N23: =C5+C6 -> 553000
A24: 일매출 | C24: 일평균매출 | E24: 누적총매출 | H24: 일매출 | I24: =I23/A25 -> 0.047705096 | J24: 일매출 | K24: =K23/A25 -> 0.066255782
A25: =C2 -> 4980600 | C25: =E25/I1 -> 2747750 | E25: =SUM('1'!$A$25) -> 5495500 | H25: 누계 | I25: =SUM('1'!$I$23) -> 2507713 | J25: 누계 | K25: =SUM('1'!$K$23) -> 28543.548
A26: 전 월 | H26: 누적매출 | I26: =I25/$E$25 -> 0.45632117 | J26: 누적매출 | K26: =K25/$E$25 -> 0.0051939857
A27: 인 건 비 | B27: 직원A | C27: =4000000/31 -> 129032.26 | H27: 인건비합계 | I27: =SUM(C27:D34,F27:G32) -> 710741.94
B28: 직원B | C28: =3800000/31 -> 122580.65 | H28: 일매출 | I28: =I27/$A$25 -> 0.14270207
B29: 직원D | C29: =3200000/31 -> 103225.81 | H29: 누계 | I29: =SUM('1'!$I$27) -> 781741.94
H30: 누적매출 | I30: =I29/$I$27 -> 1.0998956
B31: 직원C | C31: =3500000/31 -> 112903.23 | E31: 파출 | F31: 120000
B32: 알바A | E32: 홀 파출 | F32: 71000
B33: 알바B | C33: =13000*4 -> 52000

Sheet 3
C1: 2025년 | E1: 5 | F1: 3 | G1: 토 | H1: 실영업일수 | I1: =F1-K1 -> 3 | J1: 휴무일수
A2: 매출 | C2: =SUM(C4:D7) -> 4682000 | E2: 시재 | G2: 194250 | H2: 식자재 | J2: 비품 및 기타경비
H3: 업체 | I3: 금액 | J3: 업체 | K3: 금액
A4: 카드 | C4: 3932000 | E4: 카드수수료(2.75%) | G4: =C4*0.0275 -> 108130 | H4: 고기 | I4: =955200+904000+210600+359290+499040+10+841464 -> 3769604 | J4: 숯
A5: 현금 | C5: 750000 | E5: 현금수수료(1%) | G5: =INT(C5*0.01) -> 7500 | H5: 식자재 | I5: =59312+72160+25600+20130+7790 -> 184992
A6: 페이결제 | E6: 통장입금 | G6: 843000 | J6: 음식물스티커
H7: 주류 | J7: 종량제봉투
A8: 금고 실잔액 | C8: 101250 | E8: 마감잔금 | G8: =C5+G2-G6-C22 -> 101250 | H8: 쌀
J9: 뚝배기
A10: 현금할인 | C10: 13000 | E10: 카드할인 | J10: 발매트
A11: 할인내역 | H11: 참기름 | J11: 불판세척 | K11: =440000/31 -> 14193.548
A12: 개수 | B12: 목살 | C12: 17 | D12: LA갈비 | F12: 7 | H12: 부탄가스
A13: 매출누계 | C13: =SUM('1:3'!$C$12) -> 61 | F13: =SUM('1:3'!$F$12) -> 28 | H13: 코카콜라음료
A14: 개수 | B14: 생갈비 | C14: 55 | D14: 돼지양념갈비 | F14: 34 | H14: 깍두기,계란
A15: 매출누계 | C15: =SUM('1:3'!$C$14) -> 120 | F15: =SUM('1:3'!$F$14) -> 76 | H15: 식자재2 | I15: =5500+9800+104000+3200+9000+24000+52000+11800+17000+19200+2200+13500+3500+6200+4400+4250+26000+6600 -> 322150 | J15: 비품 및 기타경비
A16: 개수 | B16: 육회 | C16: 5 | D16: 한우업진살 | F16: 19 | J16: 인터넷 주문
A17: 매출누계 | C17: =SUM('1:3'!$C$16) -> 23 | F17: =SUM('1:3'!$F$16) -> 43 | H17: 막걸리 | J17: 다이소 구매
A18: 개수 | B18: 소갈비살 | C18: 31 | D18: LA양념갈비 | F18: 32
A19: 매출누계 | C19: =SUM('1:3'!$C$18) -> 157 | F19: =SUM('1:3'!$F$18) -> 74
D20: 테이블수 | F20: 64
D21: 누적테이블 | F21: =SUM('1:3'!$F$20) -> 214
A22: 중간출금
A23: 출금내역 | H23: 식자재합계 | I23: =SUM(I4:I22) -> 4276746 | J23: 기타경비합계 | K23: =SUM(K4:K22) -> 14193.548 | M23: 현금합계 | N23: =C5+C6 -> 750000
A24: 일매출 | C24: 일평균매출 | E24: 누적총매출 | H24: 일매출 | I24: =I23/A25 -> 0.91344425 | J24: 일매출 | K24: =K23/A25 -> 0.003031514
A25: =C2 -> 4682000 | C25: =E25/I1 -> 5052700 | E25: =SUM('1:3'!$A$25) -> 15158100 | H25: 누계 | I25: =SUM('1:3'!$I$23) -> 7022059 | J25: 누계 | K25: =SUM('1:3'!$K$23) -> 372730.65
A26: 전 월 | H26: 누적매출 | I26: =I25/$E$25 -> 0.46325456 | J26: 누적매출 | K26: =K25/$E$25 -> 0.024589536
A27: 인 건 비 | B27: 직원A | C27: =4000000/31 -> 129032.26 | H27: 인건비합계 | I27: =SUM(C27:D34,F27:G32) -> 667741.94
B28: 직원B | C28: =3800000/31 -> 122580.65 | H28: 일매출 | I28: =I27/$A$25 -> 0.14261895
B29: 직원D | C29: =3200000/31 -> 103225.81 | H29: 누계 | I29: =SUM('1:3'!$I$27) -> 2160225.8
H30: 누적매출 | I30: =I29/$I$27 -> 3.2351208
B31: 직원C | C31: =3500000/31 -> 112903.23 | E31: 파출 | F31: 130000
B32: 알바A | C32: =14000*5 -> 70000 | E32: 홀 파출
B33: 알바B

Sheet 4
C1: 2025년 | E1: 5 | F1: 4 | G1: 일요일 | H1: 실영업일수 | I1: =F1-K1 -> 4 | J1: 휴무일수
A2: 매출 | C2: =SUM(C4:D7) -> 5933000 | E2: 시재 | G2: 101250 | H2: 식자재 | J2: 비품 및 기타경비
H3: 업체 | I3: 금액 | J3: 업체 | K3: 금액
A4: 카드 | C4: 5116000 | E4: 카드수수료(2.75%) | G4: =INT(C4*0.0275) -> 140690 | H4: 고기 | J4: 숯
A5: 현금 | C5: 817000 | E5: 현금수수료(1%) | G5: =INT(C5*0.01) -> 8170 | H5: 식자재
A6: 페이결제 | E6: 통장입금 | G6: 800000 | J6: 음식물스티커
H7: 주류 | J7: 종량제봉투
A8: 금고 실잔액 | C8: 118250 | E8: 마감잔금 | G8: =C5+G2-G6-C22 -> 118250 | H8: 쌀
J9: 뚝배기
A10: 현금할인 | E10: 카드할인 | J10: 발매트
A11: 할인내역 | H11: 참기름 | J11: 불판세척 | K11: =440000/31 -> 14193.548
A12: 개수 | B12: 목살 | C12: 26 | D12: LA갈비 | F12: 21 | H12: 부탄가스
A13: 매출누계 | C13: =SUM('1:4'!$C$12) -> 87 | F13: =SUM('1:4'!$F$12) -> 49 | H13: 코카콜라음료
A14: 개수 | B14: 생갈비 | C14: 58 | D14: 돼지양념갈비 | F14: 51 | H14: 깍두기,계란
A15: 매출누계 | C15: =SUM('1:4'!$C$14) -> 178 | F15: =SUM('1:4'!$F$14) -> 127 | H15: 식자재2 | J15: 비품 및 기타경비
A16: 개수 | B16: 육회 | C16: 14 | D16: 한우업진살 | F16: 0 | J16: 인터넷 주문 | K16: 460300
A17: 매출누계 | C17: =SUM('1:4'!$C$16) -> 37 | F17: =SUM('1:4'!$F$16) -> 43 | H17: 막걸리 | J17: 다이소 구매
A18: 개수 | B18: 소갈비살 | C18: 58 | D18: LA양념갈비 | F18: 25
A19: 매출누계 | C19: =SUM('1:4'!$C$18) -> 215 | F19: =SUM('1:4'!$F$18) -> 99
D20: 테이블수 | F20: 82
D21: 누적테이블 | F21: =SUM('1:4'!$F$20) -> 296
A22: 중간출금
A23: 출금내역 | H23: 식자재합계 | I23: =SUM(I4:I22) -> 0 | J23: 기타경비합계 | K23: =SUM(K4:K22) -> 474493.55 | M23: 현금합계 | N23: =C5+C6 -> 817000
A24: 일매출 | C24: 일평균매출 | E24: 누적총매출 | H24: 일매출 | I24: =I23/A25 -> 0 | J24: 일매출 | K24: =K23/A25 -> 0.079975316
A25: =C2 -> 5933000 | C25: =E25/I1 -> 5272775 | E25: =SUM('1:4'!$A$25) -> 21091100 | H25: 누계 | I25: =SUM('1:4'!$I$23) -> 7022059 | J25: 누계 | K25: =SUM('1:4'!$K$23) -> 847224.19
A26: 전 월 | H26: 누적매출 | I26: =I25/$E$25 -> 0.33293944 | J26: 누적매출 | K26: =K25/$E$25 -> 0.040169749
A27: 인 건 비 | B27: 직원A | C27: =4000000/31 -> 129032.26 | H27: 인건비합계 | I27: =SUM(C27:D34,F27:G32) -> 732741.94
B28: 직원B | C28: =3800000/31 -> 122580.65 | H28: 일매출 | I28: =I27/$A$25 -> 0.12350277
B29: 직원D | C29: =3200000/31 -> 103225.81 | H29: 누계 | I29: =SUM('1:4'!$I$27) -> 2892967.7
H30: 누적매출 | I30: =I29/$I$27 -> 3.94814
B31: 직원C | C31: =3500000/31 -> 112903.23 | E31: 파출 | F31: 130000
B32: 알바A | C32: =14000*5 -> 70000 | E32: 홀 파출
B33: 알바B | C33: =13000*5 -> 65000

Sheet 5
C1: 2025년 | E1: 5 | F1: 5 | G1: 월 | H1: 실영업일수 | I1: =F1-K1 -> 5 | J1: 휴무일수
A2: 매출 | C2: =SUM(C4:D7) -> 4832000 | E2: 시재 | G2: 118250 | H2: 식자재 | J2: 비품 및 기타경비
H3: 업체 | I3: 금액 | J3: 업체 | K3: 금액
A4: 카드 | C4: 4017000 | E4: 카드수수료(2.75%) | G4: =INT(C4*0.0275) -> 110467 | H4: 고기 | I4: =56220+955200+904000+405000+372527+424184+554190 -> 3671321 | J4: 숯
A5: 현금 | C5: 815000 | E5: 현금수수료(1%) | G5: =INT(C5*0.01) -> 8150 | H5: 식자재
A6: 페이결제 | E6: 통장입금 | G6: 850000 | J6: 음식물스티커
H7: 주류 | J7: 종량제봉투 | K7: 12500
A8: 금고 실잔액 | C8: 83250 | E8: 마감잔금 | G8: =C5+G2-G6-C22 -> 83250 | H8: 쌀
J9: 뚝배기
A10: 현금할인 | E10: 카드할인 | J10: 발매트
A11: 할인내역 | H11: 참기름 | J11: 불판세척 | K11: =440000/31 -> 14193.548
A12: 개수 | B12: 목살 | C12: 26 | D12: LA갈비 | F12: 56 | H12: 부탄가스
A13: 매출누계 | C13: =SUM('1:5'!$C$12) -> 113 | F13: =SUM('1:5'!$F$12) -> 105 | H13: 코카콜라음료
A14: 개수 | B14: 생갈비 | C14: 56 | D14: 돼지양념갈비 | F14: 27 | H14: 깍두기,계란
A15: 매출누계 | C15: =SUM('1:5'!$C$14) -> 234 | F15: =SUM('1:5'!$F$14) -> 154 | H15: 식자재2 | I15: =4900+52000+3200+28000+6200+11800+3500+6000+4800+3150+4800 -> 128350 | J15: 비품 및 기타경비
A16: 개수 | B16: 육회 | C16: 10 | D16: 한우업진살 | F16: 24 | J16: 인터넷 주문
A17: 매출누계 | C17: =SUM('1:5'!$C$16) -> 47 | F17: =SUM('1:5'!$F$16) -> 67 | H17: 막걸리 | J17: 다이소 구매
A18: 개수 | B18: 소갈비살 | C18: 47 | D18: LA양념갈비 | F18: 17
A19: 매출누계 | C19: =SUM('1:5'!$C$18) -> 262 | F19: =SUM('1:5'!$F$18) -> 116
D20: 테이블수 | F20: 69
D21: 누적테이블 | F21: =SUM('1:5'!$F$20) -> 365
A22: 중간출금
A23: 출금내역 | H23: 식자재합계 | I23: =SUM(I4:I22) -> 3799671 | J23: 기타경비합계 | K23: =SUM(K4:K22) -> 26693.548 | M23: 현금합계 | N23: =C5+C6 -> 815000
A24: 일매출 | C24: 일평균매출 | E24: 누적총매출 | H24: 일매출 | I24: =I23/A25 -> 0.78635575 | J24: 일매출 | K24: =K23/A25 -> 0.0055243271
A25: =C2 -> 4832000 | C25: =E25/I1 -> 5184620 | E25: =SUM('1:5'!$A$25) -> 25923100 | H25: 누계 | I25: =SUM('1:5'!$I$23) -> 10821730 | J25: 누계 | K25: =SUM('1:5'!$K$23) -> 873917.74
A26: 전 월 | H26: 누적매출 | I26: =I25/$E$25 -> 0.41745509 | J26: 누적매출 | K26: =K25/$E$25 -> 0.03371193
A27: 인 건 비 | B27: 직원A | C27: =4000000/31 -> 129032.26 | H27: 인건비합계 | I27: =SUM(C27:D34,F27:G32) -> 719741.94
B28: 직원B | C28: =3800000/31 -> 122580.65 | H28: 일매출 | I28: =I27/$A$25 -> 0.14895322
B29: 직원D | C29: =3200000/31 -> 103225.81 | H29: 누계 | I29: =SUM('1:5'!$I$27) -> 3612709.7
H30: 누적매출 | I30: =I29/$I$27 -> 5.0194514
B31: 직원C | C31: =3500000/31 -> 112903.23 | E31: 파출 | F31: 130000
B32: 알바A | C32: =14000*5 -> 70000 | E32: 홀 파출
B33: 알바B | C33: =13000*4 -> 52000

Sheet 6
C1: 2025년 | E1: 5 | F1: 6 | G1: 화 | H1: 실영업일수 | I1: =F1-K1 -> 6 | J1: 휴무일수
A2: 매출 | C2: =SUM(C4:D7) -> 2567000 | E2: 시재 | G2: 83250 | H2: 식자재 | J2: 비품 및 기타경비
H3: 업체 | I3: 금액 | J3: 업체 | K3: 금액
A4: 카드 | C4: 1986000 | E4: 카드수수료(2.75%) | G4: =INT(C4*0.0275) -> 54615 | H4: 고기 | J4: 숯
A5: 현금 | C5: 581000 | E5: 현금수수료(1%) | G5: =INT(C5*0.01) -> 5810 | H5: 식자재
A6: 페이결제 | E6: 통장입금 | G6: 580000 | J6: 음식물스티커
H7: 주류 | J7: 종량제봉투
A8: 금고 실잔액 | C8: 84250 | E8: 마감잔금 | G8: =C5+G2-G6-C22 -> 84250 | H8: 쌀
J9: 뚝배기
A10: 현금할인 | E10: 카드할인 | J10: 발매트 | K10: 13000
A11: 할인내역 | H11: 참기름 | J11: 불판세척 | K11: =440000/31 -> 14193.548
A12: 개수 | B12: 목살 | C12: 15 | D12: LA갈비 | F12: 31 | H12: 부탄가스
A13: 매출누계 | C13: =SUM('1:6'!$C$12) -> 128 | F13: =SUM('1:6'!$F$12) -> 136 | H13: 코카콜라음료
A14: 개수 | B14: 생갈비 | C14: 31 | D14: 돼지양념갈비 | F14: 21 | H14: 깍두기,계란
A15: 매출누계 | C15: =SUM('1:6'!$C$14) -> 265 | F15: =SUM('1:6'!$F$14) -> 175 | H15: 식자재2 | I15: =3900+11000+9000+9250+13000+9000+19200+1200+13500 -> 89050 | J15: 비품 및 기타경비
A16: 개수 | B16: 육회 | C16: 2 | D16: 한우업진살 | F16: 4 | J16: 인터넷 주문 | K16: 209680
A17: 매출누계 | C17: =SUM('1:6'!$C$16) -> 49 | F17: =SUM('1:6'!$F$16) -> 71 | H17: 막걸리 | J17: 다이소 구매
A18: 개수 | B18: 소갈비살 | C18: 19 | D18: LA양념갈비 | F18: 8
A19: 매출누계 | C19: =SUM('1:6'!$C$18) -> 281 | F19: =SUM('1:6'!$F$18) -> 124
D20: 테이블수 | F20: 50
D21: 누적테이블 | F21: =SUM('1:6'!$F$20) -> 415
A22: 중간출금
A23: 출금내역 | H23: 식자재합계 | I23: =SUM(I4:I22) -> 89050 | J23: 기타경비합계 | K23: =SUM(K4:K22) -> 236873.55 | M23: 현금합계 | N23: =C5+C6 -> 581000
A24: 일매출 | C24: 일평균매출 | E24: 누적총매출 | H24: 일매출 | I24: =I23/A25 -> 0.0346903 | J24: 일매출 | K24: =K23/A25 -> 0.092276412
A25: =C2 -> 2567000 | C25: =E25/I1 -> 4748350 | E25: =SUM('1:6'!$A$25) -> 28490100 | H25: 누계 | I25: =SUM('1:6'!$I$23) -> 10910780 | J25: 누계 | K25: =SUM('1:6'!$K$23) -> 1110791.3
A26: 전 월 | H26: 누적매출 | I26: =I25/$E$25 -> 0.38296742 | J26: 누적매출 | K26: =K25/$E$25 -> 0.038988676
A27: 인 건 비 | B27: 직원A | C27: =4000000/31 -> 129032.26 | H27: 인건비합계 | I27: =SUM(C27:D34,F27:G32) -> 768741.94
B28: 직원B | C28: =3800000/31 -> 122580.65 | H28: 일매출 | I28: =I27/$A$25 -> 0.29947095
B29: 직원D | C29: =3200000/31 -> 103225.81 | H29: 누계 | I29: =SUM('1:6'!$I$27) -> 4381451.6
H30: 누적매출 | I30: =I29/$I$27 -> 5.699509
B31: 직원C | C31: =3500000/31 -> 112903.23 | E31: 파출 | F31: 130000
B32: 알바A | E32: 홀 파출 | F32: 132000
B33: 알바B | C33: =13000*3 -> 39000

Sheet 7
C1: 2025년 | E1: 5 | F1: 7 | G1: 수 | H1: 실영업일수 | I1: =F1-K1 -> 7 | J1: 휴무일수
A2: 매출 | C2: =SUM(C4:D7) -> 2882500 | E2: 시재 | G2: 84250 | H2: 식자재 | J2: 비품 및 기타경비
H3: 업체 | I3: 금액 | J3: 업체 | K3: 금액
A4: 카드 | C4: 2554500 | E4: 카드수수료(2.75%) | G4: =INT(C4*0.0275) -> 70248 | H4: 고기 | J4: 숯 | K4: 255000
A5: 현금 | C5: 328000 | E5: 현금수수료(1%) | G5: =INT(C5*0.01) -> 3280 | H5: 식자재
A6: 페이결제 | E6: 통장입금 | G6: 300000 | J6: 음식물스티커
H7: 주류 | J7: 종량제봉투
A8: 금고 실잔액 | C8: 112250 | E8: 마감잔금 | G8: =C5+G2-G6-C22 -> 112250 | H8: 쌀 | I8: 56000
J9: 뚝배기
A10: 현금할인 | E10: 카드할인 | J10: 발매트
A11: 할인내역 | H11: 참기름 | J11: 불판세척 | K11: =440000/31 -> 14193.548
A12: 개수 | B12: 목살 | C12: 5 | D12: LA갈비 | F12: 6 | H12: 부탄가스
A13: 매출누계 | C13: =SUM('1:7'!$C$12) -> 133 | F13: =SUM('1:7'!$F$12) -> 142 | H13: 코카콜라음료
A14: 개수 | B14: 생갈비 | C14: 27 | D14: 돼지양념갈비 | F14: 9 | H14: 깍두기,계란
A15: 매출누계 | C15: =SUM('1:7'!$C$14) -> 292 | F15: =SUM('1:7'!$F$14) -> 184 | H15: 식자재2 | I15: =25500+24000+22000+3200+21000 -> 95700 | J15: 비품 및 기타경비
A16: 개수 | B16: 육회 | C16: 3 | D16: 한우업진살 | F16: 11 | J16: 인터넷 주문 | K16: 40860
A17: 매출누계 | C17: =SUM('1:7'!$C$16) -> 52 | F17: =SUM('1:7'!$F$16) -> 82 | H17: 막걸리 | J17: 다이소 구매
A18: 개수 | B18: 소갈비살 | C18: 15 | D18: LA양념갈비 | F18: 14
A19: 매출누계 | C19: =SUM('1:7'!$C$18) -> 296 | F19: =SUM('1:7'!$F$18) -> 138
D20: 테이블수 | F20: 47
D21: 누적테이블 | F21: =SUM('1:7'!$F$20) -> 462
A22: 중간출금
A23: 출금내역 | H23: 식자재합계 | I23: =SUM(I4:I22) -> 151700 | J23: 기타경비합계 | K23: =SUM(K4:K22) -> 310053.55 | M23: 현금합계 | N23: =C5+C6 -> 328000
A24: 일매출 | C24: 일평균매출 | E24: 누적총매출 | H24: 일매출 | I24: =I23/A25 -> 0.052627927 | J24: 일매출 | K24: =K23/A25 -> 0.10756411
A25: =C2 -> 2882500 | C25: =E25/I1 -> 4481800 | E25: =SUM('1:7'!$A$25) -> 31372600 | H25: 누계 | I25: =SUM('1:7'!$I$23) -> 11062480 | J25: 누계 | K25: =SUM('1:7'!$K$23) -> 1420844.8
A26: 전 월 | H26: 누적매출 | I26: =I25/$E$25 -> 0.35261598 | J26: 누적매출 | K26: =K25/$E$25 -> 0.045289356
A27: 인 건 비 | B27: 직원A | C27: =4000000/31 -> 129032.26 | H27: 인건비합계 | I27: =SUM(C27:D34,F27:G32) -> 758741.94
B28: 직원B | C28: =3800000/31 -> 122580.65 | H28: 일매출 | I28: =I27/$A$25 -> 0.26322357
B29: 직원D | C29: =3200000/31 -> 103225.81 | H29: 누계 | I29: =SUM('1:7'!$I$27) -> 5140193.5
H30: 누적매출 | I30: =I29/$I$27 -> 6.7746269
B31: 직원C | C31: =3500000/31 -> 112903.23 | E31: 파출 | F31: 120000
B32: 알바A | E32: 홀 파출 | F32: 132000
B33: 알바B | C33: =13000*3 -> 39000

Sheet 8
C1: 2025년 | E1: 5 | F1: 8 | G1: 목 | H1: 실영업일수 | I1: =F1-K1 -> 8 | J1: 휴무일수
A2: 매출 | C2: =SUM(C4:D7) -> 3826500 | E2: 시재 | G2: 112250 | H2: 식자재 | J2: 비품 및 기타경비
H3: 업체 | I3: 금액 | J3: 업체 | K3: 금액
A4: 카드 | C4: 3484000 | E4: 카드수수료(2.75%) | G4: =INT(C4*0.0275) -> 95810 | H4: 고기 | I4: =955200+904000+210600+380091+199616+10+282750 -> 2932267 | J4: 숯
A5: 현금 | C5: 342500 | E5: 현금수수료(1%) | G5: =INT(C5*0.01) -> 3425 | H5: 식자재 | I5: =34540+41250+38940+118624+40700+108240+96600+76800+40260+30300+17060+41780+171500 -> 856594
A6: 페이결제 | E6: 통장입금 | G6: 300000 | J6: 음식물스티커
H7: 주류 | J7: 종량제봉투
A8: 금고 실잔액 | C8: 154750 | E8: 마감잔금 | G8: =C5+G2-G6-C22 -> 154750 | H8: 쌀 | I8: 56000
J9: 뚝배기
A10: 현금할인 | E10: 카드할인 | J10: 발매트
A11: 할인내역 | H11: 참기름 | J11: 불판세척 | K11: =440000/31 -> 14193.548
A12: 개수 | B12: 목살 | C12: 12 | D12: LA갈비 | F12: 4 | H12: 부탄가스
A13: 매출누계 | C13: =SUM('1:8'!$C$12) -> 145 | F13: =SUM('1:8'!$F$12) -> 146 | H13: 코카콜라음료
A14: 개수 | B14: 생갈비 | C14: 36 | D14: 돼지양념갈비 | F14: 19 | H14: 깍두기,계란
A15: 매출누계 | C15: =SUM('1:8'!$C$14) -> 328 | F15: =SUM('1:8'!$F$14) -> 203 | H15: 식자재2 | I15: 153200 | J15: 비품 및 기타경비
A16: 개수 | B16: 육회 | C16: 1 | D16: 한우업진살 | F16: 14 | J16: 인터넷 주문
A17: 매출누계 | C17: =SUM('1:8'!$C$16) -> 53 | F17: =SUM('1:8'!$F$16) -> 96 | H17: 막걸리 | J17: 다이소 구매
A18: 개수 | B18: 소갈비살 | C18: 22 | D18: LA양념갈비 | F18: 11
A19: 매출누계 | C19: =SUM('1:8'!$C$18) -> 318 | F19: =SUM('1:8'!$F$18) -> 149
D20: 테이블수 | F20: 67
D21: 누적테이블 | F21: =SUM('1:8'!$F$20) -> 529
A22: 중간출금
A23: 출금내역 | H23: 식자재합계 | I23: =SUM(I4:I22) -> 3998061 | J23: 기타경비합계 | K23: =SUM(K4:K22) -> 14193.548 | M23: 현금합계 | N23: =C5+C6 -> 342500
A24: 일매출 | C24: 일평균매출 | E24: 누적총매출 | H24: 일매출 | I24: =I23/A25 -> 1.044835 | J24: 일매출 | K24: =K23/A25 -> 0.003709277
A25: =C2 -> 3826500 | C25: =E25/I1 -> 4399887.5 | E25: =SUM('1:8'!$A$25) -> 35199100 | H25: 누계 | I25: =SUM('1:8'!$I$23) -> 15060541 | J25: 누계 | K25: =SUM('1:8'!$K$23) -> 1435038.4
A26: 전 월 | H26: 누적매출 | I26: =I25/$E$25 -> 0.42786722 | J26: 누적매출 | K26: =K25/$E$25 -> 0.040769178
A27: 인 건 비 | B27: 직원A | C27: =4000000/31 -> 129032.26 | H27: 인건비합계 | I27: =SUM(C27:D34,F27:G32) -> 771741.94
B28: 직원B | C28: =3800000/31 -> 122580.65 | H28: 일매출 | I28: =I27/$A$25 -> 0.20168351
B29: 직원D | C29: =3200000/31 -> 103225.81 | H29: 누계 | I29: =SUM('1:8'!$I$27) -> 5911935.5 | M29: `
H30: 누적매출 | I30: =I29/$I$27 -> 7.6605083
B31: 직원C | C31: =3500000/31 -> 112903.23 | E31: 파출 | F31: 120000
B32: 알바A | E32: 홀 파출 | F32: 132000
B33: 알바B | C33: =13000*4 -> 52000

Sheet 9
C1: 2025년 | E1: 5 | F1: 9 | G1: 금 | H1: 실영업일수 | I1: =F1-K1 -> 9 | J1: 휴무일수
A2: 매출 | C2: =SUM(C4:D7) -> 3273500 | E2: 시재 | G2: 154750 | H2: 식자재 | J2: 비품 및 기타경비
H3: 업체 | I3: 금액 | J3: 업체 | K3: 금액
A4: 카드 | C4: 2692000 | E4: 카드수수료(2.75%) | G4: =INT(C4*0.0275) -> 74030 | H4: 고기 | I4: =226800 -> 226800 | J4: 숯
A5: 현금 | C5: 581500 | E5: 현금수수료(1%) | G5: =INT(C5*0.01) -> 5815 | H5: 식자재 | I5: =59312+16100+25600 -> 101012
A6: 페이결제 | E6: 통장입금 | G6: 600000 | J6: 음식물스티커
H7: 주류 | I7: =715100-19700 -> 695400 | J7: 종량제봉투
A8: 금고 실잔액 | C8: 136250 | E8: 마감잔금 | G8: =C5+G2-G6-C22 -> 136250 | H8: 쌀
J9: 뚝배기
A10: 현금할인 | E10: 카드할인 | J10: 발매트
A11: 할인내역 | H11: 참기름 | J11: 불판세척 | K11: =440000/31 -> 14193.548
A12: 개수 | B12: 목살 | C12: 15 | D12: LA갈비 | F12: 7 | H12: 부탄가스
A13: 매출누계 | C13: =SUM('1:9'!$C$12) -> 160 | F13: =SUM('1:9'!$F$12) -> 153 | H13: 코카콜라음료
A14: 개수 | B14: 생갈비 | C14: 30 | D14: 돼지양념갈비 | F14: 8 | H14: 깍두기,계란
A15: 매출누계 | C15: =SUM('1:9'!$C$14) -> 358 | F15: =SUM('1:9'!$F$14) -> 211 | H15: 식자재2 | I15: =9800+11000+6200+19500+5400+26000+3900+3500+3200 -> 88500 | J15: 비품 및 기타경비
A16: 개수 | B16: 육회 | C16: 2 | D16: 한우업진살 | F16: 17 | J16: 인터넷 주문
A17: 매출누계 | C17: =SUM('1:9'!$C$16) -> 55 | F17: =SUM('1:9'!$F$16) -> 113 | H17: 막걸리 | J17: 다이소 구매
A18: 개수 | B18: 소갈비살 | C18: 29 | D18: LA양념갈비 | F18: 12
A19: 매출누계 | C19: =SUM('1:9'!$C$18) -> 347 | F19: =SUM('1:9'!$F$18) -> 161
D20: 테이블수 | F20: 56
D21: 누적테이블 | F21: =SUM('1:9'!$F$20) -> 585
A22: 중간출금
A23: 출금내역 | H23: 식자재합계 | I23: =SUM(I4:I22) -> 1111712 | J23: 기타경비합계 | K23: =SUM(K4:K22) -> 14193.548 | M23: 현금합계 | N23: =C5+C6 -> 581500
A24: 일매출 | C24: 일평균매출 | E24: 누적총매출 | H24: 일매출 | I24: =I23/A25 -> 0.33960959 | J24: 일매출 | K24: =K23/A25 -> 0.0043358938
A25: =C2 -> 3273500 | C25: =E25/I1 -> 4274733.3 | E25: =SUM('1:9'!$A$25) -> 38472600 | H25: 누계 | I25: =SUM('1:9'!$I$23) -> 16172253 | J25: 누계 | K25: =SUM('1:9'!$K$23) -> 1449231.9
A26: 전 월 | H26: 누적매출 | I26: =I25/$E$25 -> 0.42035768 | J26: 누적매출 | K26: =K25/$E$25 -> 0.037669197
A27: 인 건 비 | B27: 직원A | C27: =4000000/31 -> 129032.26 | H27: 인건비합계 | I27: =SUM(C27:D34,F27:G32) -> 771741.94
B28: 직원B | C28: =3800000/31 -> 122580.65 | H28: 일매출 | I28: =I27/$A$25 -> 0.23575437
B29: 직원D | C29: =3200000/31 -> 103225.81 | H29: 누계 | I29: =SUM('1:9'!$I$27) -> 6683677.4
H30: 누적매출 | I30: =I29/$I$27 -> 8.6605083
B31: 직원C | C31: =3500000/31 -> 112903.23 | E31: 파출 | F31: 120000
B32: 알바A | E32: 홀 파출 | F32: 132000
B33: 알바B | C33: =13000*4 -> 52000

Sheet 10
C1: 2025년 | E1: 5 | F1: 10 | G1: 토 | H1: 실영업일수 | I1: =F1-K1 -> 10 | J1: 휴무일수
A2: 매출 | C2: =SUM(C4:D7) -> 3716000 | E2: 시재 | G2: 136250 | H2: 식자재 | J2: 비품 및 기타경비
H3: 업체 | I3: 금액 | J3: 업체 | K3: 금액
A4: 카드 | C4: 3153000 | E4: 카드수수료(2.75%) | G4: =INT(C4*0.0275) -> 86707 | H4: 고기 | I4: =486000+190259+183427+452000 -> 1311686 | J4: 숯
A5: 현금 | C5: 563000 | E5: 현금수수료(1%) | G5: =INT(C5*0.01) -> 5630 | H5: 식자재 | I5: =48300+25600+88968+20130 -> 182998
A6: 페이결제 | E6: 통장입금 | G6: 640000 | J6: 음식물스티커
H7: 주류 | J7: 종량제봉투
A8: 금고 실잔액 | C8: 59250 | E8: 마감잔금 | G8: =C5+G2-G6-C22 -> 59250 | H8: 쌀
J9: 뚝배기
A10: 현금할인 | C10: 500000 | E10: 카드할인 | J10: 발매트
A11: 할인내역 | C11: 리뷰노트 50,000원 | H11: 참기름 | J11: 불판세척 | K11: =440000/31 -> 14193.548
A12: 개수 | B12: 목살 | C12: 15 | D12: LA갈비 | F12: 9 | H12: 부탄가스
A13: 매출누계 | C13: =SUM('1:10'!$C$12) -> 175 | F13: =SUM('1:10'!$F$12) -> 162 | H13: 코카콜라음료
A14: 개수 | B14: 생갈비 | C14: 35 | D14: 돼지양념갈비 | F14: 23 | H14: 깍두기,계란
A15: 매출누계 | C15: =SUM('1:10'!$C$14) -> 393 | F15: =SUM('1:10'!$F$14) -> 234 | H15: 식자재2 | I15: =4900+5500+6200+78000+3200+38400+13500+3500+17000+23600+7800+1200+13000 -> 215800 | J15: 비품 및 기타경비
A16: 개수 | B16: 육회 | C16: 5 | D16: 한우업진살 | F16: 22 | J16: 인터넷 주문 | K16: 68940
A17: 매출누계 | C17: =SUM('1:10'!$C$16) -> 60 | F17: =F19 -> 178 | H17: 막걸리 | I17: 3200 | J17: 다이소 구매
A18: 개수 | B18: 소갈비살 | C18: 39 | D18: LA양념갈비 | F18: 17
A19: 매출누계 | C19: =SUM('1:10'!$C$18) -> 386 | F19: =SUM('1:10'!$F$18) -> 178
D20: 테이블수 | F20: 54
D21: 누적테이블 | F21: =SUM('1:10'!$F$20) -> 639
A22: 중간출금
A23: 출금내역 | H23: 식자재합계 | I23: =SUM(I4:I22) -> 1713684 | J23: 기타경비합계 | K23: =SUM(K4:K22) -> 83133.548 | M23: 현금합계 | N23: =C5+C6 -> 563000
A24: 일매출 | C24: 일평균매출 | E24: 누적총매출 | H24: 일매출 | I24: =I23/A25 -> 0.46116362 | J24: 일매출 | K24: =K23/A25 -> 0.022371784
A25: =C2 -> 3716000 | C25: =E25/I1 -> 4218860 | E25: =SUM('1:10'!$A$25) -> 42188600 | H25: 누계 | I25: =SUM('1:10'!$I$21) -> 0 | J25: 누계 | K25: =SUM('1:10'!$K$21) -> 0
A26: 전 월 | H26: 누적매출 | I26: =I25/$E$25 -> 0 | J26: 누적매출 | K26: =K25/$E$25 -> 0
A27: 인 건 비 | B27: 직원A | C27: =4000000/31 -> 129032.26 | H27: 인건비합계 | I27: =SUM(C27:D34,F27:G32) -> 667741.94
B28: 직원B | C28: =3800000/31 -> 122580.65 | H28: 일매출 | I28: =I27/$A$25 -> 0.17969374
B29: 직원D | C29: =3200000/31 -> 103225.81 | H29: 누계 | I29: =SUM('1:10'!$I$25) -> 83087328
H30: 누적매출 | I30: =I29/$I$27 -> 124.4303
B31: 직원C | C31: =3500000/31 -> 112903.23 | E31: 파출 | F31: 130000
B32: 알바A | C32: =14000*5 -> 70000 | E32: 홀 파출
B33: 알바B

Sheet 11
C1: 2025년 | E1: 5 | F1: 11 | G1: 일 | H1: 실영업일수 | I1: =F1-K1 -> 11 | J1: 휴무일수
A2: 매출 | C2: =SUM(C4:D7) -> 5059500 | E2: 시재 | G2: 59250 | H2: 식자재 | J2: 비품 및 기타경비
H3: 업체 | I3: 금액 | J3: 업체 | K3: 금액
A4: 카드 | C4: 4228500 | E4: 카드수수료(2.75%) | G4: =INT(C4*0.0275) -> 116283 | H4: 고기 | J4: 숯
A5: 현금 | C5: 831000 | E5: 현금수수료(1%) | G5: =INT(C5*0.01) -> 8310 | H5: 식자재
A6: 페이결제 | E6: 통장입금 | G6: 740000 | J6: 음식물스티커
H7: 주류 | J7: 종량제봉투
A8: 금고 실잔액 | C8: 150250 | E8: 마감잔금 | G8: =C5+G2-G6-C22 -> 150250 | H8: 쌀
J9: 뚝배기
A10: 현금할인 | E10: 카드할인 | J10: 발매트
A11: 할인내역 | H11: 참기름 | J11: 불판세척 | K11: =440000/31 -> 14193.548
A12: 개수 | B12: 목살 | C12: 29 | D12: LA갈비 | F12: 6 | H12: 부탄가스
A13: 매출누계 | C13: =SUM('1:11'!$C$12) -> 204 | F13: =SUM('1:11'!$F$12) -> 168 | H13: 코카콜라음료
A14: 개수 | B14: 생갈비 | C14: 81 | D14: 돼지양념갈비 | F14: 14 | H14: 깍두기,계란
A15: 매출누계 | C15: =SUM('1:11'!$C$14) -> 474 | F15: =SUM('1:11'!$F$14) -> 248 | H15: 식자재2 | J15: 비품 및 기타경비
A16: 개수 | B16: 육회 | C16: 6 | D16: 한우업진살 | F16: 31 | J16: 인터넷 주문
A17: 매출누계 | C17: =SUM('1:11'!$C$16) -> 66 | F17: =SUM('1:11'!$F$16) -> 166 | H17: 막걸리 | J17: 다이소 구매
A18: 개수 | B18: 소갈비살 | C18: 45 | D18: LA양념갈비 | F18: 13
A19: 매출누계 | C19: =SUM('1:11'!$C$18) -> 431 | F19: =SUM('1:11'!$F$18) -> 191
D20: 테이블수 | F20: 60
D21: 누적테이블 | F21: =SUM('1:11'!$F$20) -> 699
A22: 중간출금
A23: 출금내역 | H23: 식자재합계 | I23: =SUM(I4:I22) -> 0 | J23: 기타경비합계 | K23: =SUM(K4:K22) -> 14193.548 | M23: 현금합계 | N23: =C5+C6 -> 831000
A24: 일매출 | C24: 일평균매출 | E24: 누적총매출 | H24: 일매출 | I24: =I23/A25 -> 0 | J24: 일매출 | K24: =K23/A25 -> 0.0028053263
A25: =C2 -> 5059500 | C25: =E25/I1 -> 4295281.8 | E25: =SUM('1:11'!$A$25) -> 47248100 | H25: 누계 | I25: =SUM('1:11'!$I$21) -> 0 | J25: 누계 | K25: =SUM('1:11'!$K$21) -> 0
A26: 전 월 | H26: 누적매출 | I26: =I25/$E$25 -> 0 | J26: 누적매출 | K26: =K25/$E$25 -> 0
A27: 인 건 비 | B27: 직원A | C27: =4000000/31 -> 129032.26 | H27: 인건비합계 | I27: =SUM(C27:D34,F27:G32) -> 667741.94
B28: 직원B | C28: =3800000/31 -> 122580.65 | H28: 일매출 | I28: =I27/$A$25 -> 0.13197785
B29: 직원D | C29: =3200000/31 -> 103225.81 | H29: 누계 | I29: =SUM('1:11'!$I$25) -> 83087328
E30: 홀파출 | H30: 누적매출 | I30: =I29/$I$27 -> 124.4303
B31: 직원C | C31: =3500000/31 -> 112903.23 | E31: 파출 | F31: 130000
B32: 알바A | C32: =14000*5 -> 70000 | E32: 홀 파출
B33: 알바B

Sheet 12
C1: 2025년 | E1: 5 | F1: 12 | G1: 월 | H1: 실영업일수 | I1: =F1-K1 -> 12 | J1: 휴무일수
A2: 매출 | C2: =SUM(C4:D7) -> 3676000 | E2: 시재 | G2: 150250 | H2: 식자재 | J2: 비품 및 기타경비
H3: 업체 | I3: 금액 | J3: 업체 | K3: 금액
A4: 카드 | C4: 2918000 | E4: 카드수수료(2.75%) | G4: =INT(C4*0.0275) -> 80245 | H4: 고기 | I4: =30650+477600+452000+216000+183427+282750 -> 1642427 | J4: 숯
A5: 현금 | C5: 758000 | E5: 현금수수료(1%) | G5: =INT(C5*0.01) -> 7580 | H5: 식자재 | I5: =23440+25600+29656+36080 -> 114776
A6: 페이결제 | E6: 통장입금 | G6: 760000 | J6: 음식물스티커
H7: 주류 | I7: =7500-48700 -> -41200 | J7: 종량제봉투
A8: 금고 실잔액 | C8: 150250 | E8: 마감잔금 | G8: =C5+G2-G6-C22 -> 148250 | H8: 쌀 | I8: 56000
J9: 뚝배기
A10: 현금할인 | E10: 카드할인 | J10: 발매트 | K10: 6000
A11: 할인내역 | H11: 참기름 | J11: 불판세척 | K11: =440000/31 -> 14193.548
A12: 개수 | B12: 목살 | C12: 19 | D12: LA갈비 | F12: 7 | H12: 부탄가스
A13: 매출누계 | C13: =SUM('1:12'!$C$12) -> 223 | F13: =SUM('1:12'!$F$12) -> 175 | H13: 코카콜라음료
A14: 개수 | B14: 생갈비 | C14: 34 | D14: 돼지양념갈비 | F14: 15 | H14: 깍두기,계란
A15: 매출누계 | C15: =SUM('1:12'!$C$14) -> 508 | F15: =SUM('1:12'!$F$14) -> 263 | H15: 식자재2 | I15: =19500+5400+8500+6600 -> 40000 | J15: 비품 및 기타경비
A16: 개수 | B16: 육회 | C16: 3 | D16: 한우업진살 | F16: 11 | J16: 인터넷 주문
A17: 매출누계 | C17: =SUM('1:12'!$C$16) -> 69 | F17: =SUM('1:12'!$F$16) -> 177 | H17: 막걸리 | J17: 다이소 구매
A18: 개수 | B18: 소갈비살 | C18: 28 | D18: LA양념갈비 | F18: 11
A19: 매출누계 | C19: =SUM('1:12'!$C$18) -> 459 | F19: =SUM('1:12'!$F$18) -> 202
D20: 테이블수 | F20: 60
D21: 누적테이블 | F21: =SUM('1:12'!$F$20) -> 759
A22: 중간출금
A23: 출금내역 | H23: 식자재합계 | I23: =SUM(I4:I22) -> 1812003 | J23: 기타경비합계 | K23: =SUM(K4:K22) -> 20193.548 | M23: 현금합계 | N23: =C5+C6 -> 758000
A24: 일매출 | C24: 일평균매출 | E24: 누적총매출 | H24: 일매출 | I24: =I23/A25 -> 0.49292791 | J24: 일매출 | K24: =K23/A25 -> 0.0054933483
A25: =C2 -> 3676000 | C25: =E25/I1 -> 4243675 | E25: =SUM('1:12'!$A$25) -> 50924100 | H25: 누계 | I25: =SUM('1:12'!$I$21) -> 0 | J25: 누계 | K25: =SUM('1:12'!$K$21) -> 0
A26: 전 월 | H26: 누적매출 | I26: =I25/$E$25 -> 0 | J26: 누적매출 | K26: =K25/$E$25 -> 0
A27: 인 건 비 | B27: 직원A | C27: =4000000/31 -> 129032.26 | H27: 인건비합계 | I27: =SUM(C27:D34,F27:G32) -> 771741.94
B28: 직원B | C28: =3800000/31 -> 122580.65 | H28: 일매출 | I28: =I27/$A$25 -> 0.20994068
B29: 직원D | C29: =3200000/31 -> 103225.81 | H29: 누계 | I29: =SUM('1:12'!$I$25) -> 83087328
H30: 누적매출 | I30: =I29/$I$27 -> 107.66206
B31: 직원C | C31: =3500000/31 -> 112903.23 | E31: 파출 | F31: 120000
B32: 알바A | E32: 홀 파출 | F32: 132000
B33: 알바B | C33: =13000*4 -> 52000

Sheet 13
C1: 2025년 | E1: 5 | F1: 13 | G1: 화 | H1: 실영업일수 | I1: =F1-K1 -> 13 | J1: 휴무일수
A2: 매출 | C2: =SUM(C4:D7) -> 4715000 | E2: 시재 | G2: 150250 | H2: 식자재 | J2: 비품 및 기타경비
H3: 업체 | I3: 금액 | J3: 업체 | K3: 금액
A4: 카드 | C4: 3988000 | E4: 카드수수료(2.75%) | G4: =INT(C4*0.0275) -> 109670 | H4: 고기 | I4: =477600+452000+210600+275964 -> 1416164 | J4: 숯
A5: 현금 | C5: 727000 | E5: 현금수수료(1%) | G5: =INT(C5*0.01) -> 7270 | H5: 식자재 | I5: =23650+29656+36080+48300+7790+17650 -> 163126
A6: 페이결제 | E6: 통장입금 | G6: 700000 | J6: 음식물스티커
H7: 주류 | I7: =165600-4600 -> 161000 | J7: 종량제봉투
A8: 금고 실잔액 | C8: 177250 | E8: 마감잔금 | G8: =C5+G2-G6-C22 -> 177250 | H8: 쌀
J9: 뚝배기
A10: 현금할인 | E10: 카드할인 | J10: 발매트
A11: 할인내역 | H11: 참기름 | J11: 불판세척 | K11: =440000/31 -> 14193.548
A12: 개수 | B12: 목살 | C12: 8 | D12: LA갈비 | F12: 8 | H12: 부탄가스
A13: 매출누계 | C13: =SUM('1:13'!$C$12) -> 231 | F13: =SUM('1:13'!$F$12) -> 183 | H13: 코카콜라음료
A14: 개수 | B14: 생갈비 | C14: 22 | D14: 돼지양념갈비 | F14: 18 | H14: 깍두기,계란
A15: 매출누계 | C15: =SUM('1:13'!$C$14) -> 530 | F15: =SUM('1:13'!$F$14) -> 281 | H15: 식자재2 | I15: =32500+19200+11800+4900+3500+13500+4500+9250+3200+2200+3150+8500+12000 -> 128200 | J15: 비품 및 기타경비
A16: 개수 | B16: 육회 | C16: 10 | D16: 한우업진살 | F16: 33 | J16: 인터넷 주문 | K16: 123873
A17: 매출누계 | C17: =SUM('1:13'!$C$16) -> 79 | F17: =SUM('1:13'!$F$16) -> 210 | H17: 막걸리 | J17: 다이소 구매
A18: 개수 | B18: 소갈비살 | C18: 40 | D18: LA양념갈비 | F18: 5
A19: 매출누계 | C19: =SUM('1:13'!$C$18) -> 499 | F19: =SUM('1:13'!$F$18) -> 207
D20: 테이블수 | F20: 73
D21: 누적테이블 | F21: =SUM('1:13'!$F$20) -> 832
A22: 중간출금
A23: 출금내역 | H23: 식자재합계 | I23: =SUM(I4:I22) -> 1868490 | J23: 기타경비합계 | K23: =SUM(K4:K22) -> 138066.55 | M23: 현금합계 | N23: =C5+C6 -> 727000
A24: 일매출 | C24: 일평균매출 | E24: 누적총매출 | H24: 일매출 | I24: =I23/A25 -> 0.39628632 | J24: 일매출 | K24: =K23/A25 -> 0.029282407
A25: =C2 -> 4715000 | C25: =E25/I1 -> 4279930.8 | E25: =SUM('1:13'!$A$25) -> 55639100 | H25: 누계 | I25: =SUM('1:13'!$I$21) -> 0 | J25: 누계 | K25: =SUM('1:13'!$K$21) -> 0
A26: 전 월 | H26: 누적매출 | I26: =I25/$E$25 -> 0 | J26: 누적매출 | K26: =K25/$E$25 -> 0
A27: 인 건 비 | B27: 직원A | C27: =4000000/31 -> 129032.26 | H27: 인건비합계 | I27: =SUM(C27:D34,F27:G32) -> 771741.94
B28: 직원B | C28: =3800000/31 -> 122580.65 | H28: 일매출 | I28: =I27/$A$25 -> 0.16367804
B29: 직원D | C29: =3200000/31 -> 103225.81 | H29: 누계 | I29: =SUM('1:13'!$I$25) -> 83087328
H30: 누적매출 | I30: =I29/$I$27 -> 107.66206
B31: 직원C | C31: =3500000/31 -> 112903.23 | E31: 파출 | F31: 120000
B32: 알바A | E32: 홀 파출 | F32: 132000
B33: 알바B | C33: =13000*4 -> 52000

Sheet 14
C1: 2025년 | E1: 5 | F1: 14 | G1: 수 | H1: 실영업일수 | I1: =F1-K1 -> 14 | J1: 휴무일수
A2: 매출 | C2: =SUM(C4:D7) -> 3861500 | E2: 시재 | G2: 177250 | H2: 식자재 | J2: 비품 및 기타경비
H3: 업체 | I3: 금액 | J3: 업체 | K3: 금액
A4: 카드 | C4: 3272500 | E4: 카드수수료(2.75%) | G4: =INT(C4*0.0275) -> 89993 | H4: 고기 | I4: =210600+452000+280488+199616+10 -> 1142714 | J4: 숯 | K4: 255000
A5: 현금 | C5: 589000 | E5: 현금수수료(1%) | G5: =INT(C5*0.01) -> 5890 | H5: 식자재 | I5: =38940+29656+36080+48300+25600+23440+7790+68600 -> 278406
A6: 페이결제 | E6: 통장입금 | G6: 650000 | J6: 음식물스티커
H7: 주류 | J7: 종량제봉투
A8: 금고 실잔액 | C8: 116250 | E8: 마감잔금 | G8: =C5+G2-G6-C22 -> 116250 | H8: 쌀 | I8: 56000
J9: 뚝배기
A10: 현금할인 | E10: 카드할인 | J10: 발매트
A11: 할인내역 | H11: 참기름 | J11: 불판세척 | K11: =440000/31 -> 14193.548
A12: 개수 | B12: 목살 | C12: 18 | D12: LA갈비 | F12: 4 | H12: 부탄가스
A13: 매출누계 | C13: =SUM('1:14'!$C$12) -> 249 | F13: =SUM('1:14'!$F$12) -> 187 | H13: 코카콜라음료
A14: 개수 | B14: 생갈비 | C14: 33 | D14: 돼지양념갈비 | F14: 16 | H14: 깍두기,계란
A15: 매출누계 | C15: =SUM('1:14'!$C$14) -> 563 | F15: =SUM('1:14'!$F$14) -> 297 | H15: 식자재2 | I15: 72000 | J15: 비품 및 기타경비
A16: 개수 | B16: 육회 | C16: 3 | D16: 한우업진살 | F16: 18 | J16: 인터넷 주문
A17: 매출누계 | C17: =SUM('1:14'!$C$16) -> 82 | F17: =SUM('1:14'!$F$16) -> 228 | H17: 막걸리 | J17: 다이소 구매
A18: 개수 | B18: 소갈비살 | C18: 19 | D18: LA양념갈비 | F18: 9
A19: 매출누계 | C19: =SUM('1:14'!$C$18) -> 518 | F19: =SUM('1:14'!$F$18) -> 216
D20: 테이블수 | F20: 54
D21: 누적테이블 | F21: =SUM('1:14'!$F$20) -> 886
A22: 중간출금
A23: 출금내역 | H23: 식자재합계 | I23: =SUM(I4:I22) -> 1549120 | J23: 기타경비합계 | K23: =SUM(K4:K22) -> 269193.55 | M23: 현금합계 | N23: =C5+C6 -> 589000
A24: 일매출 | C24: 일평균매출 | E24: 누적총매출 | H24: 일매출 | I24: =I23/A25 -> 0.40117053 | J24: 일매출 | K24: =K23/A25 -> 0.069712171
A25: =C2 -> 3861500 | C25: =E25/I1 -> 4250042.9 | E25: =SUM('1:14'!$A$25) -> 59500600 | H25: 누계 | I25: =SUM('1:14'!$I$21) -> 0 | J25: 누계 | K25: =SUM('1:14'!$K$21) -> 0
A26: 전 월 | H26: 누적매출 | I26: =I25/$E$25 -> 0 | J26: 누적매출 | K26: =K25/$E$25 -> 0
A27: 인 건 비 | B27: 직원A | C27: =4000000/31 -> 129032.26 | H27: 인건비합계 | I27: =SUM(C27:D34,F27:G32) -> 771741.94
B28: 직원B | C28: =3800000/31 -> 122580.65 | H28: 일매출 | I28: =I27/$A$25 -> 0.19985548
B29: 직원D | C29: =3200000/31 -> 103225.81 | H29: 누계 | I29: =SUM('1:14'!$I$25) -> 83087328 | M29: `
H30: 누적매출 | I30: =I29/$I$27 -> 107.66206
B31: 직원C | C31: =3500000/31 -> 112903.23 | E31: 파출 | F31: 120000
B32: 알바A | E32: 홀 파출 | F32: 132000
B33: 알바B | C33: =13000*4 -> 52000

Sheet 15
C1: 2025년 | E1: 5 | F1: 15 | G1: 목요일 | H1: 실영업일수 | I1: =F1-K1 -> 15 | J1: 휴무일수
A2: 매출 | C2: =SUM(C4:D7) -> 4759000 | E2: 시재 | G2: 116250 | H2: 식자재 | J2: 비품 및 기타경비
H3: 업체 | I3: 금액 | J3: 업체 | K3: 금액
A4: 카드 | C4: 4495000 | E4: 카드수수료(2.75%) | G4: =INT(C4*0.0275) -> 123612 | H4: 고기 | I4: =43500+56220+452000+216000+198555+287274 -> 1253549 | J4: 숯
A5: 현금 | C5: 264000 | E5: 현금수수료(1%) | G5: =INT(C5*0.01) -> 2640 | H5: 식자재 | I5: 38940
A6: 페이결제 | E6: 통장입금 | G6: 180000 | J6: 음식물스티커
H7: 주류 | I7: 324300 | J7: 종량제봉투
A8: 금고 실잔액 | C8: 200250 | E8: 마감잔금 | G8: =C5+G2-G6-C22 -> 200250 | H8: 쌀
J9: 뚝배기
A10: 현금할인 | E10: 카드할인 | J10: 발매트
A11: 할인내역 | H11: 참기름 | J11: 불판세척 | K11: =440000/31 -> 14193.548
A12: 개수 | B12: 목살 | C12: 17 | D12: LA갈비 | F12: 19 | H12: 부탄가스
A13: 매출누계 | C13: =SUM('1:15'!$C$12) -> 266 | F13: =SUM('1:15'!$F$12) -> 206 | H13: 코카콜라음료
A14: 개수 | B14: 생갈비 | C14: 28 | D14: 돼지양념갈비 | F14: 12 | H14: 깍두기,계란
A15: 매출누계 | C15: =SUM('1:15'!$C$14) -> 591 | F15: =SUM('1:15'!$F$14) -> 309 | H15: 식자재2 | I15: 164100 | J15: 비품 및 기타경비 | K15: 12500
A16: 개수 | B16: 육회 | C16: 12 | D16: 한우업진살 | F16: 27 | J16: 인터넷 주문 | K16: 17960
A17: 매출누계 | C17: =SUM('1:15'!$C$16) -> 94 | F17: =SUM('1:15'!$F$16) -> 255 | H17: 막걸리 | J17: 다이소 구매
A18: 개수 | B18: 소갈비살 | C18: 38 | D18: LA양념갈비 | F18: 9
A19: 매출누계 | C19: =SUM('1:15'!$C$18) -> 556 | F19: =SUM('1:15'!$F$18) -> 225
D20: 테이블수 | F20: 51
D21: 누적테이블 | F21: =SUM('1:15'!$F$20) -> 937
A22: 중간출금
A23: 출금내역 | H23: 식자재합계 | I23: =SUM(I4:I22) -> 1780889 | J23: 기타경비합계 | K23: =SUM(K4:K22) -> 44653.548 | M23: 현금합계 | N23: =C5+C6 -> 264000
A24: 일매출 | C24: 일평균매출 | E24: 누적총매출 | H24: 일매출 | I24: =I23/A25 -> 0.37421496 | J24: 일매출 | K24: =K23/A25 -> 0.0093829688
A25: =C2 -> 4759000 | C25: =E25/I1 -> 4283973.3 | E25: =SUM('1:15'!$A$25) -> 64259600 | H25: 누계 | I25: =SUM('1:15'!$I$21) -> 0 | J25: 누계 | K25: =SUM('1:15'!$K$21) -> 0
A26: 전 월 | H26: 누적매출 | I26: =I25/$E$25 -> 0 | J26: 누적매출 | K26: =K25/$E$25 -> 0
A27: 인 건 비 | B27: 직원A | C27: =4000000/31 -> 129032.26 | H27: 인건비합계 | I27: =SUM(C27:D34,F27:G32) -> 626741.94
B28: 직원B | C28: =3800000/31 -> 122580.65 | H28: 일매출 | I28: =I27/$A$25 -> 0.13169614
B29: 직원D | C29: =3200000/31 -> 103225.81 | H29: 누계 | I29: =SUM('1:15'!$I$25) -> 83087328
H30: 누적매출 | I30: =I29/$I$27 -> 132.57024
B31: 직원C | C31: =3500000/31 -> 112903.23 | E31: 파출 | F31: 120000
B32: 알바A | E32: 홀 파출
B33: 알바B | C33: =13000*3 -> 39000

Sheet 16
C1: 2025년 | E1: 5 | F1: 16 | G1: 금요일 | H1: 실영업일수 | I1: =F1-K1 -> 16 | J1: 휴무일수
A2: 매출 | C2: =SUM(C4:D7) -> 3848000 | E2: 시재 | G2: 200250 | H2: 식자재 | J2: 비품 및 기타경비
H3: 업체 | I3: 금액 | J3: 업체 | K3: 금액
A4: 카드 | C4: 3607000 | E4: 카드수수료(2.75%) | G4: =INT(C4*0.0275) -> 99192 | H4: 고기 | I4: =477600+452000+216000+208010 -> 1353610 | J4: 숯
A5: 현금 | C5: 241000 | E5: 현금수수료(1%) | G5: =INT(C5*0.01) -> 2410 | H5: 식자재 | I5: =12980+23650+41250+38940 -> 116820
A6: 페이결제 | E6: 통장입금 | G6: 290000 | J6: 음식물스티커
H7: 주류 | J7: 종량제봉투
A8: 금고 실잔액 | C8: 151250 | E8: 마감잔금 | G8: =C5+G2-G6-C22 -> 151250 | H8: 쌀 | I8: 56000
J9: 뚝배기
A10: 현금할인 | E10: 카드할인 | J10: 발매트
A11: 할인내역 | H11: 참기름 | I11: 100000 | J11: 불판세척 | K11: =440000/31 -> 14193.548
A12: 개수 | B12: 목살 | C12: 15 | D12: LA갈비 | F12: 14 | H12: 부탄가스
A13: 매출누계 | C13: =SUM('1:16'!$C$12) -> 281 | F13: =SUM('1:16'!$F$12) -> 220 | H13: 코카콜라음료 | I13: 240000
A14: 개수 | B14: 생갈비 | C14: 35 | D14: 돼지양념갈비 | F14: 16 | H14: 깍두기,계란
A15: 매출누계 | C15: =SUM('1:16'!$C$14) -> 626 | F15: =SUM('1:16'!$F$14) -> 325 | H15: 식자재2 | I15: 108100 | J15: 비품 및 기타경비
A16: 개수 | B16: 육회 | C16: 5 | D16: 한우업진살 | F16: 10 | J16: 인터넷 주문
A17: 매출누계 | C17: =SUM('1:16'!$C$16) -> 99 | F17: =SUM('1:16'!$F$16) -> 265 | H17: 막걸리 | J17: 다이소 구매
A18: 개수 | B18: 소갈비살 | C18: 39 | D18: LA양념갈비 | F18: 10
A19: 매출누계 | C19: =SUM('1:16'!$C$18) -> 595 | F19: =SUM('1:16'!$F$18) -> 235
D20: 테이블수 | F20: 48
D21: 누적테이블 | F21: =SUM('1:16'!$F$20) -> 985
A22: 중간출금
A23: 출금내역 | H23: 식자재합계 | I23: =SUM(I4:I22) -> 1974530 | J23: 기타경비합계 | K23: =SUM(K4:K22) -> 14193.548 | M23: 현금합계 | N23: =C5+C6 -> 241000
A24: 일매출 | C24: 일평균매출 | E24: 누적총매출 | H24: 일매출 | I24: =I23/A25 -> 0.5131315 | J24: 일매출 | K24: =K23/A25 -> 0.0036885521
A25: =C2 -> 3848000 | C25: =E25/I1 -> 4256725 | E25: =SUM('1:16'!$A$25) -> 68107600 | H25: 누계 | I25: =SUM('1:16'!$I$21) -> 0 | J25: 누계 | K25: =SUM('1:16'!$K$21) -> 0
A26: 전 월 | H26: 누적매출 | I26: =I25/$E$25 -> 0 | J26: 누적매출 | K26: =K25/$E$25 -> 0
A27: 인 건 비 | B27: 직원A | C27: =4000000/31 -> 129032.26 | H27: 인건비합계 | I27: =SUM(C27:D34,F27:G32) -> 771741.94
B28: 직원B | C28: =3800000/31 -> 122580.65 | H28: 일매출 | I28: =I27/$A$25 -> 0.20055664
B29: 직원D | C29: =3200000/31 -> 103225.81 | H29: 누계 | I29: =SUM('1:16'!$I$25) -> 83087328
H30: 누적매출 | I30: =I29/$I$27 -> 107.66206
B31: 직원C | C31: =3500000/31 -> 112903.23 | E31: 파출 | F31: 120000
B32: 알바A | E32: 홀 파출 | F32: 132000
B33: 알바B | C33: =13000*4 -> 52000

Sheet 17
C1: 2025년 | E1: 5 | F1: 17 | G1: 토 | H1: 실영업일수 | I1: =F1-K1 -> 17 | J1: 휴무일수
A2: 매출 | C2: =SUM(C4:D7) -> 4488000 | E2: 시재 | G2: 151250 | H2: 식자재 | J2: 비품 및 기타경비
H3: 업체 | I3: 금액 | J3: 업체 | K3: 금액
A4: 카드 | C4: 3672000 | E4: 카드수수료(2.75%) | G4: =INT(C4*0.0275) -> 100980 | H4: 고기 | I4: =30650+421200+209901+187140+264654+10 -> 1113555 | J4: 숯
A5: 현금 | C5: 816000 | E5: 현금수수료(1%) | G5: =INT(C5*0.01) -> 8160 | H5: 식자재 | I5: =29656+36080+25600+48300 -> 139636
A6: 페이결제 | E6: 통장입금 | G6: 850000 | J6: 음식물스티커
H7: 주류 | J7: 종량제봉투
A8: 금고 실잔액 | C8: 117250 | E8: 마감잔금 | G8: =C5+G2-G6-C22 -> 117250 | H8: 쌀
J9: 뚝배기
A10: 현금할인 | E10: 카드할인 | J10: 발매트
A11: 할인내역 | H11: 참기름 | J11: 불판세척 | K11: =440000/31 -> 14193.548
A12: 개수 | B12: 목살 | C12: 21 | D12: LA갈비 | F12: 5 | H12: 부탄가스
A13: 매출누계 | C13: =SUM('1:17'!$C$12) -> 302 | F13: =SUM('1:17'!$F$12) -> 225 | H13: 코카콜라음료
A14: 개수 | B14: 생갈비 | C14: 60 | D14: 돼지양념갈비 | F14: 30 | H14: 깍두기,계란
A15: 매출누계 | C15: =SUM('1:17'!$C$14) -> 686 | F15: =SUM('1:17'!$F$14) -> 355 | H15: 식자재2 | I15: =5500+22000+9800+5400+78000+6200+13500+17700+19200+3900+3500+8500+16500+3200+6900 -> 219800 | J15: 비품 및 기타경비
A16: 개수 | B16: 육회 | C16: 3 | D16: 한우업진살 | F16: 24 | J16: 인터넷 주문
A17: 매출누계 | C17: =SUM('1:17'!$C$16) -> 102 | F17: =SUM('1:17'!$F$16) -> 289 | H17: 막걸리 | J17: 다이소 구매
A18: 개수 | B18: 소갈비살 | C18: 36 | D18: LA양념갈비 | F18: 11
A19: 매출누계 | C19: =SUM('1:17'!$C$18) -> 631 | F19: =SUM('1:17'!$F$18) -> 246
D20: 테이블수 | F20: 64
D21: 누적테이블 | F21: =SUM('1:17'!$F$20) -> 1049
A22: 중간출금
A23: 출금내역 | H23: 식자재합계 | I23: =SUM(I4:I22) -> 1472991 | J23: 기타경비합계 | K23: =SUM(K4:K22) -> 14193.548 | M23: 현금합계 | N23: =C5+C6 -> 816000
A24: 일매출 | C24: 일평균매출 | E24: 누적총매출 | H24: 일매출 | I24: =I23/A25 -> 0.32820655 | J24: 일매출 | K24: =K23/A25 -> 0.0031625553
A25: =C2 -> 4488000 | C25: =E25/I1 -> 4270329.4 | E25: =SUM('1:17'!$A$25) -> 72595600 | H25: 누계 | I25: =SUM('1:17'!$I$21) -> 0 | J25: 누계 | K25: =SUM('1:17'!$K$21) -> 0
A26: 전 월 | H26: 누적매출 | I26: =I25/$E$25 -> 0 | J26: 누적매출 | K26: =K25/$E$25 -> 0
A27: 인 건 비 | B27: 직원A | C27: =4000000/31 -> 129032.26 | H27: 인건비합계 | I27: =SUM(C27:D34,F27:G32) -> 752241.94
B28: 직원B | C28: =3800000/31 -> 122580.65 | H28: 일매출 | I28: =I27/$A$25 -> 0.16761184
B29: 직원D | C29: =3200000/31 -> 103225.81 | H29: 누계 | I29: =SUM('1:17'!$I$25) -> 83087328
H30: 누적매출 | I30: =I29/$I$27 -> 110.45293
B31: 직원C | C31: =3500000/31 -> 112903.23 | E31: 파출 | F31: 130000
B32: 알바A | C32: =14000*5 -> 70000 | E32: 홀 파출
B33: 알바B | C33: =13000*6.5 -> 84500

Sheet 18
C1: 2025년 | E1: 5 | F1: 18 | G1: 일 | H1: 실영업일수 | I1: =F1-K1 -> 18 | J1: 휴무일수
A2: 매출 | C2: =SUM(C4:D7) -> 4610000 | E2: 시재 | G2: 117250 | H2: 식자재 | J2: 비품 및 기타경비
H3: 업체 | I3: 금액 | J3: 업체 | K3: 금액
A4: 카드 | C4: 3787000 | E4: 카드수수료(2.75%) | G4: =INT(C4*0.0275) -> 104142 | H4: 고기 | J4: 숯
A5: 현금 | C5: 823000 | E5: 현금수수료(1%) | G5: =INT(C5*0.01) -> 8230 | H5: 식자재
A6: 페이결제 | E6: 통장입금 | G6: 800000 | J6: 음식물스티커
H7: 주류 | J7: 종량제봉투
A8: 금고 실잔액 | E8: 마감잔금 | G8: =C5+G2-G6-C22 -> 140250 | H8: 쌀
J9: 뚝배기
A10: 현금할인 | C10: 4000 | E10: 카드할인 | J10: 발매트
A11: 할인내역 | C11: 카드 없고 현금 부족한 외국인 할인처리(현금 뽑아서 채워두겠습니다 -명성올림-) | H11: 참기름 | J11: 불판세척 | K11: =440000/31 -> 14193.548
A12: 개수 | B12: 목살 | C12: 23 | D12: LA갈비 | F12: 13 | H12: 부탄가스
A13: 매출누계 | C13: =SUM('1:18'!$C$12) -> 325 | F13: =SUM('1:18'!$F$12) -> 238 | H13: 코카콜라음료
A14: 개수 | B14: 생갈비 | C14: 55 | D14: 돼지양념갈비 | F14: 27 | H14: 깍두기,계란
A15: 매출누계 | C15: =SUM('1:18'!$C$14) -> 741 | F15: =SUM('1:18'!$F$14) -> 382 | H15: 식자재2 | J15: 비품 및 기타경비
A16: 개수 | B16: 육회 | C16: 4 | D16: 한우업진살 | F16: 26 | J16: 인터넷 주문
A17: 매출누계 | C17: =SUM('1:18'!$C$16) -> 106 | F17: =SUM('1:18'!$F$16) -> 315 | H17: 막걸리 | J17: 다이소 구매
A18: 개수 | B18: 소갈비살 | C18: 30 | D18: LA양념갈비 | F18: 18
A19: 매출누계 | C19: =SUM('1:18'!$C$18) -> 661 | F19: =SUM('1:18'!$F$18) -> 264
D20: 테이블수 | F20: 74
D21: 누적테이블 | F21: =SUM('1:18'!$F$20) -> 1123
A22: 중간출금
A23: 출금내역 | H23: 식자재합계 | I23: =SUM(I4:I22) -> 0 | J23: 기타경비합계 | K23: =SUM(K4:K22) -> 14193.548 | M23: 현금합계 | N23: =C5+C6 -> 823000
A24: 일매출 | C24: 일평균매출 | E24: 누적총매출 | H24: 일매출 | I24: =I23/A25 -> 0 | J24: 일매출 | K24: =K23/A25 -> 0.0030788608
A25: =C2 -> 4610000 | C25: =E25/I1 -> 4289200 | E25: =SUM('1:18'!$A$25) -> 77205600 | H25: 누계 | I25: =SUM('1:18'!$I$21) -> 0 | J25: 누계 | K25: =SUM('1:18'!$K$21) -> 0
A26: 전 월 | H26: 누적매출 | I26: =I25/$E$25 -> 0 | J26: 누적매출 | K26: =K25/$E$25 -> 0
A27: 인 건 비 | B27: 직원A | C27: =4000000/31 -> 129032.26 | H27: 인건비합계 | I27: =SUM(C27:D34,F27:G32) -> 712741.94
B28: 직원B | C28: =3800000/31 -> 122580.65 | H28: 일매출 | I28: =I27/$A$25 -> 0.1546078
B29: 직원D | C29: =3200000/31 -> 103225.81 | H29: 누계 | I29: =SUM('1:18'!$I$25) -> 83087328
H30: 누적매출 | I30: =I29/$I$27 -> 116.57421
B31: 직원C | C31: =3500000/31 -> 112903.23 | E31: 파출 | F31: 130000
B32: 알바A | C32: =14000*4.5 -> 63000 | E32: 홀 파출
B33: 알바B | C33: =13000*4 -> 52000

Sheet 19
C1: 2025년 | E1: 5 | F1: 19 | G1: 월 | H1: 실영업일수 | I1: =F1-K1 -> 19 | J1: 휴무일수
A2: 매출 | C2: =SUM(C4:D7) -> 3897000 | E2: 시재 | G2: 140250 | H2: 식자재 | J2: 비품 및 기타경비
H3: 업체 | I3: 금액 | J3: 업체 | K3: 금액
A4: 카드 | C4: 3598000 | E4: 카드수수료(2.75%) | G4: =INT(C4*0.0275) -> 98945 | H4: 고기 | I4: =452000+216000+213683+199616+285012 -> 1366311 | J4: 숯
A5: 현금 | C5: 299000 | E5: 현금수수료(1%) | G5: =INT(C5*0.01) -> 2990 | H5: 식자재 | I5: =38940+88968+72160+22260 -> 222328
A6: 페이결제 | E6: 통장입금 | G6: 330000 | J6: 음식물스티커
H7: 주류 | I7: =433300-64300 -> 369000 | J7: 종량제봉투
A8: 금고 실잔액 | C8: 109250 | E8: 마감잔금 | G8: =C5+G2-G6-C22 -> 109250 | H8: 쌀 | I8: 56000
J9: 뚝배기
A10: 현금할인 | C10: 83000 | E10: 카드할인 | J10: 발매트 | K10: 13000
A11: 할인내역 | C11: 선결제 | H11: 참기름 | J11: 불판세척 | K11: =440000/31 -> 14193.548
A12: 개수 | B12: 목살 | C12: 11 | D12: LA갈비 | F12: 6 | H12: 부탄가스
A13: 매출누계 | C13: =SUM('1:19'!$C$12) -> 336 | F13: =SUM('1:19'!$F$12) -> 244 | H13: 코카콜라음료
A14: 개수 | B14: 생갈비 | C14: 19 | D14: 돼지양념갈비 | F14: 13 | H14: 깍두기,계란
A15: 매출누계 | C15: =SUM('1:19'!$C$14) -> 760 | F15: =SUM('1:19'!$F$14) -> 395 | H15: 식자재2 | I15: =38400+17000+33000+11800+25500 -> 125700 | J15: 비품 및 기타경비 | K15: 286000
A16: 개수 | B16: 육회 | C16: 5 | D16: 한우업진살 | F16: 20 | J16: 인터넷 주문 | K16: 224230
A17: 매출누계 | C17: =SUM('1:19'!$C$16) -> 111 | F17: =SUM('1:19'!$F$16) -> 335 | H17: 막걸리 | J17: 다이소 구매
A18: 개수 | B18: 소갈비살 | C18: 20 | D18: LA양념갈비 | F18: 23
A19: 매출누계 | C19: =SUM('1:19'!$C$18) -> 681 | F19: =SUM('1:19'!$F$18) -> 287
D20: 테이블수 | F20: 63
D21: 누적테이블 | F21: =SUM('1:19'!$F$20) -> 1186
A22: 중간출금
A23: 출금내역 | H23: 식자재합계 | I23: =SUM(I4:I22) -> 2139339 | J23: 기타경비합계 | K23: =SUM(K4:K22) -> 537423.55 | M23: 현금합계 | N23: =C5+C6 -> 299000
A24: 일매출 | C24: 일평균매출 | E24: 누적총매출 | H24: 일매출 | I24: =I23/A25 -> 0.54897075 | J24: 일매출 | K24: =K23/A25 -> 0.13790699
A25: =C2 -> 3897000 | C25: =E25/I1 -> 4268557.9 | E25: =SUM('1:19'!$A$25) -> 81102600 | H25: 누계 | I25: =SUM('1:18'!$I$21) -> 0 | J25: 누계 | K25: =SUM('1:18'!$K$21) -> 0
A26: 전 월 | H26: 누적매출 | I26: =I25/$E$25 -> 0 | J26: 누적매출 | K26: =K25/$E$25 -> 0
A27: 인 건 비 | B27: 직원A | C27: =4000000/31 -> 129032.26 | H27: 인건비합계 | I27: =SUM(C27:D34,F27:G32) -> 658741.94
B28: 직원B | C28: =3800000/31 -> 122580.65 | H28: 일매출 | I28: =I27/$A$25 -> 0.16903822
B29: 직원D | C29: =3200000/31 -> 103225.81 | H29: 누계 | I29: =SUM('1:18'!$I$25) -> 83087328
H30: 누적매출 | I30: =I29/$I$27 -> 126.13032
B31: 직원C | C31: =3500000/31 -> 112903.23 | E31: 파출 | F31: 120000
B32: 알바A | E32: 홀 파출 | F32: 71000
B33: 알바B

Sheet 20
C1: 2025년 | E1: 5 | F1: 20 | G1: 화 | H1: 실영업일수 | I1: =F1-K1 -> 20 | J1: 휴무일수
A2: 매출 | C2: =SUM(C4:D7) -> 3442500 | E2: 시재 | G2: 109250 | H2: 식자재 | J2: 비품 및 기타경비
H3: 업체 | I3: 금액 | J3: 업체 | K3: 금액
A4: 카드 | C4: 3120000 | E4: 카드수수료(2.75%) | G4: =INT(C4*0.0275) -> 85800 | H4: 고기 | I4: =43500+226800+208010 -> 478310 | J4: 숯
A5: 현금 | C5: 322500 | E5: 현금수수료(1%) | G5: =INT(C5*0.01) -> 3225 | H5: 식자재 | I5: =38940+29656+36080+48300+25600+22260+125340+12360 -> 338536
A6: 페이결제 | E6: 통장입금 | G6: 350000 | J6: 음식물스티커
H7: 주류 | J7: 종량제봉투
A8: 금고 실잔액 | C8: 81750 | E8: 마감잔금 | G8: =C5+G2-G6-C22 -> 81750 | H8: 쌀
J9: 뚝배기
A10: 현금할인 | E10: 카드할인 | J10: 발매트
A11: 할인내역 | H11: 참기름 | J11: 불판세척 | K11: =440000/31 -> 14193.548
A12: 개수 | B12: 목살 | C12: 9 | D12: LA갈비 | F12: 5 | H12: 부탄가스
A13: 매출누계 | C13: =SUM('1:20'!$C$12) -> 345 | F13: =SUM('1:20'!$F$12) -> 249 | H13: 코카콜라음료
A14: 개수 | B14: 생갈비 | C14: 29 | D14: 돼지양념갈비 | F14: 20 | H14: 깍두기,계란
A15: 매출누계 | C15: =SUM('1:20'!$C$14) -> 789 | F15: =SUM('1:20'!$F$14) -> 415 | H15: 식자재2 | I15: =11800+10500+33000+1200+3200+4000+3500+3500 -> 70700 | J15: 비품 및 기타경비
A16: 개수 | B16: 육회 | C16: 8 | D16: 한우업진살 | F16: 9 | J16: 인터넷 주문 | K16: 11112
A17: 매출누계 | C17: =SUM('1:20'!$C$16) -> 119 | F17: =SUM('1:20'!$F$16) -> 344 | H17: 막걸리 | J17: 다이소 구매
A18: 개수 | B18: 소갈비살 | C18: 32 | D18: LA양념갈비 | F18: 11
A19: 매출누계 | C19: =SUM('1:20'!$C$18) -> 713 | F19: =SUM('1:20'!$F$18) -> 298
D20: 테이블수 | F20: 52
D21: 누적테이블 | F21: =SUM('1:20'!$F$20) -> 1238
A22: 중간출금
A23: 출금내역 | H23: 식자재합계 | I23: =SUM(I4:I22) -> 887546 | J23: 기타경비합계 | K23: =SUM(K4:K22) -> 25305.548 | M23: 현금합계 | N23: =C5+C6 -> 322500
A24: 일매출 | C24: 일평균매출 | E24: 누적총매출 | H24: 일매출 | I24: =I23/A25 -> 0.25782019 | J24: 일매출 | K24: =K23/A25 -> 0.0073509218
A25: =C2 -> 3442500 | C25: =E25/I1 -> 4227255 | E25: =SUM('1:20'!$A$25) -> 84545100 | H25: 누계 | I25: =SUM('1:20'!$I$21) -> 0 | J25: 누계 | K25: =SUM('1:20'!$K$21) -> 0
A26: 전 월 | H26: 누적매출 | I26: =I25/$E$25 -> 0 | J26: 누적매출 | K26: =K25/$E$25 -> 0
A27: 인 건 비 | B27: 직원A | C27: =4000000/31 -> 129032.26 | H27: 인건비합계 | I27: =SUM(C27:D34,F27:G32) -> 719741.94
B28: 직원B | C28: =3800000/31 -> 122580.65 | H28: 일매출 | I28: =I27/$A$25 -> 0.20907536
B29: 직원D | C29: =3200000/31 -> 103225.81 | H29: 누계 | I29: =SUM('1:20'!$I$25) -> 83087328
H30: 누적매출 | I30: =I29/$I$27 -> 115.44044
B31: 직원C | C31: =3500000/31 -> 112903.23 | E31: 파출 | F31: 120000
B32: 알바A | E32: 홀 파출 | F32: 132000
B33: 알바B

Sheet 21
C1: 2025년 | E1: 5 | F1: 21 | G1: 수 | H1: 실영업일수 | I1: =F1-K1 -> 21 | J1: 휴무일수
A2: 매출 | C2: =SUM(C4:D7) -> 4697500 | E2: 시재 | G2: 81750 | H2: 식자재 | J2: 비품 및 기타경비
H3: 업체 | I3: 금액 | J3: 업체 | K3: 금액
A4: 카드 | C4: 4094500 | E4: 카드수수료(2.75%) | G4: =INT(C4*0.0275) -> 112598 | H4: 고기 | I4: =452000 -> 452000 | J4: 숯 | K4: 217000
A5: 현금 | C5: 603000 | E5: 현금수수료(1%) | G5: =INT(C5*0.01) -> 6030 | H5: 식자재 | I5: =47300+41250+38940+29656+36080+25600+22260+15340+10390 -> 266816
A6: 페이결제 | E6: 통장입금 | G6: 570000 | J6: 음식물스티커
H7: 주류 | I7: 324000 | J7: 종량제봉투
A8: 금고 실잔액 | C8: 114750 | E8: 마감잔금 | G8: =C5+G2-G6-C22 -> 114750 | H8: 쌀 | I8: 56000
J9: 뚝배기
A10: 현금할인 | E10: 카드할인 | J10: 발매트
A11: 할인내역 | H11: 참기름 | J11: 불판세척 | K11: =440000/31 -> 14193.548
A12: 개수 | B12: 목살 | C12: 16 | D12: LA갈비 | F12: 12 | H12: 부탄가스
A13: 매출누계 | C13: =SUM('1:21'!$C$12) -> 361 | F13: =SUM('1:21'!$F$12) -> 261 | H13: 코카콜라음료
A14: 개수 | B14: 생갈비 | C14: 42 | D14: 돼지양념갈비 | F14: 17 | H14: 깍두기,계란
A15: 매출누계 | C15: =SUM('1:21'!$C$14) -> 831 | F15: =SUM('1:21'!$F$14) -> 432 | H15: 식자재2 | I15: 181750 | J15: 비품 및 기타경비
A16: 개수 | B16: 육회 | C16: 6 | D16: 한우업진살 | F16: 17 | J16: 인터넷 주문 | K16: 182752
A17: 매출누계 | C17: =SUM('1:21'!$C$16) -> 125 | F17: =SUM('1:21'!$F$16) -> 361 | H17: 막걸리 | J17: 다이소 구매
A18: 개수 | B18: 소갈비살 | C18: 40 | D18: LA양념갈비 | F18: 11
A19: 매출누계 | C19: =SUM('1:21'!$C$18) -> 753 | F19: =SUM('1:21'!$F$18) -> 309
D20: 테이블수 | F20: 72
D21: 누적테이블 | F21: =SUM('1:21'!$F$20) -> 1310
A22: 중간출금
A23: 출금내역 | H23: 식자재합계 | I23: =SUM(I4:I22) -> 1280566 | J23: 기타경비합계 | K23: =SUM(K4:K22) -> 413945.55 | M23: 현금합계 | N23: =C5+C6 -> 603000
A24: 일매출 | C24: 일평균매출 | E24: 누적총매출 | H24: 일매출 | I24: =I23/A25 -> 0.27260585 | J24: 일매출 | K24: =K23/A25 -> 0.088120393
A25: =C2 -> 4697500 | C25: =E25/I1 -> 4249647.6 | E25: =SUM('1:21'!$A$25) -> 89242600 | H25: 누계 | I25: =SUM('1:21'!$I$21) -> 0 | J25: 누계 | K25: =SUM('1:21'!$K$21) -> 0
A26: 전 월 | H26: 누적매출 | I26: =I25/$E$25 -> 0 | J26: 누적매출 | K26: =K25/$E$25 -> 0
A27: 인 건 비 | B27: 직원A | C27: =4000000/31 -> 129032.26 | H27: 인건비합계 | I27: =SUM(C27:D34,F27:G32) -> 771741.94
B28: 직원B | C28: =3800000/31 -> 122580.65 | H28: 일매출 | I28: =I27/$A$25 -> 0.1642878
B29: 직원D | C29: =3200000/31 -> 103225.81 | H29: 누계 | I29: =SUM('1:21'!$I$25) -> 83087328
H30: 누적매출 | I30: =I29/$I$27 -> 107.66206
B31: 직원C | C31: =3500000/31 -> 112903.23 | E31: 파출 | F31: 120000
B32: 알바A | E32: 홀 파출 | F32: 132000
B33: 알바B | C33: =13000*4 -> 52000

Sheet 22
C1: 2025년 | E1: 5 | F1: 22 | G1: 목 | H1: 실영업일수 | I1: =F1-K1 -> 22 | J1: 휴무일수
A2: 매출 | C2: =SUM(C4:D7) -> 4946000 | E2: 시재 | G2: 114750 | H2: 식자재 | J2: 비품 및 기타경비
H3: 업체 | I3: 금액 | J3: 업체 | K3: 금액
A4: 카드 | C4: 4537000 | E4: 카드수수료(2.75%) | G4: =INT(C4*0.0275) -> 124767 | H4: 고기 | I4: =56220+955200+452000+253800+412238+246401+10+547404 -> 2923273 | J4: 숯
A5: 현금 | C5: 409000 | E5: 현금수수료(1%) | G5: =INT(C5*0.01) -> 4090 | H5: 식자재
A6: 페이결제 | E6: 통장입금 | G6: 400000 | J6: 음식물스티커
H7: 주류 | J7: 종량제봉투
A8: 금고 실잔액 | C8: 123750 | E8: 마감잔금 | G8: =C5+G2-G6-C22 -> 123750 | H8: 쌀
J9: 뚝배기
A10: 현금할인 | E10: 카드할인 | J10: 발매트
A11: 할인내역 | H11: 참기름 | J11: 불판세척 | K11: =440000/31 -> 14193.548
A12: 개수 | B12: 목살 | C12: 13 | D12: LA갈비 | F12: 4 | H12: 부탄가스
A13: 매출누계 | C13: =SUM('1:22'!$C$12) -> 374 | F13: =SUM('1:22'!$F$12) -> 265 | H13: 코카콜라음료
A14: 개수 | B14: 생갈비 | C14: 36 | D14: 돼지양념갈비 | F14: 18 | H14: 깍두기,계란
A15: 매출누계 | C15: =SUM('1:22'!$C$14) -> 867 | F15: =SUM('1:22'!$F$14) -> 450 | H15: 식자재2 | I15: =13500+52000+19200+4900+5500+11800+54400+7800+3200 -> 172300 | J15: 비품 및 기타경비
A16: 개수 | B16: 육회 | C16: 6 | D16: 한우업진살 | F16: 27 | J16: 인터넷 주문 | K16: 74260
A17: 매출누계 | C17: =SUM('1:22'!$C$16) -> 131 | F17: =SUM('1:22'!$F$16) -> 388 | H17: 막걸리 | J17: 다이소 구매
A18: 개수 | B18: 소갈비살 | C18: 50 | D18: LA양념갈비 | F18: 8
A19: 매출누계 | C19: =SUM('1:22'!$C$18) -> 803 | F19: =SUM('1:22'!$F$18) -> 317
D20: 테이블수 | F20: 78
D21: 누적테이블 | F21: =SUM('1:22'!$F$20) -> 1388
A22: 중간출금
A23: 출금내역 | H23: 식자재합계 | I23: =SUM(I4:I22) -> 3095573 | J23: 기타경비합계 | K23: =SUM(K4:K22) -> 88453.548 | M23: 현금합계 | N23: =C5+C6 -> 409000
A24: 일매출 | C24: 일평균매출 | E24: 누적총매출 | H24: 일매출 | I24: =I23/A25 -> 0.62587404 | J24: 일매출 | K24: =K23/A25 -> 0.017883855
A25: =C2 -> 4946000 | C25: =E25/I1 -> 4281300 | E25: =SUM('1:22'!$A$25) -> 94188600 | H25: 누계 | I25: =SUM('1:22'!$I$21) -> 0 | J25: 누계 | K25: =SUM('1:22'!$K$21) -> 0
A26: 전 월 | H26: 누적매출 | I26: =I25/$E$25 -> 0 | J26: 누적매출 | K26: =K25/$E$25 -> 0
A27: 인 건 비 | B27: 직원A | C27: =4000000/31 -> 129032.26 | H27: 인건비합계 | I27: =SUM(C27:D34,F27:G32) -> 771741.94
B28: 직원B | C28: =3800000/31 -> 122580.65 | H28: 일매출 | I28: =I27/$A$25 -> 0.15603355
B29: 직원D | C29: =3200000/31 -> 103225.81 | H29: 누계 | I29: =SUM('1:22'!$I$25) -> 83087328
H30: 누적매출 | I30: =I29/$I$27 -> 107.66206
B31: 직원C | C31: =3500000/31 -> 112903.23 | E31: 파출 | F31: 120000
B32: 알바A | E32: 홀 파출 | F32: 132000
B33: 알바B | C33: =13000*4 -> 52000

Sheet 23
C1: 2025년 | E1: 5 | F1: 23 | G1: 금 | H1: 실영업일수 | I1: =F1-K1 -> 23 | J1: 휴무일수
A2: 매출 | C2: =SUM(C4:D7) -> 5983500 | E2: 시재 | G2: 123750 | H2: 식자재 | J2: 비품 및 기타경비
H3: 업체 | I3: 금액 | J3: 업체 | K3: 금액
A4: 카드 | C4: 5285500 | E4: 카드수수료(2.75%) | G4: =INT(C4*0.0275) -> 145351 | H4: 고기 | I4: =452000+243000+269178 -> 964178 | J4: 숯
A5: 현금 | C5: 698000 | E5: 현금수수료(1%) | G5: 0 | H5: 식자재 | I5: =22260+13600+9150 -> 45010
A6: 페이결제 | E6: 통장입금 | G6: 650000 | J6: 음식물스티커
H7: 주류 | J7: 종량제봉투 | K7: 12500
A8: 금고 실잔액 | C8: 173000 | E8: 마감잔금 | G8: =C5+G2-G6-C22 -> 171750 | H8: 쌀 | I8: 56000
J9: 뚝배기
A10: 현금할인 | E10: 카드할인 | J10: 발매트
A11: 할인내역 | H11: 참기름 | J11: 불판세척 | K11: =440000/31 -> 14193.548
A12: 개수 | B12: 목살 | C12: 26 | D12: LA갈비 | F12: 7 | H12: 부탄가스
A13: 매출누계 | C13: =SUM('1:23'!$C$12) -> 400 | F13: =SUM('1:23'!$F$12) -> 272 | H13: 코카콜라음료
A14: 개수 | B14: 생갈비 | C14: 62 | D14: 돼지양념갈비 | F14: 23 | H14: 깍두기,계란
A15: 매출누계 | C15: =SUM('1:23'!$C$14) -> 929 | F15: =SUM('1:23'!$F$14) -> 473 | H15: 식자재2 | I15: =6600+12400+4900+5500+11800+27200 -> 68400 | J15: 비품 및 기타경비
A16: 개수 | B16: 육회 | C16: 7 | D16: 한우업진살 | F16: 24 | J16: 인터넷 주문
A17: 매출누계 | C17: =SUM('1:23'!$C$16) -> 138 | F17: =SUM('1:23'!$F$16) -> 412 | H17: 막걸리 | J17: 다이소 구매
A18: 개수 | B18: 소갈비살 | C18: 52 | D18: LA양념갈비 | F18: 17
A19: 매출누계 | C19: =SUM('1:23'!$C$18) -> 855 | F19: =SUM('1:23'!$F$18) -> 334
D20: 테이블수 | F20: 78
