Workbook

Sheet 월합산
A1: 월 합 산
A2: 매출 | C2: =C3+G3+C5 -> 0 | E2: 시제 | H2: 비 고
A3: 카드매출 | C3: =SUM('1'!C3) -> 0 | E3: 현금매출 | G3: =SUM('1'!G3) -> 0
A4: 금고잔액 | C4: =C21 -> 0 | E4: 입금 | G4: =C17 -> 0
A5: 할인금액 | C5: =C6+G6 -> 0 | E5: 잔금 | G5: =C4-G4 -> 0
A6: 현금할인 | C6: =SUM('1'!C7) -> 0 | E6: 카드할인 | G6: =SUM('1'!G7) -> 0
A7: 할인내역
H8: take out | I8: 매출누계 | K8: =SUM('1'!K9) -> 0
H9: 배달 | I9: 매출누계 | K9: =SUM('1'!K10) -> 0
I10: 배달료누계 | K10: =SUM('1'!K11) -> 14666.667
A11: 중간출금 | H11: 중간입금
A12: 출금내역 | H12: 입금내역
A13: 영업일수 | C13: 일평균매출 | E13: 누적총매출 | H13: 목표일매출 | J13: 목표월매출
A14: =C2 -> 0 | C14: =ROUNDDOWN((E14/A14),-4) -> #DIV/0! | E14: =C2 -> 0
A15: 전 월
A16: 마 감 잔 금 | G16: 마 감 잔 금
A17: 만 | G17: 만
A18: 천 | G18: 천
A19: 오백 | G19: 오백
A20: 백이하 | G20: 백이하
A21: 합계 | C21: =SUM(C17:E20) -> 0 | G21: 합계 | H21: =SUM(H17:K20) -> 0

Sheet 결산
E1: 6월
A4: 고정비용 | F4: 변동비용
A5: 항목 | D5: 항목별 소계 | E5: 매출대비 비율 | F5: 항목 | G5: 업체 | H5: 금액 | J5: 항목별 소계 | M5: 통장입금 | N5: =SUM('1:30'!G6) -> 20391000
A6: 월세 | C6: 6985000 | D6: =C6 -> 6985000 | E6: =D6/$B$45 -> 0.052995558 | F6: 식자재 | G6: 고기 | H6: =SUM('1:30'!I4) -> 33512194 | I6: =H6/$B$45 -> 0.25425876 | J6: =SUM(H6:H18) -> 47950692 | K6: =J6/$B$45 -> 0.36380439
A7: 마케팅 | C7: 2600000 | D7: =C7 -> 2600000 | E7: =D7/$B$45 -> 0.019726335 | G7: 식자재 | H7: =SUM('1:30'!I5) -> 5249108 | I7: =H7/$B$45 -> 0.039825255 | M7: 생갈비 | N7: =SUM('30'!C15) -> 1310
A8: 포스 | C8: 154000 | D8: =C8 -> 154000 | E8: =D8/$B$45 -> 0.001168406 | G8: 주류 | H8: =SUM('1:30'!I7) -> 3976890 | I8: =H8/$B$45 -> 0.030172871 | M8: 목살 | N8: =SUM('30'!C13) -> 451
A9: 수도 | C9: 670000 | D9: =C9 -> 670000 | E9: =D9/$B$45 -> 0.0050833248 | G9: 쌀 | H9: =SUM('1:30'!I8) -> 798000 | I9: =H9/$B$45 -> 0.0060544674 | M9: 육회 | N9: =SUM('30'!C17) -> 194
A10: 화재보험 | C10: 66000 | D10: =C10 -> 66000 | E10: =D10/$B$45 -> 0.00050074543 | G10: 참기름 | H10: =SUM('1:30'!I11) -> 200000 | I10: =H10/$B$45 -> 0.0015174104 | M10: LA갈비 | N10: =SUM('30'!F13) -> 266
A11: 세무사 | C11: 330000 | D11: =C11 -> 330000 | E11: =D11/$B$45 -> 0.0025037271 | G11: 부탄가스 | H11: =SUM('1:30'!I12) -> 0 | I11: =H11/$B$45 -> 0 | M11: 돼지양념갈비 | N11: =SUM('30'!F15) -> 560
A12: 인터넷 | C12: 48000 | D12: =C12 -> 48000 | E12: =D12/$B$45 -> 0.00036417849 | G12: 코카콜라 | H12: =SUM('1:30'!I13) -> 240000 | I12: =H12/$B$45 -> 0.0018208925 | M12: 한우업진살 | N12: =SUM('30'!F17) -> 552
A13: 쿠쿠(블루문) | C13: 66000 | D13: =C13 -> 66000 | E13: =D13/$B$45 -> 0.00050074543 | G13: 깍두기,계란 | H13: =SUM('1:30'!I14) -> 0 | I13: =H13/$B$45 -> 0 | M13: 소갈비살 | N13: =SUM('30'!C19) -> 1080
D14: =C14 -> 0 | E14: =D14/$B$45 -> 0 | G14: 막걸리 | H14: =SUM('1:30'!I17) -> 36800 | I14: =H14/$B$45 -> 0.00027920351 | M14: LA양념갈비 | N14: =SUM('30'!F19) -> 403
D15: =C15 -> 0 | E15: =D15/$B$45 -> 0 | G15: 식자재2 | H15: =SUM('1:30'!I15) -> 3937700 | I15: =H15/$B$45 -> 0.029875534 | M15: 6월 테이블수 | N15: =SUM('30'!F21) -> 1809
A16: 전기세 | D16: =C16 -> 0 | E16: =D16/$B$45 -> 0
A17: 가스비 | C17: 1508770 | D17: =C17 -> 1508770 | E17: =D17/$B$45 -> 0.011447116
A18: 소 계 | C18: 0 | E18: =SUM(E6:E17) -> 0.094290136
A19: 급여 | B19: 직원A | C19: 4000000 | D19: =SUM(C19:C30) -> 23645725 | E19: =D19/$B$45 -> 0.17940134 | F19: 비품 및 기타경비 | G19: 숯 | H19: =SUM('1:30'!K4) -> 1108400 | I19: =H19/$B$45 -> 0.0084094884 | J19: =SUM(H19:H32) -> 3950768 | K19: =J19/$B$45 -> 0.029974682
B20: 직원B | C20: 3800000 | G20: 음식물스티커 | H20: =SUM('1:30'!K6) -> 0 | I20: =H20/$B$45 -> 0
B21: 직원C | C21: =3500000 -> 3500000 | G21: 종량재봉투 | H21: =SUM('1:30'!K7) -> 25000 | I21: =H21/$B$45 -> 0.0001896763
B22: 직원D | C22: 3200000 | G22: 뚝배기 | H22: =SUM('1:30'!K9) -> 0 | I22: =H22/$B$45 -> 0
G23: 발매트 | H23: =SUM('1:30'!K10) -> 58000 | I23: =H23/$B$45 -> 0.00044004901
B24: 직원F | C24: 1500000 | G24: 불판세척 | H24: =SUM('1:30'!K11) -> 440000 | I24: =H24/$B$45 -> 0.0033383029
B25: 알바A | C25: =SUM('1:30'!C32) -> 546000 | G25: 비품 및 기타경비 | H25: =SUM('1:30'!K15) -> 0
B26: 알바B | C26: =SUM('1:30'!C33) -> 1605500 | G26: 인터넷 주문 | H26: =SUM('1:30'!K16) -> 2292362 | I26: =H26/$B$45 -> 0.01739227
B27: 알바C | C27: =SUM('1:30'!F27) -> 470925 | G27: 다이소 구매 | H27: =SUM('1:30'!K17) -> 27006 | I27: =H27/$B$45 -> 0.00020489592
B28: 알바X | C28: =SUM('1:30'!C34) -> 456300
B29: 홀 파출 | C29: =SUM('1:30'!F32) -> 813000
B30: 파출 | C30: =SUM('1:30'!F31) -> 3754000
B31: 합계 | C31: =SUM(C19:C30) -> 23645725
A32: 퇴직금(10%) | C32: =(C19+C20+C21+C22)*0.1 -> 1450000 | D32: =C32 -> 1450000 | E32: =(D32:D33)/$B$45 -> 0.011001225
A33: 4대보험료 | D33: =C33 -> 0 | F33: 현금수수료 (1%) | H33: =SUM('1:30'!$G$5) -> 195510 | J33: =H33 -> 195510 | K33: =J33/$B$45 -> 0.0014833445
A34: 소 계 | C34: =SUM(C6:D17,C19:C24,C32:C33) -> 42305540 | E34: =SUM(E19:E33) -> 0.19040257 | F34: 카드수수료(2.75%) | H34: =SUM('1:30'!$G$4) -> 3064331 | J34: =H34 -> 3064331 | K34: =J34/$B$45 -> 0.023249238
A35: 합 계 | E35: =E18+E34 -> 0.28469271 | H35: =SUM(J6:J34) -> 55161301 | K35: =SUM(K6:K34) -> 0.41851166
A38: 항목 | B38: 금액 | C38: 항목 비율 | D38: 매출 비율 | F38: 손익분기점
A39: 고정비용 | B39: =$C$34 -> 42305540 | C39: =B39/$B$41 -> 0.43405059 | D39: =B39/$B$45 -> 0.32097433 | F39: 손익분기점 매출액 X
A40: 변동비용 | B40: =$H$35 -> 55161301 | C40: =B40/$B$41 -> 0.56594941 | D40: =B40/$B$45 -> 0.41851166 | F40: 고정비 | H40: F | K40: =$C$34 -> 42305540
A41: 총비용 | B41: =SUM(B39:B40) -> 97466841 | C41: =SUM(C39:C40) -> 1 | D41: =SUM(D39:D40) -> 0.73948598 | F41: 변동비 | H41: V | K41: =$H$35 -> 55161301
A42: 카드매출 | B42: =SUM('1:30'!C4) -> 111430500 | D42: =B42/$B$45 -> 0.84542899 | F42: 매출액 | H42: S | K42: =$B$45 -> 131803500
A43: 현금매출 | B43: =SUM('1:30'!C5) -> 20373000 | D43: =B43/$B$45 -> 0.15457101 | F43: 변동비율 | H43: V/S | K43: =(K41)/K42 -> 0.41851166
A44: 페이매출 | B44: =SUM('1:30'!C6) -> 0 | D44: =B44/$B$45 -> 0 | F44: 손익분기점 매출액 | H44: X=F/(1-(V/S)) | K44: =K40/(1-K43) -> 72753892
...

Sheet 1
C1: 2025년 | E1: 6월 | F1: 1 | G1: 일 | H1: 실영업일수 | I1: =F1-K1 -> 1 | J1: 휴무일수
A2: 매출 | C2: =SUM(C4:D7) -> 3136000 | E2: 시재 | G2: 196000 | H2: 식자재 | J2: 비품 및 기타경비
H3: 업체 | I3: 금액 | J3: 업체 | K3: 금액
A4: 카드 | C4: 2731000 | E4: 카드수수료(2.75%) | G4: =INT(C4*0.0275) -> 75102 | H4: 고기 | J4: 숯
A5: 현금 | C5: 405000 | E5: 현금수수료(1%) | G5: =INT(C5*0.01) -> 4050 | H5: 식자재
A6: 페이결제 | E6: 통장입금 | G6: 440000 | J6: 음식물스티커
H7: 주류 | J7: 종량제봉투
A8: 금고 실잔액 | C8: 140000 | E8: 마감잔금 | G8: =C5+G2-G6-C22 -> 161000 | H8: 쌀
J9: 뚝배기
A10: 현금할인 | E10: 카드할인 | J10: 발매트
A11: 할인내역 | H11: 참기름 | J11: 불판세척 | K11: =440000/30 -> 14666.667
A12: 개수 | B12: 목살 | C12: 9 | D12: LA갈비 | F12: 6 | H12: 부탄가스
A13: 매출누계 | C13: =SUM('1'!$C$12) -> 9 | F13: =SUM('1'!$F$12) -> 6 | H13: 코카콜라음료
A14: 개수 | B14: 생갈비 | C14: 30 | D14: 돼지양념갈비 | F14: 14 | H14: 깍두기,계란
A15: 매출누계 | C15: =SUM('1'!$C$14) -> 30 | F15: =SUM('1'!$F$14) -> 14 | H15: 식자재2 | J15: 비품 및 기타경비
A16: 개수 | B16: 육회 | C16: 5 | D16: 한우업진살 | F16: 14 | J16: 인터넷 주문
A17: 매출누계 | C17: =SUM('1'!$C$16) -> 5 | F17: =SUM('1'!$F$16) -> 14 | H17: 막걸리 | I17: 6400 | J17: 다이소 구매
A18: 개수 | B18: 소갈비살 | C18: 27 | D18: LA양념갈비 | F18: 14
A19: 매출누계 | C19: =SUM('1'!$C$18) -> 27 | F19: =SUM('1'!$F$18) -> 14
A20: 개수 | D20: 테이블수 | F20: 52
A21: 매출누계 | D21: 누적테이블 | F21: =SUM('1'!$F$20) -> 52
A22: 중간출금
A23: 출금내역 | H23: 식자재합계 | I23: =SUM(I4:I22) -> 6400 | J23: 기타경비합계 | K23: =SUM(K4:K22) -> 14666.667 | M23: 현금합계 | N23: =C5+C6 -> 405000
A24: 일매출 | C24: 일평균매출 | E24: 누적총매출 | H24: 일매출 | I24: =I23/A25 -> 0.0020408163 | J24: 일매출 | K24: =K23/A25 -> 0.0046768707
A25: =C2 -> 3136000 | C25: =E25/I1 -> 3136000 | E25: =SUM('1'!$A$25) -> 3136000 | H25: 누계 | I25: =SUM('1'!$I$23) -> 6400 | J25: 누계 | K25: =SUM('1'!$K$23) -> 14666.667
A26: 전 월 | H26: 누적매출 | I26: =I25/$E$25 -> 0.0020408163 | J26: 누적매출 | K26: =K25/$E$25 -> 0.0046768707
A27: 인 건 비 | B27: 직원A | C27: =4000000/31 -> 129032.26 | E27: 알바C | H27: 인건비합계 | I27: =SUM(C27:D34,F27:G32) -> 738741.94
B28: 직원B | C28: =3800000/31 -> 122580.65 | E28: 직원F | F28: =1500000/30 -> 50000 | H28: 일매출 | I28: =I27/$A$25 -> 0.23556822
B29: 직원D | C29: =3200000/31 -> 103225.81 | H29: 누계 | I29: =SUM('1'!$I$27) -> 738741.94
H30: 누적매출 | I30: =I29/$I$27 -> 1
B31: 직원C | C31: =3500000/31 -> 112903.23 | E31: 파출 | F31: 130000
B32: 알바A | E32: 홀 파출
B33: 알바B | C33: 91000
B34: 알바X

Sheet 2
C1: 2025년 | E1: 6월 | F1: 2 | G1: 월 | H1: 실영업일수 | I1: =F1-K1 -> 2 | J1: 휴무일수
A2: 매출 | C2: =SUM(C4:D7) -> 4562500 | E2: 시재 | G2: 140000 | H2: 식자재 | J2: 비품 및 기타경비
H3: 업체 | I3: 금액 | J3: 업체 | K3: 금액
A4: 카드 | C4: 4011500 | E4: 카드수수료(2.75%) | G4: =INT(C4*0.0275) -> 110316 | H4: 고기 | I4: 1920996 | J4: 숯
A5: 현금 | C5: 551000 | E5: 현금수수료(1%) | G5: =INT(C5*0.01) -> 5510 | H5: 식자재 | I5: 466498
A6: 페이결제 | E6: 통장입금 | G6: 500000 | J6: 음식물스티커
H7: 주류 | J7: 종량제봉투
A8: 금고 실잔액 | C8: 191000 | E8: 마감잔금 | G8: =C5+G2-G6-C22 -> 191000 | H8: 쌀 | I8: 56000
J9: 뚝배기
A10: 현금할인 | E10: 카드할인 | J10: 발매트 | K10: 13000
A11: 할인내역 | H11: 참기름 | J11: 불판세척 | K11: =440000/30 -> 14666.667
A12: 개수 | B12: 목살 | C12: 26 | D12: LA갈비 | F12: 5 | H12: 부탄가스
A13: 매출누계 | C13: =SUM('1:2'!$C$12) -> 35 | F13: =SUM('1:2'!$F$12) -> 11 | H13: 코카콜라음료
A14: 개수 | B14: 생갈비 | C14: 45 | D14: 돼지양념갈비 | F14: 11 | H14: 깍두기,계란
A15: 매출누계 | C15: =SUM('1:2'!$C$14) -> 75 | F15: =SUM('1:2'!$F$14) -> 25 | H15: 식자재2 | I15: 170950 | J15: 비품 및 기타경비
A16: 개수 | B16: 육회 | C16: 0 | D16: 한우업진살 | F16: 20 | J16: 인터넷 주문
A17: 매출누계 | C17: =SUM('1:2'!$C$16) -> 5 | F17: =SUM('1:2'!$F$16) -> 34 | H17: 막걸리 | I17: 6400 | J17: 다이소 구매 | K17: 20000
A18: 개수 | B18: 소갈비살 | C18: 44 | D18: LA양념갈비 | F18: 16
A19: 매출누계 | C19: =SUM('1:2'!$C$18) -> 71 | F19: =SUM('1:2'!$F$18) -> 30
D20: 테이블수 | F20: 68
D21: 누적테이블 | F21: =SUM('1:2'!$F$20) -> 120
A22: 중간출금
A23: 출금내역 | H23: 식자재합계 | I23: =SUM(I4:I22) -> 2620844 | J23: 기타경비합계 | K23: =SUM(K4:K22) -> 47666.667 | M23: 현금합계 | N23: =C5+C6 -> 551000
A24: 일매출 | C24: 일평균매출 | E24: 누적총매출 | H24: 일매출 | I24: =I23/A25 -> 0.57443156 | J24: 일매출 | K24: =K23/A25 -> 0.010447489
A25: =C2 -> 4562500 | C25: =E25/I1 -> 1568000 | E25: =SUM('1'!$A$25) -> 3136000 | H25: 누계 | I25: =SUM('1'!$I$23) -> 6400 | J25: 누계 | K25: =SUM('1'!$K$23) -> 14666.667
A26: 전 월 | H26: 누적매출 | I26: =I25/$E$25 -> 0.0020408163 | J26: 누적매출 | K26: =K25/$E$25 -> 0.0046768707
A27: 인 건 비 | B27: 직원A | C27: =4000000/31 -> 129032.26 | E27: 알바C | H27: 인건비합계 | I27: =SUM(C27:D34,F27:G32) -> 769741.94
B28: 직원B | C28: =3800000/31 -> 122580.65 | E28: 직원F | F28: =1500000/30 -> 50000 | H28: 일매출 | I28: =I27/$A$25 -> 0.16871056
B29: 직원D | C29: =3200000/31 -> 103225.81 | H29: 누계 | I29: =SUM('1'!$I$27) -> 738741.94
H30: 누적매출 | I30: =I29/$I$27 -> 0.95972676
B31: 직원C | C31: =3500000/31 -> 112903.23 | E31: 파출 | F31: 120000
B32: 알바A | E32: 홀 파출 | F32: 132000
B33: 알바B
B34: 알바X

Sheet 3
C1: 2025년 | E1: 6월 | F1: 3 | G1: 화 | H1: 실영업일수 | I1: =F1-K1 -> 3 | J1: 휴무일수
A2: 매출 | C2: =SUM(C4:D7) -> 2887000 | E2: 시재 | G2: 191000 | H2: 식자재 | J2: 비품 및 기타경비
H3: 업체 | I3: 금액 | J3: 업체 | K3: 금액
A4: 카드 | C4: 2504000 | E4: 카드수수료(2.75%) | G4: =C4*0.0275 -> 68860 | H4: 고기 | I4: 1284276 | J4: 숯
A5: 현금 | C5: 383000 | E5: 현금수수료(1%) | G5: =INT(C5*0.01) -> 3830 | H5: 식자재 | I5: 191662
A6: 페이결제 | E6: 통장입금 | G6: 400000 | J6: 음식물스티커
H7: 주류 | J7: 종량제봉투
A8: 금고 실잔액 | C8: 174000 | E8: 마감잔금 | G8: =C5+G2-G6-C22 -> 174000 | H8: 쌀
J9: 뚝배기
A10: 현금할인 | E10: 카드할인 | J10: 발매트
A11: 할인내역 | H11: 참기름 | J11: 불판세척 | K11: =440000/30 -> 14666.667
A12: 개수 | B12: 목살 | C12: 6 | D12: LA갈비 | F12: 2 | H12: 부탄가스
A13: 매출누계 | C13: =SUM('1:3'!$C$12) -> 41 | F13: =SUM('1:3'!$F$12) -> 13 | H13: 코카콜라음료
A14: 개수 | B14: 생갈비 | C14: 40 | D14: 돼지양념갈비 | F14: 39 | H14: 깍두기,계란
A15: 매출누계 | C15: =SUM('1:3'!$C$14) -> 115 | F15: =SUM('1:3'!$F$14) -> 64 | H15: 식자재2 | I15: 104800 | J15: 비품 및 기타경비
A16: 개수 | B16: 육회 | C16: 5 | D16: 한우업진살 | F16: 7 | J16: 인터넷 주문
A17: 매출누계 | C17: =SUM('1:3'!$C$16) -> 10 | F17: =SUM('1:3'!$F$16) -> 41 | H17: 막걸리 | J17: 다이소 구매
A18: 개수 | B18: 소갈비살 | C18: 21 | D18: LA양념갈비 | F18: 4
A19: 매출누계 | C19: =SUM('1:3'!$C$18) -> 92 | F19: =SUM('1:3'!$F$18) -> 34
D20: 테이블수 | F20: 44
D21: 누적테이블 | F21: =SUM('1:3'!$F$20) -> 164
A22: 중간출금
A23: 출금내역 | H23: 식자재합계 | I23: =SUM(I4:I22) -> 1580738 | J23: 기타경비합계 | K23: =SUM(K4:K22) -> 14666.667 | M23: 현금합계 | N23: =C5+C6 -> 383000
A24: 일매출 | C24: 일평균매출 | E24: 누적총매출 | H24: 일매출 | I24: =I23/A25 -> 0.54753654 | J24: 일매출 | K24: =K23/A25 -> 0.0050802448
A25: =C2 -> 2887000 | C25: =E25/I1 -> 3528500 | E25: =SUM('1:3'!$A$25) -> 10585500 | H25: 누계 | I25: =SUM('1:3'!$I$23) -> 4207982 | J25: 누계 | K25: =SUM('1:3'!$K$23) -> 77000
A26: 전 월 | H26: 누적매출 | I26: =I25/$E$25 -> 0.39752322 | J26: 누적매출 | K26: =K25/$E$25 -> 0.0072741014
A27: 인 건 비 | B27: 직원A | C27: =4000000/31 -> 129032.26 | E27: 알바C | H27: 인건비합계 | I27: =SUM(C27:D34,F27:G32) -> 825841.94
B28: 직원B | C28: =3800000/31 -> 122580.65 | E28: 직원F | F28: =1500000/30 -> 50000 | H28: 일매출 | I28: =I27/$A$25 -> 0.2860554
B29: 직원D | C29: =3200000/31 -> 103225.81 | H29: 누계 | I29: =SUM('1:3'!$I$27) -> 2334325.8
H30: 누적매출 | I30: =I29/$I$27 -> 2.8266012
B31: 직원C | C31: =3500000/31 -> 112903.23 | E31: 파출 | F31: 130000
B32: 알바A | E32: 홀 파출 | F32: 143000
B33: 알바B
B34: 알바X | C34: 35100

Sheet 4
C1: 2025년 | E1: 6월 | F1: 4 | G1: 수 | H1: 실영업일수 | I1: =F1-K1 -> 4 | J1: 휴무일수
A2: 매출 | C2: =SUM(C4:D7) -> 4010500 | E2: 시재 | G2: 174000 | H2: 식자재 | J2: 비품 및 기타경비
H3: 업체 | I3: 금액 | J3: 업체 | K3: 금액
A4: 카드 | C4: 3675500 | E4: 카드수수료(2.75%) | G4: =INT(C4*0.0275) -> 101076 | H4: 고기 | J4: 숯 | K4: 243000
A5: 현금 | C5: 335000 | E5: 현금수수료(1%) | G5: =INT(C5*0.01) -> 3350 | H5: 식자재 | I5: =41250+38940+29656+36080 -> 145926
A6: 페이결제 | E6: 통장입금 | G6: 350000 | J6: 음식물스티커
H7: 주류 | I7: =522800-33500 -> 489300 | J7: 종량제봉투
A8: 금고 실잔액 | C8: 159000 | E8: 마감잔금 | G8: =C5+G2-G6-C22 -> 159000 | H8: 쌀 | I8: 56000
J9: 뚝배기
A10: 현금할인 | E10: 카드할인 | J10: 발매트
A11: 할인내역 | H11: 참기름 | J11: 불판세척 | K11: =440000/30 -> 14666.667
A12: 개수 | B12: 목살 | C12: 15 | D12: LA갈비 | F12: 7 | H12: 부탄가스
A13: 매출누계 | C13: =SUM('1:4'!$C$12) -> 56 | F13: =SUM('1:4'!$F$12) -> 20 | H13: 코카콜라음료
A14: 개수 | B14: 생갈비 | C14: 30 | D14: 돼지양념갈비 | F14: 15 | H14: 깍두기,계란
A15: 매출누계 | C15: =SUM('1:4'!$C$14) -> 145 | F15: =SUM('1:4'!$F$14) -> 79 | H15: 식자재2 | I15: =11800+13000+12500+18000+20000+15600 -> 90900 | J15: 비품 및 기타경비
A16: 개수 | B16: 육회 | C16: 3 | D16: 한우업진살 | F16: 11 | J16: 인터넷 주문 | K16: 318820
A17: 매출누계 | C17: =SUM('1:4'!$C$16) -> 13 | F17: =SUM('1:4'!$F$16) -> 52 | H17: 막걸리 | J17: 다이소 구매
A18: 개수 | B18: 소갈비살 | C18: 30 | D18: LA양념갈비 | F18: 12
A19: 매출누계 | C19: =SUM('1:4'!$C$18) -> 122 | F19: =SUM('1:4'!$F$18) -> 46
D20: 테이블수 | F20: 61
D21: 누적테이블 | F21: =SUM('1:4'!$F$20) -> 225
A22: 중간출금
A23: 출금내역 | H23: 식자재합계 | I23: =SUM(I4:I22) -> 782126 | J23: 기타경비합계 | K23: =SUM(K4:K22) -> 576486.67 | M23: 현금합계 | N23: =C5+C6 -> 335000
A24: 일매출 | C24: 일평균매출 | E24: 누적총매출 | H24: 일매출 | I24: =I23/A25 -> 0.19501957 | J24: 일매출 | K24: =K23/A25 -> 0.14374434
A25: =C2 -> 4010500 | C25: =E25/I1 -> 3649000 | E25: =SUM('1:4'!$A$25) -> 14596000 | H25: 누계 | I25: =SUM('1:4'!$I$23) -> 4990108 | J25: 누계 | K25: =SUM('1:4'!$K$23) -> 653486.67
A26: 전 월 | H26: 누적매출 | I26: =I25/$E$25 -> 0.34188189 | J26: 누적매출 | K26: =K25/$E$25 -> 0.044771627
A27: 인 건 비 | B27: 직원A | C27: =4000000/31 -> 129032.26 | E27: 알바C | H27: 인건비합계 | I27: =SUM(C27:D34,F27:G32) -> 795841.94
B28: 직원B | C28: =3800000/31 -> 122580.65 | E28: 직원F | F28: =1500000/30 -> 50000 | H28: 일매출 | I28: =I27/$A$25 -> 0.19843958
B29: 직원D | C29: =3200000/31 -> 103225.81 | H29: 누계 | I29: =SUM('1:4'!$I$27) -> 3130167.7
H30: 누적매출 | I30: =I29/$I$27 -> 3.9331526
B31: 직원C | C31: =3500000/31 -> 112903.23 | E31: 파출 | F31: 120000
B32: 알바A | E32: 홀 파출 | F32: 71000
B33: 알바B | C33: =13000*4 -> 52000
B34: 알바X | C34: =11700*3 -> 35100

Sheet 5
C1: 2025년 | E1: 6월 | F1: 5 | G1: 목 | H1: 실영업일수 | I1: =F1-K1 -> 5 | J1: 휴무일수
A2: 매출 | C2: =SUM(C4:D7) -> 4006500 | E2: 시재 | G2: 159000 | H2: 식자재 | J2: 비품 및 기타경비
H3: 업체 | I3: 금액 | J3: 업체 | K3: 금액
A4: 카드 | C4: 3356000 | E4: 카드수수료(2.75%) | G4: =INT(C4*0.0275) -> 92290 | H4: 고기 | I4: =452000+215475+226928+212982+310769 -> 1418154 | J4: 숯
A5: 현금 | C5: 650500 | E5: 현금수수료(1%) | G5: =INT(C5*0.01) -> 6505 | H5: 식자재 | I5: =47300+29656+50000+36000+17760+6430 -> 187146
A6: 페이결제 | E6: 통장입금 | G6: 660000 | J6: 음식물스티커
H7: 주류 | I7: =357200-14700 -> 342500 | J7: 종량제봉투
A8: 금고 실잔액 | C8: 150000 | E8: 마감잔금 | G8: =C5+G2-G6-C22 -> 149500 | H8: 쌀
J9: 뚝배기
A10: 현금할인 | E10: 카드할인 | J10: 발매트
A11: 할인내역 | H11: 참기름 | J11: 불판세척 | K11: =440000/30 -> 14666.667
A12: 개수 | B12: 목살 | C12: 8 | D12: LA갈비 | F12: 7 | H12: 부탄가스
A13: 매출누계 | C13: =SUM('1:5'!$C$12) -> 64 | F13: =SUM('1:5'!$F$12) -> 27 | H13: 코카콜라음료
A14: 개수 | B14: 생갈비 | C14: 42 | D14: 돼지양념갈비 | F14: 19 | H14: 깍두기,계란
A15: 매출누계 | C15: =SUM('1:5'!$C$14) -> 187 | F15: =SUM('1:5'!$F$14) -> 98 | H15: 식자재2 | I15: =36000+4900+5500+18500+3500+21000+2200+19200 -> 110800 | J15: 비품 및 기타경비
A16: 개수 | B16: 육회 | C16: 5 | D16: 한우업진살 | F16: 17 | J16: 인터넷 주문 | K16: 22500
A17: 매출누계 | C17: =SUM('1:5'!$C$16) -> 18 | F17: =SUM('1:5'!$F$16) -> 69 | H17: 막걸리 | J17: 다이소 구매
A18: 개수 | B18: 소갈비살 | C18: 38 | D18: LA양념갈비 | F18: 5
A19: 매출누계 | C19: =SUM('1:5'!$C$18) -> 160 | F19: =SUM('1:5'!$F$18) -> 51
D20: 테이블수 | F20: 61
D21: 누적테이블 | F21: =SUM('1:5'!$F$20) -> 286
A22: 중간출금
A23: 출금내역 | H23: 식자재합계 | I23: =SUM(I4:I22) -> 2058600 | J23: 기타경비합계 | K23: =SUM(K4:K22) -> 37166.667 | M23: 현금합계 | N23: =C5+C6 -> 650500
A24: 일매출 | C24: 일평균매출 | E24: 누적총매출 | H24: 일매출 | I24: =I23/A25 -> 0.51381505 | J24: 일매출 | K24: =K23/A25 -> 0.0092765922
A25: =C2 -> 4006500 | C25: =E25/I1 -> 3720500 | E25: =SUM('1:5'!$A$25) -> 18602500 | H25: 누계 | I25: =SUM('1:5'!$I$23) -> 7048708 | J25: 누계 | K25: =SUM('1:5'!$K$23) -> 690653.33
A26: 전 월 | H26: 누적매출 | I26: =I25/$E$25 -> 0.37891187 | J26: 누적매출 | K26: =K25/$E$25 -> 0.037126909
A27: 인 건 비 | B27: 직원A | C27: =4000000/31 -> 129032.26 | E27: 알바C | H27: 인건비합계 | I27: =SUM(C27:D34,F27:G32) -> 886091.94
B28: 직원B | C28: =3800000/31 -> 122580.65 | E28: 직원F | F28: =1500000/30 -> 50000 | H28: 일매출 | I28: =I27/$A$25 -> 0.22116359
B29: 직원D | C29: =3200000/31 -> 103225.81 | H29: 누계 | I29: =SUM('1:5'!$I$27) -> 4016259.7
H30: 누적매출 | I30: =I29/$I$27 -> 4.5325541
B31: 직원C | C31: =3500000/31 -> 112903.23 | E31: 파출 | F31: 120000
B32: 알바A | E32: 홀 파출 | F32: 132000
B33: 알바B | C33: =13000*4 -> 52000
B34: 알바X | C34: =11700*5.5 -> 64350

Sheet 6
C1: 2025년 | E1: 6월 | F1: 6 | G1: 금 | H1: 실영업일수 | I1: =F1-K1 -> 6 | J1: 휴무일수
A2: 매출 | C2: =SUM(C4:D7) -> 3819000 | E2: 시재 | G2: 150000 | H2: 식자재 | J2: 비품 및 기타경비
H3: 업체 | I3: 금액 | J3: 업체 | K3: 금액
A4: 카드 | C4: 3366000 | E4: 카드수수료(2.75%) | G4: =INT(C4*0.0275) -> 92565 | H4: 고기 | I4: =56220+955200+1356000+442000+715696+396921+10+885814 -> 4807861 | J4: 숯
A5: 현금 | C5: 453000 | E5: 현금수수료(1%) | G5: =INT(C5*0.01) -> 4530 | H5: 식자재 | I5: =41250+59312+72160+50000+36000+17760+6930+12980 -> 296392
A6: 페이결제 | E6: 통장입금 | G6: 450000 | J6: 음식물스티커
H7: 주류 | J7: 종량제봉투
A8: 금고 실잔액 | C8: 153000 | E8: 마감잔금 | G8: =C5+G2-G6-C22 -> 153000 | H8: 쌀 | I8: 56000
J9: 뚝배기
A10: 현금할인 | C10: 62000 | E10: 카드할인 | J10: 발매트
A11: 할인내역 | C11: e-식권 62,000원 | H11: 참기름 | J11: 불판세척 | K11: =440000/30 -> 14666.667
A12: 개수 | B12: 목살 | C12: 18 | D12: LA갈비 | F12: 3 | H12: 부탄가스
A13: 매출누계 | C13: =SUM('1:6'!$C$12) -> 82 | F13: =SUM('1:6'!$F$12) -> 30 | H13: 코카콜라음료
A14: 개수 | B14: 생갈비 | C14: 32 | D14: 돼지양념갈비 | F14: 39 | H14: 깍두기,계란
A15: 매출누계 | C15: =SUM('1:6'!$C$14) -> 219 | F15: =SUM('1:6'!$F$14) -> 137 | H15: 식자재2 | I15: 266000 | J15: 비품 및 기타경비
A16: 개수 | B16: 육회 | C16: 6 | D16: 한우업진살 | F16: 16 | J16: 인터넷 주문
A17: 매출누계 | C17: =SUM('1:6'!$C$16) -> 24 | F17: =SUM('1:6'!$F$16) -> 85 | H17: 막걸리 | J17: 다이소 구매
A18: 개수 | B18: 소갈비살 | C18: 45 | D18: LA양념갈비 | F18: 7
A19: 매출누계 | C19: =SUM('1:6'!$C$18) -> 205 | F19: =SUM('1:6'!$F$18) -> 58
D20: 테이블수 | F20: 43
D21: 누적테이블 | F21: =SUM('1:6'!$F$20) -> 329
A22: 중간출금
A23: 출금내역 | H23: 식자재합계 | I23: =SUM(I4:I22) -> 5426253 | J23: 기타경비합계 | K23: =SUM(K4:K22) -> 14666.667 | M23: 현금합계 | N23: =C5+C6 -> 453000
A24: 일매출 | C24: 일평균매출 | E24: 누적총매출 | H24: 일매출 | I24: =I23/A25 -> 1.420857 | J24: 일매출 | K24: =K23/A25 -> 0.0038404469
A25: =C2 -> 3819000 | C25: =E25/I1 -> 3736916.7 | E25: =SUM('1:6'!$A$25) -> 22421500 | H25: 누계 | I25: =SUM('1:6'!$I$23) -> 12474961 | J25: 누계 | K25: =SUM('1:6'!$K$23) -> 705320
A26: 전 월 | H26: 누적매출 | I26: =I25/$E$25 -> 0.55638387 | J26: 누적매출 | K26: =K25/$E$25 -> 0.031457307
A27: 인 건 비 | B27: 직원A | C27: =4000000/31 -> 129032.26 | E27: 알바C | H27: 인건비합계 | I27: =SUM(C27:D34,F27:G32) -> 758241.94
B28: 직원B | C28: =3800000/31 -> 122580.65 | E28: 직원F | F28: =1500000/30 -> 50000 | H28: 일매출 | I28: =I27/$A$25 -> 0.19854463
B29: 직원D | C29: =3200000/31 -> 103225.81 | H29: 누계 | I29: =SUM('1:6'!$I$27) -> 4774501.6
H30: 누적매출 | I30: =I29/$I$27 -> 6.296805
B31: 직원C | C31: =3500000/31 -> 112903.23 | E31: 파출 | F31: 130000
B32: 알바A | E32: 홀 파출
B33: 알바B | C33: =13000*4 -> 52000
B34: 알바X | C34: =11700*5 -> 58500

Sheet 7
C1: 2025년 | E1: 6월 | F1: 7 | G1: 토 | H1: 실영업일수 | I1: =F1-K1 -> 7 | J1: 휴무일수
A2: 매출 | C2: =SUM(C4:D7) -> 3778500 | E2: 시재 | G2: 153000 | H2: 식자재 | J2: 비품 및 기타경비
H3: 업체 | I3: 금액 | J3: 업체 | K3: 금액
A4: 카드 | C4: 3036500 | E4: 카드수수료(2.75%) | G4: =INT(C4*0.0275) -> 83503 | H4: 고기 | J4: 숯
A5: 현금 | C5: 742000 | E5: 현금수수료(1%) | G5: =INT(C5*0.01) -> 7420 | H5: 식자재
A6: 페이결제 | E6: 통장입금 | G6: 740000 | J6: 음식물스티커
H7: 주류 | J7: 종량제봉투
A8: 금고 실잔액 | C8: 155000 | E8: 마감잔금 | G8: =C5+G2-G6-C22 -> 155000 | H8: 쌀
J9: 뚝배기
A10: 현금할인 | E10: 카드할인 | J10: 발매트
A11: 할인내역 | H11: 참기름 | J11: 불판세척 | K11: =440000/30 -> 14666.667
A12: 개수 | B12: 목살 | C12: 11 | D12: LA갈비 | F12: 3 | H12: 부탄가스
A13: 매출누계 | C13: =SUM('1:7'!$C$12) -> 93 | F13: =SUM('1:7'!$F$12) -> 33 | H13: 코카콜라음료
A14: 개수 | B14: 생갈비 | C14: 43 | D14: 돼지양념갈비 | F14: 21 | H14: 깍두기,계란
A15: 매출누계 | C15: =SUM('1:7'!$C$14) -> 262 | F15: =SUM('1:7'!$F$14) -> 158 | H15: 식자재2 | J15: 비품 및 기타경비
A16: 개수 | B16: 육회 | C16: 3 | D16: 한우업진살 | F16: 22 | J16: 인터넷 주문
A17: 매출누계 | C17: =SUM('1:7'!$C$16) -> 27 | F17: =SUM('1:7'!$F$16) -> 107 | H17: 막걸리 | J17: 다이소 구매
A18: 개수 | B18: 소갈비살 | C18: 40 | D18: LA양념갈비 | F18: 10
A19: 매출누계 | C19: =SUM('1:7'!$C$18) -> 245 | F19: =SUM('1:7'!$F$18) -> 68
D20: 테이블수 | F20: 55
D21: 누적테이블 | F21: =SUM('1:7'!$F$20) -> 384
A22: 중간출금
A23: 출금내역 | H23: 식자재합계 | I23: =SUM(I4:I22) -> 0 | J23: 기타경비합계 | K23: =SUM(K4:K22) -> 14666.667 | M23: 현금합계 | N23: =C5+C6 -> 742000
A24: 일매출 | C24: 일평균매출 | E24: 누적총매출 | H24: 일매출 | I24: =I23/A25 -> 0 | J24: 일매출 | K24: =K23/A25 -> 0.0038816109
A25: =C2 -> 3778500 | C25: =E25/I1 -> 3742857.1 | E25: =SUM('1:7'!$A$25) -> 26200000 | H25: 누계 | I25: =SUM('1:7'!$I$23) -> 12474961 | J25: 누계 | K25: =SUM('1:7'!$K$23) -> 719986.67
A26: 전 월 | H26: 누적매출 | I26: =I25/$E$25 -> 0.47614355 | J26: 누적매출 | K26: =K25/$E$25 -> 0.027480407
A27: 인 건 비 | B27: 직원A | C27: =4000000/31 -> 129032.26 | E27: 알바C | H27: 인건비합계 | I27: =SUM(C27:D34,F27:G32) -> 712741.94
B28: 직원B | C28: =3800000/31 -> 122580.65 | E28: 직원F | F28: =1500000/30 -> 50000 | H28: 일매출 | I28: =I27/$A$25 -> 0.18863092
B29: 직원D | C29: =3200000/31 -> 103225.81 | H29: 누계 | I29: =SUM('1:7'!$I$27) -> 5487243.5
H30: 누적매출 | I30: =I29/$I$27 -> 7.6987803
B31: 직원C | C31: =3500000/31 -> 112903.23 | E31: 파출 | F31: 130000
B32: 알바A | E32: 홀 파출
B33: 알바B | C33: =13000*5 -> 65000
B34: 알바X

Sheet 8
C1: 2025년 | E1: 6월 | F1: 8 | G1: 일 | H1: 실영업일수 | I1: =F1-K1 -> 8 | J1: 휴무일수
A2: 매출 | C2: =SUM(C4:D7) -> 4371000 | E2: 시재 | G2: 155000 | H2: 식자재 | J2: 비품 및 기타경비
H3: 업체 | I3: 금액 | J3: 업체 | K3: 금액
A4: 카드 | C4: 3804000 | E4: 카드수수료(2.75%) | G4: =INT(C4*0.0275) -> 104610 | H4: 고기 | J4: 숯
A5: 현금 | C5: 567000 | E5: 현금수수료(1%) | G5: =INT(C5*0.01) -> 5670 | H5: 식자재
A6: 페이결제 | E6: 통장입금 | G6: 560000 | J6: 음식물스티커
H7: 주류 | J7: 종량제봉투
A8: 금고 실잔액 | C8: 162000 | E8: 마감잔금 | G8: =C5+G2-G6-C22 -> 162000 | H8: 쌀
J9: 뚝배기
A10: 현금할인 | E10: 카드할인 | J10: 발매트
A11: 할인내역 | H11: 참기름 | J11: 불판세척 | K11: =440000/30 -> 14666.667
A12: 개수 | B12: 목살 | C12: 20 | D12: LA갈비 | F12: 9 | H12: 부탄가스
A13: 매출누계 | C13: =SUM('1:8'!$C$12) -> 113 | F13: =SUM('1:8'!$F$12) -> 42 | H13: 코카콜라음료
A14: 개수 | B14: 생갈비 | C14: 49 | D14: 돼지양념갈비 | F14: 17 | H14: 깍두기,계란
A15: 매출누계 | C15: =SUM('1:8'!$C$14) -> 311 | F15: =SUM('1:8'!$F$14) -> 175 | H15: 식자재2 | J15: 비품 및 기타경비
A16: 개수 | B16: 육회 | C16: 6 | D16: 한우업진살 | F16: 23 | J16: 인터넷 주문 | K16: 314940
A17: 매출누계 | C17: =SUM('1:8'!$C$16) -> 33 | F17: =SUM('1:8'!$F$16) -> 130 | H17: 막걸리 | J17: 다이소 구매
A18: 개수 | B18: 소갈비살 | C18: 31 | D18: LA양념갈비 | F18: 29
A19: 매출누계 | C19: =SUM('1:8'!$C$18) -> 276 | F19: =SUM('1:8'!$F$18) -> 97
D20: 테이블수 | F20: 40
D21: 누적테이블 | F21: =SUM('1:8'!$F$20) -> 424
A22: 중간출금
A23: 출금내역 | H23: 식자재합계 | I23: =SUM(I4:I22) -> 0 | J23: 기타경비합계 | K23: =SUM(K4:K22) -> 329606.67 | M23: 현금합계 | N23: =C5+C6 -> 567000
A24: 일매출 | C24: 일평균매출 | E24: 누적총매출 | H24: 일매출 | I24: =I23/A25 -> 0 | J24: 일매출 | K24: =K23/A25 -> 0.075407611
A25: =C2 -> 4371000 | C25: =E25/I1 -> 3821375 | E25: =SUM('1:8'!$A$25) -> 30571000 | H25: 누계 | I25: =SUM('1:8'!$I$23) -> 12474961 | J25: 누계 | K25: =SUM('1:8'!$K$23) -> 1049593.3
A26: 전 월 | H26: 누적매출 | I26: =I25/$E$25 -> 0.40806519 | J26: 누적매출 | K26: =K25/$E$25 -> 0.034332974
A27: 인 건 비 | B27: 직원A | C27: =4000000/31 -> 129032.26 | E27: 알바C | H27: 인건비합계 | I27: =SUM(C27:D34,F27:G32) -> 699741.94
B28: 직원B | C28: =3800000/31 -> 122580.65 | E28: 직원F | F28: =1500000/30 -> 50000 | H28: 일매출 | I28: =I27/$A$25 -> 0.16008738
B29: 직원D | C29: =3200000/31 -> 103225.81 | H29: 누계 | I29: =SUM('1:8'!$I$27) -> 6186985.5 | M29: `
H30: 누적매출 | I30: =I29/$I$27 -> 8.8418103
B31: 직원C | C31: =3500000/31 -> 112903.23 | E31: 파출 | F31: 130000
B32: 알바A | E32: 홀 파출
B33: 알바B | C33: =13000*4 -> 52000
B34: 알바X

Sheet 9
C1: 2025년 | E1: 6월 | F1: 9 | G1: 월 | H1: 실영업일수 | I1: =F1-K1 -> 9 | J1: 휴무일수
A2: 매출 | C2: =SUM(C4:D7) -> 4148000 | E2: 시재 | G2: 162000 | H2: 식자재 | J2: 비품 및 기타경비
H3: 업체 | I3: 금액 | J3: 업체 | K3: 금액
A4: 카드 | C4: 3360000 | E4: 카드수수료(2.75%) | G4: =INT(C4*0.0275) -> 92400 | H4: 고기 | I4: =452000+221000+242202+235571+293640 -> 1444413 | J4: 숯
A5: 현금 | C5: 788000 | E5: 현금수수료(1%) | G5: =INT(C5*0.01) -> 7880 | H5: 식자재 | I5: =29656+36080+36000+16100+50000+15990+30300+7050+12360+68600 -> 302136
A6: 페이결제 | E6: 통장입금 | G6: 800000 | J6: 음식물스티커
H7: 주류 | I7: 421570 | J7: 종량제봉투 | K7: 12500
A8: 금고 실잔액 | C8: 140000 | E8: 마감잔금 | G8: =C5+G2-G6-C22 -> 150000 | H8: 쌀
J9: 뚝배기
A10: 현금할인 | E10: 카드할인 | J10: 발매트 | K10: 13000
A11: 할인내역 | H11: 참기름 | J11: 불판세척 | K11: =440000/30 -> 14666.667
A12: 개수 | B12: 목살 | C12: 11 | D12: LA갈비 | F12: 13 | H12: 부탄가스
A13: 매출누계 | C13: =SUM('1:9'!$C$12) -> 124 | F13: =SUM('1:9'!$F$12) -> 55 | H13: 코카콜라음료
A14: 개수 | B14: 생갈비 | C14: 51 | D14: 돼지양념갈비 | F14: 16 | H14: 깍두기,계란
A15: 매출누계 | C15: =SUM('1:9'!$C$14) -> 362 | F15: =SUM('1:9'!$F$14) -> 191 | H15: 식자재2 | I15: 107500 | J15: 비품 및 기타경비
A16: 개수 | B16: 육회 | C16: 9 | D16: 한우업진살 | F16: 10 | J16: 인터넷 주문 | K16: 192550
A17: 매출누계 | C17: =SUM('1:9'!$C$16) -> 42 | F17: =SUM('1:9'!$F$16) -> 140 | H17: 막걸리 | I17: 3200 | J17: 다이소 구매 | K17: 6
A18: 개수 | B18: 소갈비살 | C18: 22 | D18: LA양념갈비 | F18: 9
A19: 매출누계 | C19: =SUM('1:9'!$C$18) -> 298 | F19: =SUM('1:9'!$F$18) -> 106
D20: 테이블수 | F20: 69
D21: 누적테이블 | F21: =SUM('1:9'!$F$20) -> 493
A22: 중간출금
A23: 출금내역 | H23: 식자재합계 | I23: =SUM(I4:I22) -> 2278819 | J23: 기타경비합계 | K23: =SUM(K4:K22) -> 232722.67 | M23: 현금합계 | N23: =C5+C6 -> 788000
A24: 일매출 | C24: 일평균매출 | E24: 누적총매출 | H24: 일매출 | I24: =I23/A25 -> 0.54937777 | J24: 일매출 | K24: =K23/A25 -> 0.056104789
A25: =C2 -> 4148000 | C25: =E25/I1 -> 3857666.7 | E25: =SUM('1:9'!$A$25) -> 34719000 | H25: 누계 | I25: =SUM('1:9'!$I$23) -> 14753780 | J25: 누계 | K25: =SUM('1:9'!$K$23) -> 1282316
A26: 전 월 | H26: 누적매출 | I26: =I25/$E$25 -> 0.4249483 | J26: 누적매출 | K26: =K25/$E$25 -> 0.036934128
A27: 인 건 비 | B27: 직원A | C27: =4000000/31 -> 129032.26 | E27: 알바C | H27: 인건비합계 | I27: =SUM(C27:D34,F27:G32) -> 822391.94
B28: 직원B | C28: =3800000/31 -> 122580.65 | E28: 직원F | F28: =1500000/30 -> 50000 | H28: 일매출 | I28: =I27/$A$25 -> 0.19826228
B29: 직원D | C29: =3200000/31 -> 103225.81 | H29: 누계 | I29: =SUM('1:9'!$I$27) -> 7009377.4
H30: 누적매출 | I30: =I29/$I$27 -> 8.5231592
B31: 직원C | C31: =3500000/31 -> 112903.23 | E31: 파출 | F31: 120000
B32: 알바A | E32: 홀 파출 | F32: 132000
B33: 알바B
B34: 알바X | C34: =11700*4.5 -> 52650

Sheet 10
C1: 2025년 | E1: 6월 | F1: 10 | G1: 화 | H1: 실영업일수 | I1: =F1-K1 -> 10 | J1: 휴무일수
A2: 매출 | C2: =SUM(C4:D7) -> 4054000 | E2: 시재 | G2: 140000 | H2: 식자재 | J2: 비품 및 기타경비
H3: 업체 | I3: 금액 | J3: 업체 | K3: 금액
A4: 카드 | C4: 3868000 | E4: 카드수수료(2.75%) | G4: =INT(C4*0.0275) -> 106370 | H4: 고기 | I4: =221000 -> 221000 | J4: 숯
A5: 현금 | C5: 186000 | E5: 현금수수료(1%) | G5: =INT(C5*0.01) -> 1860 | H5: 식자재 | I5: =23650+29656+36080+15990+14100 -> 119476
A6: 페이결제 | E6: 통장입금 | G6: 200000 | J6: 음식물스티커
H7: 주류 | J7: 종량제봉투
A8: 금고 실잔액 | C8: 126000 | E8: 마감잔금 | G8: =C5+G2-G6-C22 -> 126000 | H8: 쌀 | I8: 56000
J9: 뚝배기
A10: 현금할인 | C10: 157000 | E10: 카드할인 | J10: 발매트
A11: 할인내역 | C11: 배문설고객님 143,000원 선결제 사용 | H11: 참기름 | J11: 불판세척 | K11: =440000/30 -> 14666.667
A12: 개수 | B12: 목살 | C12: 7 | D12: LA갈비 | F12: 6 | H12: 부탄가스
A13: 매출누계 | C13: =SUM('1:10'!$C$12) -> 131 | F13: =SUM('1:10'!$F$12) -> 61 | H13: 코카콜라음료
A14: 개수 | B14: 생갈비 | C14: 24 | D14: 돼지양념갈비 | F14: 8 | H14: 깍두기,계란
A15: 매출누계 | C15: =SUM('1:10'!$C$14) -> 386 | F15: =SUM('1:10'!$F$14) -> 199 | H15: 식자재2 | I15: 61800 | J15: 비품 및 기타경비
A16: 개수 | B16: 육회 | C16: 7 | D16: 한우업진살 | F16: 26 | J16: 인터넷 주문
A17: 매출누계 | C17: =SUM('1:10'!$C$16) -> 49 | F17: =F19 -> 115 | H17: 막걸리 | J17: 다이소 구매
A18: 개수 | B18: 소갈비살 | D18: LA양념갈비 | F18: 9
A19: 매출누계 | C19: =SUM('1:10'!$C$18) -> 298 | F19: =SUM('1:10'!$F$18) -> 115
D20: 테이블수 | F20: 54
D21: 누적테이블 | F21: =SUM('1:10'!$F$20) -> 547
A22: 중간출금
A23: 출금내역 | H23: 식자재합계 | I23: =SUM(I4:I22) -> 458276 | J23: 기타경비합계 | K23: =SUM(K4:K22) -> 14666.667 | M23: 현금합계 | N23: =C5+C6 -> 186000
A24: 일매출 | C24: 일평균매출 | E24: 누적총매출 | H24: 일매출 | I24: =I23/A25 -> 0.11304292 | J24: 일매출 | K24: =K23/A25 -> 0.003617826
A25: =C2 -> 4054000 | C25: =E25/I1 -> 3877300 | E25: =SUM('1:10'!$A$25) -> 38773000 | H25: 누계 | I25: =SUM('1:10'!$I$21) -> 0 | J25: 누계 | K25: =SUM('1:10'!$K$21) -> 0
A26: 전 월 | H26: 누적매출 | I26: =I25/$E$25 -> 0 | J26: 누적매출 | K26: =K25/$E$25 -> 0
A27: 인 건 비 | B27: 직원A | C27: =4000000/31 -> 129032.26 | E27: 알바C | H27: 인건비합계 | I27: =SUM(C27:D34,F27:G32) -> 822391.94
B28: 직원B | C28: =3800000/31 -> 122580.65 | E28: 직원F | F28: =1500000/30 -> 50000 | H28: 일매출 | I28: =I27/$A$25 -> 0.20285938
B29: 직원D | C29: =3200000/31 -> 103225.81 | H29: 누계 | I29: =SUM('1:10'!$I$25) -> 68438261
H30: 누적매출 | I30: =I29/$I$27 -> 83.218546
B31: 직원C | C31: =3500000/31 -> 112903.23 | E31: 파출 | F31: 120000
B32: 알바A | E32: 홀 파출 | F32: 132000
B33: 알바B
B34: 알바X | C34: =11700*4.5 -> 52650

Sheet 11
C1: 2025년 | E1: 6월 | F1: 11 | H1: 실영업일수 | I1: =F1-K1 -> 11 | J1: 휴무일수
A2: 매출 | C2: =SUM(C4:D7) -> 4982500 | E2: 시재 | G2: 126000 | H2: 식자재 | J2: 비품 및 기타경비
H3: 업체 | I3: 금액 | J3: 업체 | K3: 금액
A4: 카드 | C4: 4607500 | E4: 카드수수료(2.75%) | G4: =INT(C4*0.0275) -> 126706 | H4: 고기 | I4: =221000+193620+278958 -> 693578 | J4: 숯 | K4: 316000
A5: 현금 | C5: 375000 | E5: 현금수수료(1%) | G5: =INT(C5*0.01) -> 3750 | H5: 식자재 | I5: =34540+29656+40700+36000+7300+14340+85750 -> 248286
A6: 페이결제 | E6: 통장입금 | G6: 400000 | J6: 음식물스티커
H7: 주류 | I7: 248400 | J7: 종량제봉투
A8: 금고 실잔액 | C8: 101000 | E8: 마감잔금 | G8: =C5+G2-G6-C22 -> 101000 | H8: 쌀
J9: 뚝배기
A10: 현금할인 | C10: 196000 | E10: 카드할인 | J10: 발매트
A11: 할인내역 | C11: 3053 고객님 선결제 남은 금액 196,000 전액 사용했습니다. | H11: 참기름 | J11: 불판세척 | K11: =440000/30 -> 14666.667
A12: 개수 | B12: 목살 | C12: 13 | D12: LA갈비 | F12: 10 | H12: 부탄가스
A13: 매출누계 | C13: =SUM('1:11'!$C$12) -> 144 | F13: =SUM('1:11'!$F$12) -> 71 | H13: 코카콜라음료 | I13: 240000
A14: 개수 | B14: 생갈비 | C14: 45 | D14: 돼지양념갈비 | F14: 11 | H14: 깍두기,계란 | M14: ㄴ
A15: 매출누계 | C15: =SUM('1:11'!$C$14) -> 431 | F15: =SUM('1:11'!$F$14) -> 210 | H15: 식자재2 | I15: 95600 | J15: 비품 및 기타경비
A16: 개수 | B16: 육회 | C16: 3 | D16: 한우업진살 | F16: 22 | J16: 인터넷 주문 | K16: 16890
A17: 매출누계 | C17: =SUM('1:11'!$C$16) -> 52 | F17: =SUM('1:11'!$F$16) -> 188 | H17: 막걸리 | J17: 다이소 구매
A18: 개수 | B18: 소갈비살 | C18: 20 | D18: LA양념갈비 | F18: 8
A19: 매출누계 | C19: =SUM('1:11'!$C$18) -> 318 | F19: =SUM('1:11'!$F$18) -> 123
D20: 테이블수 | F20: 63
D21: 누적테이블 | F21: =SUM('1:11'!$F$20) -> 610
A22: 중간출금
A23: 출금내역 | H23: 식자재합계 | I23: =SUM(I4:I22) -> 1525864 | J23: 기타경비합계 | K23: =SUM(K4:K22) -> 347556.67 | M23: 현금합계 | N23: =C5+C6 -> 375000
A24: 일매출 | C24: 일평균매출 | E24: 누적총매출 | H24: 일매출 | I24: =I23/A25 -> 0.30624466 | J24: 일매출 | K24: =K23/A25 -> 0.069755478
A25: =C2 -> 4982500 | C25: =E25/I1 -> 3977772.7 | E25: =SUM('1:11'!$A$25) -> 43755500 | H25: 누계 | I25: =SUM('1:11'!$I$21) -> 0 | J25: 누계 | K25: =SUM('1:11'!$K$21) -> 0
A26: 전 월 | H26: 누적매출 | I26: =I25/$E$25 -> 0 | J26: 누적매출 | K26: =K25/$E$25 -> 0
A27: 인 건 비 | B27: 직원A | C27: =4000000/31 -> 129032.26 | E27: 알바C | H27: 인건비합계 | I27: =SUM(C27:D34,F27:G32) -> 690391.94
B28: 직원B | C28: =3800000/31 -> 122580.65 | E28: 직원F | F28: =1500000/30 -> 50000 | H28: 일매출 | I28: =I27/$A$25 -> 0.13856336
B29: 직원D | C29: =3200000/31 -> 103225.81 | H29: 누계 | I29: =SUM('1:11'!$I$25) -> 68438261
H30: 누적매출 | I30: =I29/$I$27 -> 99.129578
B31: 직원C | C31: =3500000/31 -> 112903.23 | E31: 파출 | F31: 120000
B32: 알바A | E32: 홀 파출
B33: 알바B
B34: 알바X | C34: =11700*4.5 -> 52650

Sheet 12
C1: 2025년 | E1: 6월 | F1: 12 | G1: 목요일 | H1: 실영업일수 | I1: =F1-K1 -> 12 | J1: 휴무일수
A2: 매출 | C2: =SUM(C4:D7) -> 4599000 | E2: 시재 | G2: 101000 | H2: 식자재 | J2: 비품 및 기타경비
H3: 업체 | I3: 금액 | J3: 업체 | K3: 금액
A4: 카드 | C4: 3902000 | E4: 카드수수료(2.75%) | G4: =INT(C4*0.0275) -> 107305 | H4: 고기 | I4: =221000+233474 -> 454474 | J4: 숯
A5: 현금 | C5: 697000 | E5: 현금수수료(1%) | G5: =INT(C5*0.01) -> 6970 | H5: 식자재 | I5: =36000+16100+15990+6430 -> 74520
A6: 페이결제 | E6: 통장입금 | G6: 700000 | J6: 음식물스티커
H7: 주류 | J7: 종량제봉투
A8: 금고 실잔액 | C8: 98000 | E8: 마감잔금 | G8: =C5+G2-G6-C22 -> 98000 | H8: 쌀 | I8: 56000
J9: 뚝배기
A10: 현금할인 | E10: 카드할인 | J10: 발매트
A11: 할인내역 | H11: 참기름 | I11: 100000 | J11: 불판세척 | K11: =440000/30 -> 14666.667
A12: 개수 | B12: 목살 | C12: 25 | D12: LA갈비 | F12: 7 | H12: 부탄가스
A13: 매출누계 | C13: =SUM('1:12'!$C$12) -> 169 | F13: =SUM('1:12'!$F$12) -> 78 | H13: 코카콜라음료
A14: 개수 | B14: 생갈비 | C14: 61 | D14: 돼지양념갈비 | F14: 11 | H14: 깍두기,계란
A15: 매출누계 | C15: =SUM('1:12'!$C$14) -> 492 | F15: =SUM('1:12'!$F$14) -> 221 | H15: 식자재2 | I15: =19200+5500+14700+26000+17700+36000+10500+1700 -> 131300 | J15: 비품 및 기타경비
A16: 개수 | B16: 육회 | C16: 0 | D16: 한우업진살 | F16: 39 | J16: 인터넷 주문 | K16: 307832
A17: 매출누계 | C17: =SUM('1:12'!$C$16) -> 52 | F17: =SUM('1:12'!$F$16) -> 227 | H17: 막걸리 | J17: 다이소 구매
A18: 개수 | B18: 소갈비살 | C18: 20 | D18: LA양념갈비 | F18: 6
A19: 매출누계 | C19: =SUM('1:12'!$C$18) -> 338 | F19: =SUM('1:12'!$F$18) -> 129
D20: 테이블수 | F20: 63
D21: 누적테이블 | F21: =SUM('1:12'!$F$20) -> 673
A22: 중간출금
A23: 출금내역 | H23: 식자재합계 | I23: =SUM(I4:I22) -> 816294 | J23: 기타경비합계 | K23: =SUM(K4:K22) -> 322498.67 | M23: 현금합계 | N23: =C5+C6 -> 697000
A24: 일매출 | C24: 일평균매출 | E24: 누적총매출 | H24: 일매출 | I24: =I23/A25 -> 0.1774938 | J24: 일매출 | K24: =K23/A25 -> 0.07012365
A25: =C2 -> 4599000 | C25: =E25/I1 -> 4029541.7 | E25: =SUM('1:12'!$A$25) -> 48354500 | H25: 누계 | I25: =SUM('1:12'!$I$21) -> 0 | J25: 누계 | K25: =SUM('1:12'!$K$21) -> 0
A26: 전 월 | H26: 누적매출 | I26: =I25/$E$25 -> 0 | J26: 누적매출 | K26: =K25/$E$25 -> 0
A27: 인 건 비 | B27: 직원A | C27: =4000000/31 -> 129032.26 | E27: 알바C | H27: 인건비합계 | I27: =SUM(C27:D34,F27:G32) -> 736541.94
B28: 직원B | C28: =3800000/31 -> 122580.65 | E28: 직원F | F28: =1500000/30 -> 50000 | H28: 일매출 | I28: =I27/$A$25 -> 0.16015263
B29: 직원D | C29: =3200000/31 -> 103225.81 | H29: 누계 | I29: =SUM('1:12'!$I$25) -> 68438261
H30: 누적매출 | I30: =I29/$I$27 -> 92.91835
B31: 직원C | C31: =3500000/31 -> 112903.23 | E31: 파출 | F31: 120000
B32: 알바A | E32: 홀 파출
B33: 알바B | C33: =13000*4 -> 52000
B34: 알바X | C34: =11700*4 -> 46800

Sheet 13
C1: 2025년 | E1: 6월 | F1: 13 | G1: 금요일 | H1: 실영업일수 | I1: =F1-K1 -> 13 | J1: 휴무일수
A2: 매출 | C2: =SUM(C4:D7) -> 4812000 | E2: 시재 | G2: 98000 | H2: 식자재 | J2: 비품 및 기타경비
H3: 업체 | I3: 금액 | J3: 업체 | K3: 금액
A4: 카드 | C4: 4010000 | E4: 카드수수료(2.75%) | G4: =INT(C4*0.0275) -> 110275 | H4: 고기 | I4: =43500+215475+216209+229110 -> 704294 | J4: 숯
A5: 현금 | C5: 802000 | E5: 현금수수료(1%) | G5: =INT(C5*0.01) -> 8020 | H5: 식자재 | I5: =36000+50000+38940+59312 -> 184252
A6: 페이결제 | E6: 통장입금 | G6: 700000 | J6: 음식물스티커
H7: 주류 | I7: 263700 | J7: 종량제봉투
A8: 금고 실잔액 | C8: 200000 | E8: 마감잔금 | G8: =C5+G2-G6-C22 -> 200000 | H8: 쌀 | I8: 112000
J9: 뚝배기
A10: 현금할인 | E10: 카드할인 | J10: 발매트
A11: 할인내역 | H11: 참기름 | J11: 불판세척 | K11: =440000/30 -> 14666.667
A12: 개수 | B12: 목살 | C12: 15 | D12: LA갈비 | F12: 8 | H12: 부탄가스
A13: 매출누계 | C13: =SUM('1:13'!$C$12) -> 184 | F13: =SUM('1:13'!$F$12) -> 86 | H13: 코카콜라음료
A14: 개수 | B14: 생갈비 | C14: 52 | D14: 돼지양념갈비 | F14: 14 | H14: 깍두기,계란
A15: 매출누계 | C15: =SUM('1:13'!$C$14) -> 544 | F15: =SUM('1:13'!$F$14) -> 235 | H15: 식자재2 | I15: =36000+3200+64800+3500+19200+1200+6200+5500+14500+5400+20800 -> 180300 | J15: 비품 및 기타경비
A16: 개수 | B16: 육회 | C16: 2 | D16: 한우업진살 | F16: 24 | J16: 인터넷 주문 | K16: 49500
A17: 매출누계 | C17: =SUM('1:13'!$C$16) -> 54 | F17: =SUM('1:13'!$F$16) -> 251 | H17: 막걸리 | J17: 다이소 구매
A18: 개수 | B18: 소갈비살 | C18: 43 | D18: LA양념갈비 | F18: 12
A19: 매출누계 | C19: =SUM('1:13'!$C$18) -> 381 | F19: =SUM('1:13'!$F$18) -> 141
D20: 테이블수 | F20: 60
D21: 누적테이블 | F21: =SUM('1:13'!$F$20) -> 733
A22: 중간출금
A23: 출금내역 | H23: 식자재합계 | I23: =SUM(I4:I22) -> 1444546 | J23: 기타경비합계 | K23: =SUM(K4:K22) -> 64166.667 | M23: 현금합계 | N23: =C5+C6 -> 802000
A24: 일매출 | C24: 일평균매출 | E24: 누적총매출 | H24: 일매출 | I24: =I23/A25 -> 0.30019659 | J24: 일매출 | K24: =K23/A25 -> 0.013334719
A25: =C2 -> 4812000 | C25: =E25/I1 -> 4089730.8 | E25: =SUM('1:13'!$A$25) -> 53166500 | H25: 누계 | I25: =SUM('1:13'!$I$21) -> 0 | J25: 누계 | K25: =SUM('1:13'!$K$21) -> 0
A26: 전 월 | H26: 누적매출 | I26: =I25/$E$25 -> 0 | J26: 누적매출 | K26: =K25/$E$25 -> 0
A27: 인 건 비 | B27: 직원A | C27: =4000000/31 -> 129032.26 | E27: 알바C | H27: 인건비합계 | I27: =SUM(C27:D34,F27:G32) -> 831241.94
B28: 직원B | C28: =3800000/31 -> 122580.65 | E28: 직원F | F28: =1500000/30 -> 50000 | H28: 일매출 | I28: =I27/$A$25 -> 0.17274354
B29: 직원D | C29: =3200000/31 -> 103225.81 | H29: 누계 | I29: =SUM('1:13'!$I$25) -> 68438261
H30: 누적매출 | I30: =I29/$I$27 -> 82.332541
B31: 직원C | C31: =3500000/31 -> 112903.23 | E31: 파출 | F31: 132000
B32: 알바A | E32: 홀 파출 | F32: 71000
B33: 알바B | C33: =13000*4 -> 52000
B34: 알바X | C34: =11700*5 -> 58500

Sheet 14
C1: 2025년 | E1: 6월 | F1: 14 | G1: 토 | H1: 실영업일수 | I1: =F1-K1 -> 14 | J1: 휴무일수
A2: 매출 | C2: =SUM(C4:D7) -> 4585000 | E2: 시재 | G2: 200000 | H2: 식자재 | J2: 비품 및 기타경비
H3: 업체 | I3: 금액 | J3: 업체 | K3: 금액
A4: 카드 | C4: 3871500 | E4: 카드수수료(2.75%) | G4: =INT(C4*0.0275) -> 106466 | H4: 고기 | I4: =30650+477600+381225+218200+597068 -> 1704743 | J4: 숯
A5: 현금 | C5: 713500 | E5: 현금수수료(1%) | G5: =INT(C5*0.01) -> 7135 | H5: 식자재 | I5: =100000+72000+16100+34540+41250+38940+59312+72160 -> 434302
A6: 페이결제 | E6: 통장입금 | G6: 810000 | J6: 음식물스티커
H7: 주류 | J7: 종량제봉투
A8: 금고 실잔액 | C8: 103500 | E8: 마감잔금 | G8: =C5+G2-G6-C22 -> 103500 | H8: 쌀
J9: 뚝배기
A10: 현금할인 | E10: 카드할인 | J10: 발매트
A11: 할인내역 | H11: 참기름 | J11: 불판세척 | K11: =440000/30 -> 14666.667
A12: 개수 | B12: 목살 | C12: 16 | D12: LA갈비 | F12: 4 | H12: 부탄가스
A13: 매출누계 | C13: =SUM('1:14'!$C$12) -> 200 | F13: =SUM('1:14'!$F$12) -> 90 | H13: 코카콜라음료
A14: 개수 | B14: 생갈비 | C14: 51 | D14: 돼지양념갈비 | F14: 28 | H14: 깍두기,계란
A15: 매출누계 | C15: =SUM('1:14'!$C$14) -> 595 | F15: =SUM('1:14'!$F$14) -> 263 | H15: 식자재2 | I15: =57600+3200+19200+5400+5500+6200+1200+5900+9800+13500+6600+3900+13000+14500+11000+15800+18000+6600+52000 -> 268900 | J15: 비품 및 기타경비
A16: 개수 | B16: 육회 | C16: 4 | D16: 한우업진살 | F16: 30 | J16: 인터넷 주문
A17: 매출누계 | C17: =SUM('1:14'!$C$16) -> 58 | F17: =SUM('1:14'!$F$16) -> 281 | H17: 막걸리 | J17: 다이소 구매 | K17: 7000
A18: 개수 | B18: 소갈비살 | C18: 47 | D18: LA양념갈비 | F18: 10
A19: 매출누계 | C19: =SUM('1:14'!$C$18) -> 428 | F19: =SUM('1:14'!$F$18) -> 151
D20: 테이블수 | F20: 61
D21: 누적테이블 | F21: =SUM('1:14'!$F$20) -> 794
A22: 중간출금
A23: 출금내역 | H23: 식자재합계 | I23: =SUM(I4:I22) -> 2407945 | J23: 기타경비합계 | K23: =SUM(K4:K22) -> 21666.667 | M23: 현금합계 | N23: =C5+C6 -> 713500
A24: 일매출 | C24: 일평균매출 | E24: 누적총매출 | H24: 일매출 | I24: =I23/A25 -> 0.52517884 | J24: 일매출 | K24: =K23/A25 -> 0.0047255543
A25: =C2 -> 4585000 | C25: =E25/I1 -> 4125107.1 | E25: =SUM('1:14'!$A$25) -> 57751500 | H25: 누계 | I25: =SUM('1:14'!$I$21) -> 0 | J25: 누계 | K25: =SUM('1:14'!$K$21) -> 0
A26: 전 월 | H26: 누적매출 | I26: =I25/$E$25 -> 0 | J26: 누적매출 | K26: =K25/$E$25 -> 0
A27: 인 건 비 | B27: 직원A | C27: =4000000/31 -> 129032.26 | E27: 알바C | H27: 인건비합계 | I27: =SUM(C27:D34,F27:G32) -> 751741.94
B28: 직원B | C28: =3800000/31 -> 122580.65 | E28: 직원F | F28: =1500000/30 -> 50000 | H28: 일매출 | I28: =I27/$A$25 -> 0.1639568
B29: 직원D | C29: =3200000/31 -> 103225.81 | H29: 누계 | I29: =SUM('1:14'!$I$25) -> 68438261 | M29: `
H30: 누적매출 | I30: =I29/$I$27 -> 91.039568
B31: 직원C | C31: =3500000/31 -> 112903.23 | E31: 파출 | F31: 130000
B32: 알바A | E32: 홀 파출
B33: 알바B | C33: =13000*8 -> 104000
B34: 알바X

Sheet 15
C1: 2025년 | E1: 6월 | F1: 15 | G1: 일 | H1: 실영업일수 | I1: =F1-K1 -> 15 | J1: 휴무일수
A2: 매출 | C2: =SUM(C4:D7) -> 4815500 | E2: 시재 | G2: 103500 | H2: 식자재 | J2: 비품 및 기타경비
H3: 업체 | I3: 금액 | J3: 업체 | K3: 금액
A4: 카드 | C4: 3716500 | E4: 카드수수료(2.75%) | G4: =INT(C4*0.0275) -> 102203 | H4: 고기 | J4: 숯
A5: 현금 | C5: 1099000 | E5: 현금수수료(1%) | G5: =INT(C5*0.01) -> 10990 | H5: 식자재
A6: 페이결제 | E6: 통장입금 | G6: 1110000 | J6: 음식물스티커
H7: 주류 | J7: 종량제봉투
A8: 금고 실잔액 | C8: 92500 | E8: 마감잔금 | G8: =C5+G2-G6-C22 -> 92500 | H8: 쌀
J9: 뚝배기
A10: 현금할인 | E10: 카드할인 | J10: 발매트
A11: 할인내역 | H11: 참기름 | J11: 불판세척 | K11: =440000/30 -> 14666.667
A12: 개수 | B12: 목살 | C12: 21 | D12: LA갈비 | F12: 8 | H12: 부탄가스
A13: 매출누계 | C13: =SUM('1:15'!$C$12) -> 221 | F13: =SUM('1:15'!$F$12) -> 98 | H13: 코카콜라음료
A14: 개수 | B14: 생갈비 | C14: 50 | D14: 돼지양념갈비 | F14: 28 | H14: 깍두기,계란
A15: 매출누계 | C15: =SUM('1:15'!$C$14) -> 645 | F15: =SUM('1:15'!$F$14) -> 291 | H15: 식자재2 | J15: 비품 및 기타경비
A16: 개수 | B16: 육회 | C16: 9 | D16: 한우업진살 | F16: 6 | J16: 인터넷 주문
A17: 매출누계 | C17: =SUM('1:15'!$C$16) -> 67 | F17: =SUM('1:15'!$F$16) -> 287 | H17: 막걸리 | I17: =1600*3 -> 4800 | J17: 다이소 구매
A18: 개수 | B18: 소갈비살 | C18: 67 | D18: LA양념갈비 | F18: 18
A19: 매출누계 | C19: =SUM('1:15'!$C$18) -> 495 | F19: =SUM('1:15'!$F$18) -> 169
D20: 테이블수 | F20: 69
D21: 누적테이블 | F21: =SUM('1:15'!$F$20) -> 863
A22: 중간출금
A23: 출금내역 | H23: 식자재합계 | I23: =SUM(I4:I22) -> 4800 | J23: 기타경비합계 | K23: =SUM(K4:K22) -> 14666.667 | M23: 현금합계 | N23: =C5+C6 -> 1099000
A24: 일매출 | C24: 일평균매출 | E24: 누적총매출 | H24: 일매출 | I24: =I23/A25 -> 0.00099678123 | J24: 일매출 | K24: =K23/A25 -> 0.0030457204
A25: =C2 -> 4815500 | C25: =E25/I1 -> 4171133.3 | E25: =SUM('1:15'!$A$25) -> 62567000 | H25: 누계 | I25: =SUM('1:15'!$I$21) -> 0 | J25: 누계 | K25: =SUM('1:15'!$K$21) -> 0
A26: 전 월 | H26: 누적매출 | I26: =I25/$E$25 -> 0 | J26: 누적매출 | K26: =K25/$E$25 -> 0
A27: 인 건 비 | B27: 직원A | C27: =4000000/31 -> 129032.26 | E27: 알바C | H27: 인건비합계 | I27: =SUM(C27:D34,F27:G32) -> 811741.94
B28: 직원B | C28: =3800000/31 -> 122580.65 | E28: 직원F | F28: =1500000/30 -> 50000 | H28: 일매출 | I28: =I27/$A$25 -> 0.16856857
B29: 직원D | C29: =3200000/31 -> 103225.81 | H29: 누계 | I29: =SUM('1:15'!$I$25) -> 68438261
H30: 누적매출 | I30: =I29/$I$27 -> 84.310368
B31: 직원C | C31: =3500000/31 -> 112903.23 | E31: 파출 | F31: 130000
B32: 알바A | C32: =14000*8 -> 112000 | E32: 홀 파출
B33: 알바B | C33: =13000*4 -> 52000
B34: 알바X

Sheet 16
C1: 2025년 | E1: 6월 | F1: 16 | G1: 월 | H1: 실영업일수 | I1: =F1-K1 -> 16 | J1: 휴무일수
A2: 매출 | C2: =SUM(C4:D7) -> 2179500 | E2: 시재 | G2: 92500 | H2: 식자재 | J2: 비품 및 기타경비
H3: 업체 | I3: 금액 | J3: 업체 | K3: 금액
A4: 카드 | C4: 1709500 | E4: 카드수수료(2.75%) | G4: =INT(C4*0.0275) -> 47011 | H4: 고기 | I4: =30650+477600+154700+253112+203301+10+296087+904000 -> 2319460 | J4: 숯
A5: 현금 | C5: 470000 | E5: 현금수수료(1%) | G5: =INT(C5*0.01) -> 4700 | H5: 식자재
A6: 페이결제 | E6: 통장입금 | G6: 450000 | J6: 음식물스티커
H7: 주류 | I7: =568700-47300 -> 521400 | J7: 종량제봉투
A8: 금고 실잔액 | C8: 112500 | E8: 마감잔금 | G8: =C5+G2-G6-C22 -> 112500 | H8: 쌀
J9: 뚝배기
A10: 현금할인 | C10: 50000 | E10: 카드할인 | J10: 발매트 | K10: 13000
A11: 할인내역 | C11: 리뷰노트 50,000원 | H11: 참기름 | J11: 불판세척 | K11: =440000/30 -> 14666.667
A12: 개수 | B12: 목살 | C12: 9 | D12: LA갈비 | F12: 0 | H12: 부탄가스
A13: 매출누계 | C13: =SUM('1:16'!$C$12) -> 230 | F13: =SUM('1:16'!$F$12) -> 98 | H13: 코카콜라음료
A14: 개수 | B14: 생갈비 | C14: 17 | D14: 돼지양념갈비 | F14: 13 | H14: 깍두기,계란
A15: 매출누계 | C15: =SUM('1:16'!$C$14) -> 662 | F15: =SUM('1:16'!$F$14) -> 304 | H15: 식자재2 | I15: =28800+19200+5900+13000+18000+15600+13000 -> 113500 | J15: 비품 및 기타경비
A16: 개수 | B16: 육회 | C16: 1 | D16: 한우업진살 | F16: 2 | J16: 인터넷 주문 | K16: 150000
A17: 매출누계 | C17: =SUM('1:16'!$C$16) -> 68 | F17: =SUM('1:16'!$F$16) -> 289 | H17: 막걸리 | I17: 6400 | J17: 다이소 구매
A18: 개수 | B18: 소갈비살 | C18: 23 | D18: LA양념갈비 | F18: 4
A19: 매출누계 | C19: =SUM('1:16'!$C$18) -> 518 | F19: =SUM('1:16'!$F$18) -> 173
D20: 테이블수
D21: 누적테이블 | F21: =SUM('1:16'!$F$20) -> 863
A22: 중간출금
A23: 출금내역 | H23: 식자재합계 | I23: =SUM(I4:I22) -> 2960760 | J23: 기타경비합계 | K23: =SUM(K4:K22) -> 177666.67 | M23: 현금합계 | N23: =C5+C6 -> 470000
A24: 일매출 | C24: 일평균매출 | E24: 누적총매출 | H24: 일매출 | I24: =I23/A25 -> 1.3584584 | J24: 일매출 | K24: =K23/A25 -> 0.081517168
A25: =C2 -> 2179500 | C25: =E25/I1 -> 4046656.2 | E25: =SUM('1:16'!$A$25) -> 64746500 | H25: 누계 | I25: =SUM('1:16'!$I$21) -> 0 | J25: 누계 | K25: =SUM('1:16'!$K$21) -> 0
A26: 전 월 | H26: 누적매출 | I26: =I25/$E$25 -> 0 | J26: 누적매출 | K26: =K25/$E$25 -> 0
A27: 인 건 비 | B27: 직원A | C27: =4000000/31 -> 129032.26 | E27: 알바C | H27: 인건비합계 | I27: =SUM(C27:D34,F27:G32) -> 754741.94
B28: 직원B | C28: =3800000/31 -> 122580.65 | E28: 직원F | F28: =1500000/30 -> 50000 | H28: 일매출 | I28: =I27/$A$25 -> 0.34629132
B29: 직원D | C29: =3200000/31 -> 103225.81 | H29: 누계 | I29: =SUM('1:16'!$I$25) -> 68438261
H30: 누적매출 | I30: =I29/$I$27 -> 90.677698
B31: 직원C | C31: =3500000/31 -> 112903.23 | E31: 파출 | F31: 120000
B32: 알바A | E32: 홀 파출
B33: 알바B | C33: =13000*9 -> 117000
B34: 알바X

Sheet 17
C1: 2025년 | E1: 6월 | F1: 17 | G1: 화 | H1: 실영업일수 | I1: =F1-K1 -> 17 | J1: 휴무일수
A2: 매출 | C2: =SUM(C4:D7) -> 4233000 | E2: 시재 | G2: 112500 | H2: 식자재 | J2: 비품 및 기타경비
H3: 업체 | I3: 금액 | J3: 업체 | K3: 금액
A4: 카드 | C4: 3642000 | E4: 카드수수료(2.75%) | G4: =INT(C4*0.0275) -> 100155 | H4: 고기 | I4: =226525+288746+452000 -> 967271 | J4: 숯
A5: 현금 | C5: 591000 | E5: 현금수수료(1%) | G5: =INT(C5*0.01) -> 5910 | H5: 식자재 | I5: =23650+59312+36080+100000+72000+13620+9150 -> 313812
A6: 페이결제 | E6: 통장입금 | G6: 600000 | J6: 음식물스티커
H7: 주류 | J7: 종량제봉투
A8: 금고 실잔액 | C8: 103500 | E8: 마감잔금 | G8: =C5+G2-G6-C22 -> 103500 | H8: 쌀 | I8: 58000
J9: 뚝배기
A10: 현금할인 | E10: 카드할인 | J10: 발매트
A11: 할인내역 | H11: 참기름 | J11: 불판세척 | K11: =440000/30 -> 14666.667
A12: 개수 | B12: 목살 | C12: 11 | D12: LA갈비 | F12: 9 | H12: 부탄가스
A13: 매출누계 | C13: =SUM('1:17'!$C$12) -> 241 | F13: =SUM('1:17'!$F$12) -> 107 | H13: 코카콜라음료
A14: 개수 | B14: 생갈비 | C14: 32 | D14: 돼지양념갈비 | F14: 10 | H14: 깍두기,계란
A15: 매출누계 | C15: =SUM('1:17'!$C$14) -> 694 | F15: =SUM('1:17'!$F$14) -> 314 | H15: 식자재2 | I15: 195250 | J15: 비품 및 기타경비
A16: 개수 | B16: 육회 | C16: 13 | D16: 한우업진살 | F16: 30 | J16: 인터넷 주문 | K16: 90920
A17: 매출누계 | C17: =SUM('1:17'!$C$16) -> 81 | F17: =SUM('1:17'!$F$16) -> 319 | H17: 막걸리 | J17: 다이소 구매
A18: 개수 | B18: 소갈비살 | C18: 35 | D18: LA양념갈비 | F18: 10
A19: 매출누계 | C19: =SUM('1:17'!$C$18) -> 553 | F19: =SUM('1:17'!$F$18) -> 183
D20: 테이블수 | F20: 63
D21: 누적테이블 | F21: =SUM('1:17'!$F$20) -> 926
A22: 중간출금
A23: 출금내역 | H23: 식자재합계 | I23: =SUM(I4:I22) -> 1534333 | J23: 기타경비합계 | K23: =SUM(K4:K22) -> 105586.67 | M23: 현금합계 | N23: =C5+C6 -> 591000
A24: 일매출 | C24: 일평균매출 | E24: 누적총매출 | H24: 일매출 | I24: =I23/A25 -> 0.36246941 | J24: 일매출 | K24: =K23/A25 -> 0.024943696
A25: =C2 -> 4233000 | C25: =E25/I1 -> 4057617.6 | E25: =SUM('1:17'!$A$25) -> 68979500 | H25: 누계 | I25: =SUM('1:17'!$I$21) -> 0 | J25: 누계 | K25: =SUM('1:17'!$K$21) -> 0
A26: 전 월 | H26: 누적매출 | I26: =I25/$E$25 -> 0 | J26: 누적매출 | K26: =K25/$E$25 -> 0
A27: 인 건 비 | B27: 직원A | C27: =4000000/31 -> 129032.26 | E27: 알바C | H27: 인건비합계 | I27: =SUM(C27:D34,F27:G32) -> 817241.94
B28: 직원B | C28: =3800000/31 -> 122580.65 | E28: 직원F | F28: =1500000/30 -> 50000 | H28: 일매출 | I28: =I27/$A$25 -> 0.19306448
B29: 직원D | C29: =3200000/31 -> 103225.81 | H29: 누계 | I29: =SUM('1:17'!$I$25) -> 68438261
H30: 누적매출 | I30: =I29/$I$27 -> 83.742963
B31: 직원C | C31: =3500000/31 -> 112903.23 | E31: 파출 | F31: 120000
B32: 알바A | C32: =14000*4 -> 56000 | E32: 홀 파출
B33: 알바B | C33: =13000*9.5 -> 123500
B34: 알바X

Sheet 18
C1: 2025년 | E1: 6월 | F1: 18 | G1: 수 | H1: 실영업일수 | I1: =F1-K1 -> 18 | J1: 휴무일수
A2: 매출 | C2: =SUM(C4:D7) -> 4819500 | E2: 시재 | G2: 103500 | H2: 식자재 | J2: 비품 및 기타경비
H3: 업체 | I3: 금액 | J3: 업체 | K3: 금액
A4: 카드 | C4: 4045000 | E4: 카드수수료(2.75%) | G4: =INT(C4*0.0275) -> 111237 | H4: 고기 | I4: =452000+56220+221000+250930 -> 980150 | J4: 숯
A5: 현금 | C5: 774500 | E5: 현금수수료(1%) | G5: =INT(C5*0.01) -> 7745 | H5: 식자재 | I5: =29656+50000+36000 -> 115656
A6: 페이결제 | E6: 통장입금 | G6: 741000 | J6: 음식물스티커
H7: 주류 | J7: 종량제봉투
A8: 금고 실잔액 | C8: 131000 | E8: 마감잔금 | G8: =C5+G2-G6-C22 -> 137000 | H8: 쌀
J9: 뚝배기
A10: 현금할인 | C10: =91000+24000 -> 115000 | E10: 카드할인 | J10: 발매트
A11: 할인내역 | C11: e-식권 91,000원 24,000원 육회 할인 | H11: 참기름 | J11: 불판세척 | K11: =440000/30 -> 14666.667
A12: 개수 | B12: 목살 | C12: 11 | D12: LA갈비 | F12: 7 | H12: 부탄가스
A13: 매출누계 | C13: =SUM('1:18'!$C$12) -> 252 | F13: =SUM('1:18'!$F$12) -> 114 | H13: 코카콜라음료
A14: 개수 | B14: 생갈비 | C14: 39 | D14: 돼지양념갈비 | F14: 20 | H14: 깍두기,계란
A15: 매출누계 | C15: =SUM('1:18'!$C$14) -> 733 | F15: =SUM('1:18'!$F$14) -> 334 | H15: 식자재2 | I15: 73800 | J15: 비품 및 기타경비
A16: 개수 | B16: 육회 | C16: 14 | D16: 한우업진살 | F16: 22 | J16: 인터넷 주문
A17: 매출누계 | C17: =SUM('1:18'!$C$16) -> 95 | F17: =SUM('1:18'!$F$16) -> 341 | H17: 막걸리 | J17: 다이소 구매
A18: 개수 | B18: 소갈비살 | C18: 41 | D18: LA양념갈비 | F18: 13
A19: 매출누계 | C19: =SUM('1:18'!$C$18) -> 594 | F19: =SUM('1:18'!$F$18) -> 196
D20: 테이블수 | F20: 77
D21: 누적테이블 | F21: =SUM('1:18'!$F$20) -> 1003
A22: 중간출금
A23: 출금내역 | H23: 식자재합계 | I23: =SUM(I4:I22) -> 1169606 | J23: 기타경비합계 | K23: =SUM(K4:K22) -> 14666.667 | M23: 현금합계 | N23: =C5+C6 -> 774500
A24: 일매출 | C24: 일평균매출 | E24: 누적총매출 | H24: 일매출 | I24: =I23/A25 -> 0.24268202 | J24: 일매출 | K24: =K23/A25 -> 0.0030431926
A25: =C2 -> 4819500 | C25: =E25/I1 -> 4099944.4 | E25: =SUM('1:18'!$A$25) -> 73799000 | H25: 누계 | I25: =SUM('1:18'!$I$21) -> 0 | J25: 누계 | K25: =SUM('1:18'!$K$21) -> 0
A26: 전 월 | H26: 누적매출 | I26: =I25/$E$25 -> 0 | J26: 누적매출 | K26: =K25/$E$25 -> 0
A27: 인 건 비 | B27: 직원A | C27: =4000000/31 -> 129032.26 | E27: 알바C | F27: =11700*5 -> 58500 | H27: 인건비합계 | I27: =SUM(C27:D34,F27:G32) -> 696241.94
B28: 직원B | C28: =3800000/31 -> 122580.65 | E28: 직원F | F28: =1500000/30 -> 50000 | H28: 일매출 | I28: =I27/$A$25 -> 0.14446352
B29: 직원D | C29: =3200000/31 -> 103225.81 | H29: 누계 | I29: =SUM('1:18'!$I$25) -> 68438261
H30: 누적매출 | I30: =I29/$I$27 -> 98.296666
B31: 직원C | C31: =3500000/31 -> 112903.23 | E31: 파출 | F31: 120000
B32: 알바A | E32: 홀 파출
B33: 알바B
B34: 알바X

Sheet 19
C1: 2025년 | E1: 6월 | F1: 19 | G1: 목 | H1: 실영업일수 | I1: =F1-K1 -> 19 | J1: 휴무일수
A2: 매출 | C2: =SUM(C4:D7) -> 5146500 | E2: 시재 | G2: 131000 | H2: 식자재 | J2: 비품 및 기타경비
H3: 업체 | I3: 금액 | J3: 업체 | K3: 금액
A4: 카드 | C4: 4223500 | E4: 카드수수료(2.75%) | G4: =INT(C4*0.0275) -> 116146 | H4: 고기 | I4: =904000+254150+242202+183939+323004 -> 1907295 | J4: 숯 | K4: 305000
A5: 현금 | C5: 923000 | E5: 현금수수료(1%) | G5: =INT(C5*0.01) -> 9230 | H5: 식자재 | I5: =13620+30300+6430+15700+100000+29656 -> 195706
A6: 페이결제 | E6: 통장입금 | G6: 900000 | J6: 음식물스티커
H7: 주류 | J7: 종량제봉투
A8: 금고 실잔액 | C8: 157000 | E8: 마감잔금 | G8: =C5+G2-G6-C22 -> 154000 | H8: 쌀 | I8: 58000
J9: 뚝배기
A10: 현금할인 | E10: 카드할인 | J10: 발매트
A11: 할인내역 | H11: 참기름 | J11: 불판세척 | K11: =440000/30 -> 14666.667
A12: 개수 | B12: 목살 | C12: 19 | D12: LA갈비 | F12: 11 | H12: 부탄가스
A13: 매출누계 | C13: =SUM('1:19'!$C$12) -> 271 | F13: =SUM('1:19'!$F$12) -> 125 | H13: 코카콜라음료
A14: 개수 | B14: 생갈비 | C14: 33 | D14: 돼지양념갈비 | F14: 18 | H14: 깍두기,계란
A15: 매출누계 | C15: =SUM('1:19'!$C$14) -> 766 | F15: =SUM('1:19'!$F$14) -> 352 | H15: 식자재2 | I15: 146000 | J15: 비품 및 기타경비
A16: 개수 | B16: 육회 | C16: 10 | D16: 한우업진살 | F16: 29 | J16: 인터넷 주문 | K16: 26919
A17: 매출누계 | C17: =SUM('1:19'!$C$16) -> 105 | F17: =SUM('1:19'!$F$16) -> 370 | H17: 막걸리 | J17: 다이소 구매
A18: 개수 | B18: 소갈비살 | C18: 48 | D18: LA양념갈비 | F18: 12
A19: 매출누계 | C19: =SUM('1:19'!$C$18) -> 642 | F19: =SUM('1:19'!$F$18) -> 208
D20: 테이블수 | F20: 66
D21: 누적테이블 | F21: =SUM('1:19'!$F$20) -> 1069
A22: 중간출금
A23: 출금내역 | H23: 식자재합계 | I23: =SUM(I4:I22) -> 2307001 | J23: 기타경비합계 | K23: =SUM(K4:K22) -> 346585.67 | M23: 현금합계 | N23: =C5+C6 -> 923000
A24: 일매출 | C24: 일평균매출 | E24: 누적총매출 | H24: 일매출 | I24: =I23/A25 -> 0.44826601 | J24: 일매출 | K24: =K23/A25 -> 0.067343955
A25: =C2 -> 5146500 | C25: =E25/I1 -> 4155026.3 | E25: =SUM('1:19'!$A$25) -> 78945500 | H25: 누계 | I25: =SUM('1:18'!$I$21) -> 0 | J25: 누계 | K25: =SUM('1:18'!$K$21) -> 0
A26: 전 월 | H26: 누적매출 | I26: =I25/$E$25 -> 0 | J26: 누적매출 | K26: =K25/$E$25 -> 0
A27: 인 건 비 | B27: 직원A | C27: =4000000/31 -> 129032.26 | E27: 알바C | F27: =11700*4.5 -> 52650 | H27: 인건비합계 | I27: =SUM(C27:D34,F27:G32) -> 843891.94
B28: 직원B | C28: =3800000/31 -> 122580.65 | E28: 직원F | F28: =1500000/30 -> 50000 | H28: 일매출 | I28: =I27/$A$25 -> 0.16397395
B29: 직원D | C29: =3200000/31 -> 103225.81 | H29: 누계 | I29: =SUM('1:18'!$I$25) -> 68438261
H30: 누적매출 | I30: =I29/$I$27 -> 81.098371
B31: 직원C | C31: =3500000/31 -> 112903.23 | E31: 파출 | F31: 120000
B32: 알바A | C32: =14000*4 -> 56000 | E32: 홀 파출
B33: 알바B | C33: =13000*7.5 -> 97500
B34: 알바X

Sheet 20
C1: 2025년 | E1: 6월 | F1: 20 | G1: 금 | H1: 실영업일수 | I1: =F1-K1 -> 20 | J1: 휴무일수
A2: 매출 | C2: =SUM(C4:D7) -> 3939000 | E2: 시재 | G2: 157000 | H2: 식자재 | J2: 비품 및 기타경비
H3: 업체 | I3: 금액 | J3: 업체 | K3: 금액
A4: 카드 | C4: 3718500 | E4: 카드수수료(2.75%) | G4: =INT(C4*0.0275) -> 102258 | H4: 고기 | I4: =477600+452000+221000 -> 1150600 | J4: 숯
A5: 현금 | C5: 220500 | E5: 현금수수료(1%) | G5: =INT(C5*0.01) -> 2205 | H5: 식자재
A6: 페이결제 | E6: 통장입금 | G6: 200000 | J6: 음식물스티커
H7: 주류 | I7: 638000 | J7: 종량제봉투
A8: 금고 실잔액 | C8: 176500 | E8: 마감잔금 | G8: =C5+G2-G6-C22 -> 177500 | H8: 쌀
J9: 뚝배기
A10: 현금할인 | E10: 카드할인 | J10: 발매트
A11: 할인내역 | H11: 참기름 | J11: 불판세척 | K11: =440000/30 -> 14666.667
A12: 개수 | B12: 목살 | C12: 16 | D12: LA갈비 | F12: 4 | H12: 부탄가스
A13: 매출누계 | C13: =SUM('1:20'!$C$12) -> 287 | F13: =SUM('1:20'!$F$12) -> 129 | H13: 코카콜라음료
A14: 개수 | B14: 생갈비 | C14: 36 | D14: 돼지양념갈비 | F14: 4 | H14: 깍두기,계란
A15: 매출누계 | C15: =SUM('1:20'!$C$14) -> 802 | F15: =SUM('1:20'!$F$14) -> 356 | H15: 식자재2 | I15: =12500+20000+13500+11000+52000+6200+9800+57600+16000+19200+6600+3900+6900+3200 -> 238400 | J15: 비품 및 기타경비
A16: 개수 | B16: 육회 | C16: 5 | D16: 한우업진살 | F16: 22 | J16: 인터넷 주문 | K16: 32480
A17: 매출누계 | C17: =SUM('1:20'!$C$16) -> 110 | F17: =SUM('1:20'!$F$16) -> 392 | H17: 막걸리 | I17: 4800 | J17: 다이소 구매
A18: 개수 | B18: 소갈비살 | C18: 41 | D18: LA양념갈비 | F18: 13
A19: 매출누계 | C19: =SUM('1:20'!$C$18) -> 683 | F19: =SUM('1:20'!$F$18) -> 221
D20: 테이블수 | F20: 56
D21: 누적테이블 | F21: =SUM('1:20'!$F$20) -> 1125
A22: 중간출금
A23: 출금내역 | H23: 식자재합계 | I23: =SUM(I4:I22) -> 2031800 | J23: 기타경비합계 | K23: =SUM(K4:K22) -> 47146.667 | M23: 현금합계 | N23: =C5+C6 -> 220500
A24: 일매출 | C24: 일평균매출 | E24: 누적총매출 | H24: 일매출 | I24: =I23/A25 -> 0.5158162 | J24: 일매출 | K24: =K23/A25 -> 0.011969197
A25: =C2 -> 3939000 | C25: =E25/I1 -> 4144225 | E25: =SUM('1:20'!$A$25) -> 82884500 | H25: 누계 | I25: =SUM('1:20'!$I$21) -> 0 | J25: 누계 | K25: =SUM('1:20'!$K$21) -> 0
A26: 전 월 | H26: 누적매출 | I26: =I25/$E$25 -> 0 | J26: 누적매출 | K26: =K25/$E$25 -> 0
A27: 인 건 비 | B27: 직원A | C27: =4000000/31 -> 129032.26 | E27: 알바C | F27: =11700*3.5 -> 40950 | H27: 인건비합계 | I27: =SUM(C27:D34,F27:G32) -> 724191.94
B28: 직원B | C28: =3800000/31 -> 122580.65 | E28: 직원F | F28: =1500000/30 -> 50000 | H28: 일매출 | I28: =I27/$A$25 -> 0.18385172
B29: 직원D | C29: =3200000/31 -> 103225.81 | H29: 누계 | I29: =SUM('1:20'!$I$25) -> 68438261
H30: 누적매출 | I30: =I29/$I$27 -> 94.502932
B31: 직원C | C31: =3500000/31 -> 112903.23 | E31: 파출 | F31: 120000
B32: 알바A | E32: 홀 파출
B33: 알바B | C33: =13000*3.5 -> 45500
B34: 알바X

Sheet 21
C1: 2025년 | E1: 6월 | F1: 21 | G1: 토 | H1: 실영업일수 | I1: =F1-K1 -> 21 | J1: 휴무일수
A2: 매출 | C2: =SUM(C4:D7) -> 5309000 | E2: 시재 | G2: 176500 | H2: 식자재 | J2: 비품 및 기타경비
H3: 업체 | I3: 금액 | J3: 업체 | K3: 금액
A4: 카드 | C4: 3843000 | E4: 카드수수료(2.75%) | G4: =INT(C4*0.0275) -> 105682 | H4: 고기 | J4: 숯
A5: 현금 | C5: 1466000 | E5: 현금수수료(1%) | G5: =INT(C5*0.01) -> 14660 | H5: 식자재 | I5: 459148
A6: 페이결제 | E6: 통장입금 | G6: 1540000 | J6: 음식물스티커
H7: 주류 | J7: 종량제봉투
A8: 금고 실잔액 | C8: 102500 | E8: 마감잔금 | G8: =C5+G2-G6-C22 -> 102500 | H8: 쌀
J9: 뚝배기
A10: 현금할인 | C10: 49000 | E10: 카드할인 | J10: 발매트
A11: 할인내역 | C11: 리뷰노트 49,000원 | H11: 참기름 | J11: 불판세척 | K11: =440000/30 -> 14666.667
A12: 개수 | B12: 목살 | C12: 15 | D12: LA갈비 | F12: 13 | H12: 부탄가스
A13: 매출누계 | C13: =SUM('1:21'!$C$12) -> 302 | F13: =SUM('1:21'!$F$12) -> 142 | H13: 코카콜라음료
A14: 개수 | B14: 생갈비 | C14: 59 | D14: 돼지양념갈비 | F14: 35 | H14: 깍두기,계란
A15: 매출누계 | C15: =SUM('1:21'!$C$14) -> 861 | F15: =SUM('1:21'!$F$14) -> 391 | H15: 식자재2 | I15: 188900 | J15: 비품 및 기타경비
A16: 개수 | B16: 육회 | C16: 10 | D16: 한우업진살 | F16: 0 | J16: 인터넷 주문
A17: 매출누계 | C17: =SUM('1:21'!$C$16) -> 120 | F17: =SUM('1:21'!$F$16) -> 392 | H17: 막걸리 | J17: 다이소 구매
A18: 개수 | B18: 소갈비살 | C18: 67 | D18: LA양념갈비 | F18: 36
A19: 매출누계 | C19: =SUM('1:21'!$C$18) -> 750 | F19: =SUM('1:21'!$F$18) -> 257
D20: 테이블수 | F20: 71
D21: 누적테이블 | F21: =SUM('1:21'!$F$20) -> 1196
A22: 중간출금
A23: 출금내역 | H23: 식자재합계 | I23: =SUM(I4:I22) -> 648048 | J23: 기타경비합계 | K23: =SUM(K4:K22) -> 14666.667 | M23: 현금합계 | N23: =C5+C6 -> 1466000
A24: 일매출 | C24: 일평균매출 | E24: 누적총매출 | H24: 일매출 | I24: =I23/A25 -> 0.12206593 | J24: 일매출 | K24: =K23/A25 -> 0.0027626044
A25: =C2 -> 5309000 | C25: =E25/I1 -> 4199690.5 | E25: =SUM('1:21'!$A$25) -> 88193500 | H25: 누계 | I25: =SUM('1:21'!$I$21) -> 0 | J25: 누계 | K25: =SUM('1:21'!$K$21) -> 0
A26: 전 월 | H26: 누적매출 | I26: =I25/$E$25 -> 0 | J26: 누적매출 | K26: =K25/$E$25 -> 0
A27: 인 건 비 | B27: 직원A | C27: =4000000/31 -> 129032.26 | E27: 알바C | H27: 인건비합계 | I27: =SUM(C27:D34,F27:G32) -> 821741.94
B28: 직원B | C28: =3800000/31 -> 122580.65 | E28: 직원F | F28: =1500000/30 -> 50000 | H28: 일매출 | I28: =I27/$A$25 -> 0.15478281
B29: 직원D | C29: =3200000/31 -> 103225.81 | H29: 누계 | I29: =SUM('1:21'!$I$25) -> 68438261
H30: 누적매출 | I30: =I29/$I$27 -> 83.284372
B31: 직원C | C31: =3500000/31 -> 112903.23 | E31: 파출 | F31: 130000
B32: 알바A | C32: =14000*5 -> 70000 | E32: 홀 파출
B33: 알바B | C33: =13000*8 -> 104000
B34: 알바X

Sheet 22
C1: 2025년 | E1: 6월 | F1: 22 | G1: 일 | H1: 실영업일수 | I1: =F1-K1 -> 22 | J1: 휴무일수
A2: 매출 | C2: =SUM(C4:D7) -> 3400500 | E2: 시재 | G2: 102500 | H2: 식자재 | J2: 비품 및 기타경비
H3: 업체 | I3: 금액 | J3: 업체 | K3: 금액
A4: 카드 | C4: 3020500 | E4: 카드수수료(2.75%) | G4: =INT(C4*0.0275) -> 83063 | H4: 고기 | J4: 숯
A5: 현금 | C5: 380000 | E5: 현금수수료(1%) | G5: =INT(C5*0.01) -> 3800 | H5: 식자재
A6: 페이결제 | E6: 통장입금 | G6: 400000 | J6: 음식물스티커
H7: 주류 | J7: 종량제봉투
A8: 금고 실잔액 | C8: 82500 | E8: 마감잔금 | G8: =C5+G2-G6-C22 -> 82500 | H8: 쌀
J9: 뚝배기
A10: 현금할인 | C10: 50000 | E10: 카드할인 | J10: 발매트
A11: 할인내역 | C11: 리뷰노트 50,000원 | H11: 참기름 | J11: 불판세척 | K11: =440000/30 -> 14666.667
A12: 개수 | B12: 목살 | C12: 18 | D12: LA갈비 | F12: 16 | H12: 부탄가스
A13: 매출누계 | C13: =SUM('1:22'!$C$12) -> 320 | F13: =SUM('1:22'!$F$12) -> 158 | H13: 코카콜라음료
A14: 개수 | B14: 생갈비 | C14: 33 | D14: 돼지양념갈비 | F14: 15 | H14: 깍두기,계란
A15: 매출누계 | C15: =SUM('1:22'!$C$14) -> 894 | F15: =SUM('1:22'!$F$14) -> 406 | H15: 식자재2 | J15: 비품 및 기타경비
A16: 개수 | B16: 육회 | C16: 11 | D16: 한우업진살 | F16: 0 | J16: 인터넷 주문 | K16: 179973
A17: 매출누계 | C17: =SUM('1:22'!$C$16) -> 131 | F17: =SUM('1:22'!$F$16) -> 392 | H17: 막걸리 | I17: 4800 | J17: 다이소 구매
A18: 개수 | B18: 소갈비살 | C18: 0 | D18: LA양념갈비 | F18: 17
A19: 매출누계 | C19: =SUM('1:22'!$C$18) -> 750 | F19: =SUM('1:22'!$F$18) -> 274
D20: 테이블수 | F20: 50
D21: 누적테이블 | F21: =SUM('1:22'!$F$20) -> 1246
A22: 중간출금
A23: 출금내역 | H23: 식자재합계 | I23: =SUM(I4:I22) -> 4800 | J23: 기타경비합계 | K23: =SUM(K4:K22) -> 194639.67 | M23: 현금합계 | N23: =C5+C6 -> 380000
A24: 일매출 | C24: 일평균매출 | E24: 누적총매출 | H24: 일매출 | I24: =I23/A25 -> 0.0014115571 | J24: 일매출 | K24: =K23/A25 -> 0.057238543
A25: =C2 -> 3400500 | C25: =E25/I1 -> 4163363.6 | E25: =SUM('1:22'!$A$25) -> 91594000 | H25: 누계 | I25: =SUM('1:22'!$I$21) -> 0 | J25: 누계 | K25: =SUM('1:22'!$K$21) -> 0
A26: 전 월 | H26: 누적매출 | I26: =I25/$E$25 -> 0 | J26: 누적매출 | K26: =K25/$E$25 -> 0
A27: 인 건 비 | B27: 직원A | C27: =4000000/31 -> 129032.26 | E27: 알바C | H27: 인건비합계 | I27: =SUM(C27:D34,F27:G32) -> 710741.94
B28: 직원B | C28: =3800000/31 -> 122580.65 | E28: 직원F | F28: =1500000/30 -> 50000 | H28: 일매출 | I28: =I27/$A$25 -> 0.20901101
B29: 직원D | C29: =3200000/31 -> 103225.81 | H29: 누계 | I29: =SUM('1:22'!$I$25) -> 68438261
H30: 누적매출 | I30: =I29/$I$27 -> 96.291294
B31: 직원C | C31: =3500000/31 -> 112903.23 | E31: 파출 | F31: 130000
B32: 알바A | C32: =14000*4.5 -> 63000 | E32: 홀 파출
B33: 알바B
B34: 알바X

Sheet 23
C1: 2025년 | E1: 6월 | F1: 23 | G1: 월요일 | H1: 실영업일수 | I1: =F1-K1 -> 23 | J1: 휴무일수
A2: 매출 | C2: =SUM(C4:D7) -> 4388500 | E2: 시재 | G2: 82500 | H2: 식자재 | J2: 비품 및 기타경비
H3: 업체 | I3: 금액 | J3: 업체 | K3: 금액
