Workbook

Sheet 월합산
A1: 월 합 산
A2: 매출 | C2: =C3+G3+C5 -> 0 | E2: 시제 | H2: 비 고
A3: 카드매출 | C3: =SUM('1'!C3) -> 0 | E3: 현금매출 | G3: =SUM('1'!G3) -> 0
A4: 금고잔액 | C4: =C21 -> 0 | E4: 입금 | G4: =C17 -> 0
A5: 할인금액 | C5: =C6+G6 -> 0 | E5: 잔금 | G5: =C4-G4 -> 0
A6: 현금할인 | C6: =SUM('1'!C7) -> 0 | E6: 카드할인 | G6: =SUM('1'!G7) -> 0
A7: 할인내역
H8: take out | I8: 매출누계 | K8: =SUM('1'!K9) -> 0
H9: 배달 | I9: 매출누계 | K9: =SUM('1'!K10) -> 13000
I10: 배달료누계 | K10: =SUM('1'!K11) -> 0
A11: 중간출금 | H11: 중간입금
A12: 출금내역 | H12: 입금내역
A13: 영업일수 | C13: 일평균매출 | E13: 누적총매출 | H13: 목표일매출 | J13: 목표월매출
A14: =C2 -> 0 | C14: =ROUNDDOWN((E14/A14),-4) -> #DIV/0! | E14: =C2 -> 0
A15: 전 월
A16: 마 감 잔 금 | G16: 마 감 잔 금
A17: 만 | G17: 만
A18: 천 | G18: 천
A19: 오백 | G19: 오백
A20: 백이하 | G20: 백이하
A21: 합계 | C21: =SUM(C17:E20) -> 0 | G21: 합계 | H21: =SUM(H17:K20) -> 0

Sheet 결산
E1: 9월
A4: 고정비용 | F4: 변동비용
A5: 항목 | D5: 항목별 소계 | E5: 매출대비 비율 | F5: 항목 | G5: 업체 | H5: 금액 | J5: 항목별 소계 | M5: 통장입금 | N5: =SUM('1:30'!G6) -> 14593000
A6: 월세 | C6: 6985000 | D6: =C6 -> 6985000 | E6: =D6/$B$45 -> 0.053627392 | F6: 식자재 | G6: 고기 | H6: =SUM('1:30'!I4) -> 32558426 | I6: =H6/$B$45 -> 0.24996757 | J6: =SUM(H6:H18) -> 48274173 | K6: =J6/$B$45 -> 0.37062534
A7: 마케팅 | C7: 2600000 | D7: =C7 -> 2600000 | E7: =D7/$B$45 -> 0.01996152 | G7: 식자재 | H7: =SUM('1:30'!I5) -> 5627947 | I7: =H7/$B$45 -> 0.043208607 | M7: 삼겹살 | N7: =SUM('30'!C15) -> 575
A8: 포스 | C8: 154000 | D8: =C8 -> 154000 | E8: =D8/$B$45 -> 0.0011823362 | G8: 주류 | H8: =SUM('1:30'!I7) -> 4510050 | I8: =H8/$B$45 -> 0.034625944 | M8: 목살 | N8: =SUM('30'!C13) -> 251
A9: 수도 | C9: 670000 | D9: =C9 -> 670000 | E9: =D9/$B$45 -> 0.0051439302 | G9: 쌀 | H9: =SUM('1:30'!I8) -> 710000 | I9: =H9/$B$45 -> 0.0054510306 | M9: 육회 | N9: =SUM('30'!C17) -> 130
A10: 화재보험 | C10: 66000 | D10: =C10 -> 66000 | E10: =D10/$B$45 -> 0.00050671552 | G10: 참기름 | H10: =SUM('1:30'!I11) -> 200000 | I10: =H10/$B$45 -> 0.0015355016 | M10: LA갈비 | N10: =SUM('30'!F13) -> 166
A11: 세무사 | C11: 330000 | D11: =C11 -> 330000 | E11: =D11/$B$45 -> 0.0025335776 | G11: 부탄가스 | H11: =SUM('1:30'!I12) -> 53400 | I11: =H11/$B$45 -> 0.00040997892 | M11: 돼지양념갈비 | N11: =SUM('30'!F15) -> 248
A12: 인터넷 | C12: 48000 | D12: =C12 -> 48000 | E12: =D12/$B$45 -> 0.00036852038 | G12: 코카콜라 | H12: =SUM('1:30'!I13) -> 480000 | I12: =H12/$B$45 -> 0.0036852038 | M12: 한우업진살 | N12: =SUM('30'!F17) -> 317
A13: 쿠쿠(블루문) | C13: 66000 | D13: =C13 -> 66000 | E13: =D13/$B$45 -> 0.00050671552 | G13: 깍두기,계란 | H13: =SUM('1:Chart1'!I14) -> 0 | I13: =H13/$B$45 -> 0 | M13: 소갈비살 | N13: =SUM('30'!C19) -> 286
D14: =C14 -> 0 | E14: =D14/$B$45 -> 0 | G14: 막걸리 | H14: =SUM('1:30'!I17) -> 9600 | I14: =H14/$B$45 -> 7.3704075e-05 | M14: LA양념갈비 | N14: =SUM('30'!F19) -> 110
D15: =C15 -> 0 | E15: =D15/$B$45 -> 0 | G15: 식자재2 | H15: =SUM('1:30'!I15) -> 4124750 | I15: =H15/$B$45 -> 0.0316678 | M15: 9월 테이블수 | N15: =SUM('30'!F21) -> 1638
A16: 전기세 | D16: =C16 -> 0 | E16: =D16/$B$45 -> 0
A17: 가스비 | C17: 1177000 | D17: =C17 -> 1177000 | E17: =D17/$B$45 -> 0.0090364267
A18: 소 계 | C18: =SUM(D6:D17) -> 12096000 | E18: =SUM(E6:E17) -> 0.092867135
A19: 급여 | B19: 직원A | C19: 4000000 | D19: =SUM(C19:C30) -> 23838250 | E19: =D19/$B$45 -> 0.18301835 | F19: 비품 및 기타경비 | G19: 숯 | H19: =SUM('1:30'!K4) -> 1129000 | I19: =H19/$B$45 -> 0.0086679063 | J19: =SUM(H19:H32) -> 2776020 | K19: =J19/$B$45 -> 0.021312915
B20: 직원B | C20: 3800000 | G20: 음식물스티커 | H20: =SUM('1:30'!K6) -> 84000 | I20: =H20/$B$45 -> 0.00064491066
B21: 직원C | C21: 3500000 | G21: 종량재봉투 | H21: =SUM('1:30'!K7) -> 25000 | I21: =H21/$B$45 -> 0.0001919377
B22: 직원D | C22: 3200000 | G22: 뚝배기 | H22: =SUM('1:30'!K9) -> 0 | I22: =H22/$B$45 -> 0
G23: 발매트 | H23: =SUM('1:30'!K10) -> 52000 | I23: =H23/$B$45 -> 0.00039923041
B24: 직원F | C24: 1500000 | G24: 불판세척 | H24: =SUM('1:Chart1'!K11) -> 0 | I24: =H24/$B$45 -> 0
B25: 알바A | C25: =SUM('1:Chart1'!C32) -> 0 | G25: 비품 및 기타경비 | H25: =SUM('1:30'!K15) -> 7000 | I25: =H25/$B$45 -> 5.3742555e-05
B26: 알바B | C26: =SUM('1:30'!C33) -> 1105000 | G26: 인터넷 주문 | H26: =SUM('1:30'!K16) -> 1371080 | I26: =H26/$B$45 -> 0.010526477
B27: 알바C | C27: =SUM('1:30'!F27) -> 1254500 | G27: 다이소 구매 | H27: =SUM('1:30'!K17) -> 107940 | I27: =H27/$B$45 -> 0.00082871019
B28: 알바X | C28: =SUM('1:30'!F29) -> 672750
B29: 홀 파출 | C29: =SUM('1:30'!F32) -> 1046000
B30: 파출 | C30: =SUM('1:30'!F31) -> 3760000
B31: 합계 | C31: =SUM(C19:C30) -> 23838250
A32: 퇴직금(10%) | C32: =SUM(C19:C22)*0.1 -> 1450000 | D32: =C32 -> 1450000 | E32: =(D32:D33)/$B$45 -> 0.011132386
A33: 4대보험료 | D33: =C33 -> 0 | F33: 현금수수료 (1%) | H33: =SUM('1:Chart1'!$G$5) -> 145980 | J33: =H33 -> 145980 | K33: =J33/$B$45 -> 0.0011207626
A34: 소 계 | C34: =SUM(C6:D17,C19:C24,C32:C33) -> 41642000 | E34: =SUM(E19:E33) -> 0.19415074 | F34: 카드수수료(2.75%) | H34: =SUM('1:Chart1'!$G$4) -> 3180432.2 | J34: =H34 -> 3180432.2 | K34: =J34/$B$45 -> 0.024417793
A35: 합 계 | E35: =E18+E34 -> 0.28701787 | H35: =SUM(J6:J34) -> 54376605 | K35: =SUM(K6:K34) -> 0.41747681
A38: 항목 | B38: 금액 | C38: 항목 비율 | D38: 매출 비율 | F38: 손익분기점
A39: 고정비용 | B39: =$C$34 -> 41642000 | C39: =B39/$B$41 -> 0.43368678 | D39: =B39/$B$45 -> 0.31970678 | F39: 손익분기점 매출액 X
A40: 변동비용 | B40: =$H$35 -> 54376605 | C40: =B40/$B$41 -> 0.56631322 | D40: =B40/$B$45 -> 0.41747681 | F40: 고정비 | H40: F | K40: =$C$34 -> 41642000
A41: 총비용 | B41: =SUM(B39:B40) -> 96018605 | C41: =SUM(C39:C40) -> 1 | D41: =SUM(D39:D40) -> 0.73718359 | F41: 변동비 | H41: V | K41: =$H$35 -> 54376605
A42: 카드매출 | B42: =SUM('1:Chart1'!C4) -> 115652600 | D42: =B42/$B$45 -> 0.88792374 | F42: 매출액 | H42: S | K42: =$B$45 -> 130250600
A43: 현금매출 | B43: =SUM('1:Chart1'!C5) -> 14598000 | D43: =B43/$B$45 -> 0.11207626 | F43: 변동비율 | H43: V/S | K43: =(K41)/K42 -> 0.41747681
A44: 페이매출 | B44: =SUM('1:Chart1'!C6) -> 0 | D44: =B44/$B$45 -> 0 | F44: 손익분기점 매출액 | H44: X=F/(1-(V/S)) | K44: =K40/(1-K43) -> 71485566
...

Sheet 1
C1: 2025년 | E1: 9월 | F1: 1 | G1: 월 | H1: 실영업일수 | I1: =F1-K1 -> 1 | J1: 휴무일수
A2: 매출 | C2: =SUM(C4:D7) -> 2966000 | E2: 시재 | G2: 88900 | H2: 식자재 | J2: 비품 및 기타경비
H3: 업체 | I3: 금액 | J3: 업체 | K3: 금액
A4: 카드 | C4: 2626500 | E4: 카드수수료(2.75%) | G4: =INT(C4*0.0275) -> 72228 | H4: 고기 | I4: 1423918 | J4: 숯
A5: 현금 | C5: 339500 | E5: 현금수수료(1%) | G5: =INT(C5*0.01) -> 3395 | H5: 식자재 | I5: 298336
A6: 페이결제 | E6: 통장입금 | G6: 300000 | J6: 음식물스티커
H7: 주류 | I7: 141400 | J7: 종량제봉투
A8: 금고 실잔액 | C8: 128900 | E8: 마감잔금 | G8: 128400 | H8: 쌀
J9: 뚝배기
A10: 현금할인 | E10: 카드할인 | J10: 발매트 | K10: 13000
A11: 할인내역 | H11: 참기름 | J11: 불판세척
A12: 개수 | B12: 목살 | C12: 9 | D12: LA갈비 | F12: 1 | H12: 부탄가스
A13: 매출누계 | C13: =SUM('1'!$C$12) -> 9 | F13: =SUM('1'!$F$12) -> 1 | H13: 코카콜라음료 | I13: 240000
A14: 개수 | B14: 삼겹살 | C14: 18 | D14: 돼지양념갈비 | F14: 6 | H14: 깍두기,계란
A15: 매출누계 | C15: =SUM('1'!$C$14) -> 18 | F15: =SUM('1'!$F$14) -> 6 | H15: 식자재2 | I15: 124850 | J15: 비품 및 기타경비
A16: 개수 | B16: 육회 | C16: 3 | D16: 한우업진살 | F16: 7 | J16: 인터넷 주문
A17: 매출누계 | C17: =SUM('1'!$C$16) -> 3 | F17: =SUM('1'!$F$16) -> 7 | H17: 막걸리 | I17: 1600 | J17: 다이소 구매
A18: 개수 | B18: 소갈비살 | C18: 9 | D18: LA양념갈비 | F18: 1
A19: 매출누계 | C19: =SUM('1'!$C$18) -> 9 | F19: =SUM('1'!$F$18) -> 1
A20: 개수 | B20: 오겹살 | C20: 8 | D20: 테이블수 | F20: 56
A21: 매출누계 | C21: =SUM('1'!$C$20) -> 8 | D21: 누적테이블 | F21: =SUM('1'!$F$20) -> 56
A22: 중간출금
A23: 출금내역 | H23: 식자재합계 | I23: =SUM(I4:I22) -> 2230104 | J23: 기타경비합계 | K23: =SUM(K4:K22) -> 13000 | M23: 현금합계 | N23: =C5+C6 -> 339500
A24: 일매출 | C24: 일평균매출 | E24: 누적총매출 | H24: 일매출 | I24: =I23/A25 -> 0.75188941 | J24: 일매출 | K24: =K23/A25 -> 0.0043830074
A25: =C2 -> 2966000 | C25: =E25/I1 -> 2966000 | E25: =SUM('1'!$A$25) -> 2966000 | H25: 누계 | I25: =SUM('1'!$I$23) -> 2230104 | J25: 누계 | K25: =SUM('1'!$K$23) -> 13000
A26: 전 월 | H26: 누적매출 | I26: =I25/$E$25 -> 0.75188941 | J26: 누적매출 | K26: =K25/$E$25 -> 0.0043830074
A27: 인 건 비 | B27: 직원A | C27: =4000000/30 -> 133333.33 | E27: 알바C | F27: =13000*4 -> 52000 | H27: 인건비합계 | I27: =SUM(C27:D34,F27:G32) -> 705333.33
B28: 직원B | C28: =3800000/30 -> 126666.67 | E28: 직원F | F28: =1500000/30 -> 50000 | H28: 일매출 | I28: =I27/$A$25 -> 0.23780625
B29: 직원D | C29: =3200000/30 -> 106666.67 | E29: 알바X | H29: 누계 | I29: =SUM('1'!$I$27) -> 705333.33
H30: 누적매출 | I30: =I29/$I$27 -> 1
B31: 직원C | C31: =3500000/30 -> 116666.67 | E31: 파출 | F31: 120000
E32: 홀 파출
B33: 알바B

Sheet 2
C1: 2025년 | E1: 9월 | F1: 2 | G1: 화 | H1: 실영업일수 | I1: =F1-K1 -> 2 | J1: 휴무일수
A2: 매출 | C2: =SUM(C4:D7) -> 4247500 | E2: 시재 | G2: 128900 | H2: 식자재 | J2: 비품 및 기타경비
H3: 업체 | I3: 금액 | J3: 업체 | K3: 금액
A4: 카드 | C4: 3787500 | E4: 카드수수료(2.75%) | G4: =INT(C4*0.0275) -> 104156 | H4: 고기 | I4: 1185955 | J4: 숯
A5: 현금 | C5: 460000 | E5: 현금수수료(1%) | G5: =INT(C5*0.01) -> 4600 | H5: 식자재 | I5: 119500
A6: 페이결제 | E6: 통장입금 | G6: 470000 | J6: 음식물스티커
H7: 주류 | J7: 종량제봉투
A8: 금고 실잔액 | C8: 118900 | E8: 마감잔금 | G8: =C5+G2-G6-C22 -> 118900 | H8: 쌀 | I8: 64000
J9: 뚝배기
A10: 현금할인 | E10: 카드할인 | J10: 발매트
A11: 할인내역 | H11: 참기름 | I11: 100000 | J11: 불판세척
A12: 개수 | B12: 목살 | C12: 15 | D12: LA갈비 | F12: 6 | H12: 부탄가스
A13: 매출누계 | C13: =SUM('1:2'!$C$12) -> 24 | F13: =SUM('1:2'!$F$12) -> 7 | H13: 코카콜라음료
A14: 개수 | B14: 삼겹살 | C14: 6 | D14: 돼지양념갈비 | F14: 5 | H14: 깍두기,계란
A15: 매출누계 | C15: =SUM('1:2'!$C$14) -> 24 | F15: =SUM('1:2'!$F$14) -> 11 | H15: 식자재2 | I15: 111400 | J15: 비품 및 기타경비
A16: 개수 | B16: 육회 | C16: 3 | D16: 한우업진살 | F16: 8 | J16: 인터넷 주문
A17: 매출누계 | C17: =SUM('1:2'!$C$16) -> 6 | F17: =SUM('1:2'!$F$16) -> 15 | H17: 막걸리 | J17: 다이소 구매
A18: 개수 | B18: 소갈비살 | C18: 11 | D18: LA양념갈비 | F18: 2
A19: 매출누계 | C19: =SUM('1:2'!$C$18) -> 20 | F19: =SUM('1:2'!$F$18) -> 3
B20: 오겹살 | D20: 테이블수 | F20: 65
D21: 누적테이블 | F21: =SUM('1:2'!$F$20) -> 121
A22: 중간출금
A23: 출금내역 | H23: 식자재합계 | I23: =SUM(I4:I22) -> 1580855 | J23: 기타경비합계 | K23: =SUM(K4:K22) -> 0 | M23: 현금합계 | N23: =C5+C6 -> 460000
A24: 일매출 | C24: 일평균매출 | E24: 누적총매출 | H24: 일매출 | I24: =I23/A25 -> 0.37218481 | J24: 일매출 | K24: =K23/A25 -> 0
A25: =C2 -> 4247500 | C25: =E25/I1 -> 1483000 | E25: =SUM('1'!$A$25) -> 2966000 | H25: 누계 | I25: =SUM('1'!$I$23) -> 2230104 | J25: 누계 | K25: =SUM('1'!$K$23) -> 13000
A26: 전 월 | H26: 누적매출 | I26: =I25/$E$25 -> 0.75188941 | J26: 누적매출 | K26: =K25/$E$25 -> 0.0043830074
A27: 인 건 비 | B27: 직원A | C27: =4000000/30 -> 133333.33 | E27: 알바C | F27: =13000*5 -> 65000 | H27: 인건비합계 | I27: =SUM(C27:D34,F27:G32) -> 822983.33
B28: 직원B | C28: =3800000/30 -> 126666.67 | E28: 직원F | F28: =1500000/30 -> 50000 | H28: 일매출 | I28: =I27/$A$25 -> 0.19375711
B29: 직원D | C29: =3200000/30 -> 106666.67 | E29: 알바X | F29: 52650 | H29: 누계 | I29: =SUM('1:2'!$I$27) -> 1528316.7
H30: 누적매출 | I30: =I29/$I$27 -> 1.8570445
B31: 직원C | C31: =3500000/30 -> 116666.67 | E31: 파출 | F31: 120000
E32: 홀 파출
B33: 알바B | C33: 52000

Sheet 3
C1: 2025년 | E1: 9월 | F1: 3 | G1: 수 | H1: 실영업일수 | I1: =F1-K1 -> 3 | J1: 휴무일수
A2: 매출 | C2: =SUM(C4:D7) -> 3539000 | E2: 시재 | G2: 118900 | H2: 식자재 | J2: 비품 및 기타경비
H3: 업체 | I3: 금액 | J3: 업체 | K3: 금액
A4: 카드 | C4: 3069500 | E4: 카드수수료(2.75%) | G4: =C4*0.0275 -> 84411.25 | H4: 고기 | I4: 623031 | J4: 숯 | K4: 183000
A5: 현금 | C5: 469500 | E5: 현금수수료(1%) | G5: =INT(C5*0.01) -> 4695 | H5: 식자재 | I5: 101340
A6: 페이결제 | E6: 통장입금 | G6: 500000 | J6: 음식물스티커
H7: 주류 | I7: 334100 | J7: 종량제봉투
A8: 금고 실잔액 | C8: 88400 | E8: 마감잔금 | G8: =C5+G2-G6-C22 -> 88400 | H8: 쌀
J9: 뚝배기
A10: 현금할인 | E10: 카드할인 | J10: 발매트
A11: 할인내역 | H11: 참기름 | J11: 불판세척
A12: 개수 | B12: 목살 | C12: 8 | D12: LA갈비 | F12: 4 | H12: 부탄가스
A13: 매출누계 | C13: =SUM('1:3'!$C$12) -> 32 | F13: =SUM('1:3'!$F$12) -> 11 | H13: 코카콜라음료
A14: 개수 | B14: 삼겹살 | C14: 22 | D14: 돼지양념갈비 | F14: 11 | H14: 깍두기,계란
A15: 매출누계 | C15: =SUM('1:3'!$C$14) -> 46 | F15: =SUM('1:3'!$F$14) -> 22 | H15: 식자재2 | J15: 비품 및 기타경비
A16: 개수 | B16: 육회 | C16: 1 | D16: 한우업진살 | F16: 8 | J16: 인터넷 주문
A17: 매출누계 | C17: =SUM('1:3'!$C$16) -> 7 | F17: =SUM('1:3'!$F$16) -> 23 | H17: 막걸리 | J17: 다이소 구매
A18: 개수 | B18: 소갈비살 | C18: 6 | D18: LA양념갈비 | F18: 0
A19: 매출누계 | C19: =SUM('1:3'!$C$18) -> 26 | F19: =SUM('1:3'!$F$18) -> 3
B20: 오겹살 | D20: 테이블수 | F20: 53
D21: 누적테이블 | F21: =SUM('1:3'!$F$20) -> 174
A22: 중간출금
A23: 출금내역 | H23: 식자재합계 | I23: =SUM(I4:I22) -> 1058471 | J23: 기타경비합계 | K23: =SUM(K4:K22) -> 183000 | M23: 현금합계 | N23: =C5+C6 -> 469500
A24: 일매출 | C24: 일평균매출 | E24: 누적총매출 | H24: 일매출 | I24: =I23/A25 -> 0.2990876 | J24: 일매출 | K24: =K23/A25 -> 0.051709522
A25: =C2 -> 3539000 | C25: =E25/I1 -> 3584166.7 | E25: =SUM('1:3'!$A$25) -> 10752500 | H25: 누계 | I25: =SUM('1'!$I$23) -> 2230104 | J25: 누계 | K25: =SUM('1:3'!$K$23) -> 196000
A26: 전 월 | H26: 누적매출 | I26: =I25/$E$25 -> 0.2074033 | J26: 누적매출 | K26: =K25/$E$25 -> 0.018228319
A27: 인 건 비 | B27: 직원A | C27: =4000000/30 -> 133333.33 | E27: 알바C | F27: =13000*4.5 -> 58500 | H27: 인건비합계 | I27: =SUM(C27:D34,F27:G32) -> 810633.33
B28: 직원B | C28: =3800000/30 -> 126666.67 | E28: 직원F | F28: =1500000/30 -> 50000 | H28: 일매출 | I28: =I27/$A$25 -> 0.22905717
B29: 직원D | C29: =3200000/30 -> 106666.67 | E29: 알바X | F29: 46800 | H29: 누계 | I29: =SUM('1:3'!$I$27) -> 2338950
H30: 누적매출 | I30: =I29/$I$27 -> 2.8853366
B31: 직원C | C31: =3500000/30 -> 116666.67 | E31: 파출 | F31: 120000
E32: 홀 파출
B33: 알바B | C33: 52000

Sheet 4
C1: 2025년 | E1: 9월 | F1: 4 | G1: 목 | H1: 실영업일수 | I1: =F1-K1 -> 4 | J1: 휴무일수
A2: 매출 | C2: =SUM(C4:D7) -> 4157500 | E2: 시재 | G2: 88400 | H2: 식자재 | J2: 비품 및 기타경비
H3: 업체 | I3: 금액 | J3: 업체 | K3: 금액
A4: 카드 | C4: 3802500 | E4: 카드수수료(2.75%) | G4: =INT(C4*0.0275) -> 104568 | H4: 고기 | I4: 507896 | J4: 숯
A5: 현금 | C5: 355000 | E5: 현금수수료(1%) | G5: =INT(C5*0.01) -> 3550 | H5: 식자재 | I5: 225460
A6: 페이결제 | E6: 통장입금 | G6: 360000 | J6: 음식물스티커
H7: 주류 | I7: 68600 | J7: 종량제봉투
A8: 금고 실잔액 | C8: 83400 | E8: 마감잔금 | G8: =C5+G2-G6-C22 -> 83400 | H8: 쌀 | I8: 64000
J9: 뚝배기
A10: 현금할인 | C10: 99000 | E10: 카드할인 | J10: 발매트
A11: 할인내역 | H11: 참기름 | J11: 불판세척
A12: 개수 | B12: 목살 | C12: 3 | D12: LA갈비 | F12: 7 | H12: 부탄가스
A13: 매출누계 | C13: =SUM('1:4'!$C$12) -> 35 | F13: =SUM('1:4'!$F$12) -> 18 | H13: 코카콜라음료
A14: 개수 | B14: 삼겹살 | C14: 11 | D14: 돼지양념갈비 | F14: 12 | H14: 깍두기,계란
A15: 매출누계 | C15: =SUM('1:4'!$C$14) -> 57 | F15: =SUM('1:4'!$F$14) -> 34 | H15: 식자재2 | I15: 87500 | J15: 비품 및 기타경비
A16: 개수 | B16: 육회 | C16: 3 | D16: 한우업진살 | F16: 12 | J16: 인터넷 주문 | K16: 140150
A17: 매출누계 | C17: =SUM('1:4'!$C$16) -> 10 | F17: =SUM('1:4'!$F$16) -> 35 | H17: 막걸리 | J17: 다이소 구매
A18: 개수 | B18: 소갈비살 | C18: 4 | D18: LA양념갈비 | F18: 1
A19: 매출누계 | C19: =SUM('1:4'!$C$18) -> 30 | F19: =SUM('1:4'!$F$18) -> 4
B20: 오겹살 | D20: 테이블수 | F20: 66
D21: 누적테이블 | F21: =SUM('1:4'!$F$20) -> 240
A22: 중간출금
A23: 출금내역 | H23: 식자재합계 | I23: =SUM(I4:I22) -> 953456 | J23: 기타경비합계 | K23: =SUM(K4:K22) -> 140150 | M23: 현금합계 | N23: =C5+C6 -> 355000
A24: 일매출 | C24: 일평균매출 | E24: 누적총매출 | H24: 일매출 | I24: =I23/A25 -> 0.22933397 | J24: 일매출 | K24: =K23/A25 -> 0.033710162
A25: =C2 -> 4157500 | C25: =E25/I1 -> 3727500 | E25: =SUM('1:4'!$A$25) -> 14910000 | H25: 누계 | I25: =SUM('1'!$I$23) -> 2230104 | J25: 누계 | K25: =SUM('1:4'!$K$23) -> 336150
A26: 전 월 | H26: 누적매출 | I26: =I25/$E$25 -> 0.14957103 | J26: 누적매출 | K26: =K25/$E$25 -> 0.022545272
A27: 인 건 비 | B27: 직원A | C27: =4000000/30 -> 133333.33 | E27: 알바C | H27: 인건비합계 | I27: =SUM(C27:D34,F27:G32) -> 769983.33
B28: 직원B | C28: =3800000/30 -> 126666.67 | E28: 직원F | F28: =1500000/30 -> 50000 | H28: 일매출 | I28: =I27/$A$25 -> 0.18520345
B29: 직원D | C29: =3200000/30 -> 106666.67 | E29: 알바X | F29: 52650 | H29: 누계 | I29: =SUM('1:4'!$I$27) -> 3108933.3
H30: 누적매출 | I30: =I29/$I$27 -> 4.0376632
B31: 직원C | C31: =3500000/30 -> 116666.67 | E31: 파출 | F31: 132000
E32: 홀 파출
B33: 알바B | C33: 52000

Sheet 5
C1: 2025년 | E1: 9월 | F1: 5 | G1: 금 | H1: 실영업일수 | I1: =F1-K1 -> 5 | J1: 휴무일수
A2: 매출 | C2: =SUM(C4:D7) -> 4649500 | E2: 시재 | G2: 83400 | H2: 식자재 | J2: 비품 및 기타경비
H3: 업체 | I3: 금액 | J3: 업체 | K3: 금액
A4: 카드 | C4: 4023000 | E4: 카드수수료(2.75%) | G4: =INT(C4*0.0275) -> 110632 | H4: 고기 | I4: 495356 | J4: 숯
A5: 현금 | C5: 626500 | E5: 현금수수료(1%) | G5: =INT(C5*0.01) -> 6265 | H5: 식자재 | I5: 268581
A6: 페이결제 | E6: 통장입금 | G6: 571000 | J6: 음식물스티커
H7: 주류 | I7: 204300 | J7: 종량제봉투
A8: 금고 실잔액 | C8: 138900 | E8: 마감잔금 | G8: =C5+G2-G6 -> 138900 | H8: 쌀 | I8: 64000
J9: 뚝배기
A10: 현금할인 | E10: 카드할인 | J10: 발매트
A11: 할인내역 | H11: 참기름 | J11: 불판세척
A12: 개수 | B12: 목살 | C12: 6 | D12: LA갈비 | F12: 4 | H12: 부탄가스
A13: 매출누계 | C13: =SUM('1:5'!$C$12) -> 41 | F13: =SUM('1:5'!$F$12) -> 22 | H13: 코카콜라음료
A14: 개수 | B14: 삼겹살 | C14: 18 | D14: 돼지양념갈비 | F14: 3 | H14: 깍두기,계란
A15: 매출누계 | C15: =SUM('1:5'!$C$14) -> 75 | F15: =SUM('1:5'!$F$14) -> 37 | H15: 식자재2 | I15: 95900 | J15: 비품 및 기타경비
A16: 개수 | B16: 육회 | C16: 3 | D16: 한우업진살 | F16: 13 | J16: 인터넷 주문 | K16: 88330
A17: 매출누계 | C17: =SUM('1:5'!$C$16) -> 13 | F17: =SUM('1:5'!$F$16) -> 48 | H17: 막걸리 | J17: 다이소 구매
A18: 개수 | B18: 소갈비살 | C18: 17 | D18: LA양념갈비 | F18: 6
A19: 매출누계 | C19: =SUM('1:5'!$C$18) -> 47 | F19: =SUM('1:5'!$F$18) -> 10
B20: 오겹살 | D20: 테이블수 | F20: 59
D21: 누적테이블 | F21: =SUM('1:5'!$F$20) -> 299
A22: 중간출금
A23: 출금내역 | H23: 식자재합계 | I23: =SUM(I4:I22) -> 1128137 | J23: 기타경비합계 | K23: =SUM(K4:K22) -> 88330 | M23: 현금합계 | N23: =C5+C6 -> 626500
A24: 일매출 | C24: 일평균매출 | E24: 누적총매출 | H24: 일매출 | I24: =I23/A25 -> 0.2426362 | J24: 일매출 | K24: =K23/A25 -> 0.018997742
A25: =C2 -> 4649500 | C25: =E25/I1 -> 3911900 | E25: =SUM('1:5'!$A$25) -> 19559500 | H25: 누계 | I25: =SUM('1'!$I$23) -> 2230104 | J25: 누계 | K25: =SUM('1:5'!$K$23) -> 424480
A26: 전 월 | H26: 누적매출 | I26: =I25/$E$25 -> 0.11401641 | J26: 누적매출 | K26: =K25/$E$25 -> 0.021701986
A27: 인 건 비 | B27: 직원A | C27: =4000000/30 -> 133333.33 | E27: 알바C | F27: =13000*5 -> 65000 | H27: 인건비합계 | I27: =SUM(C27:D34,F27:G32) -> 770983.33
B28: 직원B | C28: =3800000/30 -> 126666.67 | E28: 직원F | F28: =1500000/30 -> 50000 | H28: 일매출 | I28: =I27/$A$25 -> 0.1658207
B29: 직원D | C29: =3200000/30 -> 106666.67 | E29: 알바X | F29: 52650 | H29: 누계 | I29: =SUM('1:5'!$I$27) -> 3879916.7
H30: 누적매출 | I30: =I29/$I$27 -> 5.0324261
B31: 직원C | C31: =3500000/30 -> 116666.67 | E31: 파출 | F31: 120000
E32: 홀 파출
B33: 알바B

Sheet 6
C1: 2025년 | E1: 9월 | F1: 6 | G1: 토 | H1: 실영업일수 | I1: =F1-K1 -> 6 | J1: 휴무일수
A2: 매출 | C2: =SUM(C4:D7) -> 4226000 | E2: 시재 | G2: 138900 | H2: 식자재 | J2: 비품 및 기타경비
H3: 업체 | I3: 금액 | J3: 업체 | K3: 금액
A4: 카드 | C4: 3836000 | E4: 카드수수료(2.75%) | G4: =INT(C4*0.0275) -> 105490 | H4: 고기 | I4: 221000 | J4: 숯
A5: 현금 | C5: 390000 | E5: 현금수수료(1%) | G5: =INT(C5*0.01) -> 3900 | H5: 식자재
A6: 페이결제 | E6: 통장입금 | G6: 442000 | J6: 음식물스티커
H7: 주류 | J7: 종량제봉투
A8: 금고 실잔액 | C8: 86900 | E8: 마감잔금 | G8: =C5+G2-G6-C22 -> 86900 | H8: 쌀
J9: 뚝배기
A10: 현금할인 | C10: 142000 | E10: 카드할인 | J10: 발매트
A11: 할인내역 | H11: 참기름 | J11: 불판세척
A12: 개수 | B12: 목살 | C12: 4 | D12: LA갈비 | F12: 4 | H12: 부탄가스
A13: 매출누계 | C13: =SUM('1:6'!$C$12) -> 45 | F13: =SUM('1:6'!$F$12) -> 26 | H13: 코카콜라음료
A14: 개수 | B14: 삼겹살 | C14: 31 | D14: 돼지양념갈비 | F14: 23 | H14: 깍두기,계란
A15: 매출누계 | C15: =SUM('1:6'!$C$14) -> 106 | F15: =SUM('1:6'!$F$14) -> 60 | H15: 식자재2 | I15: 283150 | J15: 비품 및 기타경비
A16: 개수 | B16: 육회 | C16: 5 | D16: 한우업진살 | F16: 22 | J16: 인터넷 주문
A17: 매출누계 | C17: =SUM('1:6'!$C$16) -> 18 | F17: =SUM('1:6'!$F$16) -> 70 | H17: 막걸리 | J17: 다이소 구매
A18: 개수 | B18: 소갈비살 | C18: 8 | D18: LA양념갈비 | F18: 3
A19: 매출누계 | C19: =SUM('1:6'!$C$18) -> 55 | F19: =SUM('1:6'!$F$18) -> 13
B20: 오겹살 | D20: 테이블수 | F20: 55
D21: 누적테이블 | F21: =SUM('1:6'!$F$20) -> 354
A22: 중간출금
A23: 출금내역 | H23: 식자재합계 | I23: =SUM(I4:I22) -> 504150 | J23: 기타경비합계 | K23: =SUM(K4:K22) -> 0 | M23: 현금합계 | N23: =C5+C6 -> 390000
A24: 일매출 | C24: 일평균매출 | E24: 누적총매출 | H24: 일매출 | I24: =I23/A25 -> 0.11929721 | J24: 일매출 | K24: =K23/A25 -> 0
A25: =C2 -> 4226000 | C25: =E25/I1 -> 3964250 | E25: =SUM('1:6'!$A$25) -> 23785500 | H25: 누계 | I25: =SUM('1'!$I$23) -> 2230104 | J25: 누계 | K25: =SUM('1:6'!$K$23) -> 424480
A26: 전 월 | H26: 누적매출 | I26: =I25/$E$25 -> 0.093758971 | J26: 누적매출 | K26: =K25/$E$25 -> 0.017846167
A27: 인 건 비 | B27: 직원A | C27: =4000000/30 -> 133333.33 | E27: 알바C | H27: 인건비합계 | I27: =SUM(C27:D34,F27:G32) -> 805333.33
B28: 직원B | C28: =3800000/30 -> 126666.67 | E28: 직원F | F28: =1500000/30 -> 50000 | H28: 일매출 | I28: =I27/$A$25 -> 0.19056634
B29: 직원D | C29: =3200000/30 -> 106666.67 | E29: 알바X | H29: 누계 | I29: =SUM('1:6'!$I$27) -> 4685250
H30: 누적매출 | I30: =I29/$I$27 -> 5.8177773
B31: 직원C | C31: =3500000/30 -> 116666.67 | E31: 파출 | F31: 130000
E32: 홀 파출 | F32: 142000
B33: 알바B

Sheet 7
C1: 2025년 | E1: 9월 | F1: 7 | G1: 일 | H1: 실영업일수 | I1: =F1-K1 -> 7 | J1: 휴무일수
A2: 매출 | C2: =SUM(C4:D7) -> 5719000 | E2: 시재 | G2: 86900 | H2: 식자재 | J2: 비품 및 기타경비
H3: 업체 | I3: 금액 | J3: 업체 | K3: 금액
A4: 카드 | C4: 4733000 | E4: 카드수수료(2.75%) | G4: =INT(C4*0.0275) -> 130157 | H4: 고기 | J4: 숯
A5: 현금 | C5: 986000 | E5: 현금수수료(1%) | G5: =INT(C5*0.01) -> 9860 | H5: 식자재
A6: 페이결제 | E6: 통장입금 | G6: 1000000 | J6: 음식물스티커
H7: 주류 | J7: 종량제봉투
A8: 금고 실잔액 | C8: 72900 | E8: 마감잔금 | G8: =C5+G2-G6-C22 -> 72900 | H8: 쌀
J9: 뚝배기
A10: 현금할인 | E10: 카드할인 | J10: 발매트
A11: 할인내역 | H11: 참기름 | J11: 불판세척
A12: 개수 | B12: 목살 | C12: 11 | D12: LA갈비 | F12: 5 | H12: 부탄가스
A13: 매출누계 | C13: =SUM('1:7'!$C$12) -> 56 | F13: =SUM('1:7'!$F$12) -> 31 | H13: 코카콜라음료
A14: 개수 | B14: 삼겹살 | C14: 52 | D14: 돼지양념갈비 | F14: 11 | H14: 깍두기,계란
A15: 매출누계 | C15: =SUM('1:7'!$C$14) -> 158 | F15: =SUM('1:7'!$F$14) -> 71 | H15: 식자재2 | J15: 비품 및 기타경비
A16: 개수 | B16: 육회 | C16: 6 | D16: 한우업진살 | F16: 11 | J16: 인터넷 주문
A17: 매출누계 | C17: =SUM('1:7'!$C$16) -> 24 | F17: =SUM('1:7'!$F$16) -> 81 | H17: 막걸리 | J17: 다이소 구매
A18: 개수 | B18: 소갈비살 | C18: 17 | D18: LA양념갈비 | F18: 9
A19: 매출누계 | C19: =SUM('1:7'!$C$18) -> 72 | F19: =SUM('1:7'!$F$18) -> 22
B20: 오겹살 | D20: 테이블수 | F20: 66
D21: 누적테이블 | F21: =SUM('1:7'!$F$20) -> 420
A22: 중간출금
A23: 출금내역 | H23: 식자재합계 | I23: =SUM(I4:I22) -> 0 | J23: 기타경비합계 | K23: =SUM(K4:K22) -> 0 | M23: 현금합계 | N23: =C5+C6 -> 986000
A24: 일매출 | C24: 일평균매출 | E24: 누적총매출 | H24: 일매출 | I24: =I23/A25 -> 0 | J24: 일매출 | K24: =K23/A25 -> 0
A25: =C2 -> 5719000 | C25: =E25/I1 -> 4214928.6 | E25: =SUM('1:7'!$A$25) -> 29504500 | H25: 누계 | I25: =SUM('1'!$I$23) -> 2230104 | J25: 누계 | K25: =SUM('1:7'!$K$23) -> 424480
A26: 전 월 | H26: 누적매출 | I26: =I25/$E$25 -> 0.075585216 | J26: 누적매출 | K26: =K25/$E$25 -> 0.014386958
A27: 인 건 비 | B27: 직원A | C27: =4000000/30 -> 133333.33 | E27: 알바C | H27: 인건비합계 | I27: =SUM(C27:D34,F27:G32) -> 792333.33
B28: 직원B | C28: =3800000/30 -> 126666.67 | E28: 직원F | F28: =1500000/30 -> 50000 | H28: 일매출 | I28: =I27/$A$25 -> 0.13854403
B29: 직원D | C29: =3200000/30 -> 106666.67 | E29: 알바X | H29: 누계 | I29: =SUM('1:7'!$I$27) -> 5477583.3
H30: 누적매출 | I30: =I29/$I$27 -> 6.913231
B31: 직원C | C31: =3500000/30 -> 116666.67 | E31: 파출 | F31: 130000
E32: 홀 파출 | F32: 77000
B33: 알바B | C33: 52000

Sheet 8
C1: 2025년 | E1: 9월 | F1: 8 | G1: 월 | H1: 실영업일수 | I1: =F1-K1 -> 8 | J1: 휴무일수
A2: 매출 | C2: =SUM(C4:D7) -> 3750500 | E2: 시재 | G2: 72900 | H2: 식자재 | J2: 비품 및 기타경비
H3: 업체 | I3: 금액 | J3: 업체 | K3: 금액
A4: 카드 | C4: 2928500 | E4: 카드수수료(2.75%) | G4: =INT(C4*0.0275) -> 80533 | H4: 고기 | I4: 1704682 | J4: 숯
A5: 현금 | C5: 822000 | E5: 현금수수료(1%) | G5: =INT(C5*0.01) -> 8220 | H5: 식자재 | I5: 392947
A6: 페이결제 | E6: 통장입금 | G6: 720000 | J6: 음식물스티커
H7: 주류 | I7: 228350 | J7: 종량제봉투
A8: 금고 실잔액 | C8: 174900 | E8: 마감잔금 | G8: =C5+G2-G6-C22 -> 174900 | H8: 쌀
J9: 뚝배기
A10: 현금할인 | E10: 카드할인 | J10: 발매트 | K10: 13000
A11: 할인내역 | H11: 참기름 | J11: 불판세척
A12: 개수 | B12: 목살 | C12: 7 | D12: LA갈비 | F12: 2 | H12: 부탄가스
A13: 매출누계 | C13: =SUM('1:8'!$C$12) -> 63 | F13: =SUM('1:8'!$F$12) -> 33 | H13: 코카콜라음료
A14: 개수 | B14: 삼겹살 | C14: 24 | D14: 돼지양념갈비 | F14: 7 | H14: 깍두기,계란
A15: 매출누계 | C15: =SUM('1:8'!$C$14) -> 182 | F15: =SUM('1:8'!$F$14) -> 78 | H15: 식자재2 | I15: 186200 | J15: 비품 및 기타경비
A16: 개수 | B16: 육회 | C16: 5 | D16: 한우업진살 | F16: 12 | J16: 인터넷 주문
A17: 매출누계 | C17: =SUM('1:8'!$C$16) -> 29 | F17: =SUM('1:8'!$F$16) -> 93 | H17: 막걸리 | J17: 다이소 구매
A18: 개수 | B18: 소갈비살 | C18: 5 | D18: LA양념갈비 | F18: 7
A19: 매출누계 | C19: =SUM('1:8'!$C$18) -> 77 | F19: =SUM('1:8'!$F$18) -> 29
B20: 오겹살 | D20: 테이블수 | F20: 51
D21: 누적테이블 | F21: =SUM('1:8'!$F$20) -> 471
A22: 중간출금
A23: 출금내역 | H23: 식자재합계 | I23: =SUM(I4:I22) -> 2512179 | J23: 기타경비합계 | K23: =SUM(K4:K22) -> 13000 | M23: 현금합계 | N23: =C5+C6 -> 822000
A24: 일매출 | C24: 일평균매출 | E24: 누적총매출 | H24: 일매출 | I24: =I23/A25 -> 0.66982509 | J24: 일매출 | K24: =K23/A25 -> 0.0034662045
A25: =C2 -> 3750500 | C25: =E25/I1 -> 4156875 | E25: =SUM('1:8'!$A$25) -> 33255000 | H25: 누계 | I25: =SUM('1'!$I$23) -> 2230104 | J25: 누계 | K25: =SUM('1:8'!$K$23) -> 437480
A26: 전 월 | H26: 누적매출 | I26: =I25/$E$25 -> 0.067060713 | J26: 누적매출 | K26: =K25/$E$25 -> 0.013155315
A27: 인 건 비 | B27: 직원A | C27: =4000000/30 -> 133333.33 | E27: 알바C | F27: =13000*5 -> 65000 | H27: 인건비합계 | I27: =SUM(C27:D34,F27:G32) -> 770333.33
B28: 직원B | C28: =3800000/30 -> 126666.67 | E28: 직원F | F28: =1500000/30 -> 50000 | H28: 일매출 | I28: =I27/$A$25 -> 0.20539484
B29: 직원D | C29: =3200000/30 -> 106666.67 | E29: 알바X | H29: 누계 | I29: =SUM('1:8'!$I$27) -> 6247916.7 | M29: `
H30: 누적매출 | I30: =I29/$I$27 -> 8.1106664
B31: 직원C | C31: =3500000/30 -> 116666.67 | E31: 파출 | F31: 120000
E32: 홀 파출
B33: 알바B | C33: =13000*4 -> 52000

Sheet 9
C1: 2025년 | E1: 9월 | F1: 9 | G1: 화 | H1: 실영업일수 | I1: =F1-K1 -> 9 | J1: 휴무일수
A2: 매출 | C2: =SUM(C4:D7) -> 3158000 | E2: 시재 | G2: 174900 | H2: 식자재 | J2: 비품 및 기타경비
H3: 업체 | I3: 금액 | J3: 업체 | K3: 금액
A4: 카드 | C4: 2613000 | E4: 카드수수료(2.75%) | G4: =INT(C4*0.0275) -> 71857 | H4: 고기 | I4: 3384837 | J4: 숯
A5: 현금 | C5: 545000 | E5: 현금수수료(1%) | G5: =INT(C5*0.01) -> 5450 | H5: 식자재 | I5: 184656
A6: 페이결제 | E6: 통장입금 | G6: 630000 | J6: 음식물스티커
H7: 주류 | I7: 294200 | J7: 종량제봉투
A8: 금고 실잔액 | C8: 89900 | E8: 마감잔금 | G8: =C5+G2-G6-C22 -> 89900 | H8: 쌀
J9: 뚝배기
A10: 현금할인 | E10: 카드할인 | J10: 발매트
A11: 할인내역 | H11: 참기름 | J11: 불판세척
A12: 개수 | B12: 목살 | C12: 6 | D12: LA갈비 | F12: 10 | H12: 부탄가스
A13: 매출누계 | C13: =SUM('1:9'!$C$12) -> 69 | F13: =SUM('1:9'!$F$12) -> 43 | H13: 코카콜라음료
A14: 개수 | B14: 삼겹살 | C14: 16 | D14: 돼지양념갈비 | F14: 6 | H14: 깍두기,계란
A15: 매출누계 | C15: =SUM('1:9'!$C$14) -> 198 | F15: =SUM('1:9'!$F$14) -> 84 | H15: 식자재2 | I15: 81100 | J15: 비품 및 기타경비
A16: 개수 | B16: 육회 | C16: 5 | D16: 한우업진살 | F16: 9 | J16: 인터넷 주문 | K16: 97000
A17: 매출누계 | C17: =SUM('1:9'!$C$16) -> 34 | F17: =SUM('1:9'!$F$16) -> 102 | H17: 막걸리 | J17: 다이소 구매
A18: 개수 | B18: 소갈비살 | C18: 1 | D18: LA양념갈비 | F18: 8
A19: 매출누계 | C19: =SUM('1:9'!$C$18) -> 78 | F19: =SUM('1:9'!$F$18) -> 37
B20: 오겹살 | D20: 테이블수 | F20: 55
D21: 누적테이블 | F21: =SUM('1:9'!$F$20) -> 526
A22: 중간출금
A23: 출금내역 | H23: 식자재합계 | I23: =SUM(I4:I22) -> 3944793 | J23: 기타경비합계 | K23: =SUM(K4:K22) -> 97000 | M23: 현금합계 | N23: =C5+C6 -> 545000
A24: 일매출 | C24: 일평균매출 | E24: 누적총매출 | H24: 일매출 | I24: =I23/A25 -> 1.2491428 | J24: 일매출 | K24: =K23/A25 -> 0.030715643
A25: =C2 -> 3158000 | C25: =E25/I1 -> 4045888.9 | E25: =SUM('1:9'!$A$25) -> 36413000 | H25: 누계 | I25: =SUM('1'!$I$23) -> 2230104 | J25: 누계 | K25: =SUM('1:9'!$K$23) -> 534480
A26: 전 월 | H26: 누적매출 | I26: =I25/$E$25 -> 0.06124472 | J26: 누적매출 | K26: =K25/$E$25 -> 0.014678274
A27: 인 건 비 | B27: 직원A | C27: =4000000/30 -> 133333.33 | E27: 알바C | F27: =13000*3.5 -> 45500 | H27: 인건비합계 | I27: =SUM(C27:D34,F27:G32) -> 785933.33
B28: 직원B | C28: =3800000/30 -> 126666.67 | E28: 직원F | F28: =1500000/30 -> 50000 | H28: 일매출 | I28: =I27/$A$25 -> 0.24887059
B29: 직원D | C29: =3200000/30 -> 106666.67 | E29: 알바X | F29: 35100 | H29: 누계 | I29: =SUM('1:9'!$I$27) -> 7033850
H30: 누적매출 | I30: =I29/$I$27 -> 8.9496777
B31: 직원C | C31: =3500000/30 -> 116666.67 | E31: 파출 | F31: 120000
E32: 홀 파출
B33: 알바B | C33: =13000*4 -> 52000

Sheet 10
C1: 2025년 | E1: 9월 | F1: 10 | G1: 수 | H1: 실영업일수 | I1: =F1-K1 -> 10 | J1: 휴무일수
A2: 매출 | C2: =SUM(C4:D7) -> 4417000 | E2: 시재 | G2: 89900 | H2: 식자재 | J2: 비품 및 기타경비
H3: 업체 | I3: 금액 | J3: 업체 | K3: 금액
A4: 카드 | C4: 3757500 | E4: 카드수수료(2.75%) | G4: =INT(C4*0.0275) -> 103331 | H4: 고기 | I4: 649150 | J4: 숯 | K4: 347000
A5: 현금 | C5: 659500 | E5: 현금수수료(1%) | G5: =INT(C5*0.01) -> 6595 | H5: 식자재 | I5: 138660
A6: 페이결제 | E6: 통장입금 | G6: 650000 | J6: 음식물스티커
H7: 주류 | J7: 종량제봉투 | K7: 12500
A8: 금고 실잔액 | C8: 99400 | E8: 마감잔금 | G8: =C5+G2-G6-C22 -> 99400 | H8: 쌀
J9: 뚝배기
A10: 현금할인 | C10: 56000 | E10: 카드할인 | J10: 발매트
A11: 할인내역 | H11: 참기름 | J11: 불판세척
A12: 개수 | B12: 목살 | C12: 8 | D12: LA갈비 | F12: 7 | H12: 부탄가스
A13: 매출누계 | C13: =SUM('1:10'!$C$12) -> 77 | F13: =SUM('1:10'!$F$12) -> 50 | H13: 코카콜라음료
A14: 개수 | B14: 삼겹살 | C14: 22 | D14: 돼지양념갈비 | F14: 8 | H14: 깍두기,계란
A15: 매출누계 | C15: =SUM('1:10'!$C$14) -> 220 | F15: =SUM('1:10'!$F$14) -> 92 | H15: 식자재2 | I15: 145800 | J15: 비품 및 기타경비
A16: 개수 | B16: 육회 | C16: 3 | D16: 한우업진살 | F16: 3 | J16: 인터넷 주문
A17: 매출누계 | C17: =SUM('1:10'!$C$16) -> 37 | F17: =F19 -> 38 | H17: 막걸리 | J17: 다이소 구매 | K17: 13000
A18: 개수 | B18: 소갈비살 | C18: 9 | D18: LA양념갈비 | F18: 1
A19: 매출누계 | C19: =SUM('1:10'!$C$18) -> 87 | F19: =SUM('1:10'!$F$18) -> 38
B20: 오겹살 | D20: 테이블수 | F20: 58
D21: 누적테이블 | F21: =SUM('1:10'!$F$20) -> 584
A22: 중간출금
A23: 출금내역 | H23: 식자재합계 | I23: =SUM(I4:I22) -> 933610 | J23: 기타경비합계 | K23: =SUM(K4:K22) -> 372500 | M23: 현금합계 | N23: =C5+C6 -> 659500
A24: 일매출 | C24: 일평균매출 | E24: 누적총매출 | H24: 일매출 | I24: =I23/A25 -> 0.21136744 | J24: 일매출 | K24: =K23/A25 -> 0.084333258
A25: =C2 -> 4417000 | C25: =E25/I1 -> 4083000 | E25: =SUM('1:10'!$A$25) -> 40830000 | H25: 누계 | I25: =SUM('1'!$I$23) -> 2230104 | J25: 누계 | K25: =SUM('1:10'!$K$21) -> 0
A26: 전 월 | H26: 누적매출 | I26: =I25/$E$25 -> 0.054619251 | J26: 누적매출 | K26: =K25/$E$25 -> 0
A27: 인 건 비 | B27: 직원A | C27: =4000000/30 -> 133333.33 | E27: 알바C | F27: =13000*5 -> 65000 | H27: 인건비합계 | I27: =SUM(C27:D34,F27:G32) -> 765133.33
B28: 직원B | C28: =3800000/30 -> 126666.67 | E28: 직원F | F28: =1500000/30 -> 50000 | H28: 일매출 | I28: =I27/$A$25 -> 0.17322466
B29: 직원D | C29: =3200000/30 -> 106666.67 | E29: 알바X | F29: 46800 | H29: 누계 | I29: =SUM('1:10'!$I$25) -> 22301040
H30: 누적매출 | I30: =I29/$I$27 -> 29.146606
B31: 직원C | C31: =3500000/30 -> 116666.67 | E31: 파출 | F31: 120000
E32: 홀 파출
B33: 알바B

Sheet 11
C1: 2025년 | E1: 9월 | F1: 11 | G1: 목 | H1: 실영업일수 | I1: =F1-K1 -> 11 | J1: 휴무일수
A2: 매출 | C2: =SUM(C4:D7) -> 4855500 | E2: 시재 | G2: 99400 | H2: 식자재 | J2: 비품 및 기타경비
H3: 업체 | I3: 금액 | J3: 업체 | K3: 금액
A4: 카드 | C4: 4449500 | E4: 카드수수료(2.75%) | G4: =INT(C4*0.0275) -> 122361 | H4: 고기 | I4: 2309651 | J4: 숯
A5: 현금 | C5: 406000 | E5: 현금수수료(1%) | G5: =INT(C5*0.01) -> 4060 | H5: 식자재 | I5: 352846
A6: 페이결제 | E6: 통장입금 | G6: 430000 | J6: 음식물스티커
H7: 주류 | I7: 377900 | J7: 종량제봉투
A8: 금고 실잔액 | C8: 75400 | E8: 마감잔금 | G8: =C5+G2-G6-C22 -> 75400 | H8: 쌀 | I8: 64000
J9: 뚝배기
A10: 현금할인 | E10: 카드할인 | J10: 발매트
A11: 할인내역 | H11: 참기름 | J11: 불판세척
A12: 개수 | B12: 목살 | C12: 5 | D12: LA갈비 | F12: 4 | H12: 부탄가스
A13: 매출누계 | C13: =SUM('1:11'!$C$12) -> 82 | F13: =SUM('1:11'!$F$12) -> 54 | H13: 코카콜라음료
A14: 개수 | B14: 삼겹살 | C14: 18 | D14: 돼지양념갈비 | F14: 10 | H14: 깍두기,계란 | M14: ㄴ
A15: 매출누계 | C15: =SUM('1:11'!$C$14) -> 238 | F15: =SUM('1:11'!$F$14) -> 102 | H15: 식자재2 | I15: 79000 | J15: 비품 및 기타경비
A16: 개수 | B16: 육회 | C16: 6 | D16: 한우업진살 | F16: 19 | J16: 인터넷 주문
A17: 매출누계 | C17: =SUM('1:11'!$C$16) -> 43 | F17: =SUM('1:11'!$F$16) -> 124 | H17: 막걸리 | J17: 다이소 구매 | K17: 94940
A18: 개수 | B18: 소갈비살 | C18: 17 | D18: LA양념갈비 | F18: 4
A19: 매출누계 | C19: =SUM('1:11'!$C$18) -> 104 | F19: =SUM('1:11'!$F$18) -> 42
B20: 오겹살 | D20: 테이블수 | F20: 61
D21: 누적테이블 | F21: =SUM('1:11'!$F$20) -> 645
A22: 중간출금
A23: 출금내역 | H23: 식자재합계 | I23: =SUM(I4:I22) -> 3183397 | J23: 기타경비합계 | K23: =SUM(K4:K22) -> 94940 | M23: 현금합계 | N23: =C5+C6 -> 406000
A24: 일매출 | C24: 일평균매출 | E24: 누적총매출 | H24: 일매출 | I24: =I23/A25 -> 0.65562702 | J24: 일매출 | K24: =K23/A25 -> 0.019553084
A25: =C2 -> 4855500 | C25: =E25/I1 -> 4153227.3 | E25: =SUM('1:11'!$A$25) -> 45685500 | H25: 누계 | I25: =SUM('1'!$I$23) -> 2230104 | J25: 누계 | K25: =SUM('1:11'!$K$21) -> 0
A26: 전 월 | H26: 누적매출 | I26: =I25/$E$25 -> 0.048814263 | J26: 누적매출 | K26: =K25/$E$25 -> 0
A27: 인 건 비 | B27: 직원A | C27: =4000000/30 -> 133333.33 | E27: 알바C | F27: =13000*4.5 -> 58500 | H27: 인건비합계 | I27: =SUM(C27:D34,F27:G32) -> 758633.33
B28: 직원B | C28: =3800000/30 -> 126666.67 | E28: 직원F | F28: =1500000/30 -> 50000 | H28: 일매출 | I28: =I27/$A$25 -> 0.15624206
B29: 직원D | C29: =3200000/30 -> 106666.67 | E29: 알바X | F29: =11700*4 -> 46800 | H29: 누계 | I29: =SUM('1:11'!$I$25) -> 24531144
H30: 누적매출 | I30: =I29/$I$27 -> 32.335969
B31: 직원C | C31: =3500000/30 -> 116666.67 | E31: 파출 | F31: 120000
E32: 홀 파출
B33: 알바B

Sheet 12
C1: 2025년 | E1: 9월 | F1: 12 | G1: 금 | H1: 실영업일수 | I1: =F1-K1 -> 12 | J1: 휴무일수
A2: 매출 | C2: =SUM(C4:D7) -> 5135500 | E2: 시재 | G2: 75400 | H2: 식자재 | J2: 비품 및 기타경비
H3: 업체 | I3: 금액 | J3: 업체 | K3: 금액
A4: 카드 | C4: 4374500 | E4: 카드수수료(2.75%) | G4: =INT(C4*0.0275) -> 120298 | H4: 고기 | J4: 숯
A5: 현금 | C5: 761000 | E5: 현금수수료(1%) | G5: =INT(C5*0.01) -> 7610 | H5: 식자재
A6: 페이결제 | E6: 통장입금 | G6: 750000 | J6: 음식물스티커
H7: 주류 | I7: 214400 | J7: 종량제봉투
A8: 금고 실잔액 | C8: 106000 | E8: 마감잔금 | G8: =C5+G2-G6-C22 -> 86400 | H8: 쌀 | I8: 64000
J9: 뚝배기
A10: 현금할인 | C10: 1000 | E10: 카드할인 | J10: 발매트
A11: 할인내역 | H11: 참기름 | J11: 불판세척
A12: 개수 | B12: 목살 | C12: 8 | D12: LA갈비 | F12: 9 | H12: 부탄가스
A13: 매출누계 | C13: =SUM('1:12'!$C$12) -> 90 | F13: =SUM('1:12'!$F$12) -> 63 | H13: 코카콜라음료
A14: 개수 | B14: 삼겹살 | C14: 31 | D14: 돼지양념갈비 | F14: 12 | H14: 깍두기,계란
A15: 매출누계 | C15: =SUM('1:12'!$C$14) -> 269 | F15: =SUM('1:12'!$F$14) -> 114 | H15: 식자재2 | I15: 132900 | J15: 비품 및 기타경비
A16: 개수 | B16: 육회 | C16: 2 | D16: 한우업진살 | F16: 15 | J16: 인터넷 주문
A17: 매출누계 | C17: =SUM('1:12'!$C$16) -> 45 | F17: =SUM('1:12'!$F$16) -> 139 | H17: 막걸리 | J17: 다이소 구매
A18: 개수 | B18: 소갈비살 | C18: 12 | D18: LA양념갈비 | F18: 2
A19: 매출누계 | C19: =SUM('1:12'!$C$18) -> 116 | F19: =SUM('1:12'!$F$18) -> 44
B20: 오겹살 | D20: 테이블수 | F20: 64
D21: 누적테이블 | F21: =SUM('1:12'!$F$20) -> 709
A22: 중간출금
A23: 출금내역 | H23: 식자재합계 | I23: =SUM(I4:I22) -> 411300 | J23: 기타경비합계 | K23: =SUM(K4:K22) -> 0 | M23: 현금합계 | N23: =C5+C6 -> 761000
A24: 일매출 | C24: 일평균매출 | E24: 누적총매출 | H24: 일매출 | I24: =I23/A25 -> 0.080089573 | J24: 일매출 | K24: =K23/A25 -> 0
A25: =C2 -> 5135500 | C25: =E25/I1 -> 4235083.3 | E25: =SUM('1:12'!$A$25) -> 50821000 | H25: 누계 | I25: =SUM('1'!$I$23) -> 2230104 | J25: 누계 | K25: =SUM('1:12'!$K$21) -> 0
A26: 전 월 | H26: 누적매출 | I26: =I25/$E$25 -> 0.043881545 | J26: 누적매출 | K26: =K25/$E$25 -> 0
A27: 인 건 비 | B27: 직원A | C27: =4000000/30 -> 133333.33 | E27: 알바C | F27: =13000*5 -> 65000 | H27: 인건비합계 | I27: =SUM(C27:D34,F27:G32) -> 765133.33
B28: 직원B | C28: =3800000/30 -> 126666.67 | E28: 직원F | F28: =1500000/30 -> 50000 | H28: 일매출 | I28: =I27/$A$25 -> 0.14898906
B29: 직원D | C29: =3200000/30 -> 106666.67 | E29: 알바X | F29: =11700*4 -> 46800 | H29: 누계 | I29: =SUM('1:12'!$I$25) -> 26761248
H30: 누적매출 | I30: =I29/$I$27 -> 34.975928
B31: 직원C | C31: =3500000/30 -> 116666.67 | E31: 파출 | F31: 120000
E32: 홀 파출
B33: 알바B

Sheet 13
C1: 2025년 | E1: 9월 | F1: 13 | G1: 토 | H1: 실영업일수 | I1: =F1-K1 -> 13 | J1: 휴무일수
A2: 매출 | C2: =SUM(C4:D7) -> 4970000 | E2: 시재 | G2: 106000 | H2: 식자재 | J2: 비품 및 기타경비
H3: 업체 | I3: 금액 | J3: 업체 | K3: 금액
A4: 카드 | C4: 4273000 | E4: 카드수수료(2.75%) | G4: =INT(C4*0.0275) -> 117507 | H4: 고기 | I4: 1517772 | J4: 숯
A5: 현금 | C5: 697000 | E5: 현금수수료(1%) | G5: =INT(C5*0.01) -> 6970 | H5: 식자재 | I5: 475711
A6: 페이결제 | E6: 통장입금 | G6: 710000 | J6: 음식물스티커
H7: 주류 | J7: 종량제봉투
A8: 금고 실잔액 | C8: 93000 | E8: 마감잔금 | G8: =C5+G2-G6-C22 -> 93000 | H8: 쌀
J9: 뚝배기
A10: 현금할인 | E10: 카드할인 | J10: 발매트
A11: 할인내역 | H11: 참기름 | J11: 불판세척
A12: 개수 | B12: 목살 | C12: 16 | D12: LA갈비 | F12: 5 | H12: 부탄가스
A13: 매출누계 | C13: =SUM('1:13'!$C$12) -> 106 | F13: =SUM('1:13'!$F$12) -> 68 | H13: 코카콜라음료
A14: 개수 | B14: 삼겹살 | C14: 15 | D14: 돼지양념갈비 | F14: 15 | H14: 깍두기,계란
A15: 매출누계 | C15: =SUM('1:13'!$C$14) -> 284 | F15: =SUM('1:13'!$F$14) -> 129 | H15: 식자재2 | I15: 446150 | J15: 비품 및 기타경비
A16: 개수 | B16: 육회 | C16: 6 | D16: 한우업진살 | F16: 11 | J16: 인터넷 주문
A17: 매출누계 | C17: =SUM('1:13'!$C$16) -> 51 | F17: =SUM('1:13'!$F$16) -> 150 | H17: 막걸리 | I17: 8000 | J17: 다이소 구매
A18: 개수 | B18: 소갈비살 | C18: 10 | D18: LA양념갈비 | F18: 3
A19: 매출누계 | C19: =SUM('1:13'!$C$18) -> 126 | F19: =SUM('1:13'!$F$18) -> 47
B20: 오겹살 | D20: 테이블수 | F20: 61
D21: 누적테이블 | F21: =SUM('1:13'!$F$20) -> 770
A22: 중간출금
A23: 출금내역 | H23: 식자재합계 | I23: =SUM(I4:I22) -> 2447633 | J23: 기타경비합계 | K23: =SUM(K4:K22) -> 0 | M23: 현금합계 | N23: =C5+C6 -> 697000
A24: 일매출 | C24: 일평균매출 | E24: 누적총매출 | H24: 일매출 | I24: =I23/A25 -> 0.49248149 | J24: 일매출 | K24: =K23/A25 -> 0
A25: =C2 -> 4970000 | C25: =E25/I1 -> 4291615.4 | E25: =SUM('1:13'!$A$25) -> 55791000 | H25: 누계 | I25: =SUM('1'!$I$23) -> 2230104 | J25: 누계 | K25: =SUM('1:13'!$K$21) -> 0
A26: 전 월 | H26: 누적매출 | I26: =I25/$E$25 -> 0.039972469 | J26: 누적매출 | K26: =K25/$E$25 -> 0
A27: 인 건 비 | B27: 직원A | C27: =4000000/30 -> 133333.33 | E27: 알바C | H27: 인건비합계 | I27: =SUM(C27:D34,F27:G32) -> 797333.33
B28: 직원B | C28: =3800000/30 -> 126666.67 | E28: 직원F | F28: =1500000/30 -> 50000 | H28: 일매출 | I28: =I27/$A$25 -> 0.16042924
B29: 직원D | C29: =3200000/30 -> 106666.67 | E29: 알바X | H29: 누계 | I29: =SUM('1:13'!$I$25) -> 28991352
H30: 누적매출 | I30: =I29/$I$27 -> 36.360391
B31: 직원C | C31: =3500000/30 -> 116666.67 | E31: 파출 | F31: 130000
E32: 홀 파출 | F32: 82000
B33: 알바B | C33: =13000*4 -> 52000

Sheet 14
C1: 2025년 | E1: 9월 | F1: 14 | G1: 일 | H1: 실영업일수 | I1: =F1-K1 -> 14 | J1: 휴무일수
A2: 매출 | C2: =SUM(C4:D7) -> 5096000 | E2: 시재 | G2: 93000 | H2: 식자재 | J2: 비품 및 기타경비
H3: 업체 | I3: 금액 | J3: 업체 | K3: 금액
A4: 카드 | C4: 4753000 | E4: 카드수수료(2.75%) | G4: =INT(C4*0.0275) -> 130707 | H4: 고기 | J4: 숯
A5: 현금 | C5: 343000 | E5: 현금수수료(1%) | G5: =INT(C5*0.01) -> 3430 | H5: 식자재
A6: 페이결제 | E6: 통장입금 | G6: 380000 | J6: 음식물스티커
H7: 주류 | J7: 종량제봉투
A8: 금고 실잔액 | C8: 56000 | E8: 마감잔금 | G8: =C5+G2-G6-C22 -> 56000 | H8: 쌀
J9: 뚝배기
A10: 현금할인 | C10: 98000 | E10: 카드할인 | J10: 발매트
A11: 할인내역 | H11: 참기름 | J11: 불판세척
A12: 개수 | B12: 목살 | C12: 10 | D12: LA갈비 | F12: 4 | H12: 부탄가스
A13: 매출누계 | C13: =SUM('1:14'!$C$12) -> 116 | F13: =SUM('1:14'!$F$12) -> 72 | H13: 코카콜라음료
A14: 개수 | B14: 삼겹살 | C14: 46 | D14: 돼지양념갈비 | F14: 16 | H14: 깍두기,계란
A15: 매출누계 | C15: =SUM('1:14'!$C$14) -> 330 | F15: =SUM('1:14'!$F$14) -> 145 | H15: 식자재2 | J15: 비품 및 기타경비
A16: 개수 | B16: 육회 | C16: 9 | D16: 한우업진살 | F16: 7 | J16: 인터넷 주문
A17: 매출누계 | C17: =SUM('1:14'!$C$16) -> 60 | F17: =SUM('1:14'!$F$16) -> 157 | H17: 막걸리 | J17: 다이소 구매
A18: 개수 | B18: 소갈비살 | C18: 12 | D18: LA양념갈비 | F18: 3
A19: 매출누계 | C19: =SUM('1:14'!$C$18) -> 138 | F19: =SUM('1:14'!$F$18) -> 50
B20: 오겹살 | D20: 테이블수 | F20: 63
D21: 누적테이블 | F21: =SUM('1:14'!$F$20) -> 833
A22: 중간출금
A23: 출금내역 | H23: 식자재합계 | I23: =SUM(I4:I22) -> 0 | J23: 기타경비합계 | K23: =SUM(K4:K22) -> 0 | M23: 현금합계 | N23: =C5+C6 -> 343000
A24: 일매출 | C24: 일평균매출 | E24: 누적총매출 | H24: 일매출 | I24: =I23/A25 -> 0 | J24: 일매출 | K24: =K23/A25 -> 0
A25: =C2 -> 5096000 | C25: =E25/I1 -> 4349071.4 | E25: =SUM('1:14'!$A$25) -> 60887000 | H25: 누계 | I25: =SUM('1'!$I$23) -> 2230104 | J25: 누계 | K25: =SUM('1:14'!$K$21) -> 0
A26: 전 월 | H26: 누적매출 | I26: =I25/$E$25 -> 0.036626932 | J26: 누적매출 | K26: =K25/$E$25 -> 0
A27: 인 건 비 | B27: 직원A | C27: =4000000/30 -> 133333.33 | E27: 알바C | H27: 인건비합계 | I27: =SUM(C27:D34,F27:G32) -> 792333.33
B28: 직원B | C28: =3800000/30 -> 126666.67 | E28: 직원F | F28: =1500000/30 -> 50000 | H28: 일매출 | I28: =I27/$A$25 -> 0.15548142
B29: 직원D | C29: =3200000/30 -> 106666.67 | E29: 알바X | H29: 누계 | I29: =SUM('1:14'!$I$25) -> 31221456 | M29: `
H30: 누적매출 | I30: =I29/$I$27 -> 39.404446
B31: 직원C | C31: =3500000/30 -> 116666.67 | E31: 파출 | F31: 130000
E32: 홀 파출 | F32: 77000
B33: 알바B | C33: 52000

Sheet 15
C1: 2025년 | E1: 9월 | F1: 15 | G1: 월 | H1: 실영업일수 | I1: =F1-K1 -> 15 | J1: 휴무일수
A2: 매출 | C2: =SUM(C4:D7) -> 4381000 | E2: 시재 | G2: 56000 | H2: 식자재 | J2: 비품 및 기타경비
H3: 업체 | I3: 금액 | J3: 업체 | K3: 금액
A4: 카드 | C4: 3877000 | E4: 카드수수료(2.75%) | G4: =INT(C4*0.0275) -> 106617 | H4: 고기 | I4: 1700406 | J4: 숯
A5: 현금 | C5: 504000 | E5: 현금수수료(1%) | G5: =INT(C5*0.01) -> 5040 | H5: 식자재
A6: 페이결제 | E6: 통장입금 | G6: 500000 | J6: 음식물스티커
H7: 주류 | I7: 386750 | J7: 종량제봉투
A8: 금고 실잔액 | C8: 60000 | E8: 마감잔금 | G8: 60000 | H8: 쌀
J9: 뚝배기
A10: 현금할인 | E10: 카드할인 | J10: 발매트
A11: 할인내역 | H11: 참기름 | J11: 불판세척
A12: 개수 | B12: 목살 | C12: 6 | D12: LA갈비 | F12: 2 | H12: 부탄가스
A13: 매출누계 | C13: =SUM('1:15'!$C$12) -> 122 | F13: =SUM('1:15'!$F$12) -> 74 | H13: 코카콜라음료
A14: 개수 | B14: 삼겹살 | C14: 13 | D14: 돼지양념갈비 | F14: 2 | H14: 깍두기,계란
A15: 매출누계 | C15: =SUM('1:15'!$C$14) -> 343 | F15: =SUM('1:15'!$F$14) -> 147 | H15: 식자재2 | I15: 113000 | J15: 비품 및 기타경비
A16: 개수 | B16: 육회 | C16: 8 | D16: 한우업진살 | F16: 10 | J16: 인터넷 주문
A17: 매출누계 | C17: =SUM('1:15'!$C$16) -> 68 | F17: =SUM('1:15'!$F$16) -> 167 | H17: 막걸리 | J17: 다이소 구매
A18: 개수 | B18: 소갈비살 | C18: 17 | D18: LA양념갈비 | F18: 6
A19: 매출누계 | C19: =SUM('1:15'!$C$18) -> 155 | F19: =SUM('1:15'!$F$18) -> 56
B20: 오겹살 | D20: 테이블수 | F20: 61
D21: 누적테이블 | F21: =SUM('1:15'!$F$20) -> 894
A22: 중간출금
A23: 출금내역 | H23: 식자재합계 | I23: =SUM(I4:I22) -> 2200156 | J23: 기타경비합계 | K23: =SUM(K4:K22) -> 0 | M23: 현금합계 | N23: =C5+C6 -> 504000
A24: 일매출 | C24: 일평균매출 | E24: 누적총매출 | H24: 일매출 | I24: =I23/A25 -> 0.50220406 | J24: 일매출 | K24: =K23/A25 -> 0
A25: =C2 -> 4381000 | C25: =E25/I1 -> 4351200 | E25: =SUM('1:15'!$A$25) -> 65268000 | H25: 누계 | I25: =SUM('1'!$I$23) -> 2230104 | J25: 누계 | K25: =SUM('1:15'!$K$21) -> 0
A26: 전 월 | H26: 누적매출 | I26: =I25/$E$25 -> 0.034168413 | J26: 누적매출 | K26: =K25/$E$25 -> 0
A27: 인 건 비 | B27: 직원A | C27: =4000000/30 -> 133333.33 | E27: 알바C | F27: =13000*4.5 -> 58500 | H27: 인건비합계 | I27: =SUM(C27:D34,F27:G32) -> 785833.33
B28: 직원B | C28: =3800000/30 -> 126666.67 | E28: 직원F | F28: =1500000/30 -> 50000 | H28: 일매출 | I28: =I27/$A$25 -> 0.17937305
B29: 직원D | C29: =3200000/30 -> 106666.67 | E29: 알바X | H29: 누계 | I29: =SUM('1:15'!$I$25) -> 33451560
H30: 누적매출 | I30: =I29/$I$27 -> 42.568263
B31: 직원C | C31: =3500000/30 -> 116666.67 | E31: 파출 | F31: 142000
E32: 홀 파출
B33: 알바B | C33: 52000

Sheet 16
C1: 2025년 | E1: 9월 | F1: 16 | G1: 화 | H1: 실영업일수 | I1: =F1-K1 -> 16 | J1: 휴무일수
A2: 매출 | C2: =SUM(C4:D7) -> 3754000 | E2: 시재 | G2: 60000 | H2: 식자재 | J2: 비품 및 기타경비
H3: 업체 | I3: 금액 | J3: 업체 | K3: 금액
A4: 카드 | C4: 3545000 | E4: 카드수수료(2.75%) | G4: =INT(C4*0.0275) -> 97487 | H4: 고기 | I4: 904000 | J4: 숯
A5: 현금 | C5: 209000 | E5: 현금수수료(1%) | G5: =INT(C5*0.01) -> 2090 | H5: 식자재 | I5: 394895
A6: 페이결제 | E6: 통장입금 | G6: 200000 | J6: 음식물스티커
H7: 주류 | J7: 종량제봉투
A8: 금고 실잔액 | C8: 69000 | E8: 마감잔금 | G8: =C5+G2-G6-C22 -> 69000 | H8: 쌀 | I8: 65000
J9: 뚝배기
A10: 현금할인 | E10: 카드할인 | J10: 발매트
A11: 할인내역 | H11: 참기름 | J11: 불판세척
A12: 개수 | B12: 목살 | C12: 7 | D12: LA갈비 | F12: 9 | H12: 부탄가스
A13: 매출누계 | C13: =SUM('1:16'!$C$12) -> 129 | F13: =SUM('1:16'!$F$12) -> 83 | H13: 코카콜라음료
A14: 개수 | B14: 삼겹살 | C14: 7 | D14: 돼지양념갈비 | F14: 13 | H14: 깍두기,계란
A15: 매출누계 | C15: =SUM('1:16'!$C$14) -> 350 | F15: =SUM('1:16'!$F$14) -> 160 | H15: 식자재2 | I15: 125700 | J15: 비품 및 기타경비
A16: 개수 | B16: 육회 | C16: 5 | D16: 한우업진살 | F16: 6 | J16: 인터넷 주문 | K16: 157040
A17: 매출누계 | C17: =SUM('1:16'!$C$16) -> 73 | F17: =SUM('1:16'!$F$16) -> 173 | H17: 막걸리 | J17: 다이소 구매
A18: 개수 | B18: 소갈비살 | C18: 9 | D18: LA양념갈비 | F18: 9
A19: 매출누계 | C19: =SUM('1:16'!$C$18) -> 164 | F19: =SUM('1:16'!$F$18) -> 65
B20: 오겹살 | D20: 테이블수 | F20: 44
D21: 누적테이블 | F21: =SUM('1:16'!$F$20) -> 938
A22: 중간출금
A23: 출금내역 | H23: 식자재합계 | I23: =SUM(I4:I22) -> 1489595 | J23: 기타경비합계 | K23: =SUM(K4:K22) -> 157040 | M23: 현금합계 | N23: =C5+C6 -> 209000
A24: 일매출 | C24: 일평균매출 | E24: 누적총매출 | H24: 일매출 | I24: =I23/A25 -> 0.39680208 | J24: 일매출 | K24: =K23/A25 -> 0.041832712
A25: =C2 -> 3754000 | C25: =E25/I1 -> 4313875 | E25: =SUM('1:16'!$A$25) -> 69022000 | H25: 누계 | I25: =SUM('1'!$I$23) -> 2230104 | J25: 누계 | K25: =SUM('1:16'!$K$21) -> 0
A26: 전 월 | H26: 누적매출 | I26: =I25/$E$25 -> 0.032310046 | J26: 누적매출 | K26: =K25/$E$25 -> 0
A27: 인 건 비 | B27: 직원A | C27: =4000000/30 -> 133333.33 | E27: 알바C | F27: =13000*3.5 -> 45500 | H27: 인건비합계 | I27: =SUM(C27:D34,F27:G32) -> 750833.33
B28: 직원B | C28: =3800000/30 -> 126666.67 | E28: 직원F | F28: =1500000/30 -> 50000 | H28: 일매출 | I28: =I27/$A$25 -> 0.20000888
B29: 직원D | C29: =3200000/30 -> 106666.67 | E29: 알바X | H29: 누계 | I29: =SUM('1:16'!$I$25) -> 35681664
H30: 누적매출 | I30: =I29/$I$27 -> 47.522749
B31: 직원C | C31: =3500000/30 -> 116666.67 | E31: 파출 | F31: 120000
E32: 홀 파출
B33: 알바B | C33: =13000*4 -> 52000

Sheet 17
C1: 2025년 | E1: 9월 | F1: 17 | G1: 수 | H1: 실영업일수 | I1: =F1-K1 -> 17 | J1: 휴무일수
A2: 매출 | C2: =SUM(C4:D7) -> 3765500 | E2: 시재 | G2: 69000 | H2: 식자재 | J2: 비품 및 기타경비
H3: 업체 | I3: 금액 | J3: 업체 | K3: 금액
A4: 카드 | C4: 3366500 | E4: 카드수수료(2.75%) | G4: =INT(C4*0.0275) -> 92578 | H4: 고기 | I4: 1046660 | J4: 숯 | K4: 305000
A5: 현금 | C5: 399000 | E5: 현금수수료(1%) | G5: =INT(C5*0.01) -> 3990 | H5: 식자재 | I5: 87220
A6: 페이결제 | E6: 통장입금 | G6: 380000 | J6: 음식물스티커
H7: 주류 | I7: 310400 | J7: 종량제봉투
A8: 금고 실잔액 | C8: 88000 | E8: 마감잔금 | G8: =C5+G2-G6-C22 -> 88000 | H8: 쌀
J9: 뚝배기
A10: 현금할인 | E10: 카드할인 | J10: 발매트
A11: 할인내역 | H11: 참기름 | J11: 불판세척
A12: 개수 | B12: 목살 | C12: 12 | D12: LA갈비 | F12: 1 | H12: 부탄가스
A13: 매출누계 | C13: =SUM('1:17'!$C$12) -> 141 | F13: =SUM('1:17'!$F$12) -> 84 | H13: 코카콜라음료
A14: 개수 | B14: 삼겹살 | C14: 16 | D14: 돼지양념갈비 | F14: 6 | H14: 깍두기,계란
A15: 매출누계 | C15: =SUM('1:17'!$C$14) -> 366 | F15: =SUM('1:17'!$F$14) -> 166 | H15: 식자재2 | I15: 221950 | J15: 비품 및 기타경비
A16: 개수 | B16: 육회 | C16: 3 | D16: 한우업진살 | F16: 3 | J16: 인터넷 주문
A17: 매출누계 | C17: =SUM('1:17'!$C$16) -> 76 | F17: =SUM('1:17'!$F$16) -> 176 | H17: 막걸리 | J17: 다이소 구매
A18: 개수 | B18: 소갈비살 | C18: 2 | D18: LA양념갈비 | F18: 1
A19: 매출누계 | C19: =SUM('1:17'!$C$18) -> 166 | F19: =SUM('1:17'!$F$18) -> 66
B20: 오겹살 | D20: 테이블수 | F20: 53
D21: 누적테이블 | F21: =SUM('1:17'!$F$20) -> 991
A22: 중간출금
A23: 출금내역 | H23: 식자재합계 | I23: =SUM(I4:I22) -> 1666230 | J23: 기타경비합계 | K23: =SUM(K4:K22) -> 305000 | M23: 현금합계 | N23: =C5+C6 -> 399000
A24: 일매출 | C24: 일평균매출 | E24: 누적총매출 | H24: 일매출 | I24: =I23/A25 -> 0.442499 | J24: 일매출 | K24: =K23/A25 -> 0.080998539
A25: =C2 -> 3765500 | C25: =E25/I1 -> 4281617.6 | E25: =SUM('1:17'!$A$25) -> 72787500 | H25: 누계 | I25: =SUM('1'!$I$23) -> 2230104 | J25: 누계 | K25: =SUM('1:17'!$K$21) -> 0
A26: 전 월 | H26: 누적매출 | I26: =I25/$E$25 -> 0.030638557 | J26: 누적매출 | K26: =K25/$E$25 -> 0
A27: 인 건 비 | B27: 직원A | C27: =4000000/30 -> 133333.33 | E27: 알바C | F27: =13000*4.5 -> 58500 | H27: 인건비합계 | I27: =SUM(C27:D34,F27:G32) -> 723833.33
B28: 직원B | C28: =3800000/30 -> 126666.67 | E28: 직원F | F28: =1500000/30 -> 50000 | H28: 일매출 | I28: =I27/$A$25 -> 0.19222768
B29: 직원D | C29: =3200000/30 -> 106666.67 | E29: 알바X | H29: 누계 | I29: =SUM('1:17'!$I$25) -> 37911768
H30: 누적매출 | I30: =I29/$I$27 -> 52.376378
B31: 직원C | C31: =3500000/30 -> 116666.67 | E31: 파출 | F31: 132000
E32: 홀 파출
B33: 알바B

Sheet 18
C1: 2025년 | E1: 9월 | F1: 18 | G1: 목 | H1: 실영업일수 | I1: =F1-K1 -> 18 | J1: 휴무일수
A2: 매출 | C2: =SUM(C4:D7) -> 3994500 | E2: 시재 | G2: 88000 | H2: 식자재 | J2: 비품 및 기타경비
H3: 업체 | I3: 금액 | J3: 업체 | K3: 금액
A4: 카드 | C4: 3651000 | E4: 카드수수료(2.75%) | G4: =INT(C4*0.0275) -> 100402 | H4: 고기 | I4: 1611201 | J4: 숯
A5: 현금 | C5: 343500 | E5: 현금수수료(1%) | G5: =INT(C5*0.01) -> 3435 | H5: 식자재 | I5: 184560
A6: 페이결제 | E6: 통장입금 | G6: 340000 | J6: 음식물스티커
H7: 주류 | I7: 158800 | J7: 종량제봉투
A8: 금고 실잔액 | C8: 91500 | E8: 마감잔금 | G8: =C5+G2-G6-C22 -> 91500 | H8: 쌀 | I8: 65000
J9: 뚝배기
A10: 현금할인 | E10: 카드할인 | J10: 발매트
A11: 할인내역 | H11: 참기름 | J11: 불판세척
A12: 개수 | B12: 목살 | C12: 4 | D12: LA갈비 | F12: 3 | H12: 부탄가스
A13: 매출누계 | C13: =SUM('1:18'!$C$12) -> 145 | F13: =SUM('1:18'!$F$12) -> 87 | H13: 코카콜라음료
A14: 개수 | B14: 삼겹살 | C14: 22 | D14: 돼지양념갈비 | F14: 5 | H14: 깍두기,계란
A15: 매출누계 | C15: =SUM('1:18'!$C$14) -> 388 | F15: =SUM('1:18'!$F$14) -> 171 | H15: 식자재2 | I15: 153450 | J15: 비품 및 기타경비
A16: 개수 | B16: 육회 | C16: 8 | D16: 한우업진살 | F16: 16 | J16: 인터넷 주문 | K16: 81720
A17: 매출누계 | C17: =SUM('1:18'!$C$16) -> 84 | F17: =SUM('1:18'!$F$16) -> 192 | H17: 막걸리 | J17: 다이소 구매
A18: 개수 | B18: 소갈비살 | C18: 19 | D18: LA양념갈비 | F18: 3
A19: 매출누계 | C19: =SUM('1:18'!$C$18) -> 185 | F19: =SUM('1:18'!$F$18) -> 69
B20: 오겹살 | D20: 테이블수 | F20: 51
D21: 누적테이블 | F21: =SUM('1:18'!$F$20) -> 1042
A22: 중간출금
A23: 출금내역 | H23: 식자재합계 | I23: =SUM(I4:I22) -> 2173011 | J23: 기타경비합계 | K23: =SUM(K4:K22) -> 81720 | M23: 현금합계 | N23: =C5+C6 -> 343500
A24: 일매출 | C24: 일평균매출 | E24: 누적총매출 | H24: 일매출 | I24: =I23/A25 -> 0.54400075 | J24: 일매출 | K24: =K23/A25 -> 0.02045813
A25: =C2 -> 3994500 | C25: =E25/I1 -> 4265666.7 | E25: =SUM('1:18'!$A$25) -> 76782000 | H25: 누계 | I25: =SUM('1'!$I$23) -> 2230104 | J25: 누계 | K25: =SUM('1:18'!$K$21) -> 0
A26: 전 월 | H26: 누적매출 | I26: =I25/$E$25 -> 0.02904462 | J26: 누적매출 | K26: =K25/$E$25 -> 0
A27: 인 건 비 | B27: 직원A | C27: =4000000/30 -> 133333.33 | E27: 알바C | F27: =13000*4.5 -> 58500 | H27: 인건비합계 | I27: =SUM(C27:D34,F27:G32) -> 932333.33
B28: 직원B | C28: =3800000/30 -> 126666.67 | E28: 직원F | F28: =1500000/30 -> 50000 | H28: 일매출 | I28: =I27/$A$25 -> 0.23340426
B29: 직원D | C29: =3200000/30 -> 106666.67 | E29: 알바X | F29: 58500 | H29: 누계 | I29: =SUM('1:18'!$I$25) -> 40141872
H30: 누적매출 | I30: =I29/$I$27 -> 43.055279
B31: 직원C | C31: =3500000/30 -> 116666.67 | E31: 파출 | F31: 120000
E32: 홀 파출 | F32: 71000
B33: 알바B | C33: =13000*7 -> 91000

Sheet 19
C1: 2025년 | E1: 9월 | F1: 19 | G1: 금 | H1: 실영업일수 | I1: =F1-K1 -> 19 | J1: 휴무일수
A2: 매출 | C2: =SUM(C4:D7) -> 4394500 | E2: 시재 | G2: 91500 | H2: 식자재 | J2: 비품 및 기타경비
H3: 업체 | I3: 금액 | J3: 업체 | K3: 금액
A4: 카드 | C4: 3989500 | E4: 카드수수료(2.75%) | G4: =INT(C4*0.0275) -> 109711 | H4: 고기 | I4: 1163264 | J4: 숯
A5: 현금 | C5: 405000 | E5: 현금수수료(1%) | G5: =INT(C5*0.01) -> 4050 | H5: 식자재 | I5: 254330
A6: 페이결제 | E6: 통장입금 | G6: 420000 | J6: 음식물스티커
H7: 주류 | J7: 종량제봉투
A8: 금고 실잔액 | C8: 76500 | E8: 마감잔금 | G8: =C5+G2-G6-C22 -> 76500 | H8: 쌀
J9: 뚝배기
A10: 현금할인 | E10: 카드할인 | J10: 발매트
A11: 할인내역 | H11: 참기름 | J11: 불판세척
A12: 개수 | B12: 목살 | C12: 6 | D12: LA갈비 | F12: 7 | H12: 부탄가스 | I12: 53400
A13: 매출누계 | C13: =SUM('1:19'!$C$12) -> 151 | F13: =SUM('1:19'!$F$12) -> 94 | H13: 코카콜라음료
A14: 개수 | B14: 삼겹살 | C14: 20 | D14: 돼지양념갈비 | F14: 7 | H14: 깍두기,계란
A15: 매출누계 | C15: =SUM('1:19'!$C$14) -> 408 | F15: =SUM('1:19'!$F$14) -> 178 | H15: 식자재2 | I15: 184450 | J15: 비품 및 기타경비
A16: 개수 | B16: 육회 | C16: 7 | D16: 한우업진살 | F16: 14 | J16: 인터넷 주문
A17: 매출누계 | C17: =SUM('1:19'!$C$16) -> 91 | F17: =SUM('1:19'!$F$16) -> 206 | H17: 막걸리 | J17: 다이소 구매
A18: 개수 | B18: 소갈비살 | C18: 24 | D18: LA양념갈비 | F18: 1
A19: 매출누계 | C19: =SUM('1:19'!$C$18) -> 209 | F19: =SUM('1:19'!$F$18) -> 70
B20: 오겹살 | D20: 테이블수 | F20: 58
D21: 누적테이블 | F21: =SUM('1:19'!$F$20) -> 1100
A22: 중간출금
A23: 출금내역 | H23: 식자재합계 | I23: =SUM(I4:I22) -> 1655444 | J23: 기타경비합계 | K23: =SUM(K4:K22) -> 0 | M23: 현금합계 | N23: =C5+C6 -> 405000
A24: 일매출 | C24: 일평균매출 | E24: 누적총매출 | H24: 일매출 | I24: =I23/A25 -> 0.37670816 | J24: 일매출 | K24: =K23/A25 -> 0
A25: =C2 -> 4394500 | C25: =E25/I1 -> 4272447.4 | E25: =SUM('1:19'!$A$25) -> 81176500 | H25: 누계 | I25: =SUM('1'!$I$23) -> 2230104 | J25: 누계 | K25: =SUM('1:18'!$K$21) -> 0
A26: 전 월 | H26: 누적매출 | I26: =I25/$E$25 -> 0.027472286 | J26: 누적매출 | K26: =K25/$E$25 -> 0
A27: 인 건 비 | B27: 직원A | C27: =4000000/30 -> 133333.33 | E27: 알바C | F27: =13000*5 -> 65000 | H27: 인건비합계 | I27: =SUM(C27:D34,F27:G32) -> 807333.33
B28: 직원B | C28: =3800000/30 -> 126666.67 | E28: 직원F | F28: =1500000/30 -> 50000 | H28: 일매출 | I28: =I27/$A$25 -> 0.18371449
B29: 직원D | C29: =3200000/30 -> 106666.67 | E29: 알바X | H29: 누계 | I29: =SUM('1:18'!$I$25) -> 40141872
H30: 누적매출 | I30: =I29/$I$27 -> 49.721559
B31: 직원C | C31: =3500000/30 -> 116666.67 | E31: 파출 | F31: 132000
E32: 홀 파출 | F32: 77000
B33: 알바B

Sheet 20
C1: 2025년 | E1: 9월 | F1: 20 | G1: 토 | H1: 실영업일수 | I1: =F1-K1 -> 20 | J1: 휴무일수
A2: 매출 | C2: =SUM(C4:D7) -> 4152000 | E2: 시재 | G2: 76500 | H2: 식자재 | J2: 비품 및 기타경비
H3: 업체 | I3: 금액 | J3: 업체 | K3: 금액
A4: 카드 | C4: 3907000 | E4: 카드수수료(2.75%) | G4: =INT(C4*0.0275) -> 107442 | H4: 고기 | I4: 2608912 | J4: 숯
A5: 현금 | C5: 245000 | E5: 현금수수료(1%) | G5: =INT(C5*0.01) -> 2450 | H5: 식자재 | I5: 429330
A6: 페이결제 | E6: 통장입금 | G6: 200000 | J6: 음식물스티커
H7: 주류 | J7: 종량제봉투
A8: 금고 실잔액 | C8: 121500 | E8: 마감잔금 | G8: =C5+G2-G6-C22 -> 121500 | H8: 쌀
J9: 뚝배기
A10: 현금할인 | E10: 카드할인 | J10: 발매트
A11: 할인내역 | H11: 참기름 | J11: 불판세척
A12: 개수 | B12: 목살 | C12: 6 | D12: LA갈비 | F12: 5 | H12: 부탄가스
A13: 매출누계 | C13: =SUM('1:20'!$C$12) -> 157 | F13: =SUM('1:20'!$F$12) -> 99 | H13: 코카콜라음료
A14: 개수 | B14: 삼겹살 | C14: 17 | D14: 돼지양념갈비 | F14: 4 | H14: 깍두기,계란
A15: 매출누계 | C15: =SUM('1:20'!$C$14) -> 425 | F15: =SUM('1:20'!$F$14) -> 182 | H15: 식자재2 | I15: 200800 | J15: 비품 및 기타경비
A16: 개수 | B16: 육회 | C16: 2 | D16: 한우업진살 | F16: 13 | J16: 인터넷 주문
A17: 매출누계 | C17: =SUM('1:20'!$C$16) -> 93 | F17: =SUM('1:20'!$F$16) -> 219 | H17: 막걸리 | J17: 다이소 구매
A18: 개수 | B18: 소갈비살 | C18: 7 | D18: LA양념갈비 | F18: 8
A19: 매출누계 | C19: =SUM('1:20'!$C$18) -> 216 | F19: =SUM('1:20'!$F$18) -> 78
B20: 오겹살 | D20: 테이블수 | F20: 39
D21: 누적테이블 | F21: =SUM('1:20'!$F$20) -> 1139
A22: 중간출금
A23: 출금내역 | H23: 식자재합계 | I23: =SUM(I4:I22) -> 3239042 | J23: 기타경비합계 | K23: =SUM(K4:K22) -> 0 | M23: 현금합계 | N23: =C5+C6 -> 245000
A24: 일매출 | C24: 일평균매출 | E24: 누적총매출 | H24: 일매출 | I24: =I23/A25 -> 0.78011609 | J24: 일매출 | K24: =K23/A25 -> 0
A25: =C2 -> 4152000 | C25: =E25/I1 -> 4266425 | E25: =SUM('1:20'!$A$25) -> 85328500 | H25: 누계 | I25: =SUM('1'!$I$23) -> 2230104 | J25: 누계 | K25: =SUM('1:20'!$K$21) -> 0
A26: 전 월 | H26: 누적매출 | I26: =I25/$E$25 -> 0.026135512 | J26: 누적매출 | K26: =K25/$E$25 -> 0
A27: 인 건 비 | B27: 직원A | C27: =4000000/30 -> 133333.33 | E27: 알바C | H27: 인건비합계 | I27: =SUM(C27:D34,F27:G32) -> 857333.33
B28: 직원B | C28: =3800000/30 -> 126666.67 | E28: 직원F | F28: =1500000/30 -> 50000 | H28: 일매출 | I28: =I27/$A$25 -> 0.20648683
B29: 직원D | C29: =3200000/30 -> 106666.67 | E29: 알바X | H29: 누계 | I29: =SUM('1:20'!$I$25) -> 44602080
H30: 누적매출 | I30: =I29/$I$27 -> 52.024199
B31: 직원C | C31: =3500000/30 -> 116666.67 | E31: 파출 | F31: 130000
E32: 홀 파출 | F32: 142000
B33: 알바B | C33: =13000*4 -> 52000

Sheet 21
C1: 2025년 | E1: 9월 | F1: 21 | G1: 일 | H1: 실영업일수 | I1: =F1-K1 -> 21 | J1: 휴무일수
A2: 매출 | C2: =SUM(C4:D7) -> 4190000 | E2: 시재 | G2: 121500 | H2: 식자재 | J2: 비품 및 기타경비
H3: 업체 | I3: 금액 | J3: 업체 | K3: 금액
A4: 카드 | C4: 3349000 | E4: 카드수수료(2.75%) | G4: =INT(C4*0.0275) -> 92097 | H4: 고기 | J4: 숯
A5: 현금 | C5: 841000 | E5: 현금수수료(1%) | G5: =INT(C5*0.01) -> 8410 | H5: 식자재
A6: 페이결제 | E6: 통장입금 | G6: 880000 | J6: 음식물스티커
H7: 주류 | J7: 종량제봉투
A8: 금고 실잔액 | C8: 82500 | E8: 마감잔금 | G8: =C5+G2-G6-C22 -> 82500 | H8: 쌀
J9: 뚝배기
A10: 현금할인 | E10: 카드할인 | J10: 발매트
A11: 할인내역 | H11: 참기름 | J11: 불판세척
A12: 개수 | B12: 목살 | C12: 7 | D12: LA갈비 | F12: 4 | H12: 부탄가스
A13: 매출누계 | C13: =SUM('1:21'!$C$12) -> 164 | F13: =SUM('1:21'!$F$12) -> 103 | H13: 코카콜라음료
A14: 개수 | B14: 삼겹살 | C14: 18 | D14: 돼지양념갈비 | F14: 6 | H14: 깍두기,계란
A15: 매출누계 | C15: =SUM('1:21'!$C$14) -> 443 | F15: =SUM('1:21'!$F$14) -> 188 | H15: 식자재2 | J15: 비품 및 기타경비
A16: 개수 | B16: 육회 | C16: 4 | D16: 한우업진살 | F16: 6 | J16: 인터넷 주문
A17: 매출누계 | C17: =SUM('1:21'!$C$16) -> 97 | F17: =SUM('1:21'!$F$16) -> 225 | H17: 막걸리 | J17: 다이소 구매
A18: 개수 | B18: 소갈비살 | C18: 14 | D18: LA양념갈비 | F18: 3
A19: 매출누계 | C19: =SUM('1:21'!$C$18) -> 230 | F19: =SUM('1:21'!$F$18) -> 81
B20: 오겹살 | D20: 테이블수 | F20: 58
D21: 누적테이블 | F21: =SUM('1:21'!$F$20) -> 1197
A22: 중간출금
A23: 출금내역 | H23: 식자재합계 | I23: =SUM(I4:I22) -> 0 | J23: 기타경비합계 | K23: =SUM(K4:K22) -> 0 | M23: 현금합계 | N23: =C5+C6 -> 841000
A24: 일매출 | C24: 일평균매출 | E24: 누적총매출 | H24: 일매출 | I24: =I23/A25 -> 0 | J24: 일매출 | K24: =K23/A25 -> 0
A25: =C2 -> 4190000 | C25: =E25/I1 -> 4262785.7 | E25: =SUM('1:21'!$A$25) -> 89518500 | H25: 누계 | I25: =SUM('1'!$I$23) -> 2230104 | J25: 누계 | K25: =SUM('1:21'!$K$21) -> 0
A26: 전 월 | H26: 누적매출 | I26: =I25/$E$25 -> 0.024912214 | J26: 누적매출 | K26: =K25/$E$25 -> 0
A27: 인 건 비 | B27: 직원A | C27: =4000000/30 -> 133333.33 | E27: 알바C | H27: 인건비합계 | I27: =SUM(C27:D34,F27:G32) -> 858333.33
B28: 직원B | C28: =3800000/30 -> 126666.67 | E28: 직원F | F28: =1500000/30 -> 50000 | H28: 일매출 | I28: =I27/$A$25 -> 0.20485282
B29: 직원D | C29: =3200000/30 -> 106666.67 | E29: 알바X | H29: 누계 | I29: =SUM('1:21'!$I$25) -> 46832184
H30: 누적매출 | I30: =I29/$I$27 -> 54.561768
B31: 직원C | C31: =3500000/30 -> 116666.67 | E31: 파출 | F31: 130000
E32: 홀 파출 | F32: 143000
B33: 알바B | C33: 52000

Sheet 22
C1: 2025년 | E1: 9월 | F1: 22 | G1: 월 | H1: 실영업일수 | I1: =F1-K1 -> 22 | J1: 휴무일수
A2: 매출 | C2: =SUM(C4:D7) -> 5606000 | E2: 시재 | G2: 82500 | H2: 식자재 | J2: 비품 및 기타경비
H3: 업체 | I3: 금액 | J3: 업체 | K3: 금액
A4: 카드 | C4: 5096500 | E4: 카드수수료(2.75%) | G4: =INT(C4*0.0275) -> 140153 | H4: 고기 | I4: 775770 | J4: 숯
A5: 현금 | C5: 509500 | E5: 현금수수료(1%) | G5: =INT(C5*0.01) -> 5095 | H5: 식자재 | I5: 320176
A6: 페이결제 | E6: 통장입금 | G6: 510000 | J6: 음식물스티커
H7: 주류 | I7: 330500 | J7: 종량제봉투
A8: 금고 실잔액 | C8: 82000 | E8: 마감잔금 | G8: =C5+G2-G6-C22 -> 82000 | H8: 쌀 | I8: 65000
J9: 뚝배기
A10: 현금할인 | C10: 60000 | E10: 카드할인 | J10: 발매트 | K10: 13000
A11: 할인내역 | H11: 참기름 | J11: 불판세척
A12: 개수 | B12: 목살 | C12: 8 | D12: LA갈비 | F12: 8 | H12: 부탄가스
A13: 매출누계 | C13: =SUM('1:22'!$C$12) -> 172 | F13: =SUM('1:22'!$F$12) -> 111 | H13: 코카콜라음료
A14: 개수 | B14: 삼겹살 | C14: 21 | D14: 돼지양념갈비 | F14: 9 | H14: 깍두기,계란
A15: 매출누계 | C15: =SUM('1:22'!$C$14) -> 464 | F15: =SUM('1:22'!$F$14) -> 197 | H15: 식자재2 | J15: 비품 및 기타경비
A16: 개수 | B16: 육회 | C16: 4 | D16: 한우업진살 | F16: 10 | J16: 인터넷 주문
A17: 매출누계 | C17: =SUM('1:22'!$C$16) -> 101 | F17: =SUM('1:22'!$F$16) -> 235 | H17: 막걸리 | J17: 다이소 구매
A18: 개수 | B18: 소갈비살 | C18: 7 | D18: LA양념갈비 | F18: 3
A19: 매출누계 | C19: =SUM('1:22'!$C$18) -> 237 | F19: =SUM('1:22'!$F$18) -> 84
B20: 오겹살 | D20: 테이블수 | F20: 50
D21: 누적테이블 | F21: =SUM('1:22'!$F$20) -> 1247
A22: 중간출금
A23: 출금내역 | H23: 식자재합계 | I23: =SUM(I4:I22) -> 1491446 | J23: 기타경비합계 | K23: =SUM(K4:K22) -> 13000 | M23: 현금합계 | N23: =C5+C6 -> 509500
A24: 일매출 | C24: 일평균매출 | E24: 누적총매출 | H24: 일매출 | I24: =I23/A25 -> 0.2660446 | J24: 일매출 | K24: =K23/A25 -> 0.002318944
A25: =C2 -> 5606000 | C25: =E25/I1 -> 4323840.9 | E25: =SUM('1:22'!$A$25) -> 95124500 | H25: 누계 | I25: =SUM('1'!$I$23) -> 2230104 | J25: 누계 | K25: =SUM('1:22'!$K$21) -> 0
A26: 전 월 | H26: 누적매출 | I26: =I25/$E$25 -> 0.023444055 | J26: 누적매출 | K26: =K25/$E$25 -> 0
A27: 인 건 비 | B27: 직원A | C27: =4000000/30 -> 133333.33 | E27: 알바C | F27: =13000*5 -> 65000 | H27: 인건비합계 | I27: =SUM(C27:D34,F27:G32) -> 817133.33
B28: 직원B | C28: =3800000/30 -> 126666.67 | E28: 직원F | F28: =1500000/30 -> 50000 | H28: 일매출 | I28: =I27/$A$25 -> 0.14576049
B29: 직원D | C29: =3200000/30 -> 106666.67 | E29: 알바X | F29: =11700*4 -> 46800 | H29: 누계 | I29: =SUM('1:22'!$I$25) -> 49062288
H30: 누적매출 | I30: =I29/$I$27 -> 60.041961
B31: 직원C | C31: =3500000/30 -> 116666.67 | E31: 파출 | F31: 120000
E32: 홀 파출
B33: 알바B | C33: 52000

Sheet 23
C1: 2025년 | E1: 9월 | F1: 23 | G1: 화 | H1: 실영업일수 | I1: =F1-K1 -> 23 | J1: 휴무일수
A2: 매출 | C2: =SUM(C4:D7) -> 5849000 | E2: 시재 | G2: 82000 | H2: 식자재 | J2: 비품 및 기타경비
H3: 업체 | I3: 금액 | J3: 업체 | K3: 금액
A4: 카드 | C4: 5331000 | E4: 카드수수료(2.75%) | G4: =INT(C4*0.0275) -> 146602 | H4: 고기 | I4: 2470258 | J4: 숯
A5: 현금 | C5: 518000 | E5: 현금수수료(1%) | G5: =INT(C5*0.01) -> 5180 | H5: 식자재 | I5: 60460
A6: 페이결제 | E6: 통장입금 | G6: 420000 | J6: 음식물스티커
H7: 주류 | J7: 종량제봉투
A8: 금고 실잔액 | C8: 180000 | E8: 마감잔금 | G8: =C5+G2-G6-C22 -> 180000 | H8: 쌀
J9: 뚝배기
A10: 현금할인 | E10: 카드할인 | J10: 발매트
A11: 할인내역 | H11: 참기름 | J11: 불판세척
A12: 개수 | B12: 목살 | C12: 2 | D12: LA갈비 | F12: 9 | H12: 부탄가스
A13: 매출누계 | C13: =SUM('1:23'!$C$12) -> 174 | F13: =SUM('1:23'!$F$12) -> 120 | H13: 코카콜라음료 | I13: 240000
A14: 개수 | B14: 삼겹살 | C14: 14 | D14: 돼지양념갈비 | F14: 7 | H14: 깍두기,계란
A15: 매출누계 | C15: =SUM('1:23'!$C$14) -> 478 | F15: =SUM('1:23'!$F$14) -> 204 | H15: 식자재2 | I15: 301700 | J15: 비품 및 기타경비
A16: 개수 | B16: 육회 | C16: 2 | D16: 한우업진살 | F16: 13 | J16: 인터넷 주문
A17: 매출누계 | C17: =SUM('1:23'!$C$16) -> 103 | F17: =SUM('1:23'!$F$16) -> 248 | H17: 막걸리 | J17: 다이소 구매
A18: 개수 | B18: 소갈비살 | C18: 12 | D18: LA양념갈비 | F18: 8
A19: 매출누계 | C19: =SUM('1:23'!$C$18) -> 249 | F19: =SUM('1:23'!$F$18) -> 92
B20: 오겹살 | D20: 테이블수 | F20: 40
D21: 누적테이블 | F21: =SUM('1:23'!$F$20) -> 1287
A22: 중간출금
A23: 출금내역 | H23: 식자재합계 | I23: =SUM(I4:I22) -> 3072418 | J23: 기타경비합계 | K23: =SUM(K4:K22) -> 0 | M23: 현금합계 | N23: =C5+C6 -> 518000
A24: 일매출 | C24: 일평균매출 | E24: 누적총매출 | H24: 일매출 | I24: =I23/A25 -> 0.52528945 | J24: 일매출 | K24: =K23/A25 -> 0
A25: =C2 -> 5849000 | C25: =E25/I1 -> 4390152.2 | E25: =SUM('1:23'!$A$25) -> 100973500 | H25: 누계 | I25: =SUM('1'!$I$23) -> 2230104 | J25: 누계 | K25: =SUM('1:23'!$K$21) -> 0
A26: 전 월 | H26: 누적매출 | I26: =I25/$E$25 -> 0.022086032 | J26: 누적매출 | K26: =K25/$E$25 -> 0
A27: 인 건 비 | B27: 직원A | C27: =4000000/30 -> 133333.33 | E27: 알바C | F27: =13000*5 -> 65000 | H27: 인건비합계 | I27: =SUM(C27:D34,F27:G32) -> 826483.33
B28: 직원B | C28: =3800000/30 -> 126666.67 | E28: 직원F | F28: =1500000/30 -> 50000 | H28: 일매출 | I28: =I27/$A$25 -> 0.14130336 | M28: `
B29: 직원D | C29: =3200000/30 -> 106666.67 | E29: 알바X | F29: 52650 | H29: 누계 | I29: =SUM('1:23'!$I$25) -> 51292392
H30: 누적매출 | I30: =I29/$I$27 -> 62.061012
B31: 직원C | C31: =3500000/30 -> 116666.67 | E31: 파출 | F31: 130000
E32: 홀 파출
B33: 알바B | C33: =13000*3.5 -> 45500

Sheet 24
C1: 2025년 | E1: 9월 | F1: 24 | G1: 수 | H1: 실영업일수 | I1: =F1-K1 -> 24 | J1: 휴무일수
A2: 매출 | C2: =SUM(C4:D7) -> 1652000 | E2: 시재 | G2: 180000 | H2: 식자재 | J2: 비품 및 기타경비
H3: 업체 | I3: 금액 | J3: 업체 | K3: 금액
A4: 카드 | C4: 1381000 | E4: 카드수수료(2.75%) | G4: =INT(C4*0.0275) -> 37977 | H4: 고기 | J4: 숯 | K4: 294000
